Workbook
Name _NG_ad662: #REF!
Name _NG_bcb16: #REF!
Name Adjusted_EBIT: #REF!
Name Adjusted_EBITDA: #REF!
Name Adjusted_EBITDA: #REF!
Name Avg_shares_out__m: #REF!
Name Avg_shares_out__m: #REF!
Name Balance_sheet: #REF!
Name Balance_sheet: #REF!
Name Beer_volumes: #REF!
Name Beer_volumes: #REF!
Name Capital_Expenditures___Goodwill: #REF!
Name Capital_Expenditures___Goodwill: #REF!
Name Cash_Balance: #REF!
Name Cash_Balance: #REF!
Name Cash_Flow: #REF!
Name Cash_Flow: #REF!
Name Cash_Flow_Available_to_Investors: #REF!
Name Cash_Flow_Available_to_Investors: #REF!
Name CCY: #REF!
Name CCY: #REF!
Name Celulose: #REF!
Name Celulose: #REF!
Name Change_in_Working_Capital: #REF!
Name Change_in_Working_Capital: #REF!
Name Class: #REF!
Name Class: #REF!
Name Commission_income: #REF!
Name Commission_income: #REF!
Name CURRENCY: #REF!
Name CURRENCY: #REF!
Name Data: OFFSET(#REF!,#REF!,0,#REF!)
Name Data: OFFSET(#REF!,#REF!,0,#REF!)
Name Dates: OFFSET(#REF!,#REF!,0,#REF!)
Name Dates: OFFSET(#REF!,#REF!,0,#REF!)
Name DCF_Valuation_Summary: #REF!
Name DCF_Valuation_Summary: #REF!
Name Debt_Target_Calculations: #REF!
Name Debt_Target_Calculations: #REF!
Name Deferred_tax_assets: #REF!
Name Deferred_tax_assets: #REF!
Name Deposits: #REF!
Name Deposits: #REF!
Name Dividends: #REF!
Name Dividends: #REF!
Name DivLiq: #REF!
Name DivLiq: #REF!
Name Dupont_Analysis: #REF!
Name Dupont_Analysis: #REF!
Name Earnings_before_taxes: #REF!
Name Earnings_before_taxes: #REF!
Name ebitda03: #REF!
Name ebitda03: #REF!
Name ebitda04: #REF!
Name ebitda04: #REF!
Name ebitda05: #REF!
Name ebitda05: #REF!
Name Economics: #REF!
Name Extra_items__after_tax: #REF!
Name Extra_items__after_tax: #REF!

Sheet Resumo
G1: #VALUE! | M1: {=+_FV(G1,"Price")} -> 40.14 | P1: =+TODAY() -> 46090 | S1: {=+_FV(G1,"Shares outstanding",TRUE)/1000000} -> 3000.619
B2: Mln MXN | C2: 2016 | D2: =+C2+1 -> 2017 | E2: =+D2+1 -> 2018 | F2: =+E2+1 -> 2019 | G2: =+F2+1 -> 2020 | H2: =+G2+1 -> 2021 | I2: =+H2+1 -> 2022 | J2: =+I2+1 -> 2023 | K2: =+J2+1 -> 2024 | ... Q2: =+P2+1 -> 2030
B3: Net Revs | C3: =+PROJ!BP3 -> 35660.295 | D3: =+PROJ!BQ3 -> 37765.76 | E3: =+PROJ!BR3 -> 41026.864 | F3: =+PROJ!BS3 -> 43500.929 | G3: =+PROJ!BT3 -> 46702.895 | H3: =+PROJ!BU3 -> 46893.963 | I3: =+PROJ!BV3 -> 51054.876 | J3: =+PROJ!BW3 -> 53307.054 | ... Q3: =+PROJ!CD3 -> 61358.787
B4: yoy | D4: =+D3/C3-1 -> 0.059042277 | E4: =+E3/D3-1 -> 0.086350811 | F4: =+F3/E3-1 -> 0.060303537 | G4: =+G3/F3-1 -> 0.073606842 | H4: =+H3/G3-1 -> 0.0040911382 | I4: =+I3/H3-1 -> 0.088730249 | J4: =+J3/I3-1 -> 0.044112887 | K4: =+K3/J3-1 -> 0.027682321 | ... Q4: =+Q3/P3-1 -> 0.02
L5: =56674/K3-1 -> 0.034523352
B6: Gross Profit | C6: =+PROJ!BP6 -> 13784.933 | D6: =+PROJ!BQ6 -> 13401.991 | E6: =+PROJ!BR6 -> 14340.566 | F6: =+PROJ!BS6 -> 16321.421 | G6: =+PROJ!BT6 -> 18009.274 | H6: =+PROJ!BU6 -> 15785.676 | I6: =+PROJ!BV6 -> 16772.482 | J6: =+PROJ!BW6 -> 20700.039 | ... Q6: =+PROJ!CD6 -> 24121.062
B7: mrgn | C7: =+C6/C$3 -> 0.38656251 | D7: =+D6/D$3 -> 0.35487148 | E7: =+E6/E$3 -> 0.34954088 | F7: =+F6/F$3 -> 0.37519707 | G7: =+G6/G$3 -> 0.38561365 | H7: =+H6/H$3 -> 0.33662491 | I7: =+I6/I$3 -> 0.32851871 | J7: =+J6/J$3 -> 0.38831707 | ... Q7: =+Q6/Q$3 -> 0.39311504
B8: SG&A | C8: =+PROJ!BP8 -> -5766.523 | D8: =+PROJ!BQ8 -> -6432.926 | E8: =+PROJ!BR8 -> -6845.842 | F8: =+PROJ!BS8 -> -7346.593 | G8: =+PROJ!BT8 -> -7504.876 | H8: =+PROJ!BU8 -> -7450.885 | I8: =+PROJ!BV8 -> -7848.084 | J8: =+PROJ!BW8 -> -8784.296 | ... Q8: =+PROJ!CD8 -> -11240.933
B9: EBIT | C9: =+PROJ!BP14 -> 8018.41 | D9: =+PROJ!BQ14 -> 6977.791 | E9: =+PROJ!BR14 -> 7503.406 | F9: =+PROJ!BS14 -> 8997.295 | G9: =+PROJ!BT14 -> 10537.29 | H9: =+PROJ!BU14 -> 8349.719 | I9: =+PROJ!BV14 -> 8940.054 | J9: =+PROJ!BW14 -> 11932.279 | ... Q9: =+PROJ!CD14 -> 12880.129
B10: Fin Res | C10: =+SUM(PROJ!BP18:BP22) -> -1073.269 | D10: =+SUM(PROJ!BQ18:BQ22) -> -1237.63 | E10: =+SUM(PROJ!BR18:BR22) -> -1512.719 | F10: =+SUM(PROJ!BS18:BS22) -> -1534.814 | G10: =+SUM(PROJ!BT18:BT22) -> -1664.172 | H10: =+SUM(PROJ!BU18:BU22) -> -1739.929 | I10: =+SUM(PROJ!BV18:BV22) -> -1689.82 | J10: =+SUM(PROJ!BW18:BW22) -> -1543.995 | ... Q10: =+SUM(PROJ!CD18:CD22) -> -819.51711
B11: EBT | C11: =+PROJ!BP23 -> 6945.141 | D11: =+PROJ!BQ23 -> 5740.161 | E11: =+PROJ!BR23 -> 5990.687 | F11: =+PROJ!BS23 -> 7462.481 | G11: =+PROJ!BT23 -> 8873.118 | H11: =+PROJ!BU23 -> 6609.79 | I11: =+PROJ!BV23 -> 7250.234 | J11: =+PROJ!BW23 -> 10388.284 | ... Q11: =+PROJ!CD23 -> 12060.612
B12: tax | C12: =+PROJ!BP24 -> -2155.929 | D12: =+PROJ!BQ24 -> -1703.605 | E12: =+PROJ!BR24 -> -1782.604 | F12: =+PROJ!BS24 -> -2314.011 | G12: =+PROJ!BT24 -> -2792.133 | H12: =+PROJ!BU24 -> -2150.052 | I12: =+PROJ!BV24 -> -2314.398 | J12: =+PROJ!BW24 -> -3375.507 | ... Q12: =+PROJ!CD24 -> -3799.0927
B13: rate | C13: =+C12/C11 -> -0.31042264 | D13: =+D12/D11 -> -0.29678697 | E13: =+E12/E11 -> -0.29756253 | F13: =+F12/F11 -> -0.31008602 | G13: =+G12/G11 -> -0.31467326 | H13: =+H12/H11 -> -0.32528295 | I13: =+I12/I11 -> -0.31921701 | J13: =+J12/J11 -> -0.32493403 | ... Q13: =+Q12/Q11 -> -0.315
B15: Net Income | C15: =+PROJ!BP27 -> 4793.565 | D15: =+PROJ!BQ27 -> 4066.689 | E15: =+PROJ!BR27 -> 4214.226 | F15: =+PROJ!BS27 -> 5141.858 | G15: =+PROJ!BT27 -> 6225.568 | H15: =+PROJ!BU27 -> 4493.868 | I15: =+PROJ!BV27 -> 4934.25 | J15: =+PROJ!BW27 -> 7012.845 | ... Q15: =+PROJ!CD27 -> 8261.5191
B17: EBITDA | C17: =+PROJ!BP16 -> 9619.329 | D17: =+PROJ!BQ16 -> 7358.424 | E17: =+PROJ!BR16 -> 7885.744 | F17: =+PROJ!BS16 -> 9456.75 | G17: =+PROJ!BT16 -> 12490.625 | H17: =+PROJ!BU16 -> 10285 | I17: =+PROJ!BV16 -> 10908.78 | J17: =+PROJ!BW16 -> 13916.799 | ... Q17: =+PROJ!CD16 -> 14895.863
B18: mrgn | C18: =+C17/C$3 -> 0.269749 | D18: =+D17/D$3 -> 0.1948438 | E18: =+E17/E$3 -> 0.19220928 | F18: =+F17/F$3 -> 0.21739191 | G18: =+G17/G$3 -> 0.26744862 | H18: =+H17/H$3 -> 0.21932461 | I18: =+I17/I$3 -> 0.21366774 | J18: =+J17/J$3 -> 0.26106862 | ... Q18: =+Q17/Q$3 -> 0.24276658
B20: MULTIPLOS | C20: =+C$2 -> 2016 | D20: =+D$2 -> 2017 | E20: =+E$2 -> 2018 | F20: =+F$2 -> 2019 | G20: =+G$2 -> 2020 | H20: =+H$2 -> 2021 | I20: =+I$2 -> 2022 | J20: =+J$2 -> 2023 | ... Q20: =+Q$2 -> 2030
B21: Mkt Cap | C21: {=+_FV($G$1,"Market cap",TRUE)/1000000} -> 120444.85 | D21: {=+_FV($G$1,"Market cap",TRUE)/1000000} -> 120444.85 | E21: {=+_FV($G$1,"Market cap",TRUE)/1000000} -> 120444.85 | F21: {=+_FV($G$1,"Market cap",TRUE)/1000000} -> 120444.85 | G21: {=+_FV($G$1,"Market cap",TRUE)/1000000} -> 120444.85 | H21: {=+_FV($G$1,"Market cap",TRUE)/1000000} -> 120444.85 | I21: {=+_FV($G$1,"Market cap",TRUE)/1000000} -> 120444.85 | J21: {=+_FV($G$1,"Market cap",TRUE)/1000000} -> 120444.85 | ... Q21: {=+_FV($G$1,"Market cap",TRUE)/1000000} -> 120444.85
B22: Net Debt | C22: =+PROJ!BP145 -> 15814.634 | D22: =+PROJ!BQ145 -> 18630.793 | E22: =+PROJ!BR145 -> 19641.065 | F22: =+PROJ!BS145 -> 17336.939 | G22: =+PROJ!BT145 -> 15907.714 | H22: =+PROJ!BU145 -> 17086.529 | I22: =+PROJ!BV145 -> 17598.026 | J22: =+PROJ!BW145 -> 12745.853 | ... Q22: =+PROJ!CD145 -> 7569.5519
B23: EV | C23: =+C21+C22 -> 136259.48 | D23: =+D21+D22 -> 139075.64 | E23: =+E21+E22 -> 140085.91 | F23: =+F21+F22 -> 137781.79 | G23: =+G21+G22 -> 136352.56 | H23: =+H21+H22 -> 137531.38 | I23: =+I21+I22 -> 138042.87 | J23: =+J21+J22 -> 133190.7 | ... Q23: =+Q21+Q22 -> 128014.4
B25: PE | C25: =+C21/C15 -> 25.126361 | D25: =+D21/D15 -> 29.617423 | E25: =+E21/E15 -> 28.580538 | F25: =+F21/F15 -> 23.424382 | G25: =+G21/G15 -> 19.346804 | H25: =+H21/H15 -> 26.802044 | I25: =+I21/I15 -> 24.40996 | J25: =+J21/J15 -> 17.174891 | ... L25: =+L21/L15 -> 15.892623 | M25: mi al | N25: =+N21/N15 -> 14.827326 | O25: =+O21/O15 -> 14.773125 | P25: =+P21/P15 -> 14.726761 | Q25: =+Q21/Q15 -> 14.579019
B26: P/BV | C26: =+C21/PROJ!BP88 -> 17.208194 | D26: =+D21/PROJ!BQ88 -> 19.776836 | E26: =+E21/PROJ!BR88 -> 21.659696 | F26: =+F21/PROJ!BS88 -> 22.791819 | G26: =+G21/PROJ!BT88 -> 20.733376 | H26: =+H21/PROJ!BU88 -> 21.043441 | I26: =+I21/PROJ!BV88 -> 23.957443 | J26: =+J21/PROJ!BW88 -> 17.402415 | ... Q26: =+Q21/PROJ!CD88 -> 7.9015827
B27: EV/EBITDA | C27: =+C23/C17 -> 14.165175 | D27: =+D23/D17 -> 18.900194 | E27: =+E23/E17 -> 17.764451 | F27: =+F23/F17 -> 14.569676 | G27: =+G23/G17 -> 10.916392 | H27: =+H23/H17 -> 13.372035 | I27: =+I23/I17 -> 12.654291 | J27: =+J23/J17 -> 9.5704982 | ... Q27: =+Q23/Q17 -> 8.5939564
B29: Div yield | C29: =+PROJ!BP121/Resumo!$M$1 -> 0 | D29: =+PROJ!BQ121/Resumo!$M$1 -> 0 | E29: =+PROJ!BR121/Resumo!$M$1 -> 0 | F29: =+PROJ!BS121/Resumo!$M$1 -> 0 | G29: =+PROJ!BT121/Resumo!$M$1 -> 0.039862211 | H29: =+PROJ!BU121/Resumo!$M$1 -> 0.039861727 | I29: =+PROJ!BV121/Resumo!$M$1 -> 0.039861741 | J29: =+PROJ!BW121/Resumo!$M$1 -> 0.039862194 | ... Q29: =+PROJ!CD121/Resumo!$M$1 -> 0.055512189
B30: FCF Yield | F30: =+F45/F21 -> 0.054502234 | G30: =+G45/G21 -> 0.15751406 | H30: =+H45/H21 -> -0.0071047797 | I30: =+I45/I21 -> 0.084117655 | J30: =+J45/J21 -> 0.035718888 | K30: =+K45/K21 -> 0.030652246 | L30: =+L45/L21 -> 0.01917099 | M30: =+M45/M21 -> 0.068321435 | ... Q30: =+Q45/Q21 -> 0.06803554
B31: ROE | C31: =+PROJ!BP165 -> 0.69791526 | D31: =+PROJ!BQ165 -> 0.62136797 | E31: =+PROJ!BR165 -> 0.72341142 | F31: =+PROJ!BS165 -> 0.94821457 | G31: =+PROJ!BT165 -> 1.1223519 | H31: =+PROJ!BU165 -> 0.77931586 | I31: =+PROJ!BV165 -> 0.91790787 | J31: =+PROJ!BW165 -> 1.1738347 | ... Q31: =+PROJ!CD165 -> 0.57436177
B32: ROIC | F32: =+PROJ!BS39 -> 0 | G32: =+PROJ!BT39 -> 0.47247207 | H32: =+PROJ!BU39 -> 0.35620917 | I32: =+PROJ!BV39 -> 0.36687444 | J32: =+PROJ!BW39 -> 0.49119914 | K32: =+PROJ!BX39 -> 0.52447156 | L32: =+PROJ!BY39 -> 0.48755109 | M32: =+PROJ!BZ39 -> 0.49312107 | ... Q32: =+PROJ!CD39 -> 0.48838835
B34: FCFF | C34: =+C$2 -> 2016 | D34: =+D$2 -> 2017 | E34: =+E$2 -> 2018 | F34: =+F$2 -> 2019 | G34: =+G$2 -> 2020 | H34: =+H$2 -> 2021 | I34: =+I$2 -> 2022 | J34: =+J$2 -> 2023 | ... Q34: =+Q$2 -> 2030
B35: EBIT | C35: =+C9 -> 8018.41 | D35: =+D9 -> 6977.791 | E35: =+E9 -> 7503.406 | F35: =+F9 -> 8997.295 | G35: =+G9 -> 10537.29 | H35: =+H9 -> 8349.719 | I35: =+I9 -> 8940.054 | J35: =+J9 -> 11932.279 | ... Q35: =+Q9 -> 12880.129
B36: Impostos | C36: =+C13*C35 -> -2489.096 | D36: =+D13*D35 -> -2070.9175 | E36: =+E13*E35 -> -2232.7325 | F36: =+F13*F35 -> -2789.9354 | G36: =+G13*G35 -> -3315.8034 | H36: =+H13*H35 -> -2716.0212 | I36: =+I13*I35 -> -2853.8173 | J36: =+J13*J35 -> -3877.2035 | ... Q36: =+Q13*Q35 -> -4057.2406
B37: NOPAT | C37: =+C35+C36 -> 5529.314 | D37: =+D35+D36 -> 4906.8735 | E37: =+E35+E36 -> 5270.6735 | F37: =+F35+F36 -> 6207.3596 | G37: =+G35+G36 -> 7221.4866 | H37: =+H35+H36 -> 5633.6978 | I37: =+I35+I36 -> 6086.2367 | J37: =+J35+J36 -> 8055.0755 | ... Q37: =+Q35+Q36 -> 8822.8883
B38: Depr | C38: =+PROJ!BP98 -> 1600.919 | D38: =+PROJ!BQ98 -> 380.633 | E38: =+PROJ!BR98 -> 382.338 | F38: =+PROJ!BS98 -> 459.455 | G38: =+PROJ!BT98 -> 1953.335 | H38: =+PROJ!BU98 -> 1935.281 | I38: =+PROJ!BV98 -> 1968.726 | J38: =+PROJ!BW98 -> 1984.52 | ... Q38: =+PROJ!CD98 -> 2015.7342
B39: Capex | C39: =+PROJ!BP105 -> -2949.503 | D39: =+PROJ!BQ105 -> -2577.711 | E39: =+PROJ!BR105 -> -1792.043 | F39: =+PROJ!BS105 -> -771.988 | G39: =+PROJ!BT105 -> -795.281 | H39: =+PROJ!BU105 -> -2150.474 | I39: =+PROJ!BV105 -> -2141.436 | J39: =+PROJ!BW105 -> -2141.436 | ... Q39: =+PROJ!CD105 -> -2147.5576
B40: WC | C40: =+PROJ!BP99 -> -449.0371 | D40: =+PROJ!BQ99 -> -816.3749 | E40: =+PROJ!BR99 -> 569.8358 | F40: =+PROJ!BS99 -> 2193.6482 | G40: =+PROJ!BT99 -> 1416.601 | H40: =+PROJ!BU99 -> 30.1109 | I40: =+PROJ!BV99 -> 212.4501 | J40: =+PROJ!BW99 -> 245.551 | ... Q40: =+PROJ!CD99 -> 64.834438
B41: Imp dif | C41: =+C12-C36 -> 333.167 | D41: =+D12-D36 -> 367.31246 | E41: =+E12-E36 -> 450.1285 | F41: =+F12-F36 -> 475.92436 | G41: =+G12-G36 -> 523.67043 | H41: =+H12-H36 -> 565.96924 | I41: =+I12-I36 -> 539.41928 | J41: =+J12-J36 -> 501.69652 | ... Q41: =+Q12-Q36 -> 258.14789 | R41: perp
B42: FCFF | C42: =+C37+C38+C39+C40+C41 -> 4064.8599 | D42: =+D37+D38+D39+D40+D41 -> 2260.7331 | E42: =+E37+E38+E39+E40+E41 -> 4880.9328 | F42: =+F37+F38+F39+F40+F41 -> 8564.3992 | G42: =+G37+G38+G39+G40+G41 -> 10319.812 | H42: =+H37+H38+H39+H40+H41 -> 6014.5849 | I42: =+I37+I38+I39+I40+I41 -> 6665.3961 | J42: =+J37+J38+J39+J40+J41 -> 8645.407 | ... Q42: =+Q37+Q38+Q39+Q40+Q41 -> 9014.0473 | R42: =+Q42*(1+Q56)/(Q48-Q56) -> 149174.95
B43: Interest | C43: =+C10 -> -1073.269 | D43: =+D10 -> -1237.63 | E43: =+E10 -> -1512.719 | F43: =+F10 -> -1534.814 | G43: =+G10 -> -1664.172 | H43: =+H10 -> -1739.929 | I43: =+I10 -> -1689.82 | J43: =+J10 -> -1543.995 | ... Q43: =+Q10 -> -819.51711
B44: New Debt | C44: =+PROJ!BP143-PROJ!BO143 -> 6037.9262 | D44: =+PROJ!BQ143-PROJ!BP143 -> 29.0058 | E44: =+PROJ!BR143-PROJ!BQ143 -> 1335.435 | F44: =+PROJ!BS143-PROJ!BR143 -> -465.072 | G44: =+PROJ!BT143-PROJ!BS143 -> 10316.117 | H44: =+PROJ!BU143-PROJ!BT143 -> -5130.39 | I44: =+PROJ!BV143-PROJ!BU143 -> 5155.962 | J44: =+PROJ!BW143-PROJ!BV143 -> -2799.256 | ... Q44: =+PROJ!CD143-PROJ!CC143 -> 0
B45: FCFE | C45: =+C42+C43+C44 -> 9029.5171 | D45: =+D42+D43+D44 -> 1052.1089 | E45: =+E42+E43+E44 -> 4703.6488 | F45: =+F42+F43+F44 -> 6564.5132 | G45: =+G42+G43+G44 -> 18971.757 | H45: =+H42+H43+H44 -> -855.7341 | I45: =+I42+I43+I44 -> 10131.538 | J45: =+J42+J43+J44 -> 4302.156 | ... Q45: =+Q42+Q43+Q44 -> 8194.5302
B47: WACC | C47: =+C$2 -> 2016 | D47: =+D$2 -> 2017 | E47: =+E$2 -> 2018 | F47: =+F$2 -> 2019 | G47: =+G$2 -> 2020 | H47: =+H$2 -> 2021 | I47: =+I$2 -> 2022 | J47: =+J$2 -> 2023 | ... Q47: =+Q$2 -> 2030
...

Sheet PROJ
B1: =+YEAR(B2) -> 2016 | C1: =+YEAR(C2) -> 2016 | D1: =+YEAR(D2) -> 2016 | E1: =+YEAR(E2) -> 2016 | F1: =+YEAR(F2) -> 2017 | G1: =+YEAR(G2) -> 2017 | H1: =+YEAR(H2) -> 2017 | I1: =+YEAR(I2) -> 2017 | ... AS1: =+YEAR(AS2) -> 2026 | AU1: 2025 | AW1: 1997 | AX1: =+AW1+1 -> 1998 | AY1: =+AX1+1 -> 1999 | AZ1: =+AY1+1 -> 2000 | BA1: =+AZ1+1 -> 2001 | BB1: =+BA1+1 -> 2002 | BC1: =+BB1+1 -> 2003 | BD1: =+BC1+1 -> 2004 | BE1: =+BD1+1 -> 2005 | ... BS1: =+BR1+1 -> 2019 | BT1: =+YEAR(BT2) -> 2020 | BU1: =+YEAR(BU2) -> 2021 | BV1: =+YEAR(BV2) -> 2022 | BW1: =+YEAR(BW2) -> 2023 | BX1: =+YEAR(BX2) -> 2024 | BY1: =+YEAR(BY2) -> 2025 | BZ1: =+YEAR(BZ2) -> 2026 | CA1: =+YEAR(CA2) -> 2027 | ... CD1: =+YEAR(CD2) -> 2030
A2: MXN Millions | B2: 42459 | C2: =+EOMONTH(B2,3) -> 42551 | D2: =+EOMONTH(C2,3) -> 42643 | E2: =+EOMONTH(D2,3) -> 42735 | F2: =+EOMONTH(E2,3) -> 42825 | G2: =+EOMONTH(F2,3) -> 42916 | H2: =+EOMONTH(G2,3) -> 43008 | I2: =+EOMONTH(H2,3) -> 43100 | J2: =+EOMONTH(I2,3) -> 43190 | ... AS2: =+EOMONTH(AR2,3) -> 46387 | AU2: 46022 | AW2: 35795 | AX2: 36160 | AY2: 36525 | AZ2: 36891 | BA2: 37256 | BB2: 37621 | BC2: 37986 | BD2: 38352 | BE2: 38717 | BF2: 39082 | BG2: 39447 | BH2: 39813 | BI2: 40178 | BJ2: 40543 | BK2: 40908 | BL2: 41274 | BM2: 41639 | BN2: 42004 | BO2: 42369 | BP2: 42735 | BQ2: =+EOMONTH(BP2,12) -> 43100 | BR2: =+EOMONTH(BQ2,12) -> 43465 | BS2: =+EOMONTH(BR2,12) -> 43830 | BT2: =+EOMONTH(BS2,12) -> 44196 | BU2: =+EOMONTH(BT2,12) -> 44561 | BV2: =+EOMONTH(BU2,12) -> 44926 | BW2: =+EOMONTH(BV2,12) -> 45291 | BX2: =+EOMONTH(BW2,12) -> 45657 | ... CD2: =+EOMONTH(CC2,12) -> 47848
A3: Revenues | B3: 8728.317 | C3: 8831.353 | D3: 8719.457 | E3: 9381.168 | F3: 9530.508 | G3: 9605.905 | H3: 9197.259 | I3: 9432.088 | J3: 10207.266 | K3: 10588.598 | L3: 9897 | M3: 10334 | N3: 11014 | O3: 11285.929 | P3: 10400 | Q3: 10801 | R3: 11692.238 | S3: 12337.259 | T3: 11097.119 | U3: 11576.279 | V3: 12108.979 | W3: 11722.218 | X3: 11343.49 | Y3: 11719.276 | Z3: 12574 | AA3: 12894.841 | AB3: 12794 | AC3: 12792.035 | AD3: 13549 | AE3: 13714.072 | AF3: 12672.559 | AG3: 13371.423 | AH3: 13789.577 | AI3: 14068 | AJ3: 13154.636 | AK3: 13770.504 | AL3: 13833 | AM3: 14070 | AN3: 13410 | AO3: 14057.927 | AP3: =+FAT!AP11 -> 14109.66 | AQ3: =+FAT!AQ11 -> 14421.75 | AR3: =+FAT!AR11 -> 13745.25 | AS3: =+FAT!AS11 -> 14409.375 | AU3: 13977.062 | AV3: =+AO3/AU3-1 -> 0.0057855823 | AW3: 10305.475 | AX3: 12289.726 | AY3: 13868.222 | AZ3: 15906.374 | BA3: 15633.955 | BB3: 16096.04 | BC3: 17100.169 | BD3: 19798.909 | BE3: 21983.114 | BF3: 20084.472 | BG3: 21480.233 | BH3: 23051.522 | BI3: 24702.207 | BJ3: 26196.519 | BK3: 26732.383 | BL3: 29288.626 | BM3: 29677.516 | BN3: 29106.853 | BO3: 32206.234 | BP3: 35660.295 | BQ3: =+SUMIFS($B3:$AK3,$B$1:$AK$1,"="&BQ$1) -> 37765.76 | BR3: =+SUMIFS($B3:$AK3,$B$1:$AK$1,"="&BR$1) -> 41026.864 | BS3: =+SUMIFS($B3:$AK3,$B$1:$AK$1,"="&BS$1) -> 43500.929 | BT3: =+SUMIFS($B3:$AK3,$B$1:$AK$1,"="&BT$1) -> 46702.895 | BU3: =+SUMIFS($B3:$AK3,$B$1:$AK$1,"="&BU$1) -> 46893.963 | BV3: =+SUMIFS($B3:$AK3,$B$1:$AK$1,"="&BV$1) -> 51054.876 | BW3: =+SUMIFS($B3:$AK3,$B$1:$AK$1,"="&BW$1) -> 53307.054 | BX3: =+SUMIFS($B3:$AO3,$B$1:$AO$1,"="&BX$1) -> 54782.717 | BY3: =+SUMIFS($B3:$AS3,$B$1:$AS$1,"="&BY$1) -> 55370.927 | BZ3: =+SUMIFS($B3:$AS3,$B$1:$AS$1,"="&BZ$1) -> 56686.035 | CA3: =+FAT!CA11 -> 57819.756 | CB3: =+FAT!CB11 -> 58976.151 | CC3: =+FAT!CC11 -> 60155.674 | CD3: =+FAT!CD11 -> 61358.787
A4: Chg YoY | C4: =C3/B3-1 -> 0.011804796 | D4: =D3/C3-1 -> -0.012670312 | E4: =E3/D3-1 -> 0.075889015 | F4: =+F3/B3-1 -> 0.091906722 | G4: =+G3/C3-1 -> 0.087704794 | H4: =+H3/D3-1 -> 0.05479722 | I4: =+I3/E3-1 -> 0.0054278955 | J4: =+J3/F3-1 -> 0.071009646 | K4: =+K3/G3-1 -> 0.10230093 | L4: =+L3/H3-1 -> 0.076081472 | M4: =+M3/I3-1 -> 0.095621669 | ... AS4: =+AS3/AO3-1 -> 0.025 | AU4: 0.015 | AX4: =AX3/AW3-1 -> 0.19254338 | AY4: =AY3/AX3-1 -> 0.12844029 | AZ4: =AZ3/AY3-1 -> 0.14696563 | BA4: =BA3/AZ3-1 -> -0.017126405 | BB4: =BB3/BA3-1 -> 0.029556501 | BC4: =BC3/BB3-1 -> 0.062383605 | BD4: =BD3/BC3-1 -> 0.15781949 | BE4: =BE3/BD3-1 -> 0.11031946 | ... CD4: =CD3/CC3-1 -> 0.02
A5: COGS | B5: -5291.904 | C5: -5378.376 | D5: -5374.796 | E5: -5830.286 | F5: -6145.84 | G5: -6206.55 | H5: -5992.561 | I5: -6018.818 | J5: -6481.295 | K5: -6774.015 | L5: -6539.368 | M5: -6891.62 | N5: =3875-N3 -> -7139 | O5: -7087.416 | P5: -6414.613 | Q5: -6538.479 | R5: -7067.539 | S5: -7617.16 | T5: -6893.956 | U5: -7114.966 | V5: -7445.987 | W5: -7678.542 | X5: -7745.158 | Y5: -8238.6 | Z5: -8636.462 | AA5: -8739.084 | AB5: -8549.618 | AC5: -8357.23 | AD5: -8626.628 | AE5: -8477.774 | AF5: -7582.014 | AG5: -7920.599 | AH5: -7961.006 | AI5: -8113.588 | AJ5: -7942.902 | AK5: =+AK6-AK3 -> -8381.493 | AL5: =+AL6-AL3 -> -8550 | AM5: =+AM6-AM3 -> -8694.075 | AN5: =+AN6-AN3 -> -8218.306 | AO5: =+AO6-AO3 -> -8377.888 | AP5: =+FAT!AP22 -> -8530.187 | AQ5: =+FAT!AQ22 -> -8642.0689 | AR5: =+FAT!AR22 -> -8355.6465 | AS5: =+FAT!AS22 -> -8469.8834 | AU5: -8420.8539 | AW5: -6257.084 | AX5: -7212.551 | AY5: -7828.87 | AZ5: -9061.387 | BA5: -8797.095 | BB5: -9296.092 | BC5: -10269.192 | BD5: -12307.609 | BE5: -13678.619 | BF5: -11326.652 | BG5: -12683.071 | BH5: -13833.201 | BI5: -14564.753 | BJ5: -15640.626 | BK5: -17054 | BL5: -17956.306 | BM5: -17759.99 | BN5: -18379.732 | BO5: -19778.457 | BP5: -21875.362 | BQ5: =+SUMIFS($B5:$AK5,$B$1:$AK$1,"="&BQ$1) -> -24363.769 | BR5: =+SUMIFS($B5:$AK5,$B$1:$AK$1,"="&BR$1) -> -26686.298 | BS5: =+SUMIFS($B5:$AK5,$B$1:$AK$1,"="&BS$1) -> -27179.508 | BT5: =+SUMIFS($B5:$AK5,$B$1:$AK$1,"="&BT$1) -> -28693.621 | BU5: =+SUMIFS($B5:$AK5,$B$1:$AK$1,"="&BU$1) -> -31108.287 | BV5: =+SUMIFS($B5:$AK5,$B$1:$AK$1,"="&BV$1) -> -34282.394 | BW5: =+SUMIFS($B5:$AK5,$B$1:$AK$1,"="&BW$1) -> -32607.015 | BX5: =+SUMIFS($B5:$AO5,$B$1:$AO$1,"="&BX$1) -> -32398.989 | BY5: =+SUMIFS($B5:$AS5,$B$1:$AS$1,"="&BY$1) -> -33840.269 | BZ5: =+SUMIFS($B5:$AS5,$B$1:$AS$1,"="&BZ$1) -> -33997.786 | CA5: =+FAT!CA22 -> -34820.992 | CB5: =+FAT!CB22 -> -35604.055 | CC5: =+FAT!CC22 -> -36409.595 | CD5: =+FAT!CD22 -> -37237.726
A6: Gross Profit | B6: =B3+B5 -> 3436.413 | C6: =C3+C5 -> 3452.977 | D6: =D3+D5 -> 3344.661 | E6: =E3+E5 -> 3550.882 | F6: =F3+F5 -> 3384.668 | G6: =G3+G5 -> 3399.355 | H6: =H3+H5 -> 3204.698 | I6: =I3+I5 -> 3413.27 | ... AJ6: =AJ3+AJ5 -> 5211.734 | AK6: 5389.011 | AL6: 5283 | AM6: 5375.925 | AN6: 5191.694 | AO6: 5680.039 | AP6: =AP3+AP5 -> 5579.473 | AQ6: =AQ3+AQ5 -> 5779.6811 | AR6: =AR3+AR5 -> 5389.6035 | AS6: =AS3+AS5 -> 5939.4918 | AU6: 5556.2076 | AV6: =+AO6/AU6-1 -> 0.022287029 | AW6: =AW3+AW5 -> 4048.391 | AX6: =AX3+AX5 -> 5077.175 | AY6: =AY3+AY5 -> 6039.352 | AZ6: =AZ3+AZ5 -> 6844.987 | BA6: =BA3+BA5 -> 6836.86 | BB6: =BB3+BB5 -> 6799.948 | BC6: =BC3+BC5 -> 6830.977 | BD6: =BD3+BD5 -> 7491.3 | ... CD6: =CD3+CD5 -> 24121.062
A7: Margin (%) | B7: =B6/B3 -> 0.39370855 | C7: =C6/C3 -> 0.39099071 | D7: =D6/D3 -> 0.38358593 | E7: =E6/E3 -> 0.37851172 | F7: =F6/F3 -> 0.35514036 | G7: =G6/G3 -> 0.3538818 | H7: =H6/H3 -> 0.34844055 | I7: =I6/I3 -> 0.36187852 | ... AS7: =AS6/AS3 -> 0.41219635 | AU7: 0.3975233 | AV7: =+AO7-AU7 -> 0.0065219761 | AW7: =AW6/AW3 -> 0.39283886 | AX7: =AX6/AX3 -> 0.41312353 | AY7: =AY6/AY3 -> 0.43548135 | AZ7: =AZ6/AZ3 -> 0.43032982 | BA7: =BA6/BA3 -> 0.43730841 | BB7: =BB6/BB3 -> 0.42246093 | BC7: =BC6/BC3 -> 0.39946839 | BD7: =BD6/BD3 -> 0.37836933 | ... CD7: =CD6/CD3 -> 0.39311504
A8: General & Admininstrative Expenses | B8: -1385.949 | C8: -1505.344 | D8: -1298.673 | E8: -1576.557 | F8: -1556.581 | G8: =+G10+G11 -> -1604.777 | H8: =+H10+H11 -> -1642.969 | I8: =+I10+I11 -> -1624.922 | J8: =+J10+J11 -> -1707.779 | K8: =+K10+K11 -> -1781.698 | L8: =+L10+L11 -> -1666.096 | M8: =+M10+M11 -> -1690.269 | N8: =+N10+N11 -> -1817.224 | ... AO8: =+AO10+AO11 -> -2467.304 | AP8: =+FAT!AP71 -> -2388.1114 | AQ8: =+FAT!AQ71 -> -2427.8699 | AR8: =+FAT!AR71 -> -2426.1828 | AS8: =+FAT!AS71 -> -2553.6596 | AU8: -2452.979 | AV8: =+AO8/AU8-1 -> 0.005839838 | AW8: -1105.632 | AX8: -1286.713 | AY8: -1459.176 | AZ8: -1757.692 | BA8: -1951.21 | BB8: -2097.291 | BC8: -2355.363 | BD8: -2668.549 | BE8: -2940.21 | BF8: -3011.227 | BG8: -3169.131 | BH8: -3267.238 | BI8: -3434.906 | BJ8: -3674.838 | BK8: -3895 | BL8: -4697.221 | BM8: -4709.51 | BN8: -4857.069 | BO8: -5289.686 | BP8: -5766.523 | BQ8: =+BQ10+BQ11 -> -6432.926 | BR8: =+BR10+BR11 -> -6845.842 | BS8: =+BS10+BS11 -> -7346.593 | BT8: =+BT10+BT11 -> -7504.876 | BU8: =+BU10+BU11 -> -7450.885 | BV8: =+BV10+BV11 -> -7848.084 | BW8: =+BW10+BW11 -> -8784.296 | BX8: =+SUMIFS($B8:$AO8,$B$1:$AO$1,"="&BX$1) -> -9572.8899 | BY8: =+SUMIFS($B8:$AS8,$B$1:$AS$1,"="&BY$1) -> -9464.564 | BZ8: =+SUMIFS($B8:$AS8,$B$1:$AS$1,"="&BZ$1) -> -9795.8237 | CA8: =+FAT!CA71 -> -10138.678 | CB8: =+FAT!CB71 -> -10493.531 | CC8: =+FAT!CC71 -> -10860.805 | CD8: =+FAT!CD71 -> -11240.933
A9: Chg YoY | C9: =C8/B8-1 -> 0.086146749 | D9: =D8/C8-1 -> -0.13729154 | E9: =E8/D8-1 -> 0.21397534 | F9: =F8/E8-1 -> -0.012670649 | G9: =G8/F8-1 -> 0.030962732 | H9: =H8/G8-1 -> 0.023798945 | I9: =I8/H8-1 -> -0.010984383 | J9: =J8/I8-1 -> 0.050991371 | ... AS9: =AS8/AR8-1 -> 0.052542128 | AU9: 0.04643114 | AW9: =AW8/A8-1 -> #VALUE! | AX9: =AX8/AW8-1 -> 0.16378053 | AY9: =AY8/AX8-1 -> 0.13403377 | AZ9: =AZ8/AY8-1 -> 0.20457847 | BA9: =BA8/AZ8-1 -> 0.11009779 | BB9: =BB8/BA8-1 -> 0.074866877 | BC9: =BC8/BB8-1 -> 0.12305016 | BD9: =BD8/BC8-1 -> 0.13296719 | BE9: =BE8/BD8-1 -> 0.10180102 | ... CD9: =CD8/CC8-1 -> 0.035
A10: Selling | F10: -1063.753 | G10: -1103.351 | H10: -1131.587 | I10: -1150.137 | J10: -1157.975 | K10: -1228.681 | L10: -1194.458 | M10: -1133.704 | N10: -1229.273 | O10: -1316.393 | P10: -1242.548 | Q10: -1175.834 | R10: -1306.122 | S10: -1308.885 | T10: -1252.027 | U10: -1218.73 | V10: -1297.448 | W10: -1226.776 | X10: -1319.511 | Y10: -1283.357 | Z10: -1310.567 | AA10: -1382.241 | AB10: -1377.03 | AC10: -1363.433 | AD10: -1461.417 | AE10: -1516.571 | AF10: -1479.836 | AG10: -1590.404 | AH10: -1718.988 | AI10: -1687.386 | AJ10: -1592.9219 | AK10: -1664.999 | AL10: -1676.541 | AM10: -1710.924 | AN10: -1684.971 | AO10: -1768.048 | BQ10: =+SUMIFS($B10:$AK10,$B$1:$AK$1,"="&BQ$1) -> -4448.828 | BR10: =+SUMIFS($B10:$AK10,$B$1:$AK$1,"="&BR$1) -> -4714.818 | BS10: =+SUMIFS($B10:$AK10,$B$1:$AK$1,"="&BS$1) -> -4964.048 | BT10: =+SUMIFS($B10:$AK10,$B$1:$AK$1,"="&BT$1) -> -5085.764 | BU10: =+SUMIFS($B10:$AK10,$B$1:$AK$1,"="&BU$1) -> -5127.092 | BV10: =+SUMIFS($B10:$AK10,$B$1:$AK$1,"="&BV$1) -> -5433.271 | BW10: =+SUMIFS($B10:$AK10,$B$1:$AK$1,"="&BW$1) -> -6048.228 | BX10: =+SUMIFS($B10:$AO10,$B$1:$AO$1,"="&BX$1) -> -6664.2949 | BY10: =+SUMIFS($B10:$AS10,$B$1:$AS$1,"="&BY$1) -> -6840.484 | BZ10: =+SUMIFS($B10:$AS10,$B$1:$AS$1,"="&BZ$1) -> 0
A11: Admin Exp | F11: -496.505 | G11: -501.426 | H11: -511.382 | I11: -474.785 | J11: -549.804 | K11: -553.017 | L11: -471.638 | M11: -556.565 | N11: -587.951 | O11: -594.767 | P11: -594.765 | Q11: -605.062 | R11: -619.809 | S11: -592.42 | T11: -592.333 | U11: -614.55 | V11: -625.846 | W11: -585.593 | X11: -546.326 | Y11: -566.028 | Z11: -624.84 | AA11: -619.07 | AB11: -622.306 | AC11: -548.597 | AD11: -681.51 | AE11: -692.352 | AF11: -668.249 | AG11: -693.957 | AH11: -717.34 | AI11: -737.826 | AJ11: -665.449 | AK11: -787.98 | AL11: -630.813 | AM11: -634.844 | AN11: -659.167 | AO11: -699.256 | BQ11: =+SUMIFS($B11:$AK11,$B$1:$AK$1,"="&BQ$1) -> -1984.098 | BR11: =+SUMIFS($B11:$AK11,$B$1:$AK$1,"="&BR$1) -> -2131.024 | BS11: =+SUMIFS($B11:$AK11,$B$1:$AK$1,"="&BS$1) -> -2382.545 | BT11: =+SUMIFS($B11:$AK11,$B$1:$AK$1,"="&BT$1) -> -2419.112 | BU11: =+SUMIFS($B11:$AK11,$B$1:$AK$1,"="&BU$1) -> -2323.793 | BV11: =+SUMIFS($B11:$AK11,$B$1:$AK$1,"="&BV$1) -> -2414.813 | BW11: =+SUMIFS($B11:$AK11,$B$1:$AK$1,"="&BW$1) -> -2736.068 | BX11: =+SUMIFS($B11:$AO11,$B$1:$AO$1,"="&BX$1) -> -2908.595 | BY11: =+SUMIFS($B11:$AS11,$B$1:$AS$1,"="&BY$1) -> -2624.08 | BZ11: =+SUMIFS($B11:$AS11,$B$1:$AS$1,"="&BZ$1) -> 0
A12: Other Income | G12: 2.357 | H12: 4.104 | I12: 2.265 | J12: 2.392 | K12: -2.708 | L12: 3.507 | M12: 5.491 | N12: 2.31 | O12: 9.186 | P12: 7.189 | Q12: 3.782 | R12: 2.831 | S12: 1.444 | T12: 1.164 | U12: 27.453 | V12: 1.755 | W12: 1.247 | X12: 4.846 | Y12: 7.08 | Z12: 3.055 | AA12: 2.676 | AB12: 7.936 | AC12: 1.989 | AD12: 2.759 | AE12: 1.93 | AF12: 1.039 | AG12: 10.808 | AH12: 7.893 | AI12: 9.07 | AJ12: 11.516 | AK12: 8.033 | AL12: 0.733 | AM12: 16.149 | AN12: 2.881 | AO12: 2.604 | BQ12: =+SUMIFS($B12:$AK12,$B$1:$AK$1,"="&BQ$1) -> 8.726 | BR12: =+SUMIFS($B12:$AK12,$B$1:$AK$1,"="&BR$1) -> 8.682 | BS12: =+SUMIFS($B12:$AK12,$B$1:$AK$1,"="&BS$1) -> 22.467 | BT12: =+SUMIFS($B12:$AK12,$B$1:$AK$1,"="&BT$1) -> 32.892 | BU12: =+SUMIFS($B12:$AK12,$B$1:$AK$1,"="&BU$1) -> 14.928 | BV12: =+SUMIFS($B12:$AK12,$B$1:$AK$1,"="&BV$1) -> 15.656 | BW12: =+SUMIFS($B12:$AK12,$B$1:$AK$1,"="&BW$1) -> 16.536 | BX12: =+SUMIFS($B12:$AO12,$B$1:$AO$1,"="&BX$1) -> 36.512 | BY12: =+SUMIFS($B12:$AS12,$B$1:$AS$1,"="&BY$1) -> 22.367 | BZ12: =+SUMIFS($B12:$AS12,$B$1:$AS$1,"="&BZ$1) -> 0
A13: As % Revenues | B13: =-B8/(B3) -> 0.15878766 | C13: =-C8/(C3) -> 0.17045452 | D13: =-D8/(D3) -> 0.14893966 | E13: =-E8/(E3) -> 0.16805551 | F13: =-F8/(F3) -> 0.16332613 | G13: =-G8/(G3) -> 0.16706151 | H13: =-H8/(H3) -> 0.17863681 | I13: =-I8/(I3) -> 0.17227596 | ... AG13: =-AG8/(AG3) -> 0.17083903 | AH13: =-AH8/AH3 -> 0.17667895 | AI13: =-AI8/AI3 -> 0.1723921 | AJ13: =-AJ8/AJ3 -> 0.17167871 | AK13: =-AK8/AK3 -> 0.17813284 | AL13: =-AL8/AL3 -> 0.16680069 | AM13: =-AM8/AM3 -> 0.16672125 | AN13: =-AN8/AN3 -> 0.17480522 | AO13: =-AO8/AO3 -> 0.1755098 | ... AS13: =-AS8/AS3 -> 0.17722209 | AU13: 0.17550034 | AW13: =-AW8/(AW3) -> 0.10728588 | AX13: =-AX8/(AX3) -> 0.10469827 | AY13: =-AY8/(AY3) -> 0.10521724 | AZ13: =-AZ8/(AZ3) -> 0.11050237 | BA13: =-BA8/(BA3) -> 0.12480591 | BB13: =-BB8/(BB3) -> 0.13029857 | BC13: =-BC8/(BC3) -> 0.13773917 | BD13: =-BD8/(BD3) -> 0.13478263 | ... BZ13: =-BZ8/(BZ3) -> 0.17280841 | CA13: =-CA8/CA3 -> 0.17534971 | CB13: =-CB8/CB3 -> 0.17792838 | CC13: =-CC8/CC3 -> 0.18054498 | CD13: =-CD8/CD3 -> 0.18320005
A14: Operating Income | B14: =B8+B6 -> 2050.464 | C14: =C8+C6 -> 1947.633 | D14: =D8+D6 -> 2045.988 | E14: =E8+E6 -> 1974.325 | F14: =F8+F6 -> 1828.087 | G14: =G8+G6+G12 -> 1796.935 | H14: =H8+H6+H12 -> 1565.833 | I14: =I8+I6+I12 -> 1790.613 | J14: =J8+J6+J12 -> 2020.584 | K14: =K8+K6+K12 -> 2030.177 | L14: =L8+L6+L12 -> 1695.043 | M14: =M8+M6+M12 -> 1757.602 | N14: =N8+N6+N12 -> 2060.086 | ... AS14: =AS8+AS6+AS12 -> 3385.8322 | AU14: 3103.2286 | AW14: =AW8+AW6 -> 2942.759 | AX14: =AX8+AX6 -> 3790.462 | AY14: =AY8+AY6 -> 4580.176 | AZ14: =AZ8+AZ6 -> 5087.295 | BA14: =BA8+BA6 -> 4885.65 | BB14: =BB8+BB6 -> 4702.657 | BC14: =BC8+BC6 -> 4475.614 | BD14: =BD8+BD6 -> 4822.751 | ... BP14: =BP8+BP6 -> 8018.41 | BQ14: =BQ8+BQ6+BQ12 -> 6977.791 | BR14: =BR8+BR6+BR12 -> 7503.406 | BS14: =BS8+BS6+BS12 -> 8997.295 | BT14: =BT8+BT6+BT12 -> 10537.29 | BU14: =BU8+BU6+BU12 -> 8349.719 | BV14: =BV8+BV6+BV12 -> 8940.054 | BW14: =BW8+BW6+BW12 -> 11932.279 | BX14: =BX8+BX6+BX12 -> 12847.35 | ... CD14: =CD8+CD6+CD12 -> 12880.129
A15: Op. Margin (%) | B15: =B14/B$3 -> 0.23492089 | C15: =C14/C$3 -> 0.2205362 | D15: =D14/D$3 -> 0.23464626 | E15: =E14/E$3 -> 0.2104562 | F15: =F14/F$3 -> 0.19181422 | G15: =G14/G$3 -> 0.18706566 | H15: =H14/H$3 -> 0.17024996 | I15: =I14/I$3 -> 0.18984269 | ... AS15: =AS14/AS$3 -> 0.23497425 | AU15: 0.22202296 | AW15: =AW14/AW$3 -> 0.28555297 | AX15: =AX14/AX$3 -> 0.30842527 | AY15: =AY14/AY$3 -> 0.33026411 | AZ15: =AZ14/AZ$3 -> 0.31982745 | BA15: =BA14/BA$3 -> 0.3125025 | BB15: =BB14/BB$3 -> 0.29216236 | BC15: =BC14/BC$3 -> 0.26172923 | BD15: =BD14/BD$3 -> 0.2435867 | ... CD15: =CD14/CD$3 -> 0.20991498
A16: EBITDA | B16: =+B14-B65 -> 2458.685 | C16: =+C14-C65 -> 2360.149 | D16: =+D14-D65 -> 2458.251 | E16: =+E14-E65 -> 2342.244 | F16: =+F14-F65 -> 2264.23 | G16: =+G14-G65 -> 2212.047 | H16: =+H14-H65 -> 1933.769 | I16: =+I14-I65 -> 2171.246 | ... AM16: =+AM14-AM65 -> 3568.889 | AN16: 3355 | AO16: =+AO14-AO65 -> 3713.259 | AP16: =+AP14-AP65 -> 3689.4182 | AQ16: =+AQ14-AQ65 -> 3876.5602 | AR16: =+AR14-AR65 -> 3459.206 | AS16: =+AS14-AS65 -> 3877.5065 | AU16: 3672.6968 | AV16: =+AO16/AU16-1 -> 0.011044257 | AW16: =+AW14-AW65 -> 3554.901 | AX16: =+AX14-AX65 -> 4499.979 | AY16: =+AY14-AY65 -> 5391.918 | AZ16: =+AZ14-AZ65 -> 5923.289 | BA16: =+BA14-BA65 -> 5816.681 | BB16: =+BB14-BB65 -> 5786.37 | BC16: =+BC14-BC65 -> 5646.98 | BD16: =+BD14-BD65 -> 6063.76 | ... CD16: =+CD14-CD65 -> 14895.863
A17: EBITDA Margin | B17: =+B16/B3 -> 0.28169062 | C17: =+C16/C3 -> 0.26724659 | D17: =+D16/D3 -> 0.28192707 | E17: =+E16/E3 -> 0.24967509 | F17: =+F16/F3 -> 0.23757705 | G17: =+G16/G3 -> 0.23027992 | H17: =+H16/H3 -> 0.21025492 | I17: =+I16/I3 -> 0.23019781 | ... AG17: =+AG16/AG3 -> 0.27744175 | AH17: =AH16/AH$3 -> 0.28240663 | AI17: =AI16/AI$3 -> 0.286721 | AJ17: =AJ16/AJ$3 -> 0.26338198 | AK17: =AK16/AK$3 -> 0.25434581 | AL17: =AL16/AL$3 -> 0.25089055 | AM17: =AM16/AM$3 -> 0.25365238 | AN17: =AN16/AN$3 -> 0.25018643 | AO17: =AO16/AO$3 -> 0.26413987 | ... AS17: =AS16/AS$3 -> 0.26909609 | AU17: 0.26276602 | AV17: =+AO17-AU17 -> 0.0013738524 | AW17: =+AW16/AW3 -> 0.34495266 | AX17: =+AX16/AX3 -> 0.3661578 | AY17: =+AY16/AY3 -> 0.38879663 | AZ17: =+AZ16/AZ3 -> 0.37238462 | BA17: =+BA16/BA3 -> 0.37205435 | BB17: =+BB16/BB3 -> 0.35949028 | BC17: =+BC16/BC3 -> 0.33022948 | BD17: =+BD16/BD3 -> 0.30626738 | ... BZ17: =+BZ16/BZ3 -> 0.2628988 | CA17: =CA16/CA$3 -> 0.25692555 | CB17: =CB16/CB$3 -> 0.25225174 | CC17: =CC16/CC$3 -> 0.24753228 | CD17: =CD16/CD$3 -> 0.24276658
A18: Financial Income | B18: 64.649 | C18: 83.848 | D18: 80.271 | E18: 41.006 | F18: 89.306 | G18: 72.796 | H18: 55.215 | I18: 47.156 | J18: 102.278 | K18: 37.924 | L18: 89.409 | M18: 58.503 | N18: 95.196 | O18: 87.87 | P18: 76.411 | Q18: 62.251 | R18: 141.812 | S18: 58.338 | T18: 211.122 | U18: 187.161 | V18: 158.794 | W18: 114.064 | X18: 113.424 | Y18: 118.997 | Z18: 113.652 | AA18: 100.584 | AB18: 187.662 | AC18: 314.18 | AD18: 321.205 | AE18: 341.753 | AF18: 316.097 | AG18: 385.093 | AH18: 368.48 | AI18: 290.533 | AJ18: 314.363 | AK18: 234.835 | AL18: 275.092 | AM18: 156.878 | AN18: 109.825 | AO18: 113.351 | AP18: =AO56*AP148/4 -> 109.24788 | AQ18: =AP56*AQ148/4 -> 182.42315 | AR18: =AQ56*AR148/4 -> 154.67496 | AS18: =AR56*AS148/4 -> 144.71073 | AU18: 129.61321 | AW18: 295.808 | AX18: 435.331 | AY18: 400.474 | AZ18: 207.069 | BA18: 131.345 | BB18: 56.392 | BC18: 49.398 | BD18: 78.32 | BE18: 93.12 | BF18: 105.203 | BG18: 198.181 | BH18: 206.737 | BI18: 269.36 | BJ18: 198.807 | BK18: 174.234 | BL18: 103.149 | BM18: 126.874 | BN18: 227.327 | BO18: 206.687 | BP18: 269.774 | BQ18: =+SUMIFS($B18:$AK18,$B$1:$AK$1,"="&BQ$1) -> 264.473 | BR18: =+SUMIFS($B18:$AK18,$B$1:$AK$1,"="&BR$1) -> 288.114 | BS18: =+SUMIFS($B18:$AK18,$B$1:$AK$1,"="&BS$1) -> 321.728 | BT18: =+SUMIFS($B18:$AK18,$B$1:$AK$1,"="&BT$1) -> 598.433 | BU18: =+SUMIFS($B18:$AK18,$B$1:$AK$1,"="&BU$1) -> 505.279 | BV18: =+SUMIFS($B18:$AK18,$B$1:$AK$1,"="&BV$1) -> 716.078 | BW18: =+SUMIFS($B18:$AK18,$B$1:$AK$1,"="&BW$1) -> 1364.148 | BX18: =+SUMIFS($B18:$AO18,$B$1:$AO$1,"="&BX$1) -> 1208.211 | BY18: =+SUMIFS($B18:$AS18,$B$1:$AS$1,"="&BY$1) -> 655.146 | BZ18: =+SUMIFS($B18:$AS18,$B$1:$AS$1,"="&BZ$1) -> 591.05673 | CA18: =BZ56*CA148 -> 441.54435 | CB18: =CA56*CB148 -> 540.60512 | CC18: =CB56*CC148 -> 643.1682 | CD18: =CC56*CD148 -> 750.15066
A19: Financial Expense | B19: -294.576 | C19: -296.024 | D19: -308.224 | E19: -326.169 | F19: -333.154 | G19: -372.366 | H19: -367.679 | I19: -428.904 | J19: -400.968 | K19: -492.473 | L19: -489.413 | M19: -417.979 | N19: -462.856 | O19: -466.389 | P19: -467.203 | Q19: -460.094 | R19: -553.41 | S19: -459.472 | T19: -638.915 | U19: -610.808 | V19: -581.016 | W19: -566.402 | X19: -558.476 | Y19: -539.314 | Z19: -532.603 | AA19: -529.227 | AB19: -612.676 | AC19: -731.392 | AD19: -736.617 | AE19: -723.034 | AF19: -730.112 | AG19: -718.38 | AH19: -684 | AI19: -646.018 | AJ19: -601.191 | AK19: -584.78 | AL19: -569.888 | AM19: -509.047 | AN19: -513.838 | AO19: -512.189 | AP19: =-AP147*AVERAGE(AO143:AP143)/4 -> -439.62335 | AQ19: =-AQ147*AVERAGE(AP143:AQ143)/4 -> -430.1401 | AR19: =-AR147*AVERAGE(AQ143:AR143)/4 -> -430.86899 | AS19: =-AS147*AVERAGE(AR143:AS143)/4 -> -429.19726 | AU19: -432.40945 | AW19: -195.328 | AX19: -218.303 | AY19: -310.505 | AZ19: -425.767 | BA19: -440.695 | BB19: -455.956 | BC19: -492.859 | BD19: -520.195 | BE19: -512.016 | BF19: -478.397 | BG19: -546.48 | BH19: -632.884 | BI19: -778.823 | BJ19: -684.813 | BK19: -805.863 | BL19: -811.661 | BM19: -746.952 | BN19: -906.458 | BO19: -1075.526 | BP19: -1224.993 | BQ19: =+SUMIFS($B19:$AK19,$B$1:$AK$1,"="&BQ$1) -> -1502.103 | BR19: =+SUMIFS($B19:$AK19,$B$1:$AK$1,"="&BR$1) -> -1800.833 | BS19: =+SUMIFS($B19:$AK19,$B$1:$AK$1,"="&BS$1) -> -1856.542 | BT19: =+SUMIFS($B19:$AK19,$B$1:$AK$1,"="&BT$1) -> -2262.605 | BU19: =+SUMIFS($B19:$AK19,$B$1:$AK$1,"="&BU$1) -> -2245.208 | BV19: =+SUMIFS($B19:$AK19,$B$1:$AK$1,"="&BV$1) -> -2405.898 | BW19: =+SUMIFS($B19:$AK19,$B$1:$AK$1,"="&BW$1) -> -2908.143 | BX19: =+SUMIFS($B19:$AO19,$B$1:$AO$1,"="&BX$1) -> -2515.989 | BY19: =+SUMIFS($B19:$AS19,$B$1:$AS$1,"="&BY$1) -> -2104.962 | BZ19: =+SUMIFS($B19:$AS19,$B$1:$AS$1,"="&BZ$1) -> -1729.8297 | CA19: =-CA147*AVERAGE(BZ143:CA143) -> -1442.9924 | CB19: =-CB147*AVERAGE(CA143:CB143) -> -1517.0241 | CC19: =-CC147*AVERAGE(CB143:CC143) -> -1588.8249 | CD19: =-CD147*AVERAGE(CC143:CD143) -> -1569.6678
A20: Equity Income
A21: FX Gain/Loss | B21: -223 | C21: 36.059 | D21: 47.209 | E21: 21.682 | F21: -33.063 | AW21: -59.502 | AX21: -643.196 | AY21: -17.908 | AZ21: -50.158 | BA21: -77.962 | BB21: -588.615 | BC21: -586.62 | BD21: -67.735 | BE21: -914.702 | BF21: -218.421 | BG21: 0 | BH21: 0 | BI21: 0 | BJ21: 0 | BK21: 0 | BL21: 0 | BM21: 0 | BN21: -116.922 | BO21: 0 | BP21: -118.05
A22: Other Income/Expense | B22: 0 | C22: 0 | D22: 0 | E22: 0 | F22: 0 | AW22: 382.728 | AX22: 11.456 | AY22: 15.041 | AZ22: 33.449 | BA22: 5.468 | BB22: 5.142 | BC22: 5.479 | BD22: 10.233 | BE22: 12.077 | BF22: -4.387 | BG22: -461.175 | BH22: 375.647 | BI22: 571.644 | BJ22: 543.926 | BK22: 487.291 | BL22: 0 | BM22: 0 | BN22: 0 | BO22: 0 | BP22: 0
A23: Pre Tax Income | B23: =+SUM(B18:B22)+B14 -> 1597.537 | C23: =+SUM(C18:C22)+C14 -> 1771.516 | D23: =+SUM(D18:D22)+D14 -> 1865.244 | E23: =+SUM(E18:E22)+E14 -> 1710.844 | F23: =+SUM(F18:F22)+F14 -> 1551.176 | G23: =+SUM(G18:G22)+G14 -> 1497.365 | H23: =+SUM(H18:H22)+H14 -> 1253.369 | I23: =+SUM(I18:I22)+I14 -> 1408.865 | ... AS23: =+SUM(AS18:AS22)+AS14 -> 3101.3457 | AU23: 2800.4324 | AW23: =+SUM(AW18:AW22)+AW14 -> 3366.465 | AX23: =+SUM(AX18:AX22)+AX14 -> 3375.75 | AY23: =+SUM(AY18:AY22)+AY14 -> 4667.278 | AZ23: =+SUM(AZ18:AZ22)+AZ14 -> 4851.888 | BA23: =+SUM(BA18:BA22)+BA14 -> 4503.806 | BB23: =+SUM(BB18:BB22)+BB14 -> 3719.62 | BC23: =+SUM(BC18:BC22)+BC14 -> 3451.012 | BD23: =+SUM(BD18:BD22)+BD14 -> 4323.374 | ... CD23: =+SUM(CD18:CD22)+CD14 -> 12060.612
A24: Income Tax | B24: -487.742 | C24: -593.461 | D24: -552.43 | E24: -522.296 | F24: -466.576 | G24: -478.738 | H24: -400.115 | I24: -358.176 | J24: -518.583 | K24: -482.316 | L24: -389.329 | M24: -392.376 | N24: -535.785 | O24: -610.962 | P24: -528.639 | Q24: -638.625 | R24: -770.255 | S24: -749.806 | T24: -619.905 | U24: -652.167 | V24: -735.677 | W24: -564.139 | X24: -418.114 | Y24: -432.122 | Z24: -494.955 | AA24: -552.252 | AB24: -583.408 | AC24: -683.783 | AD24: -754.384 | AE24: -848.714 | AF24: -858.714 | AG24: -913.695 | AH24: -1003.053 | AI24: -1049.445 | AJ24: -853.702 | AK24: -802.609 | AL24: -842.274 | AM24: -828.022 | AN24: -768.573 | AO24: -621.112 | AP24: =-AP25*AP23 -> -886.90571 | AQ24: =-AQ25*AQ23 -> -962.26921 | AR24: =-AR25*AR23 -> -833.04025 | AS24: =-AS25*AS23 -> -961.41715 | AU24: -879.78892 | AW24: -1412.197 | AX24: -1492.884 | AY24: -2098.491 | AZ24: -2035.628 | BA24: -1963.351 | BB24: -1784.682 | BC24: -1590.598 | BD24: -1678.99 | BE24: -1500.179 | BF24: -1759.949 | BG24: -1214.347 | BH24: -831.338 | BI24: -1488.116 | BJ24: -1687.168 | BK24: -1483 | BL24: -1838.273 | BM24: -1990.223 | BN24: -1529.881 | BO24: -1940.202 | BP24: -2155.929 | BQ24: =+SUMIFS($B24:$AK24,$B$1:$AK$1,"="&BQ$1) -> -1703.605 | BR24: =+SUMIFS($B24:$AK24,$B$1:$AK$1,"="&BR$1) -> -1782.604 | BS24: =+SUMIFS($B24:$AK24,$B$1:$AK$1,"="&BS$1) -> -2314.011 | BT24: =+SUMIFS($B24:$AK24,$B$1:$AK$1,"="&BT$1) -> -2792.133 | BU24: =+SUMIFS($B24:$AK24,$B$1:$AK$1,"="&BU$1) -> -2150.052 | BV24: =+SUMIFS($B24:$AK24,$B$1:$AK$1,"="&BV$1) -> -2314.398 | BW24: =+SUMIFS($B24:$AK24,$B$1:$AK$1,"="&BW$1) -> -3375.507 | BX24: =+SUMIFS($B24:$AO24,$B$1:$AO$1,"="&BX$1) -> -3708.809 | BY24: =+SUMIFS($B24:$AS24,$B$1:$AS$1,"="&BY$1) -> -3059.981 | BZ24: =+SUMIFS($B24:$AS24,$B$1:$AS$1,"="&BZ$1) -> -3643.6323 | CA24: =-CA25*CA23 -> -3735.471 | CB24: =-CB25*CB23 -> -3749.176 | CC24: =-CC25*CC23 -> -3760.9794 | CD24: =-CD25*CD23 -> -3799.0927
A25: Effective Tax Rate | B25: =-B24/B23 -> 0.30530873 | C25: =-C24/C23 -> 0.33500177 | D25: =-D24/D23 -> 0.29617037 | E25: =-E24/E23 -> 0.30528558 | F25: =-F24/F23 -> 0.30078856 | G25: =-G24/G23 -> 0.31972031 | H25: =-H24/H23 -> 0.31923161 | I25: =-I24/I23 -> 0.25423018 | ... AO25: =-AO24/AO23 -> 0.22052611 | AP25: 0.31 | AQ25: =+AP25 -> 0.31 | AR25: =+AQ25 -> 0.31 | AS25: =+AR25 -> 0.31 | AU25: 0.31416181 | AW25: =-AW24/AW23 -> 0.41948958 | AX25: =-AX24/AX23 -> 0.44223772 | AY25: =-AY24/AY23 -> 0.44961774 | AZ25: =-AZ24/AZ23 -> 0.41955379 | BA25: =-BA24/BA23 -> 0.43593152 | BB25: =-BB24/BB23 -> 0.47980224 | BC25: =-BC24/BC23 -> 0.4609077 | BD25: =-BD24/BD23 -> 0.38835178 | ... BZ25: =-BZ24/BZ23 -> 0.31 | CA25: 0.315 | CB25: 0.315 | CC25: 0.315 | CD25: 0.315
A26: Minorities | B26: 0 | C26: 0 | D26: 0 | E26: 4.353 | F26: 10.317999 | G26: -5.258 | H26: 1.219 | I26: 23.854 | J26: 3.352 | K26: 1.3 | L26: 1.491 | M26: 0 | N26: -4.209 | O26: 0 | P26: -2.403 | Q26: 0 | R26: 8.125 | S26: 69.897 | T26: 35.682 | U26: 30.879 | V26: 18.644 | W26: 6.146 | X26: 4.786 | Y26: 4.554 | Z26: 0.017 | AA26: -0.81 | AB26: 0.424 | AC26: -1.217 | AD26: 0.017 | AE26: 0.017 | AF26: 0.017 | AG26: 0.017 | AH26: 0 | AI26: 0 | AJ26: 0 | AK26: 0 | AL26: 0 | AM26: 0 | AN26: 0 | AO26: 0 | AP26: 0 | AQ26: 0 | AR26: 0 | AS26: 0 | AU26: 0 | AW26: 0 | AX26: 0 | AY26: 0 | AZ26: 0 | BA26: 0 | BB26: 0 | BC26: 0 | BD26: 0 | BE26: 0 | BF26: 0 | BG26: 0 | BH26: 0 | BI26: 0 | BJ26: 0 | BK26: 0 | BL26: 0 | BM26: 0 | BN26: 0 | BO26: 0 | BP26: 4.353 | BQ26: =+SUMIFS($B26:$AK26,$B$1:$AK$1,"="&BQ$1) -> 30.132999 | BR26: =+SUMIFS($B26:$AK26,$B$1:$AK$1,"="&BR$1) -> 6.143 | BS26: =+SUMIFS($B26:$AK26,$B$1:$AK$1,"="&BS$1) -> -6.612 | BT26: =+SUMIFS($B26:$AK26,$B$1:$AK$1,"="&BT$1) -> 144.583 | BU26: =+SUMIFS($B26:$AK26,$B$1:$AK$1,"="&BU$1) -> 34.13 | BV26: =+SUMIFS($B26:$AK26,$B$1:$AK$1,"="&BV$1) -> -1.586 | BW26: =+SUMIFS($B26:$AK26,$B$1:$AK$1,"="&BW$1) -> 0.068 | BX26: =+SUMIFS($B26:$AO26,$B$1:$AO$1,"="&BX$1) -> 0 | BY26: =+SUMIFS($B26:$AS26,$B$1:$AS$1,"="&BY$1) -> 0 | BZ26: =+SUMIFS($B26:$AS26,$B$1:$AS$1,"="&BZ$1) -> 0 | CA26: 0 | CB26: 0 | CC26: 0 | CD26: 0
A27: Net Income | B27: =+B26+B24+B23 -> 1109.795 | C27: =+C26+C24+C23 -> 1178.055 | D27: =+D26+D24+D23 -> 1312.814 | E27: =+E26+E24+E23 -> 1192.901 | F27: =+F26+F24+F23 -> 1094.918 | G27: =+G26+G24+G23 -> 1013.369 | H27: =+H26+H24+H23 -> 854.473 | I27: =+I26+I24+I23 -> 1074.543 | ... AS27: =+AS26+AS24+AS23 -> 2139.9285 | AU27: 1920.6435 | AV27: =+AO27/AU27-1 -> 0.14304868 | AW27: =+AW26+AW24+AW23 -> 1954.268 | AX27: =+AX26+AX24+AX23 -> 1882.866 | AY27: =+AY26+AY24+AY23 -> 2568.787 | AZ27: =+AZ26+AZ24+AZ23 -> 2816.26 | BA27: =+BA26+BA24+BA23 -> 2540.455 | BB27: =+BB26+BB24+BB23 -> 1934.938 | BC27: =+BC26+BC24+BC23 -> 1860.414 | BD27: =+BD26+BD24+BD23 -> 2644.384 | ... CD27: =+CD26+CD24+CD23 -> 8261.5191
A28: NI Margin | B28: =+B27/B3 -> 0.1271488 | C28: =+C27/C3 -> 0.13339462 | D28: =+D27/D3 -> 0.15056144 | E28: =+E27/E3 -> 0.12715911 | F28: =+F27/F3 -> 0.11488559 | G28: =+G27/G3 -> 0.10549438 | H28: =+H27/H3 -> 0.09290518 | I28: =+I27/I3 -> 0.11392419 | ... AS28: =+AS27/AS3 -> 0.14850946 | AU28: 0.13741397 | AW28: =+AW27/AW3 -> 0.18963396 | AX28: =+AX27/AX3 -> 0.15320651 | AY28: =+AY27/AY3 -> 0.18522829 | AZ28: =+AZ27/AZ3 -> 0.17705229 | BA28: =+BA27/BA3 -> 0.16249599 | BB28: =+BB27/BB3 -> 0.12021205 | BC28: =+BC27/BC3 -> 0.10879507 | BD28: =+BD27/BD3 -> 0.13356211 | ... CD28: =+CD27/CD3 -> 0.1346428
A30: Total Shares | B30: 3091.6731 | C30: 3088.444 | D30: 3088.054 | E30: 3087.974 | F30: 3084.932 | G30: 3084.932 | H30: 3084.932 | I30: 3084.932 | J30: 3084.932 | K30: 3084.932 | L30: 3084.932 | M30: 3084.932 | N30: 3084.932 | O30: 3084.932 | P30: 3084.932 | Q30: 3084.932 | R30: 3084.932 | S30: 3084.932 | T30: 3084.932 | U30: 3084.932 | V30: 3084.932 | W30: 3084.932 | X30: 3084.932 | Y30: 3084.932 | Z30: 3084.932 | AA30: 3084.932 | AB30: 3084.932 | AC30: 3075.1326 | AD30: 3075.1326 | AE30: 3075.1326 | AF30: 3075.1326 | AG30: 3075.1326 | AH30: 3075.1326 | AI30: 3075.1326 | AJ30: 3056.7271 | AK30: =3043.57741 -> 3043.5774 | AL30: 3038.0789 | AM30: 3026.384 | AN30: 3010.7094 | AO30: 3000.8487 | AP30: =+AO30+AP111 -> 2984.7196 | AQ30: =+AP30+AQ111 -> 2968.5906 | AR30: =+AQ30+AR111 -> 2952.4616 | AS30: =+AR30+AS111 -> 2936.3325 | AU30: 2994.5804 | AW30: 1127.635 | AX30: 1171.767 | AY30: 1189.518 | AZ30: 1257.505 | BA30: 1231.187 | BB30: 1204.017 | BC30: 1187.222 | BD30: 1169.583 | BE30: 1157.004 | BF30: 1139.845 | BG30: 1118.155 | BH30: 1098.846 | BI30: 1076.998 | BJ30: 1061.674 | BK30: 3154.6461 | BL30: 3141.2595 | BM30: 3127.3495 | BN30: 3099.0909 | BO30: 3095.5284 | BP30: =+SUMIFS($B30:$AK30,$B$2:$AK$2,"="&BP$2) -> 3087.974 | BQ30: =+SUMIFS($B30:$AK30,$B$2:$AK$2,"="&BQ$2) -> 3084.932 | BR30: =+SUMIFS($B30:$AK30,$B$2:$AK$2,"="&BR$2) -> 3084.932 | BS30: =+SUMIFS($B30:$AK30,$B$2:$AK$2,"="&BS$2) -> 3084.932 | BT30: =+SUMIFS($B30:$AK30,$B$2:$AK$2,"="&BT$2) -> 3084.932 | BU30: =+SUMIFS($B30:$AK30,$B$2:$AK$2,"="&BU$2) -> 3084.932 | BV30: =+SUMIFS($B30:$AK30,$B$2:$AK$2,"="&BV$2) -> 3075.1326 | BW30: =+SUMIFS($B30:$AK30,$B$2:$AK$2,"="&BW$2) -> 3075.1326 | BX30: =+SUMIFS($B30:$AO30,$B$2:$AO$2,"="&BX$2) -> 3043.5774 | BY30: =+SUMIFS($B30:$AS30,$B$2:$AS$2,"="&BY$2) -> 3000.8487 | BZ30: =+SUMIFS($B30:$AS30,$B$2:$AS$2,"="&BZ$2) -> 2936.3325 | CA30: =+BZ30+CA111 -> 2936.3325 | CB30: =+CA30+CB111 -> 2936.3325 | CC30: =+CB30+CC111 -> 2936.3325 | CD30: =+CC30+CD111 -> 2936.3325
A31: EPS | B31: =B27/B30 -> 0.3589626 | C31: =C27/C30 -> 0.38143965 | D31: =D27/D30 -> 0.42512663 | E31: =E27/E30 -> 0.38630539 | F31: =F27/F30 -> 0.35492452 | G31: =G27/G30 -> 0.3284899 | H31: =H27/H30 -> 0.27698277 | I31: =I27/I30 -> 0.34831983 | ... AS31: =AS27/AS30 -> 0.72877594 | AU31: 0.64137315 | AW31: =AW27/AW30 -> 1.7330679 | AX31: =AX27/AX30 -> 1.6068604 | AY31: =AY27/AY30 -> 2.1595192 | AZ31: =AZ27/AZ30 -> 2.2395617 | BA31: =BA27/BA30 -> 2.0634193 | BB31: =BB27/BB30 -> 1.6070687 | BC31: =BC27/BC30 -> 1.5670313 | BD31: =BD27/BD30 -> 2.2609631 | ... CD31: =CD27/CD30 -> 2.8135502
A32: DPS | B32: =-B113/B30 -> 0 | C32: =-C113/C30 -> 0.38059683 | D32: =-D113/D30 -> -0.3806449 | E32: =-E113/E30 -> 1.8597245 | F32: =-F113/F30 -> 1.8615584 | G32: =-G113/G30 -> 0 | H32: =-H113/H30 -> 0 | I32: =-I113/I30 -> 0 | ... AS32: =-AS113/AS30 -> 1.1529283 | AU32: 1.041434 | AW32: =-AW113/AW30 -> 1.1716007 | AX32: =-AX113/AX30 -> 1.9499346 | AY32: =-AY113/AY30 -> 1.5176139 | AZ32: =-AZ113/AZ30 -> 1.6052922 | BA32: =-BA113/BA30 -> 1.7859383 | BB32: =-BB113/BB30 -> 1.9381346 | BC32: =-BC113/BC30 -> 1.9775577 | BD32: =-BD113/BD30 -> 2.0665203 | ... CD32: =-CD113/CD30 -> 2.2282593
A33: Revenue Growth | C33: =C3/B3-1 -> 0.011804796 | D33: =D3/C3-1 -> -0.012670312 | E33: =E3/D3-1 -> 0.075889015 | F33: =F3/E3-1 -> 0.015919126 | G33: =G3/F3-1 -> 0.0079111208 | H33: =H3/G3-1 -> -0.042541124 | I33: =I3/H3-1 -> 0.025532498 | J33: =J3/I3-1 -> 0.082185196 | ... AS33: =AS3/AR3-1 -> 0.048316704 | AU33: 0.04228647 | AW33: =AW3/A3-1 -> #VALUE! | AX33: =AX3/AW3-1 -> 0.19254338 | AY33: =AY3/AX3-1 -> 0.12844029 | AZ33: =AZ3/AY3-1 -> 0.14696563 | BA33: =BA3/AZ3-1 -> -0.017126405 | BB33: =BB3/BA3-1 -> 0.029556501 | BC33: =BC3/BB3-1 -> 0.062383605 | BD33: =BD3/BC3-1 -> 0.15781949 | BE33: =BE3/BD3-1 -> 0.11031946 | ... CD33: =CD3/CC3-1 -> 0.02
A34: EBITDA Growth | C34: =C16/B16-1 -> -0.040076708 | D34: =D16/C16-1 -> 0.04156602 | E34: =E16/D16-1 -> -0.047190869 | F34: =F16/E16-1 -> -0.033307375 | G34: =G16/F16-1 -> -0.023046687 | H34: =H16/G16-1 -> -0.12580112 | I34: =I16/H16-1 -> 0.12280526 | J34: =J16/I16-1 -> 0.12220541 | ... AS34: =AS16/AR16-1 -> 0.12092385 | AU34: 0.09469353 | AW34: =AW16/A16-1 -> #VALUE! | AX34: =AX16/AW16-1 -> 0.26585213 | AY34: =AY16/AX16-1 -> 0.19820959 | AZ34: =AZ16/AY16-1 -> 0.098549533 | BA34: =BA16/AZ16-1 -> -0.017998109 | BB34: =BB16/BA16-1 -> -0.0052110473 | BC34: =BC16/BB16-1 -> -0.024089369 | BD34: =BD16/BC16-1 -> 0.073805822 | BE34: =BE16/BD16-1 -> 0.096550325 | ... CD34: =CD16/CC16-1 -> 0.0003621052
A35: EPS Growth | C35: =C31/B31-1 -> 0.062616698 | D35: =D31/C31-1 -> 0.11453183 | E35: =E31/D31-1 -> -0.091316893 | F35: =F31/E31-1 -> -0.08123333 | G35: =G31/F31-1 -> -0.074479549 | H35: =H31/G31-1 -> -0.15679974 | I35: =I31/H31-1 -> 0.25755056 | J35: =J31/I31-1 -> 0.1229546 | ... AS35: =AS31/AR31-1 -> 0.16044589 | AU35: 0.1508699 | AW35: =AW31/A31-1 -> #VALUE! | AX35: =AX31/AW31-1 -> -0.072823156 | AY35: =AY31/AX31-1 -> 0.34393705 | AZ35: =AZ31/AY31-1 -> 0.037064934 | BA35: =BA31/AZ31-1 -> -0.078650384 | BB35: =BB31/BA31-1 -> -0.22116233 | BC35: =BC31/BB31-1 -> -0.02491331 | BD35: =BD31/BC31-1 -> 0.44283215 | BE35: =BE31/BD31-1 -> -0.028042788 | ... CD35: =CD31/CC31-1 -> 0.010133884
A37: ROE (%) | B37: =B27/AVERAGE(B88:B88) -> 0.36776931 | C37: =C27/AVERAGE(B88:C88) -> 0.31821268 | D37: =D27/AVERAGE(C88:D88) -> 0.25940299 | E37: =E27/AVERAGE(D88:E88) -> 0.18734913 | F37: =F27/AVERAGE(E88:F88) -> 0.21997739 | G37: =G27/AVERAGE(F88:G88) -> 0.28966733 | H37: =H27/AVERAGE(G88:H88) -> 0.1929575 | I37: =I27/AVERAGE(H88:I88) -> 0.19706328 | J37: =J27/AVERAGE(I88:J88) -> 0.29373258 | ... AS37: =AS27/AVERAGE(AR88:AS88) -> 0.23256559 | AU37: 0.40753742 | AW37: =AW27/AVERAGE(A88:AW88) -> 0.39921364 | AX37: =AX27/AVERAGE(AW88:AX88) -> 0.1641115 | AY37: =AY27/AVERAGE(AX88:AY88) -> 0.20602107 | AZ37: =AZ27/AVERAGE(AY88:AZ88) -> 0.23367838 | BA37: =BA27/AVERAGE(AZ88:BA88) -> 0.22181158 | BB37: =BB27/AVERAGE(BA88:BB88) -> 0.16608727 | BC37: =BC27/AVERAGE(BB88:BC88) -> 0.15668538 | BD37: =BD27/AVERAGE(BC88:BD88) -> 0.2172932 | BE37: =BE27/AVERAGE(BD88:BE88) -> 0.20937826 | ... CD37: =CD27/AVERAGE(CC88:CD88) -> 0.57436177
A38: ROA (%) | B38: =B27/AVERAGE(B73:B73) -> 0.029197685 | C38: =C27/AVERAGE(B73:C73) -> 0.031933413 | D38: =D27/AVERAGE(C73:D73) -> 0.0346884 | E38: =E27/AVERAGE(D73:E73) -> 0.029593851 | F38: =F27/AVERAGE(E73:F73) -> 0.027117264 | G38: =G27/AVERAGE(F73:G73) -> 0.025496112 | H38: =H27/AVERAGE(G73:H73) -> 0.021892361 | I38: =I27/AVERAGE(H73:I73) -> 0.027564662 | J38: =J27/AVERAGE(I73:J73) -> 0.030418164 | ... AS38: =AS27/AVERAGE(AR73:AS73) -> 0.044933977 | AU38: 0.043019571 | AW38: =AW27/AVERAGE(A73:AW73) -> 0.041931177 | AX38: =AX27/AVERAGE(AW73:AX73) -> 0.11481985 | AY38: =AY27/AVERAGE(AX73:AY73) -> 0.13723274 | AZ38: =AZ27/AVERAGE(AY73:AZ73) -> 0.13876788 | BA38: =BA27/AVERAGE(AZ73:BA73) -> 0.11861909 | BB38: =BB27/AVERAGE(BA73:BB73) -> 0.086120571 | BC38: =BC27/AVERAGE(BB73:BC73) -> 0.078842084 | BD38: =BD27/AVERAGE(BC73:BD73) -> 0.10659175 | BE38: =BE27/AVERAGE(BD73:BE73) -> 0.1011541 | ... CD38: =CD27/AVERAGE(CC73:CD73) -> 0.15839218
A39: ROIC (%) | BT39: =+Resumo!G37/AVERAGE(PROJ!BS94:BT94) -> 0.47247207 | BU39: =+Resumo!H37/AVERAGE(PROJ!BT94:BU94) -> 0.35620917 | BV39: =+Resumo!I37/AVERAGE(PROJ!BU94:BV94) -> 0.36687444 | BW39: =+Resumo!J37/AVERAGE(PROJ!BV94:BW94) -> 0.49119914 | BX39: =+Resumo!K37/AVERAGE(PROJ!BW94:BX94) -> 0.52447156 | BY39: =+Resumo!L37/AVERAGE(PROJ!BX94:BY94) -> 0.48755109 | BZ39: =+Resumo!M37/AVERAGE(PROJ!BY94:BZ94) -> 0.49312107 | CA39: =+Resumo!N37/AVERAGE(PROJ!BZ94:CA94) -> 0.48915849 | ... CD39: =+Resumo!Q37/AVERAGE(PROJ!CC94:CD94) -> 0.48838835
A41: Net Debt/EBITDA | B41: =B146 -> 0.99237702 | C41: =C146 -> 1.2848131 | D41: =D146 -> 1.3820963 | E41: =E146 -> 1.6879789 | F41: =F146 -> 1.6186801 | G41: =G146 -> 1.7865752 | H41: =H146 -> 2.0913983 | I41: =I146 -> 2.145173 | ... AS41: =AS146 -> 0.9135595 | AU41: 1.1460194 | AW41: =AW146 -> 0.014071559 | AX41: =AX146 -> 0.19053289 | AY41: =AY146 -> 0.19369545 | AZ41: =AZ146 -> 0.33805965 | BA41: =BA146 -> 0.50429583 | BB41: =BB146 -> 0.6093722 | BC41: =BC146 -> 0.77084831 | BD41: =BD146 -> 0.62504189 | ... CD41: =CD146 -> 0.5081647
A42: BVPS | B42: =B88/B30 -> 0.97605372 | C42: =C88/C30 -> 1.4203139 | D42: =D88/D30 -> 1.8572379 | E42: =E88/E30 -> 2.266623 | F42: =F88/F30 -> 0.95806002 | G42: =G88/G30 -> 1.3099893 | H42: =H88/H30 -> 1.5609307 | I42: =I88/I30 -> 1.9741758 | ... AS42: =AS88/AS30 -> 2.9215599 | AU42: 1.3737469 | AW42: =AW88/AW30 -> 9.5411654 | AX42: =AX88/AX30 -> 10.400726 | AY42: =AY88/AY30 -> 10.718544 | AZ42: =AZ88/AZ30 -> 9.0288524 | BA42: =BA88/BA30 -> 9.3833 | BB42: =BB88/BB30 -> 9.7570549 | BC42: =BC88/BC30 -> 10.107183 | BD42: =BD88/BD30 -> 10.550638 | ... CD42: =CD88/CD30 -> 5.1912136
A43: Net Margin (%) | B43: =B27/B3 -> 0.1271488 | C43: =C27/C3 -> 0.13339462 | D43: =D27/D3 -> 0.15056144 | E43: =E27/E3 -> 0.12715911 | F43: =F27/F3 -> 0.11488559 | G43: =G27/G3 -> 0.10549438 | H43: =H27/H3 -> 0.09290518 | I43: =I27/I3 -> 0.11392419 | ... AS43: =AS27/AS3 -> 0.14850946 | AU43: 0.13741397 | AW43: =AW27/AW3 -> 0.18963396 | AX43: =AX27/AX3 -> 0.15320651 | AY43: =AY27/AY3 -> 0.18522829 | AZ43: =AZ27/AZ3 -> 0.17705229 | BA43: =BA27/BA3 -> 0.16249599 | BB43: =BB27/BB3 -> 0.12021205 | BC43: =BC27/BC3 -> 0.10879507 | BD43: =BD27/BD3 -> 0.13356211 | ... CD43: =CD27/CD3 -> 0.1346428
...

Sheet FAT
A1: Economic Forecasts | B1: 42460 | C1: =+EOMONTH(B1,3) -> 42551 | D1: =+EOMONTH(C1,3) -> 42643 | E1: =+EOMONTH(D1,3) -> 42735 | F1: =+EOMONTH(E1,3) -> 42825 | G1: =+EOMONTH(F1,3) -> 42916 | H1: =+EOMONTH(G1,3) -> 43008 | I1: =+EOMONTH(H1,3) -> 43100 | J1: =+EOMONTH(I1,3) -> 43190 | ... AB1: =+EOMONTH(AA1,3) -> 44834 | AC1: 44925 | AD1: =+EOMONTH(AC1,3) -> 45016 | AE1: =+EOMONTH(AD1,3) -> 45107 | AF1: =+EOMONTH(AE1,3) -> 45199 | AG1: =+EOMONTH(AF1,3) -> 45291 | AH1: =+EOMONTH(AG1,3) -> 45382 | AI1: =+EOMONTH(AH1,3) -> 45473 | AJ1: =+EOMONTH(AI1,3) -> 45565 | AK1: =+EOMONTH(AJ1,3) -> 45657 | ... AS1: =+EOMONTH(AR1,3) -> 46387 | AU1: 46022 | AW1: 35795 | AX1: =+EOMONTH(AW1,12) -> 36160 | AY1: =+EOMONTH(AX1,12) -> 36525 | AZ1: =+EOMONTH(AY1,12) -> 36891 | BA1: =+EOMONTH(AZ1,12) -> 37256 | BB1: =+EOMONTH(BA1,12) -> 37621 | BC1: =+EOMONTH(BB1,12) -> 37986 | BD1: =+EOMONTH(BC1,12) -> 38352 | BE1: =+EOMONTH(BD1,12) -> 38717 | ... CD1: =+EOMONTH(CC1,12) -> 47848
A2: MXN - eop | B2: =+macro!AD42 -> 17.2793 | C2: =+macro!AE42 -> 18.4684 | D2: =+macro!AF42 -> 19.3852 | E2: =+macro!AG42 -> 20.7272 | F2: =+macro!AH42 -> 18.7249 | G2: =+macro!AI42 -> 18.1203 | H2: =+macro!AJ42 -> 18.2545 | I2: =+macro!AK42 -> 19.659 | ... AS2: =+macro!BU42 -> 18.141521 | AU2: 18.008 | AW2: 8.055 | AX2: 9.897 | AY2: 9.505 | AZ2: 9.6225 | BA2: 9.1575 | BB2: 10.37 | BC2: 11.22 | BD2: 11.14 | BE2: 10.635 | BF2: 10.8033 | BG2: 10.8988 | BH2: 13.6733 | BI2: 13.0914 | BJ2: 12.34 | BK2: =+macro!CY42 -> 13.9357 | BL2: =+macro!CZ42 -> 12.9251 | BM2: =+macro!DA42 -> 13.0954 | BN2: =+macro!DB42 -> 14.7472 | BO2: =+macro!DC42 -> 17.2075 | BP2: =+macro!DD42 -> 20.7272 | BQ2: =+macro!DE42 -> 19.659 | BR2: =+macro!DF42 -> 19.6504 | ... CD2: =+macro!DR42 -> 19.232441
A3: Average | B3: =+macro!AD9 -> 18.0272 | C3: =+macro!AE9 -> 18.1073 | D3: =+macro!AF9 -> 18.7626 | E3: =+macro!AG9 -> 19.8451 | F3: =+macro!AH9 -> 20.29942 | G3: =+macro!AI9 -> 18.548848 | H3: =+macro!AJ9 -> 17.818892 | I3: =+macro!AK9 -> 18.986402 | ... AS3: =+macro!BU9 -> 18.032352 | AU3: 18.301782 | AX3: =+AVERAGE(AW2:AX2) -> 8.976 | AY3: =+AVERAGE(AX2:AY2) -> 9.701 | AZ3: =+AVERAGE(AY2:AZ2) -> 9.56375 | BA3: =+AVERAGE(AZ2:BA2) -> 9.39 | BB3: =+AVERAGE(BA2:BB2) -> 9.76375 | BC3: =+AVERAGE(BB2:BC2) -> 10.795 | BD3: =+AVERAGE(BC2:BD2) -> 11.18 | BE3: =+AVERAGE(BD2:BE2) -> 10.8875 | ... CD3: =+AVERAGE(CC2:CD2) -> 19.093076
A4: Chg YoY | F4: =F3/B3-1 -> 0.12604398 | G4: =G3/C3-1 -> 0.024385065 | H4: =H3/D3-1 -> -0.050297277 | I4: =I3/E3-1 -> -0.04327005 | J4: =J3/F3-1 -> -0.077888294 | K4: =K3/G3-1 -> 0.04672063 | L4: =L3/H3-1 -> 0.063037675 | M4: =M3/I3-1 -> 0.044815167 | ... AS4: =AS3/AO3-1 -> -0.014721528 | AU4: -0.088756907 | AX4: =AX3/AW3-1 -> #DIV/0! | AY4: =AY3/AX3-1 -> 0.080770945 | AZ4: =AZ3/AY3-1 -> -0.014148026 | BA4: =BA3/AZ3-1 -> -0.01816756 | BB4: =BB3/BA3-1 -> 0.039802982 | BC4: =BC3/BB3-1 -> 0.10562028 | BD4: =BD3/BC3-1 -> 0.03566466 | BE4: =BE3/BD3-1 -> -0.026162791 | ... CD4: =CD3/CC3-1 -> 0.014705882
A5: Chg QoQ | C5: =C3/B3-1 -> 0.0044432857 | D5: =D3/C3-1 -> 0.036189824 | E5: =E3/D3-1 -> 0.057694563 | F5: =F3/E3-1 -> 0.022893309 | G5: =G3/F3-1 -> -0.086237553 | H5: =H3/G3-1 -> -0.039353139 | I5: =I3/H3-1 -> 0.065520865 | J5: =J3/I3-1 -> -0.014118985 | ... AS5: =AS3/AR3-1 -> 0.0053818641 | AU5: -0.017528951
A6: Inflation YoY | B6: =+macro!AD83 -> 0.026010291 | C6: =+macro!AE83 -> 0.02537965 | D6: =+macro!AF83 -> 0.029689216 | E6: =+macro!AG83 -> 0.033602555 | F6: =+macro!AH83 -> 0.053525748 | G6: =+macro!AI83 -> 0.063136447 | H6: =+macro!AJ83 -> 0.063478818 | I6: =+macro!AK83 -> 0.067731071 | ... AS6: =+macro!BU83 -> 0.035 | AU6: 0.036919441 | BE6: 0.04 | BF6: 0.0363 | BG6: 0.0397 | BH6: 0.0512 | BI6: 0.0531 | BJ6: 0.0416 | BK6: 0.0341 | BL6: =+macro!CZ83 -> 0.035682149 | BM6: =+macro!DA83 -> 0.039741486 | BN6: =+macro!DB83 -> 0.040812891 | BO6: =+macro!DC83 -> 0.021307734 | BP6: =+macro!DD83 -> 0.033602555 | BQ6: =+macro!DE83 -> 0.067731071 | BR6: =+macro!DF83 -> 0.04830528 | BS6: =+macro!DG83 -> 0.02828577 | ... CD6: =+macro!DR83 -> 0.035
A7: US Inflation | B7: =+macro!AD76 -> 0.008916161 | C7: =+macro!AE76 -> 0.010792865 | D7: =+macro!AF76 -> 0.015486446 | E7: =+macro!AG76 -> 0.020507989 | F7: =+macro!AH76 -> 0.024411962 | G7: =+macro!AI76 -> 0.016405658 | H7: =+macro!AJ76 -> 0.021805652 | I7: =+macro!AK76 -> 0.021299307 | ... AS7: =+macro!BU76 -> 0.0268 | AU7: 0.023387688 | BH7: -0.0145 | BI7: 0.0009 | BJ7: 0.0163 | BK7: 0.0317 | BL7: =+macro!CZ76 -> 0.01759505 | BM7: =+macro!DA76 -> 0.015128384 | BN7: =+macro!DB76 -> 0.0065312139 | BO7: =+macro!DC76 -> 0.0063872475 | BP7: =+macro!DD76 -> 0.020507989 | BQ7: =+macro!DE76 -> 0.021299307 | BR7: =+macro!DF76 -> 0.020023809 | BS7: =+macro!DG76 -> 0.023195275 | ... CD7: =+macro!DR76 -> 0.02
A8: Assumptions | B8: =+B1 -> 42460 | C8: =+C1 -> 42551 | D8: =+D1 -> 42643 | E8: =+E1 -> 42735 | F8: =+F1 -> 42825 | G8: =+G1 -> 42916 | H8: =+H1 -> 43008 | I8: =+I1 -> 43100 | ... AS8: =+AS1 -> 46387 | AU8: 46022 | AW8: =+AW$1 -> 35795 | AX8: =+AX$1 -> 36160 | AY8: =+AY$1 -> 36525 | AZ8: =+AZ$1 -> 36891 | BA8: =+BA$1 -> 37256 | BB8: =+BB$1 -> 37621 | BC8: =+BC$1 -> 37986 | BD8: =+BD$1 -> 38352 | ... CD8: =+CD$1 -> 47848
B9: 3 | C9: =+B9+3 -> 6 | D9: =+C9+3 -> 9 | E9: =+D9+3 -> 12 | F9: =+E9+3 -> 15 | G9: =+F9+3 -> 18 | H9: =+G9+3 -> 21 | I9: =+H9+3 -> 24 | J9: =+I9+3 -> 27 | ... AS9: =+AR9+3 -> 132 | AU9: 120
BZ10: =+BZ11/BV11-1 -> 0.11029621
A11: Revenues (MXN) | B11: =+PROJ!B3 -> 8728.317 | C11: =+PROJ!C3 -> 8831.353 | D11: =+PROJ!D3 -> 8719.457 | E11: =+PROJ!E3 -> 9381.168 | F11: =+PROJ!F3 -> 9530.508 | G11: =+PROJ!G3 -> 9605.905 | H11: =+PROJ!H3 -> 9197.259 | I11: =+PROJ!I3 -> 9432.088 | ... AO11: =+PROJ!AO3 -> 14057.927 | AP11: =+AL11*(1+AP12) -> 14109.66 | AQ11: =+AM11*(1+AQ12) -> 14421.75 | AR11: =+AN11*(1+AR12) -> 13745.25 | AS11: =+AO11*(1+AS12) -> 14409.375 | AU11: 13977.062 | AW11: =+PROJ!AW3 -> 10305.475 | AX11: =+PROJ!AX3 -> 12289.726 | AY11: =+PROJ!AY3 -> 13868.222 | AZ11: =+PROJ!AZ3 -> 15906.374 | BA11: =+PROJ!BA3 -> 15633.955 | BB11: =+PROJ!BB3 -> 16096.04 | BC11: =+PROJ!BC3 -> 17100.169 | BD11: =+PROJ!BD3 -> 19798.909 | ... BU11: =+PROJ!BU3 -> 46893.963 | BV11: =+SUMIFS($A11:$AO11,$A$1:$AO$1,"<="&BV$1,$A$1:$AO$1,">"&BU$1) -> 51054.876 | BW11: =+SUMIFS($A11:$AO11,$A$1:$AO$1,"<="&BW$1,$A$1:$AO$1,">"&BV$1) -> 53307.054 | BX11: =+SUMIFS($A11:$AO11,$A$1:$AO$1,"<="&BX$1,$A$1:$AO$1,">"&BW$1) -> 54782.717 | BY11: =+SUMIFS($A11:$AS11,$A$1:$AS$1,"<="&BY$1,$A$1:$AS$1,">"&BX$1) -> 55370.927 | BZ11: =+SUMIFS($A11:$AS11,$A$1:$AS$1,"<="&BZ$1,$A$1:$AS$1,">"&BY$1) -> 56686.035 | CA11: =+BZ11*(1+CA12) -> 57819.756 | CB11: =+CA11*(1+CB12) -> 58976.151 | CC11: =+CB11*(1+CC12) -> 60155.674 | CD11: =+CC11*(1+CD12) -> 61358.787
A12: Chg YoY | F12: =F11/B11-1 -> 0.091906722 | G12: =G11/C11-1 -> 0.087704794 | H12: =H11/D11-1 -> 0.05479722 | I12: =I11/E11-1 -> 0.0054278955 | J12: =J11/F11-1 -> 0.071009646 | K12: =K11/G11-1 -> 0.10230093 | L12: =L11/H11-1 -> 0.076081472 | M12: =M11/I11-1 -> 0.095621669 | ... AO12: =AO11/AK11-1 -> 0.020872366 | AP12: =+AP19 -> 0.02 | AQ12: =+AQ19 -> 0.025 | AR12: =+AR19 -> 0.025 | AS12: =+AS19 -> 0.025 | AU12: 0.015 | AX12: =AX11/AW11-1 -> 0.19254338 | AY12: =AY11/AX11-1 -> 0.12844029 | AZ12: =AZ11/AY11-1 -> 0.14696563 | BA12: =BA11/AZ11-1 -> -0.017126405 | BB12: =BB11/BA11-1 -> 0.029556501 | BC12: =BC11/BB11-1 -> 0.062383605 | BD12: =BD11/BC11-1 -> 0.15781949 | BE12: =BE11/BD11-1 -> 0.11031946 | ... BZ12: =BZ11/BY11-1 -> 0.023750879 | CA12: =+CA19 -> 0.02 | CB12: =+CB19 -> 0.02 | CC12: =+CC19 -> 0.02 | CD12: =+CD19 -> 0.02
A13: Chg QoQ | C13: =C11/B11-1 -> 0.011804796 | D13: =D11/C11-1 -> -0.012670312 | E13: =E11/D11-1 -> 0.075889015 | F13: =F11/E11-1 -> 0.015919126 | G13: =G11/F11-1 -> 0.0079111208 | H13: =H11/G11-1 -> -0.042541124 | I13: =I11/H11-1 -> 0.025532498 | J13: =J11/I11-1 -> 0.082185196 | ... AS13: =AS11/AR11-1 -> 0.048316704 | AU13: 0.04228647
