Workbook
Name Celulose: #REF!
Name Class: #REF!
Name DivLiq: #REF!
Name ebitda03: #REF!
Name ebitda04: #REF!
Name ebitda05: #REF!
Name Economics: #REF!
Name IQ_CH: 110000
Name IQ_CQ: 5000
Name IQ_CY: 10000
Name IQ_DAILY: 500000
Name IQ_FH: 100000
Name IQ_FQ: 500
Name IQ_FY: 1000
Name IQ_LTM: 2000
Name IQ_MONTH: 15000
Name IQ_NTM: 6000
Name IQ_WEEK: 50000
Name IQ_YTD: 3000
Name lucro03: #REF!
Name lucro04: #REF!
Name lucro05: #REF!
Name MercadoInterno: #REF!
Name MgBruta: #REF!
Name MgEbitda: #REF!
Name multSecurities_L: #REF!
Name Nacoes: #REF!
Name ROIC: #REF!
Name target: #REF!
Name ticker: OFFSET(#REF!,1,0,COUNTA(#REF!)-1,1)

Sheet VP
B1: FATOR | C1: HOJE | D1: PROJ | E1: DIAS | M1: Preço Gmat3 | N1: {=+_FV(H4,"Price")} -> 15.6 | P1: Cagr | Q1: =+((Resumo!Z22/Resumo!U22)^(1/5))-1 -> 0.12646648
B2: =(1+WACC!I3)^(VP!E2/360) -> 1.118457 | C2: =+TODAY() -> 46105 | D2: 46387 | E2: =+DAYS360(C2,D2) -> 277 | H2: CARLA SSFEIR | J2: 55 51 2121 7006 | M2: Mkt Cap | N2: {=+_FV(H4,"Market cap",TRUE)/1000} -> 15706782
C3: FCF | M3: LL 26 | N3: =+Resumo!V22 -> 1334463.9
B4: Soma dos FCF | C4: =+SUM(WACC!I18:M18) -> 5101703.4 | D4: GR% | H4: #VALUE! | M4: P/E 2026 hj | N4: =+N2/N3 -> 11.770106
B5: (+) Perpetuidade | C5: =C30 -> 11102616 | D5: =+I10 -> 0.0825 | M5: Upside | N5: =+N7/N4-1 -> -0.39150761
B6: EV | C6: =+C4+C5 -> 16204320 | I6: LREN
B7: (-) Total Debt | C7: =PROJ!DQ142 -> 373879 | H7: ROE1 | I7: 0.155 | M7: P/E tgt | N7: =+N9*N27+Q9*Q27 -> 7.1620199
B8: (+) Caixa | C8: =PROJ!DQ140 -> 844610 | D8: =+C8-C7 -> 470731 | H8: ROE2 | I8: 0.15
B9: (+) VP Outros Ativos Fin Líquidos | C9: =PROJ!DI141 -> 0 | H9: G1 | I9: =+Resumo!AA22 -> 0.13180825 | M9: Lula | N9: 0.8 | P9: Tarcísio | Q9: =1-N9 -> 0.2
B10: (+) Investimentos | C10: 0 | H10: G2 | I10: =+I15+I14+I16 -> 0.0825
B11: (+) Outros Ativos Não Oper. | C11: 0 | H11: Ke | I11: =+(I17+I14)+(I19*I18) -> 0.1425 | M11: Gmat3 | P11: Gmat3
B12: (-) Opções | C12: 0 | H12: N (moat) | I12: 5 | M12: ROE1 | N12: =+I7 -> 0.155 | P12: ROE1 | Q12: =+N12 -> 0.155
B13: (+) Ajuste Dividendos | C13: =+PROJ!DQ197 -> 783920.48 | M13: ROE2 | N13: =+I8 -> 0.15 | P13: ROE2 | Q13: =+N13 -> 0.15
B14: (-) Minoritários | C14: =PROJ!DG195 -> 0 | H14: INFL | I14: =+MACRO!EJ8 -> 0.0475 | M14: G1 | N14: =+Q1 -> 0.12646648 | P14: G1 | Q14: =+N14 -> 0.12646648
B15: Valor de Mercado Proj | C15: =+C6-C7+C8+C9+C10+C11-C12+C13-C14 -> 17458971 | H15: GDP Perp | I15: 0.015 | M15: G2 | N15: =+N19+N20+N21 -> 0.07 | P15: G2 | Q15: =+Q19+Q20+Q21 -> 0.075
B16: Num Ações | C16: {=+_FV(H4,"Shares outstanding",TRUE)/1000} -> 1006845 | H16: Aj. G2 | I16: 0.02 | M16: Ke | N16: =+(N22+N19)+(N24*N23) -> 0.16 | P16: Ke | Q16: =+(Q22+Q19)+(Q24*Q23) -> 0.13
B17: Cot R$ DEZ/2026PROJ | C17: =+C15/C16 -> 17.340277 | H17: BNTNB | I17: 0.06 | M17: N (moat) | N17: =+I12 -> 5 | P17: N (moat) | Q17: =+N17 -> 5
B18: Cot R$ HOJE PROJ | C18: =C17/B2 -> 15.503749 | H18: ERP | I18: 0.035
B19: Cot R$ 12m | C19: =+C18*(1+WACC!I3) -> 17.931816 | H19: Beta | I19: =+WACC!$I$13 -> 1 | M19: INFL | N19: 0.045 | P19: INFL | Q19: 0.04
B20: Cot R$ HJ | C20: {=+_FV(H4,"Price")} -> 15.6 | M20: GDP Perp | N20: 0.025 | P20: GDP Perp | Q20: 0.035
B21: var% 12m | C21: =+C18/C20-1 -> -0.0061699526 | H21: P/E Target | I21: =+(((1-I9/I7)*(1+I9)*(1-(((1+I9)^I12)/((1+I11)^I12))))/(I11-I9))+(((1-I10/I8)*((1+I9)^I12)*(1+I10))/((I11-I10)*((1+I11)^I12))) -> 8.4732872 | M21: Aj. G2 | N21: 0 | P21: Aj. G2 | Q21: =+N21 -> 0
H22: vs 2025 | I22: =+I21/Resumo!U66-1 -> -0.25185779 | M22: BNTNB | N22: 0.07 | P22: BNTNB | Q22: 0.045
M23: ERP | N23: 0.045 | P23: ERP | Q23: =+N23 -> 0.045
B24: Valor de Mercado hj | C24: =C16*C20 -> 15706782 | M24: Beta | N24: =+I19 -> 1 | P24: Beta | Q24: =+N24 -> 1
B26: Noplat 2030 | C26: =PROJ!DU50 -> 2275634.5
B27: ROIC | C27: 0.2 | M27: P/E Target 2026 | N27: =+(((1-N14/N12)*(1+N14)*(1-(((1+N14)^N17)/((1+N16)^N17))))/(N16-N14))+(((1-N15/N13)*((1+N14)^N17)*(1+N15))/((N16-N15)*((1+N16)^N17))) -> 6.3193448 | P27: P/E Target 2026 | Q27: =+(((1-Q14/Q12)*(1+Q14)*(1-(((1+Q14)^Q17)/((1+Q16)^Q17))))/(Q16-Q14))+(((1-Q15/Q13)*((1+Q14)^Q17)*(1+Q15))/((Q16-Q15)*((1+Q16)^Q17))) -> 10.53272
B28: G | C28: =D5 -> 0.0825 | Q28: =+Q27/Resumo!V66-1 -> -0.10512952
B29: Wacc | C29: =WACC!M3 -> 0.15536952
B30: Perp | C30: =(C26*(1+C28)*(1-C28/C27)/(C29-C28))/WACC!M17 -> 11102616

Sheet WACC
B1: DRE | E1: 2022 | F1: =+E1+1 -> 2023 | G1: =+F1+1 -> 2024 | H1: =+G1+1 -> 2025 | I1: =+H1+1 -> 2026 | J1: =+I1+1 -> 2027 | K1: =+J1+1 -> 2028 | L1: =+K1+1 -> 2029 | M1: =+L1+1 -> 2030
B3: WACC % | I3: =+I4*I5+(1-I4)*(I9) -> 0.15661161 | J3: =+J4*J5+(1-J4)*(J9) -> 0.15871261 | K3: =+K4*K5+(1-K4)*(K9) -> 0.15613107 | L3: =+L4*L5+(1-L4)*(L9) -> 0.15574852 | M3: =+M4*M5+(1-M4)*(M9) -> 0.15536952
B4: Alavancagem | I4: 0 | J4: 0.05 | K4: 0.05 | L4: 0.05 | M4: 0.05
B5: Rdebt % | I5: =+(I6)*(1-I7) -> 0.10258778 | J5: =+(J6)*(1-J7) -> 0.086752212 | K5: =+(K6)*(1-K7) -> 0.082621315 | L5: =+(L6)*(1-L7) -> 0.074970382 | M5: =+(M6)*(1-M7) -> 0.067390352
B6: Debt Bruto % | I6: =+MACRO!EI6*110% -> 0.14575 | J6: =+MACRO!EJ6*110% -> 0.1265 | K6: =+MACRO!EK6*110% -> 0.121 | L6: =+MACRO!EL6*110% -> 0.11 | M6: =+MACRO!EM6*110% -> 0.099
B7: IR % | I7: =PROJ!DQ181 -> 0.2961387 | J7: =PROJ!DR181 -> 0.31421176 | K7: =PROJ!DS181 -> 0.31717922 | L7: =PROJ!DT181 -> 0.31845107 | M7: =PROJ!DU181 -> 0.31928937
B8: US$ %
B9: Requity % | I9: =I10+I13*I11+I12 -> 0.15661161 | J9: =J10+J13*J11+J12 -> 0.1625 | K9: =K10+K13*K11+K12 -> 0.16 | L9: =L10+L13*L11+L12 -> 0.16 | M9: =M10+M13*M11+M12 -> 0.16
B10: Juros Real | I10: 0.07 | J10: =+I10 -> 0.07 | K10: =+J10 -> 0.07 | L10: =+K10 -> 0.07 | M10: =+L10 -> 0.07
B11: Equity risk premium | I11: 0.045 | J11: =+I11 -> 0.045 | K11: =+J11 -> 0.045 | L11: =+K11 -> 0.045 | M11: =+L11 -> 0.045
B12: IPCA | I12: =+MACRO!EI8 -> 0.041611612 | J12: =+MACRO!EJ8 -> 0.0475 | K12: =+MACRO!EK8 -> 0.045 | L12: =+MACRO!EL8 -> 0.045 | M12: =+MACRO!EM8 -> 0.045
B13: Beta | I13: 1 | J13: =+I13 -> 1 | K13: =+J13 -> 1 | L13: =+K13 -> 1 | M13: =+L13 -> 1
B14: US$ % | I14: =(1+MACRO!EI8)/(1+MACRO!EI12)-1 -> 0.01620645 | J14: =(1+MACRO!EJ8)/(1+MACRO!EJ12)-1 -> 0.02195122 | K14: =(1+MACRO!EK8)/(1+MACRO!EK12)-1 -> 0.019512195 | L14: =(1+MACRO!EL8)/(1+MACRO!EL12)-1 -> 0.019512195 | M14: =(1+MACRO!EM8)/(1+MACRO!EM12)-1 -> 0.019512195
P15: perp
B16: FCFF | F16: =+F20 -> -15706782 | I16: =PROJ!DQ57 -> 970236.26 | J16: =PROJ!DR57 -> 1214524.5 | K16: =PROJ!DS57 -> 1450577.2 | L16: =PROJ!DT57 -> 1589706.6 | M16: =PROJ!DU57 -> 1741795.6 | P16: =+M16*(1+VP!$D$5)/(WACC!M3-VP!D5) -> 25874931
B17: FD | I17: 1 | J17: =+I17*(1+J3) -> 1.1587126 | K17: =+J17*(1+K3) -> 1.3396236 | L17: =+K17*(1+L3) -> 1.548268 | M17: =+L17*(1+M3) -> 1.7888217 | P17: =+M17 -> 1.7888217
B18: VP | I18: =+I16/I17 -> 970236.26 | J18: =+J16/J17 -> 1048167.2 | K18: =+K16/K17 -> 1082824.4 | L18: =+L16/L17 -> 1026764.5 | M18: =+M16/M17 -> 973711.13 | P18: =+P16/P17 -> 14464790
B20: FCFE | F20: =-VP!C24 -> -15706782 | G20: =+PROJ!DO62 -> 1011095.3 | I20: =+PROJ!DQ62 -> 821616.19 | J20: =+PROJ!DR62 -> 1102125.9 | K20: =+PROJ!DS62 -> 1419881 | L20: =+PROJ!DT62 -> 1574327.6 | M20: =+PROJ!DU62 -> 1730929.5 | P20: =+M20*(1+VP!$D$5)/(WACC!M3-VP!D5) -> 25713512
E21: IRR | F21: =+IRR(F16:P16,1) -> 0.14957805
B23: Dividendos | G23: =PROJ!DO197 -> 633574.47 | H23: =PROJ!DP197 -> 806561.37 | I23: =PROJ!DQ197 -> 783920.48 | J23: =PROJ!DR197 -> 806181.66 | K23: =PROJ!DS197 -> 871862.74 | L23: =PROJ!DT197 -> 944784.87 | M23: =PROJ!DU197 -> 1026051.6
B24: FD | G24: 1 | H24: =+G24*(1+H9) -> 1 | I24: =+H24*(1+I9) -> 1.1566116 | J24: =+I24*(1+J9) -> 1.344561 | K24: =+J24*(1+K9) -> 1.5596908 | L24: =+K24*(1+L9) -> 1.8092413 | M24: =+L24*(1+M9) -> 2.0987199
B25: VP | G25: =+G23/G24 -> 633574.47 | H25: =+H23/H24 -> 806561.37 | I25: =+I23/I24 -> 677773.31 | J25: =+J23/J24 -> 599587.27 | K25: =+K23/K24 -> 558997.18 | L25: =+L23/L24 -> 522199.49 | M25: =+M23/M24 -> 488894.02
B27: ROIC | E27: =PROJ!DM255 -> 0.14251749 | F27: =PROJ!DN255 -> 0.089808936 | G27: =PROJ!DO255 -> 0.11115528 | H27: =PROJ!DP255 -> 0.14750077 | I27: =PROJ!DQ255 -> 0.13296108 | J27: =PROJ!DR255 -> 0.17418864 | K27: =PROJ!DS255 -> 0.18717398 | L27: =PROJ!DT255 -> 0.19639868 | M27: =PROJ!DU255 -> 0.20471241
B28: EVA | E28: =+E27-E3 -> 0.14251749 | F28: =+F27-F3 -> 0.089808936 | G28: =+G27-G3 -> 0.11115528 | H28: =+H27-H3 -> 0.14750077 | I28: =+I27-I3 -> -0.023650536 | J28: =+J27-J3 -> 0.015476033 | K28: =+K27-K3 -> 0.031042915 | L28: =+L27-L3 -> 0.040650156 | M28: =+M27-M3 -> 0.049342893
B31: Net Debt | E31: =PROJ!DM111+PROJ!DM120-PROJ!DM90 -> -1679208.3 | F31: =PROJ!DN111+PROJ!DN120-PROJ!DN90 -> -1430312.2 | G31: =PROJ!DO111+PROJ!DO120-PROJ!DO90 -> -1403670 | H31: =PROJ!DP111+PROJ!DP120-PROJ!DP90 -> -519500.96 | I31: =PROJ!DQ111+PROJ!DQ120-PROJ!DQ90 -> -844610 | J31: =PROJ!DR111+PROJ!DR120-PROJ!DR90 -> -1141127.4 | K31: =PROJ!DS111+PROJ!DS120-PROJ!DS90 -> -1982886.1 | L31: =PROJ!DT111+PROJ!DT120-PROJ!DT90 -> -2821288.8 | M31: =PROJ!DU111+PROJ!DU120-PROJ!DU90 -> -3749724.3
B33: NET DEBT/COI | E33: =E31/PROJ!DM138 -> -0.19739162 | F33: =F31/PROJ!DN138 -> -0.17244006 | G33: =G31/PROJ!DO138 -> -0.17006787 | H33: =H31/PROJ!DP138 -> -0.0574352 | I33: =I31/PROJ!DQ138 -> -0.090669214 | J33: =J31/PROJ!DR138 -> -0.11645983 | K33: =K31/PROJ!DS138 -> -0.1929761 | L33: =L31/PROJ!DT138 -> -0.26084539 | M33: =M31/PROJ!DU138 -> -0.32844612
B34: CAIXA/COI | E34: =PROJ!DM90/PROJ!DM138 -> 0.33482485 | F34: =PROJ!DN90/PROJ!DN138 -> 0.30528336 | G34: =PROJ!DO90/PROJ!DO138 -> 0.23336641 | H34: =PROJ!DP90/PROJ!DP138 -> 0.0574352 | I34: =PROJ!DQ90/PROJ!DQ138 -> 0.090669214 | J34: =PROJ!DR90/PROJ!DR138 -> 0.11645983 | K34: =PROJ!DS90/PROJ!DS138 -> 0.1929761 | L34: =PROJ!DT90/PROJ!DT138 -> 0.26084539 | M34: =PROJ!DU90/PROJ!DU138 -> 0.32844612
B35: NET DEBT/BV | E35: =E31/(PROJ!DM126+PROJ!DM127) -> -0.16646402 | F35: =F31/(PROJ!DN126+PROJ!DN127) -> -0.14235899 | G35: =G31/(PROJ!DO126+PROJ!DO127) -> -0.13029578 | H35: =H31/(PROJ!DP126+PROJ!DP127) -> -0.049812962 | I35: =I31/(PROJ!DQ126+PROJ!DQ127) -> -0.076925562 | J35: =J31/(PROJ!DR126+PROJ!DR127) -> -0.095347009 | K35: =K31/(PROJ!DS126+PROJ!DS127) -> -0.15071707 | L35: =L31/(PROJ!DT126+PROJ!DT127) -> -0.19459788 | M35: =M31/(PROJ!DU126+PROJ!DU127) -> -0.23454225
B36: PAY OUT | E36: =PROJ!DM194 -> 0.25177162 | F36: =PROJ!DN194 -> 0 | G36: =PROJ!DO194 -> 0 | H36: =PROJ!DP194 -> 0 | I36: =PROJ!DQ194 -> 0 | J36: =PROJ!DR194 -> 0 | K36: =PROJ!DS194 -> 0 | L36: =PROJ!DT194 -> 0 | M36: =PROJ!DU194 -> 0
B37: Alavancagem Proj | E37: =-E31/(E31+E38) -> -1 | F37: =-F31/(F31+F38) -> -1 | G37: =-G31/(G31+G38) -> -1 | H37: =-H31/(H31+H38) -> -1 | I37: =-I31/(I31+I38) -> -1 | J37: =-J31/(J31+J38) -> -1 | K37: =-K31/(K31+K38) -> -1 | L37: =-L31/(L31+L38) -> -1 | M37: =-M31/(M31+M38) -> -1
B38: VM Proj

Sheet Resumo
B2: Lojas Renner | T2: =+TODAY() -> 46105 | U2: Preço: | V2: =+VP!C20 -> 15.6 | AC2: Bofa | AH2: Bofa | AK2: Itau | AO2: MS | AR2: BTG
B3: DRE | C3: 39447 | D3: =C3+365 -> 39812 | E3: =D3+365 -> 40177 | F3: =E3+365 -> 40542 | G3: =F3+365 -> 40907 | H3: =G3+365 -> 41272 | I3: =H3+365 -> 41637 | J3: =I3+365 -> 42002 | K3: =J3+365 -> 42367 | ... M3: =L3+365 -> 43097 | N3: 2018 | O3: =+N3+1 -> 2019 | P3: =+O3+1 -> 2020 | Q3: =+P3+1 -> 2021 | R3: =+Q3+1 -> 2022 | S3: =+R3+1 -> 2023 | T3: =+S3+1 -> 2024 | U3: =+T3+1 -> 2025 | V3: =+U3+1 -> 2026 | ... Z3: =+Y3+1 -> 2030 | AC3: 2025 | AD3: 2026 | AH3: 2025 | AI3: 2026 | AK3: 2025 | AL3: 2026 | AO3: 2025 | AP3: 2026 | AR3: 2025 | AS3: 2026
B4: Receita Líquida | C4: =+PROJ!CX6 -> 1930939 | D4: =+PROJ!CY6 -> 2183007 | E4: =+PROJ!CZ6 -> 2363628 | F4: =+PROJ!DA6 -> 2751338 | G4: =+PROJ!DB6 -> 3238542 | H4: =+PROJ!DC6 -> 3862508 | I4: =+PROJ!DD6 -> 4370382 | J4: =+PROJ!DE6 -> 5216044 | ... Z4: =+PROJ!DU6 -> 22297186 | AA4: 15837000 | AB4: Net Revenues | AC4: =+AVERAGE(AH4,AK4,AO4,AR4) -> 15291 | AD4: =+AVERAGE(AI4,AL4,AP4,AS4) -> 16260 | AE4: =+(U4/1000)/AC4-1 -> 0.034362134 | AF4: =+(V4/1000)/AD4-1 -> 0.038202688 | AH4: 15291 | AI4: 16260
B5: y-o-y | D5: =+D4/C4-1 -> 0.13054167 | E5: =+E4/D4-1 -> 0.082739542 | F5: =+F4/E4-1 -> 0.16403173 | G5: =+G4/F4-1 -> 0.17707893 | H5: =+H4/G4-1 -> 0.1926688 | I5: =+I4/H4-1 -> 0.13148814 | J5: =+J4/I4-1 -> 0.19349842 | K5: =+K4/J4-1 -> 0.17813385 | ... Z5: =+Z4/Y4-1 -> 0.068194097 | AA5: =+AA4/T4-1 -> 0.097021231 | AH5: =+AH4/($T4/1000)-1 -> 0.059200078 | AI5: =+AI4/AH4-1 -> 0.06337061
B6: Mercadorias | C6: =+FAT!CY30 -> 1751728 | D6: =+FAT!CZ30 -> 1956021 | E6: =+FAT!DA30 -> 2115969 | F6: =+FAT!DB30 -> 2462684 | G6: =+FAT!DC30 -> 2896616 | H6: =+FAT!DD30 -> 3461960 | I6: =+FAT!DE30 -> 3913806 | J6: =+FAT!DF30 -> 4642612 | ... Z6: =+FAT!DV30 -> 20109365 | AC6: =+AVERAGE(AH6,AK6,AO6,AR6) -> 13710.833 | AD6: =+AVERAGE(AI6,AL6,AP6,AS6) -> 14979.3 | AE6: =+(U6/1000)/AC6-1 -> 0.010709809 | AF6: =+(V6/1000)/AD6-1 -> -0.0079122065 | AK6: 13508 | AL6: 14661 | AO6: 13711 | AP6: 14976 | AR6: 13913.5 | AS6: 15300.9
B7: y-o-y | D7: =+D6/C6-1 -> 0.1166237 | E7: =+E6/D6-1 -> 0.081772128 | F7: =+F6/E6-1 -> 0.16385637 | G7: =+G6/F6-1 -> 0.17620287 | H7: =+H6/G6-1 -> 0.19517395 | I7: =+I6/H6-1 -> 0.13051739 | J7: =+J6/I6-1 -> 0.18621414 | K7: =+K6/J6-1 -> 0.17409165 | ... Z7: =+Z6/Y6-1 -> 0.07563575 | AC7: =+AC6/($T6/1000)-1 -> 0.08198291 | AD7: =+AD6/AC6-1 -> 0.092515651 | AK7: =+AK6/($T6/1000)-1 -> 0.065976428 | AL7: =+AL6/AK6-1 -> 0.085356826 | AO7: =+AO6/($T6/1000)-1 -> 0.081996062 | AP7: =+AP6/AO6-1 -> 0.092261688 | AR7: =+AR6/($T6/1000)-1 -> 0.097976239 | AS7: =+AS6/AR6-1 -> 0.099716103
B8: Prod/Serv Financeiros | C8: =+FAT!CY21 -> -9755 | D8: =+FAT!CZ21 -> -13038 | E8: =+FAT!DA21 -> -13703 | F8: =+FAT!DB21 -> -17480.113 | G8: =+FAT!DC21 -> -20583.276 | H8: =+FAT!DD21 -> -24096.251 | I8: =+FAT!DE21 -> -27465.241 | J8: =+FAT!DF21 -> -34494.49 | ... M8: =+FAT!DI21 -> -71380 | N8: =+FAT!DJ34 -> 941108 | O8: =+FAT!DK34 -> 1113744 | P8: =+FAT!DL34 -> 876609 | Q8: =+FAT!DM34 -> 1015829.7 | R8: =+FAT!DN34 -> 1695342 | S8: =+FAT!DO34 -> 1941509 | T8: =+FAT!DP34 -> 1764416 | U8: =+FAT!DQ34 -> 1958757.7 | ... Z8: =+FAT!DV34 -> 2187820.5
B9: y-o-y | D9: =+D8/C8-1 -> 0.33654536 | E9: =+E8/D8-1 -> 0.051004755 | F9: =+F8/E8-1 -> 0.2756413 | G9: =+G8/F8-1 -> 0.17752535 | H9: =+H8/G8-1 -> 0.17067133 | I9: =+I8/H8-1 -> 0.13981388 | J9: =+J8/I8-1 -> 0.25593253 | K9: =+K8/J8-1 -> 0.21085927 | ... Z9: =+Z8/Y8-1 -> 0.0043285472
B10: SSS | C10: =+FAT!CY300 -> 0.086 | D10: =+FAT!CZ300 -> 0.030970467 | E10: =+FAT!DA300 -> 0.019657924 | F10: =+FAT!DB300 -> 0.10374443 | G10: =+FAT!DC300 -> 0.072061827 | H10: =+FAT!DD300 -> 0.090480665 | I10: =+FAT!DE300 -> 0.058862534 | J10: =+FAT!DF300 -> 0.11259133 | ... Z10: =+FAT!DV300 -> 0.05
B11: CPV | C11: =+PROJ!CX7 -> -906712 | D11: =+PROJ!CY7 -> -1022536 | E11: =+PROJ!CZ7 -> -1084911 | F11: =+PROJ!DA7 -> -1209458 | G11: =+PROJ!DB7 -> -1396128 | H11: =+PROJ!DC7 -> -1634247 | I11: =+PROJ!DD7 -> -1867642 | J11: =+PROJ!DE7 -> -2164764 | ... Z11: =+PROJ!DU7 -> -8872728.5 | AO11: -6111 | AP11: -6644
B12: Lucro Bruto | C12: =+PROJ!CX8 -> 1024227 | D12: =+PROJ!CY8 -> 1160471 | E12: =+PROJ!CZ8 -> 1278717 | F12: =+PROJ!DA8 -> 1541880 | G12: =+PROJ!DB8 -> 1842414 | H12: =+PROJ!DC8 -> 2228261 | I12: =+PROJ!DD8 -> 2502740 | J12: =+PROJ!DE8 -> 3051280 | ... Z12: =+PROJ!DU8 -> 13424457 | AA12: 9783 | AB12: Gross Profit | AC12: =+AVERAGE(AH12,AK12,AO12,AR12) -> 7585.5667 | AD12: =+AVERAGE(AI12,AL12,AP12,AS12) -> 8330.7 | AE12: =+(U12/1000)/AC12-1 -> 0.27754952 | AF12: =+(V12/1000)/AD12-1 -> 0.23989914 | AK12: 7474 | AL12: 8196 | AO12: =+AO11+AO6 -> 7600 | AP12: =+AP11+AP6 -> 8332 | AR12: 7682.7 | AS12: 8464.1
B13: Mg Bruta | C13: =+C12/C4 -> 0.5304295 | D13: =+D12/D4 -> 0.53159289 | E13: =+E12/E4 -> 0.54099757 | F13: =+F12/F4 -> 0.56041097 | G13: =+G12/G4 -> 0.5689023 | H13: =+H12/H4 -> 0.57689486 | I13: =+I12/I4 -> 0.57265932 | J13: =+J12/J4 -> 0.58497973 | ... Z13: =+Z12/Z4 -> 0.60206957 | AA13: =1897-AA12 -> -7886 | AB13: mg | AC13: =+AC12/AC6 -> 0.55325351 | AD13: =+AD12/AD6 -> 0.55614748 | AK13: =+AK12/AK6 -> 0.55330175 | AL13: =+AL12/AL6 -> 0.55903417 | AO13: =+AO12/AO6 -> 0.55429947 | AP13: =+AP12/AP6 -> 0.55635684 | AR13: =+AR12/AR6 -> 0.55217594 | AS13: =+AS12/AS6 -> 0.55317661
B14: Mg Bruta retail | C14: =+FAT!CY54 -> 0.48238996 | D14: =+FAT!CZ54 -> 0.4772367 | E14: =+FAT!DA54 -> 0.50105696 | F14: =+FAT!DB54 -> 0.51988724 | G14: =+FAT!DC54 -> 0.52518663 | H14: =+FAT!DD54 -> 0.5330931 | I14: =+FAT!DE54 -> 0.52710814 | J14: =+FAT!DF54 -> 0.53837603 | ... Z14: =+FAT!DV54 -> 0.55743365 | AA14: -13212000
B15: SG&A | C15: =+PROJ!CX10 -> -823249 | D15: =+PROJ!CY10 -> -960711 | E15: =+PROJ!CZ10 -> -1008098 | F15: =+PROJ!DA10 -> -1130353 | G15: =+PROJ!DB10 -> -1366159 | H15: =+PROJ!DC10 -> -1669011 | I15: =+PROJ!DD10 -> -1852306 | J15: =+PROJ!DE10 -> -2060398.2 | ... Z15: =+PROJ!DU10 -> -10214423 | AA15: -1172000 | AB15: SG&A | AC15: =+AVERAGE(AH15,AK15,AO15,AR15) -> -6019.4667 | AD15: =+AVERAGE(AI15,AL15,AP15,AS15) -> -6508 | AE15: =+(U15/1000)/AC15-1 -> 0.31831498 | AF15: =+(V15/1000)/AD15-1 -> 0.32466353 | AK15: =+AK17-AK12 -> -6085 | AL15: =+AL17-AL12 -> -6594 | AO15: =+AO17-AO12 -> -5916 | AP15: =+AP17-AP12 -> -6400 | AR15: =+AR17-AR12 -> -6057.4 | AS15: =+AS17-AS12 -> -6530
B16: % rec liquida | N16: =+N15/N4 -> -0.44124895 | O16: =+O15/O4 -> -0.43610205 | P16: =+P15/P4 -> -0.45862392 | Q16: =+Q15/Q4 -> -0.50687277 | R16: =+R15/R4 -> -0.49561805 | S16: =+S15/S4 -> -0.53719271 | T16: =+T15/T4 -> -0.51831645 | U16: =+U15/U4 -> -0.50172842 | ... Z16: =+Z15/Z4 -> -0.45810367 | AA16: =+AA15+AA14 -> -14384000
B17: EBIT | C17: =+PROJ!CX17 -> 200978 | D17: =+PROJ!CY17 -> 199760 | E17: =+PROJ!CZ17 -> 270619 | F17: =+PROJ!DA17 -> 411527 | G17: =+PROJ!DB17 -> 476255 | H17: =+PROJ!DC17 -> 559250 | I17: =+PROJ!DD17 -> 650434 | J17: =+PROJ!DE17 -> 990881.79 | ... Z17: =+PROJ!DU17 -> 3210034.4 | AB17: Adj EBIT | AC17: =+AVERAGE(AH17,AK17,AO17,AR17) -> 1575.325 | AD17: =+AVERAGE(AI17,AL17,AP17,AS17) -> 1839.775 | AE17: =+(U17/1000)/AC17-1 -> 0.11429958 | AF17: =+(V17/1000)/AD17-1 -> -0.071453021 | AH17: 1603 | AI17: 1891 | AK17: 1389 | AL17: 1602 | AO17: 1684 | AP17: 1932 | AR17: 1625.3 | AS17: 1934.1
B18: Resultado Financeiro | C18: =+PROJ!CX18 -> -14000 | D18: =+PROJ!CY18 -> -6200 | E18: =+PROJ!CZ18 -> -11800 | F18: =+PROJ!DA18 -> 16538 | G18: =+PROJ!DB18 -> 5913 | H18: =+PROJ!DC18 -> -50430 | I18: =+PROJ!DD18 -> -67724 | J18: =+PROJ!DE18 -> -93874 | ... Z18: =+PROJ!DU18 -> 3980.9085 | AC18: =+AVERAGE(AH18,AK18,AO18,AR18) -> -26.325 | AD18: =+AVERAGE(AI18,AL18,AP18,AS18) -> -5.85 | AH18: =+AH19-AH17 -> 41 | AI18: =+AI19-AI17 -> 77 | AK18: =+AK19-AK17 -> 30 | AL18: =+AL19-AL17 -> 56 | AO18: -87 | AP18: -73 | AR18: =+AR19-AR17 -> -89.3 | AS18: =+AS19-AS17 -> -83.4
B19: LAIR | C19: =+PROJ!#REF! -> #REF! | D19: =+PROJ!#REF! -> #REF! | E19: =+PROJ!#REF! -> #REF! | F19: =+PROJ!#REF! -> #REF! | G19: =+PROJ!#REF! -> #REF! | H19: =+PROJ!#REF! -> #REF! | I19: =+PROJ!#REF! -> #REF! | J19: =+PROJ!#REF! -> #REF! | ... M19: =+PROJ!#REF! -> #REF! | N19: =+PROJ!DI22 -> 1370193.6 | O19: =+PROJ!DJ22 -> 1491984 | P19: =+PROJ!DK22 -> 1200731 | Q19: =+PROJ!DL22 -> 640140.15 | R19: =+PROJ!DM22 -> 1384284 | S19: =+PROJ!DN22 -> 840667 | T19: =+PROJ!DO22 -> 1320997 | U19: =+PROJ!DP22 -> 1637247.4 | ... Z19: =+PROJ!DU22 -> 3214015.4 | AC19: =+AVERAGE(AH19,AK19,AO19,AR19) -> 1549 | AD19: =+AVERAGE(AI19,AL19,AP19,AS19) -> 1833.925 | AE19: =+(U19/1000)/AC19-1 -> 0.056970541 | AF19: =+(V19/1000)/AD19-1 -> -0.14604112 | AH19: 1644 | AI19: 1968 | AK19: 1419 | AL19: 1658 | AO19: =+AO18+AO17 -> 1597 | AP19: =+AP18+AP17 -> 1859 | AR19: 1536 | AS19: 1850.7
B20: IR & CS | C20: =+PROJ!CX23 -> -57055 | D20: =+PROJ!CY23 -> -62750 | E20: =+PROJ!CZ23 -> -82278 | F20: =+PROJ!DA23 -> -123743 | G20: =+PROJ!DB23 -> -138486 | H20: =+PROJ!DC23 -> -153420 | I20: =+PROJ!DD23 -> -175310 | J20: =+PROJ!DE23 -> -236755 | ... Z20: =+PROJ!DU23 -> -698593.57 | AC20: =+AVERAGE(AH20,AK20,AO20,AR20) -> -205.275 | AD20: =+AVERAGE(AI20,AL20,AP20,AS20) -> -288.65 | AE20: =+(U20/1000)/AC20-1 -> 0.21997052 | AF20: =+(V20/1000)/AD20-1 -> -0.19753127 | AH20: =+AH22-AH19 -> -213 | AI20: =+AI22-AI19 -> -319 | AK20: =+AK22-AK19 -> -185 | AL20: =+AL22-AL19 -> -249 | AO20: =+AO22-AO19 -> -162 | AP20: =+AP22-AP19 -> -272 | AR20: =+AR22-AR19 -> -261.1 | AS20: =+AS22-AS19 -> -314.6
B21: tax rate | N21: =+N20/N19 -> -0.25547993 | O21: =+O20/O19 -> -0.2719741 | P21: =+P20/P19 -> -0.087023655 | Q21: =+Q20/Q19 -> -0.010530506 | R21: =+R20/R19 -> -0.066880062 | S21: =+S20/S19 -> 0.16129097 | T21: =+T20/T19 -> -0.094117549 | U21: =+U20/U19 -> -0.15295761 | ... Z21: =+Z20/Z19 -> -0.2173585 | AC21: =+AC20/AC19 -> -0.13252098 | AD21: =+AD20/AD19 -> -0.15739466 | AH21: =+AH20/AH19 -> -0.12956204 | AI21: =+AI20/AI19 -> -0.1620935 | AK21: =+AK20/AK19 -> -0.1303735 | AL21: =+AL20/AL19 -> -0.15018094 | AO21: =+AO20/AO19 -> -0.1014402 | AP21: =+AP20/AP19 -> -0.14631522 | AR21: =+AR20/AR19 -> -0.16998698 | AS21: =+AS20/AS19 -> -0.16998973
B22: Lucro Líquido | C22: =+PROJ!CX25 -> 129923 | D22: =+PROJ!CY25 -> 130810 | E22: =+PROJ!CZ25 -> 176541 | F22: =+PROJ!DA25 -> 304322 | G22: =+PROJ!DB25 -> 343682 | H22: =+PROJ!DC25 -> 355400 | I22: =+PROJ!DD25 -> 407400 | J22: =+PROJ!DE25 -> 660252.79 | ... Z22: =+PROJ!DU25 -> 2515421.8 | AA22: =+(Z22/T22)^(1/6)-1 -> 0.13180825 | AB22: Net Income | AC22: =+AVERAGE(AH22,AK22,AO22,AR22) -> 1343.725 | AD22: =+AVERAGE(AI22,AL22,AP22,AS22) -> 1545.275 | AE22: =+(U22/1000)/AC22-1 -> 0.032069747 | AF22: =+(V22/1000)/AD22-1 -> -0.136423 | AH22: 1431 | AI22: 1649 | AK22: 1234 | AL22: 1409 | AO22: 1435 | AP22: 1587 | AR22: 1274.9 | AS22: 1536.1
B23: y-o-y | D23: =+D22/C22-1 -> 0.0068271207 | E23: =+E22/D22-1 -> 0.34959865 | F23: =+F22/E22-1 -> 0.72380354 | G23: =+G22/F22-1 -> 0.12933669 | H23: =+H22/G22-1 -> 0.034095472 | I23: =+I22/H22-1 -> 0.14631401 | J23: =+J22/I22-1 -> 0.62064995 | K23: =+K22/J22-1 -> -0.12330784 | ... Z23: =+Z22/Y22-1 -> 0.10012739
B24: Resultado nao Operacional | N24: =+PROJ!DI31 -> -6130.6034 | O24: =+PROJ!DJ31 -> -23768 | P24: =+PROJ!DK31 -> -19977 | Q24: =+PROJ!DL31 -> -8994 | R24: =+PROJ!DM31 -> 0 | S24: =+PROJ!DN31 -> 0 | T24: =+PROJ!DO31 -> 0 | U24: =+PROJ!DP31 -> 0 | ... Z24: =+PROJ!DU31 -> 0
B27: Recup Credito Fiscal | Q27: =+Q57 -> 0 | R27: =+R57 -> 110064 | S27: =+S57 -> 219246 | T27: =+T57 -> 149681 | U27: =+U57 -> 79941.087 | V27: =+V57 -> 84405.879 | W27: =+W57 -> 91459.374 | X27: =+X57 -> 97700.936 | ... Z27: =+Z57 -> 111485.93
B28: Subv ICMS (cred presum) | N28: =+PROJ!DI216 -> 0 | O28: =+PROJ!DJ216 -> 43088 | P28: =+PROJ!DK216 -> 27445 | Q28: =+PROJ!DL216 -> 98384 | R28: =+PROJ!DM216 -> 127983 | S28: =+PROJ!DN216 -> 141639 | T28: =+PROJ!DO216 -> 45947 | U28: =+PROJ!DP216 -> 39560.193 | ... Z28: =+PROJ!DU216 -> 55801.091
B29: LL adj | N29: =+N22-N28-N27 -> 1020136.7 | O29: =+O22-O28-O27 -> 1043115 | P29: =+P22-P28-P27 -> 1068794 | Q29: =+Q22-Q28-Q27 -> 535015.15 | R29: =+R22-R28-R27 -> 1053656 | S29: =+S22-S28-S27 -> 615374 | T29: =+T22-T28-T27 -> 1001040 | U29: =+U22-U28-U27 -> 1267316.6 | ... Z29: =+Z22-Z28-Z27 -> 2348134.8 | AC29: 22219
B30: y-o-y | D30: =+D29/C29-1 -> #DIV/0! | E30: =+E29/D29-1 -> #DIV/0! | F30: =+F29/E29-1 -> #DIV/0! | G30: =+G29/F29-1 -> #DIV/0! | H30: =+H29/G29-1 -> #DIV/0! | I30: =+I29/H29-1 -> #DIV/0! | J30: =+J29/I29-1 -> #DIV/0! | K30: =+K29/J29-1 -> #DIV/0! | ... Z30: =+Z29/Y29-1 -> 0.10247541 | AC30: 7102 | AD30: 7800
AC31: =+AC30*9 -> 63918 | AD31: =+$AC$29/AD30 -> 2.8485897
AC32: BAP
B34: FLUXO DE CAIXA FIRMA | C34: =C3 -> 39447 | D34: =D3 -> 39812 | E34: =E3 -> 40177 | F34: =F3 -> 40542 | G34: =G3 -> 40907 | H34: =H3 -> 41272 | I34: =I3 -> 41637 | J34: =J3 -> 42002 | ... Z34: =Z3 -> 2030
B35: EBITDA Div | C35: =+PROJ!CX39 -> 200978 | D35: =+PROJ!CY39 -> 199760 | E35: =+PROJ!CZ39 -> 270619 | F35: =+PROJ!DA39 -> 411527 | G35: =+PROJ!DB39 -> 476255 | H35: =+PROJ!DC39 -> 559250 | I35: =+PROJ!DD39 -> 650434 | J35: =+PROJ!DE39 -> 1203613.8 | ... M35: =+PROJ!DH39 -> 1416291 | N35: =+FAT!DJ148 -> 1738395.6 | O35: =+FAT!DK148 -> 2338130 | P35: =+FAT!DL148 -> 1616520 | Q35: =+FAT!DM148 -> 1691247.2 | R35: =+FAT!DN148 -> 2401250 | S35: =+FAT!DO148 -> 1939321 | T35: =+FAT!DP148 -> 2457187 | U35: =+FAT!DQ148 -> 2998339.1 | ... Z35: =+FAT!DV148 -> 4824764.2 | AB35: EBITDA
B36: y-o-y | D36: =+D35/C35-1 -> -0.0060603648 | E36: =+E35/D35-1 -> 0.35472066 | F36: =+F35/E35-1 -> 0.52068776 | G36: =+G35/F35-1 -> 0.15728737 | H36: =+H35/G35-1 -> 0.17426589 | I36: =+I35/H35-1 -> 0.16304694 | J36: =+J35/I35-1 -> 0.85047797 | K36: =+K35/J35-1 -> -0.0046363882 | ... Z36: =+Z35/Y35-1 -> 0.088598014 | AB36: yoy
B37: Mg EBITDA | C37: =+C35/C4 -> 0.10408304 | D37: =+D35/D4 -> 0.091506807 | E37: =+E35/E4 -> 0.11449306 | F37: =+F35/F4 -> 0.14957341 | G37: =+G35/G4 -> 0.14705846 | H37: =+H35/H4 -> 0.14478934 | I37: =+I35/I4 -> 0.14882772 | J37: =+J35/J4 -> 0.23075223 | ... Z37: =+Z35/Z4 -> 0.21638445 | AB37: mrgn
R38: =+R35/$O$35-1 -> 0.026995933 | S38: =+S35/$O$35-1 -> -0.1705675
B40: EBITDA Adj (Con IFRS) | C40: =+FAT!CY139 -> 0 | D40: =+FAT!CZ139 -> 0 | E40: =+FAT!DA139 -> 0 | F40: =+FAT!DB139 -> 0 | G40: =+FAT!DC139 -> 0 | H40: =+FAT!DD139 -> 0 | I40: =+FAT!DE139 -> 0 | J40: =+FAT!DF139 -> 0 | ... M40: =+FAT!DI139 -> 0 | N40: =+FAT!DJ160 -> 1773318 | O40: =+FAT!DK160 -> 2388828 | P40: =+FAT!DL160 -> 1661248 | Q40: =+FAT!DM160 -> 1722346.2 | R40: =+FAT!DN160 -> 2463036 | S40: =+FAT!DO160 -> 2103621 | T40: =+FAT!DP160 -> 2647067 | U40: =+FAT!DQ160 -> 3158272.2 | ... Z40: =+FAT!DV160 -> 5053515.6 | AK40: 2608 | AL40: 2889
B41: Mg EBITDA | C41: =+C40/#REF! -> #REF! | D41: =+D40/#REF! -> #REF! | E41: =+E40/#REF! -> #REF! | F41: =+F40/#REF! -> #REF! | G41: =+G40/#REF! -> #REF! | H41: =+H40/#REF! -> #REF! | I41: =+I40/#REF! -> #REF! | J41: =+J40/#REF! -> #REF! | ... M41: =+M40/#REF! -> #REF! | N41: =+N40/N4 -> 0.21044436 | O41: =+O40/O4 -> 0.24913633 | P41: =+P40/P4 -> 0.2204071 | Q41: =+Q40/Q4 -> 0.16292267 | R41: =+R40/R4 -> 0.18559344 | S41: =+S40/S4 -> 0.15413572 | T41: =+T40/T4 -> 0.18336103 | U41: =+U40/U4 -> 0.19968298 | ... Z41: =+Z40/Z4 -> 0.22664365
B42: vs 2019 | R42: =+R40/O40-1 -> 0.031064606 | S42: =+S40/$O40-1 -> -0.11939202 | T42: =+T40/$O40-1 -> 0.1081028 | U42: =+U40/$O40-1 -> 0.32210113 | V42: =+V40/$O40-1 -> 0.33727136 | W42: =+W40/$O40-1 -> 0.63105556 | X42: =+X40/$O40-1 -> 0.78456069 | Y42: =+Y40/$O40-1 -> 0.94498626 | Z42: =+Z40/$O40-1 -> 1.1154791
B43: EBITDA Adj Retail (Con IFRS) | C43: =+FAT!CY142 -> 0 | D43: =+FAT!CZ142 -> 0 | E43: =+FAT!DA142 -> 0 | F43: =+FAT!DB142 -> 0 | G43: =+FAT!DC142 -> 0 | H43: =+FAT!DD142 -> 0 | I43: =+FAT!DE142 -> 0 | J43: =+FAT!DF142 -> 0 | ... M43: =+FAT!DI142 -> 0 | N43: =+FAT!DJ$177 -> 1423887.1 | O43: =+FAT!DK$177 -> 1997344.6 | P43: =+FAT!DL$177 -> 1579443.3 | Q43: =+FAT!DM$177 -> 1475785 | R43: =+FAT!DN$177 -> 2271435.8 | S43: =+FAT!DO$177 -> 1980246.5 | T43: =+FAT!DP$177 -> 2329530 | U43: =+FAT!DQ$177 -> 2614145.6 | ... Z43: =+FAT!DV$177 -> 4456743.8 | AK43: 2410 | AL43: 2801 | AR43: =+AR44*AR6 -> 2810.527 | AS43: =+AS44*AS6 -> 3182.5872
B44: Mg EBITDA | C44: =+C43/#REF! -> #REF! | D44: =+D43/#REF! -> #REF! | E44: =+E43/#REF! -> #REF! | F44: =+F43/#REF! -> #REF! | G44: =+G43/#REF! -> #REF! | H44: =+H43/#REF! -> #REF! | I44: =+I43/#REF! -> #REF! | J44: =+J43/#REF! -> #REF! | ... M44: =+M43/#REF! -> #REF! | N44: =+N43/N6 -> 0.19022108 | O44: =+O43/O6 -> 0.23568342 | P44: =+P43/P6 -> 0.23713331 | Q44: =+Q43/Q6 -> 0.15443986 | R44: =+R43/R6 -> 0.19622288 | S44: =+S43/S6 -> 0.16916017 | T44: =+T43/T6 -> 0.18383359 | U44: =+U43/U6 -> 0.18864245 | ... Z44: =+Z43/Z6 -> 0.22162529 | AR44: 0.202 | AS44: 0.208
B45: vs 2019 | R45: =+R43/O43-1 -> 0.13722781 | S45: =+S43/$O43-1 -> -0.0085604263 | T45: =+T43/$O43-1 -> 0.16631351 | U45: =+U43/$O43-1 -> 0.3088105 | V45: =+V43/$O43-1 -> 0.44987166 | W45: =+W43/$O43-1 -> 0.69218224 | X45: =+X43/$O43-1 -> 0.85965291 | Y45: =+Y43/$O43-1 -> 1.0390901 | Z45: =+Z43/$O43-1 -> 1.2313345
...

Sheet FAT
B1: 37956 | C1: 38047 | D1: 38139 | E1: 38231 | F1: 38322 | G1: 38412 | H1: 38504 | I1: 38596 | J1: 38687 | K1: 38777 | L1: 38869 | M1: 38961 | N1: 39052 | O1: 39142 | P1: 39234 | Q1: 39326 | R1: 39417 | S1: 39508 | T1: 39600 | U1: 39692 | V1: 39783 | W1: 39873 | X1: 39965 | Y1: 40057 | Z1: 40148 | AA1: 40238 | AB1: 40330 | AC1: 40422 | AD1: 40513 | AE1: 40603 | AF1: 40695 | AG1: 40787 | AH1: 40878 | AI1: 40969 | AJ1: 41061 | AK1: 41153 | AL1: 41244 | AM1: 41334 | AN1: 41426 | AO1: 41518 | AP1: 41609 | AQ1: 41699 | AR1: =+EOMONTH(AQ1,3) -> 41820 | AS1: =+EOMONTH(AR1,3) -> 41912 | AT1: =+EOMONTH(AS1,3) -> 42004 | AU1: =+EOMONTH(AT1,3) -> 42094 | AV1: =+EOMONTH(AU1,3) -> 42185 | AW1: =+EOMONTH(AV1,3) -> 42277 | AX1: =+EOMONTH(AW1,3) -> 42369 | AY1: =+EOMONTH(AX1,3) -> 42460 | ... CP1: =+EOMONTH(CO1,3) -> 46387 | CT1: 46022 | CV1: 38322 | CW1: 38687 | CX1: 39052 | CY1: 39417 | CZ1: 39783 | DA1: 40148 | DB1: 40513 | DC1: 40878 | DD1: 41244 | DE1: 41609 | DF1: 2014 | DG1: =+DF1+1 -> 2015 | DH1: =+DG1+1 -> 2016 | DI1: =+DH1+1 -> 2017 | DJ1: =+DI1+1 -> 2018 | DK1: =+DJ1+1 -> 2019 | DL1: =+DK1+1 -> 2020 | DM1: =+DL1+1 -> 2021 | DN1: =+DM1+1 -> 2022 | ... DV1: =+DU1+1 -> 2030 | DY1: 2026 | DZ1: 2027
A2: Inflação | B2: 0.0115 | C2: 0.0185 | D2: 0.016 | E2: 0.0194 | F2: 0.02 | G2: 0.0179 | H2: 0.013469458 | I2: 0.0077189382 | J2: 0.016688208 | K2: 0.014368541 | L2: 0.00099540016 | M2: 0.004476 | N2: 0.011345219 | O2: 0.0126 | P2: 0.0082 | Q2: 0.0089 | R2: 0.0143 | S2: 0.015149686 | T2: 0.020897661 | U2: 0.0107 | V2: 0.0109 | W2: 0.0124 | X2: 0.0132 | Y2: 0.0066 | Z2: 0.0102 | AA2: 0.0206 | AB2: 0.01 | AC2: 0.005 | AD2: 0.0223 | AE2: 0.0244 | AF2: 0.014 | AG2: 0.0106 | AH2: 0.0144 | AI2: 0.012246463 | AJ2: 0.010831058 | AK2: 0.01416561 | AL2: 0.01992969 | AM2: 0.019420463 | AN2: 0.011844323 | AO2: 0.0062101725 | AP2: 0.020433183 | AQ2: =MACRO!BD8 -> 0.0217 | AR2: =MACRO!BE8 -> 0.0114 | AS2: =MACRO!BF8 -> 0.0104 | AT2: =MACRO!BG8 -> 0.0167 | AU2: =MACRO!BH8 -> 0.013475174 | AV2: =MACRO!BI8 -> 0.013475174 | AW2: =MACRO!BJ8 -> 0.013475174 | AX2: =MACRO!BK8 -> 0.013475174 | ... CG2: =MACRO!CT8 -> 0.0062002866 | CH2: 0.02 | CI2: =MACRO!CV8 -> 0.020403397 | CJ2: =MACRO!CW8 -> 0.0093277668 | CK2: =MACRO!CX8 -> 0.0063043263 | CL2: =MACRO!CY8 -> 0.010934022 | CM2: =MACRO!CZ8 -> 0.015 | CN2: =MACRO!DA8 -> 0.0085 | CO2: =MACRO!DB8 -> 0.006 | CP2: =MACRO!DC8 -> 0.0115 | CT2: 0.010934022 | CV2: 0.075968463 | CW2: 0.055776604 | CX2: 0.03118516 | CY2: 0.0446 | CZ2: 0.0589 | DA2: 0.0431 | DB2: 0.0591 | DC2: 0.0648 | DD2: 0.057172822 | DE2: 0.057908141 | DF2: =MACRO!DW8 -> 0.0641 | DG2: =MACRO!DX8 -> 0.1067 | DH2: =MACRO!DY8 -> 0.062665012 | DI2: =MACRO!DZ8 -> 0.029473499 | DJ2: =MACRO!EA8 -> 0.030601831 | DK2: =MACRO!EB8 -> 0.042901847 | DL2: =MACRO!EC8 -> 0.044908326 | DM2: =MACRO!ED8 -> 0.099766039 | ... DV2: =MACRO!EM8 -> 0.045 | DY2: 0.046799601 | DZ2: 0.0475
A3: Receita Bruta | C3: 230277 | D3: 326148 | E3: 283436 | F3: 449394 | G3: 261957 | H3: 379185 | I3: 344395 | J3: 571973.41 | K3: 347895.36 | L3: 508600.35 | M3: 457408.36 | N3: 723460 | O3: 450331 | P3: 651919 | Q3: 583136 | R3: 872743 | S3: 557955 | T3: 747079 | U3: 660961 | V3: 890242 | W3: 537450 | X3: 803683 | Y3: 715447 | Z3: 1023895 | AA3: 649073 | AB3: 918672 | AC3: 835227 | AD3: 1176249.9 | AE3: 773464.63 | AF3: 1089692.7 | AG3: 963449.2 | AH3: 1387228.5 | AI3: 918699.65 | AJ3: 1243546.6 | AK3: 1175907.7 | AL3: 1689611.4 | AM3: 1079840.5 | AN3: 1379462.7 | AO3: 1327255.5 | AP3: 1901390 | AQ3: =+AQ7+AQ11 -> 1214566.3 | AR3: =+AR7+AR11 -> 1630176.7 | AS3: =+AS7+AS11 -> 1558376.3 | AT3: =+AT7+AT11 -> 2377750.6 | AU3: =+AU7+AU11 -> 1516973.9 | AV3: =+AV7+AV11 -> 1993749.3 | AW3: =+AW7+AW11 -> 1842459.9 | AX3: =+AX7+AX11 -> 2630530.3 | ... CP3: =+CP7+CP11 -> 6756780.6 | CT3: 6218948.9 | CU3: =+CK3/CT3-1 -> -0.26841673 | CV3: 1289255 | CW3: 1557510.4 | CX3: 2037364.1 | CY3: 2558129 | CZ3: 2856237 | DA3: 3080475 | DB3: 3579221.9 | DC3: 4213835 | DD3: 5027765.4 | DE3: 5687948.7 | DF3: =+DF7+DF11 -> 6780869.9 | DG3: =+DG7+DG11 -> 7983713.4 | DH3: =+DH7+DH11 -> 8381526.9 | DI3: =+DI7+DI11 -> 9603278 | DJ3: =+DJ7+DJ11 -> 11004890 | DK3: =+DK7+DK11 -> 12956886 | DL3: =+DL7+DL11 -> 10341605 | DM3: =+DM7+DM11 -> 14391001 | ... DV3: =+DV7+DV11 -> 28682678 | DY3: 21984945 | DZ3: 23787214
A4: var y-o-y | G4: 0.13757344 | H4: 0.16261636 | I4: 0.21507148 | J4: 0.27276601 | K4: 0.32806283 | L4: 0.34129871 | M4: 0.32815042 | N4: 0.26484901 | O4: 0.29444384 | P4: 0.2817903 | Q4: 0.27486957 | R4: 0.20634589 | S4: 0.23898866 | T4: 0.14596905 | U4: 0.13345943 | V4: 0.020050576 | W4: -0.036750276 | X4: 0.075767088 | Y4: 0.082434516 | Z4: 0.15013109 | AA4: 0.20769002 | AB4: 0.14307756 | AC4: 0.16741981 | AD4: 0.14879931 | AE4: 0.19164505 | AF4: 0.18616077 | AG4: 0.15351779 | AH4: 0.17936552 | AI4: 0.18777203 | AJ4: 0.1411902 | AK4: 0.22051868 | AL4: 0.21797625 | AM4: 0.17540099 | AN4: 0.10929713 | AO4: 0.12870718 | AP4: 0.12534158 | AQ4: =AQ3/AM3-1 -> 0.12476453 | AR4: =AR3/AN3-1 -> 0.18174759 | AS4: =AS3/AO3-1 -> 0.17413434 | AT4: =AT3/AP3-1 -> 0.25053286 | AU4: =AU3/AQ3-1 -> 0.24898404 | AV4: =AV3/AR3-1 -> 0.22302647 | AW4: =AW3/AS3-1 -> 0.18229466 | AX4: =AX3/AT3-1 -> 0.10631041 | ... CP4: =CP3/CL3-1 -> 0.086482727 | CT4: 0.049689405 | CW4: 0.20807009 | CX4: 0.30809018 | CY4: 0.2556072 | CZ4: 0.11653361 | DA4: 0.078508191 | DB4: 0.16190583 | DC4: 0.17730479 | DD4: 0.19315667 | DE4: 0.13130749 | DF4: =DF3/DE3-1 -> 0.19214682 | DG4: =DG3/DF3-1 -> 0.17738779 | DH4: =DH3/DG3-1 -> 0.04982813 | DI4: =DI3/DH3-1 -> 0.14576713 | DJ4: =DJ3/DI3-1 -> 0.14595137 | DK4: =DK3/DJ3-1 -> 0.17737538 | DL4: =DL3/DK3-1 -> -0.20184487 | DM4: =DM3/DL3-1 -> 0.39156359 | ... DV4: =DV3/DU3-1 -> 0.069429319 | DY4: 0.071051375 | DZ4: 0.081977441
A5: var q-o-q | D5: 0.41632903 | E5: -0.13095895 | F5: 0.58552195 | G5: -0.41708835 | H5: 0.44750856 | I5: -0.09174941 | J5: 0.66080637 | K5: -0.39176306 | L5: 0.46193487 | M5: -0.10065268 | N5: 0.58165014 | O5: -0.37753158 | P5: 0.44764407 | Q5: -0.10550851 | R5: 0.49663715 | S5: -0.36068808 | T5: 0.33895924 | U5: -0.11527295 | V5: 0.34689036 | W5: -0.39628775 | X5: 0.49536329 | Y5: -0.10978956 | Z5: 0.43112627 | AA5: -0.36607465 | AB5: 0.41536006 | AC5: -0.090832201 | AD5: 0.40829962 | AE5: -0.3424317 | AF5: 0.40884618 | AG5: -0.11585237 | AH5: 0.43985644 | AI5: -0.33774456 | AJ5: 0.3535943 | AK5: -0.054391901 | AL5: 0.43685711 | AM5: -0.36089418 | AN5: 0.27746895 | AO5: -0.037846018 | AP5: 0.43257266 | AQ5: =AQ3/AP3-1 -> -0.3612219 | AR5: =AR3/AQ3-1 -> 0.34218836 | AS5: =AS3/AR3-1 -> -0.04404457 | AT5: =AT3/AS3-1 -> 0.52578724 | AU5: =AU3/AT3-1 -> -0.36201305 | AV5: =AV3/AU3-1 -> 0.31429373 | AW5: =AW3/AV3-1 -> -0.075881817 | AX5: =AX3/AW3-1 -> 0.42772726 | ... CP5: =CP3/CO3-1 -> 0.37583222 | CT5: 0.36689839
A7: Vendas de Merc. | J7: 552336 | K7: 332565 | L7: 486121 | M7: 431726 | N7: 692534 | O7: 411087 | P7: 602910 | Q7: 531794 | R7: 823372 | S7: 506525 | T7: 687179 | U7: 595212 | V7: 827297 | W7: 477646 | X7: 741885 | Y7: 646283 | Z7: 953299 | AA7: 579418 | AB7: 842527 | AC7: 755462 | AD7: 1095680.8 | AE7: 687489.3 | AF7: 997743.67 | AG7: 873479.73 | AH7: 1292613.1 | AI7: 823199.37 | AJ7: 1137234.5 | AK7: 1067982.5 | AL7: 1574704.8 | AM7: 966274.06 | AN7: 1259455 | AO7: 1205849.2 | AP7: 1772329.2 | AQ7: =+AQ30/(1+AQ20) -> 1083003.2 | AR7: =+AR30/(1+AR20) -> 1477482.8 | AS7: =+AS30/(1+AS20) -> 1392237.2 | AT7: =+AT30/(1+AT20) -> 2220220.2 | AU7: =+AU30/(1+AU20) -> 1344113.6 | AV7: =+AV30/(1+AV20) -> 1800615.6 | AW7: =+AW30/(1+AW20) -> 1659858.9 | AX7: =+AX30/(1+AX20) -> 2443011.3 | ... BB7: =+BB30/(1+BB20) -> 2553553.7 | BC7: 1640494 | BD7: 2145733 | BE7: 1982620 | BF7: 2918819 | BG7: 1823658 | BH7: 2328836.5 | BI7: 2234198 | BJ7: 3618440 | BK7: 2295081 | BL7: 2807673 | BM7: 2679703 | BN7: 3991792 | BO7: 2148076 | BP7: 747075 | BQ7: 2386644 | BR7: =9408371-BQ7-BP7-BO7 -> 4126576 | BS7: 1919010 | BT7: 3151300 | BU7: 3291853 | BV7: 4935284 | BW7: 3069733 | BX7: 4392869 | BY7: 3588817 | BZ7: 4908186 | CA7: 3164222 | CB7: 4170321 | CC7: 3673020 | CD7: 5779854 | CE7: 3176292 | CF7: 4010926 | CG7: 3845619 | CH7: 5442480 | CI7: 3586902 | CJ7: 4789516 | CK7: 4026865 | CL7: =+CL30/(1+CL20) -> 5727542.6 | CM7: =+CM30/(1+CM20) -> 3842726.1 | CN7: =+CN30/(1+CN20) -> 5043327.9 | CO7: =+CO30/(1+CO20) -> 4362807.2 | CP7: =+CP30/(1+CP20) -> 6207763 | CT7: 5727542.6 | CU7: =+CK7/CT7-1 -> -0.29692971 | CV7: 0 | CW7: 552336 | CX7: 1942946 | CY7: 2369163 | CZ7: 2616213 | DA7: 2819113 | DB7: 3273087.8 | DC7: 3851325.8 | DD7: 4603121.2 | DE7: 5203907.4 | DF7: =+SUM(AQ7:AT7) -> 6172943.4 | DG7: =+SUM(AU7:AX7) -> 7247599.4 | DH7: =+SUM(AY7:BB7) -> 7607802.9 | DI7: =+SUM(BC7:BF7) -> 8687666 | DJ7: =+SUM(BG7:BJ7) -> 10005133 | DK7: =+SUM(BK7:BN7) -> 11774249 | DL7: =+SUM(BO7:BR7) -> 9408371 | DM7: =+SUM(BS7:BV7) -> 13297447 | DN7: =+SUM(BW7:BZ7) -> 15959605 | DO7: =+SUM(CA7:CD7) -> 16787417 | DP7: =+SUM(CE7:CH7) -> 16475317 | DQ7: =+SUM(CI7:CL7) -> 18130826 | DR7: =+SUM(CM7:CP7) -> 19456624 | DS7: =+DS30/(1+DS20) -> 21110106 | DT7: =+DT30/(1+DT20) -> 22738432 | DU7: =+DU30/(1+DU20) -> 24470734 | DV7: =+DV30/(1+DV20) -> 26322727 | DY7: 19925846 | DZ7: 21727261
A8: % Rec Bruta | J8: 0.96566727 | K8: 0.955934 | L8: 0.95580154 | M8: 0.94385244 | N8: 0.95725265 | O8: 0.91285521 | P8: 0.92482348 | Q8: 0.91195536 | R8: 0.94343008 | S8: 0.90782411 | T8: 0.91982106 | U8: 0.90052514 | V8: 0.92929451 | W8: 0.88872639 | X8: 0.9231065 | Y8: 0.90332757 | Z8: 0.93105152 | AA8: 0.89268541 | AB8: 0.91711405 | AC8: 0.90449902 | AD8: 0.9315034 | AE8: 0.88884388 | AF8: 0.91561931 | AG8: 0.90661732 | AH8: 0.93179533 | AI8: 0.89604842 | AJ8: 0.91450898 | AK8: 0.90821961 | AL8: 0.93199227 | AM8: 0.89483037 | AN8: 0.91300405 | AO8: 0.90852829 | AP8: 0.93212291 | AQ8: =1-AQ12 -> 0.89167894 | AR8: =1-AR12 -> 0.90633289 | AS8: =1-AS12 -> 0.89338965 | AT8: =1-AT12 -> 0.93374814 | AU8: =1-AU12 -> 0.88604925 | AV8: =1-AV12 -> 0.90313044 | AW8: =1-AW12 -> 0.90089282 | AX8: =1-AX12 -> 0.92871436 | ... CP8: =1-CP12 -> 0.91874569 | CT8: 0.92098241 | CV8: 0 | CW8: 0.35462749 | CX8: 0.95365675 | CY8: 0.92613117 | CZ8: 0.91596496 | DA8: 0.91515529 | DB8: 0.91446909 | DC8: 0.91397165 | DD8: 0.91554016 | DE8: 0.91490056 | DF8: =1-DF12 -> 0.91034683 | DG8: =1-DG12 -> 0.90779805 | DH8: =1-DH12 -> 0.90768699 | DI8: =1-DI12 -> 0.90465631 | DJ8: =1-DJ12 -> 0.90915338 | DK8: =1-DK12 -> 0.90872521 | DL8: =1-DL12 -> 0.90975927 | DM8: =1-DM12 -> 0.92401126 | ... DV8: =1-DV12 -> 0.9177221 | DY8: 0.90634049 | DZ8: 0.91340083
A9: yoy | AQ9: =+AQ7/AM7-1 -> 0.12080331 | AR9: =+AR7/AN7-1 -> 0.17311277 | AS9: =+AS7/AO7-1 -> 0.15456995 | AT9: =+AT7/AP7-1 -> 0.25271326 | AU9: =+AU7/AQ7-1 -> 0.24109848 | AV9: =+AV7/AR7-1 -> 0.21870501 | AW9: =+AW7/AS7-1 -> 0.19222421 | AX9: =+AX7/AT7-1 -> 0.10034636 | ... CP9: =+CP7/CL7-1 -> 0.08384407 | CT9: 0.052377328 | DG9: =+DG7/DF7-1 -> 0.17409134 | DH9: =+DH7/DG7-1 -> 0.049699695 | DI9: =+DI7/DH7-1 -> 0.14194152 | DJ9: =+DJ7/DI7-1 -> 0.15164793 | DK9: =+DK7/DJ7-1 -> 0.17682089 | DL9: =+DL7/DK7-1 -> -0.20093664 | DM9: =+DM7/DL7-1 -> 0.41336338 | DN9: =+DN7/DM7-1 -> 0.20020069 | ... DV9: =+DV7/DU7-1 -> 0.075681981 | DY9: 0.085424111 | DZ9: 0.090405982
BS10: =+BS7/BK7-1 -> -0.16385958 | BT10: =+BT7/BL7-1 -> 0.12238854 | BU10: =+BU7/BM7-1 -> 0.22843949 | BV10: =+BV7/BN7-1 -> 0.23635801 | BW10: =+BW7/BK7-1 -> 0.33752709 | BX10: =+BX7/BL7-1 -> 0.56459424 | BY10: =+BY7/BM7-1 -> 0.33925924 | BZ10: =+BZ7/BN7-1 -> 0.22956958 | CA10: =+CA7/BK7-1 -> 0.37869731
A11: Prod/Serv Fin. | J11: 19637.409 | K11: 15330.355 | L11: 22479.352 | M11: 25682.362 | N11: 30926 | O11: 39244 | P11: 49009 | Q11: 51342 | R11: 49371 | S11: 51430 | T11: 59900 | U11: 65749 | V11: 62945 | W11: 59804 | X11: 61798 | Y11: 69164 | Z11: 70596 | AA11: 69655 | AB11: 76145 | AC11: 79765 | AD11: 80569.113 | AE11: 85975.326 | AF11: 91949.016 | AG11: 89969.471 | AH11: 94615.463 | AI11: 95500.277 | AJ11: 106312.07 | AK11: 107925.27 | AL11: 114906.64 | AM11: 113566.42 | AN11: 120007.67 | AO11: 121406.33 | AP11: 129060.82 | AQ11: =AQ34/(1+AQ23) -> 131563.1 | AR11: =AR34/(1+AR23) -> 152693.94 | AS11: =AS34/(1+AS23) -> 166139.04 | AT11: =AT34/(1+AT23) -> 157530.41 | AU11: =AU34/(1+AU23) -> 172860.3 | AV11: =AV34/(1+AV23) -> 193133.62 | AW11: =AW34/(1+AW23) -> 182601.01 | AX11: =AX34/(1+AX23) -> 187519.04 | ... BB11: =BB34/(1+BB23) -> 201745.26 | BC11: 200210 | BD11: 221910 | BE11: 248799 | BF11: 244693 | BG11: 244199 | BH11: 254879 | BI11: 245807 | BJ11: 254872 | BK11: 257282 | BL11: 290023 | BM11: 311398 | BN11: 323934 | BO11: 330783 | BP11: 284466 | BQ11: 150024 | BR11: =933234-BQ11-BP11-BO11 -> 167961 | BS11: 232757 | BT11: 248487 | BU11: 275091 | BV11: 337219 | BW11: 414232 | BX11: 494287 | BY11: 446379 | BZ11: 509236 | CA11: 543159 | CB11: 572561 | CC11: 508796 | CD11: 526390 | CE11: 488560 | CF11: 480488 | CG11: 474595 | CH11: 482081 | CI11: 541317 | CJ11: 557650 | CK11: 522814 | CL11: =CL34/(1+CL23) -> 491406.35 | CM11: =CM34/(1+CM23) -> 537695.35 | CN11: =CN34/(1+CN23) -> 544246.41 | CO11: =CO34/(1+CO23) -> 548242.63 | CP11: =CP34/(1+CP23) -> 549017.53 | CT11: 491406.35 | CU11: =+CK11/CT11-1 -> 0.063913804 | CV11: 0 | CW11: 19637.409 | CX11: 95132 | CY11: 188966 | CZ11: 240024 | DA11: 261362 | DB11: 306134.11 | DC11: 362509.28 | DD11: 424644.25 | DE11: 484041.24 | DF11: =+SUM(AQ11:AT11) -> 607926.49 | DG11: =+SUM(AU11:AX11) -> 736113.97 | DH11: =+SUM(AY11:BB11) -> 773724.01 | DI11: =+SUM(BC11:BF11) -> 915612 | DJ11: =+SUM(BG11:BJ11) -> 999757 | DK11: =+SUM(BK11:BN11) -> 1182637 | DL11: =+SUM(BO11:BR11) -> 933234 | DM11: =+SUM(BS11:BV11) -> 1093554 | DN11: =+SUM(BW11:BZ11) -> 1864134 | DO11: =+SUM(CA11:CD11) -> 2150906 | DP11: =+SUM(CE11:CH11) -> 1925724 | DQ11: =+SUM(CI11:CL11) -> 2113187.4 | DR11: =+SUM(CM11:CP11) -> 2179201.9 | DS11: =DS34/(1+DS23) -> 2332881.2 | DT11: =DT34/(1+DT23) -> 2340487.4 | DU11: =DU34/(1+DU23) -> 2349812 | DV11: =DV34/(1+DV23) -> 2359950.6 | DY11: 2059099 | DZ11: 2059952.9
A12: % Rec Bruta | J12: 0.034332731 | K12: 0.044065995 | L12: 0.044198459 | M12: 0.056147557 | N12: 0.042747353 | O12: 0.087144789 | P12: 0.075176517 | Q12: 0.088044641 | R12: 0.056569918 | S12: 0.092175892 | T12: 0.080178937 | U12: 0.099474856 | V12: 0.070705494 | W12: 0.11127361 | X12: 0.076893502 | Y12: 0.09667243 | Z12: 0.068948476 | AA12: 0.10731459 | AB12: 0.082885948 | AC12: 0.095500984 | AD12: 0.068496597 | AE12: 0.11115612 | AF12: 0.084380686 | AG12: 0.093382683 | AH12: 0.068204669 | AI12: 0.10395158 | AJ12: 0.085491023 | AK12: 0.091780386 | AL12: 0.06800773 | AM12: 0.10516963 | AN12: 0.086995953 | AO12: 0.091471709 | AP12: 0.067877089 | AQ12: =AQ11/AQ3 -> 0.10832106 | AR12: =AR11/AR3 -> 0.093667109 | AS12: =AS11/AS3 -> 0.10661035 | AT12: =AT11/AT3 -> 0.066251861 | AU12: =AU11/AU3 -> 0.11395075 | AV12: =AV11/AV3 -> 0.096869562 | AW12: =AW11/AW3 -> 0.099107181 | AX12: =AX11/AX3 -> 0.071285641 | ... CP12: =CP11/CP3 -> 0.081254308 | CT12: 0.079017589 | CV12: 0 | CW12: 0.012608204 | CX12: 0.046693667 | CY12: 0.073868831 | CZ12: 0.084035043 | DA12: 0.084844707 | DB12: 0.085530913 | DC12: 0.08602835 | DD12: 0.084459838 | DE12: 0.085099439 | DF12: =DF11/DF3 -> 0.089653171 | DG12: =DG11/DG3 -> 0.092201954 | DH12: =DH11/DH3 -> 0.092313013 | DI12: =DI11/DI3 -> 0.095343694 | DJ12: =DJ11/DJ3 -> 0.090846618 | DK12: =DK11/DK3 -> 0.091274786 | DL12: =DL11/DL3 -> 0.090240731 | DM12: =DM11/DM3 -> 0.075988738 | ... DV12: =DV11/DV3 -> 0.082277903 | DY12: 0.093659505 | DZ12: 0.086599166
A13: yoy | AQ13: =+AQ11/AM11-1 -> 0.15846831 | AR13: =+AR11/AN11-1 -> 0.27236816 | AS13: =+AS11/AO11-1 -> 0.36845451 | AT13: =+AT11/AP11-1 -> 0.2205905 | AU13: =+AU11/AQ11-1 -> 0.31389653 | AV13: =+AV11/AR11-1 -> 0.26484141 | AW13: =+AW11/AS11-1 -> 0.099085507 | AX13: =+AX11/AT11-1 -> 0.19036726 | ... CP13: =+CP11/CL11-1 -> 0.11723735 | CT13: 0.01934395 | DG13: =+DG11/DF11-1 -> 0.21086017 | DH13: =+DH11/DG11-1 -> 0.051092676 | DI13: =+DI11/DH11-1 -> 0.18338321 | DJ13: =+DJ11/DI11-1 -> 0.091900281 | DK13: =+DK11/DJ11-1 -> 0.18292445 | DL13: =+DL11/DK11-1 -> -0.2108872 | DM13: =+DM11/DL11-1 -> 0.17178971 | DN13: =+DN11/DM11-1 -> 0.70465656 | ... DV13: =+DV11/DU11-1 -> 0.0043146563 | DY13: -0.05060291 | DZ13: 0.00041467961
A15: Deduções | C15: -53924 | D15: -86679 | E15: -73481 | F15: -121367 | G15: -51753 | H15: -83403 | I15: -72528 | J15: -147698.41 | K15: -81143.355 | L15: -127740.35 | M15: -110621.36 | N15: -186621 | O15: -102776 | P15: -161047 | Q15: -139124 | R15: -224243 | S15: -126158 | T15: -180732 | U15: -149591 | V15: -216749 | W15: -118316 | X15: -190269 | Y15: -163136 | Z15: -245126 | AA15: -143378 | AB15: -216654 | AC15: -191354 | AD15: -276497.87 | AE15: -174697.63 | AF15: -253273.68 | AG15: -221527.2 | AH15: -325794.54 | AI15: -209423.65 | AJ15: -288092.61 | AK15: -270849.74 | AL15: -396891.4 | AM15: -245987.48 | AN15: -319060.69 | AO15: -305820.52 | AP15: -446697.97 | AQ15: =+AQ18+AQ21 -> -275952.27 | AR15: =+AR18+AR21 -> -374948.71 | AS15: =+AS18+AS21 -> -354573.28 | AT15: =+AT18+AT21 -> -559351.64 | AU15: =+AU18+AU21 -> -343026.88 | AV15: =+AV18+AV21 -> -457348.27 | AW15: =+AW18+AW21 -> -421854.95 | AX15: =+AX18+AX21 -> -616285.29 | ... CP15: =+CP18+CP21 -> -1506598.7 | CT15: -1391131.5 | CV15: -335451 | CW15: -355382.41 | CX15: -506126.07 | CY15: -627190 | CZ15: -673230 | DA15: -716847 | DB15: -827883.87 | DC15: -975293.05 | DD15: -1165257.4 | DE15: -1317566.7 | DF15: =+DF18+DF21 -> -1564825.9 | DG15: =+DG18+DG21 -> -1838515.4 | DH15: =+DH18+DH21 -> -1929946.9 | DI15: =+DI18+DI21 -> -2158973 | DJ15: =+DJ18+DJ21 -> -2578348.5 | DK15: =+DK18+DK21 -> -3368449 | DL15: =+DL18+DL21 -> -2804425 | DM15: =+DM18+DM21 -> -3819444.8 | ... DV15: =+DV18+DV21 -> -6385492.3 | DY15: -4809653.1 | DZ15: -5250745.1
A16: % deduções | C16: -0.23417015 | D16: -0.26576585 | E16: -0.25925077 | F16: -0.27006814 | G16: -0.19756296 | H16: -0.21995332 | I16: -0.21059539 | J16: -0.25822601 | K16: -0.2332407 | L16: -0.25116057 | M16: -0.24184377 | N16: -0.25795621 | O16: -0.22822324 | P16: -0.24703529 | Q16: -0.23857899 | R16: -0.25694047 | S16: -0.22610784 | T16: -0.24191819 | U16: -0.22632349 | V16: -0.243472 | W16: -0.22014327 | X16: -0.23674633 | Y16: -0.22801969 | Z16: -0.23940541 | AA16: -0.22089657 | AB16: -0.2358339 | AC16: -0.22910418 | AD16: -0.23506729 | AE16: -0.22586376 | AF16: -0.23242671 | AG16: -0.22993138 | AH16: -0.23485282 | AI16: -0.2279566 | AJ16: -0.23167013 | AK16: -0.23033248 | AL16: -0.234901 | AM16: -0.22779983 | AN16: -0.23129345 | AO16: -0.23041571 | AP16: -0.23493233 | AQ16: =AQ15/AQ3 -> -0.22720231 | AR16: =AR15/AR3 -> -0.23000495 | AS16: =AS15/AS3 -> -0.22752738 | AT16: =AT15/AT3 -> -0.23524403 | AU16: =AU15/AU3 -> -0.22612577 | AV16: =AV15/AV3 -> -0.22939106 | AW16: =AW15/AW3 -> -0.22896289 | AX16: =AX15/AX3 -> -0.23428177 | ... CP16: =CP15/CP3 -> -0.22297582 | CT16: -0.22369239 | CV16: -0.2601898 | CW16: -0.22817338 | CX16: -0.24842201 | CY16: -0.24517528 | CZ16: -0.23570523 | DA16: -0.23270664 | DB16: -0.23130275 | DC16: -0.23145022 | DD16: -0.23176447 | DE16: -0.2316418 | DF16: =DF15/DF3 -> -0.23077067 | DG16: =DG15/DG3 -> -0.23028324 | DH16: =DH15/DH3 -> -0.23026197 | DI16: =DI15/DI3 -> -0.22481626 | DJ16: =DJ15/DJ3 -> -0.23429118 | DK16: =DK15/DK3 -> -0.25997365 | DL16: =DL15/DL3 -> -0.27117889 | DM16: =DM15/DM3 -> -0.26540509 | ... DV16: =DV15/DV3 -> -0.22262539 | DY16: -0.21877031 | DZ16: -0.22073813
A18: Imp vdas e merc | O18: -100794 | P18: -158555 | Q18: -136436 | R18: -221650 | S18: -123142 | T18: -177333 | U18: -146178 | V18: -213539 | W18: -114997 | X18: -187153 | Y18: -159553 | Z18: -241441 | AA18: -139172 | AB18: -212538 | AC18: -186722 | AD18: -271971.76 | AE18: -169782.3 | AF18: -248090.67 | AG18: -216403.73 | AH18: -320433.07 | AI18: -204000.37 | AJ18: -282065.54 | AK18: -264722.48 | AL18: -390372.77 | AM18: -239543.06 | AN18: -312252.02 | AO18: -298931.19 | AP18: -439375.16 | AQ18: =+AQ30-AQ7 -> -268487.16 | AR18: =+AR30-AR7 -> -366284.77 | AS18: =+AS30-AS7 -> -345146.24 | AT18: =+AT30-AT7 -> -550413.24 | AU18: =+AU30-AU7 -> -333218.58 | AV18: =+AV30-AV7 -> -446389.65 | AW18: =+AW30-AW7 -> -411493.94 | AX18: =+AX30-AX7 -> -605645.26 | ... CP18: =+CP30-CP7 -> -1466619.4 | CT18: -1355526.8 | CV18: 0 | CW18: 0 | CX18: 0 | CY18: -617435 | CZ18: -660192 | DA18: -703144 | DB18: -810403.76 | DC18: -954709.77 | DD18: -1141161.2 | DE18: -1290101.4 | DF18: =+SUM(AQ18:AT18) -> -1530331.4 | DG18: =+SUM(AU18:AX18) -> -1796747.4 | DH18: =+SUM(AY18:BB18) -> -1886044.9 | DI18: =+SUM(BC18:BF18) -> -2087593 | DJ18: =+SUM(BG18:BJ18) -> -2519699.5 | DK18: =+SUM(BK18:BN18) -> -3299556 | DL18: =+SUM(BO18:BR18) -> -2747800 | DM18: =+SUM(BS18:BV18) -> -3741720.6 | DN18: =+SUM(BW18:BZ18) -> -4383810 | DO18: =+SUM(CA18:CD18) -> -5081077 | DP18: =+SUM(CE18:CH18) -> -3803367 | DQ18: =+SUM(CI18:CL18) -> -4273151.8 | DR18: =+SUM(CM18:CP18) -> -4595843.6 | DS18: =+DS30-DS7 -> -4980866.7 | DT18: =+DT30-DT7 -> -5368052 | DU18: =+DU30-DU7 -> -5775403.9 | DV18: =+DV30-DV7 -> -6213362.3 | DY18: -4648191 | DZ18: -5094727.4
A19: % deduções | O19: 0.98071534 | P19: 0.98452626 | Q19: 0.98067911 | R19: 0.98843665 | S19: 0.97609347 | T19: 0.98119315 | U19: 0.97718446 | V19: 0.98519024 | W19: 0.971948 | X19: 0.98362319 | Y19: 0.97803673 | Z19: 0.98496691 | AA19: 0.97066496 | AB19: 0.98100197 | AC19: 0.97579356 | AD19: 0.98363057 | AE19: 0.97186381 | AF19: 0.97953591 | AG19: 0.97687205 | AH19: 0.98354342 | AI19: 0.9741038 | AJ19: 0.9790794 | AK19: 0.97737762 | AL19: 0.98357577 | AM19: 0.97380182 | AN19: 0.97866026 | AO19: 0.97747263 | AP19: 0.98360679 | AQ19: =AQ18/AQ15 -> 0.97294785 | AR19: =AR18/AR15 -> 0.976893 | AS19: =AS18/AS15 -> 0.973413 | AT19: =AT18/AT15 -> 0.98402006 | AU19: =AU18/AU15 -> 0.9714066 | AV19: =AV18/AV15 -> 0.97603879 | AW19: =AW18/AW15 -> 0.9754394 | AX19: =AX18/AX15 -> 0.98273521 | ... CP19: =CP18/CP15 -> 0.97346387 | CT19: 0.97440594 | CV19: 0 | CW19: 0 | CX19: 0 | CY19: 0.9844465 | CZ19: 0.98063366 | DA19: 0.98088434 | DB19: 0.97888579 | DC19: 0.97889529 | DD19: 0.97932109 | DE19: 0.97915457 | DF19: =DF18/DF15 -> 0.97795634 | DG19: =DG18/DG15 -> 0.97728168 | DH19: =DH18/DH15 -> 0.97725222 | DI19: =DI18/DI15 -> 0.96693798 | DJ19: =DJ18/DJ15 -> 0.97725327 | DK19: =DK18/DK15 -> 0.97954756 | DL19: =DL18/DL15 -> 0.9798087 | DM19: =DM18/DM15 -> 0.97965038 | ... DV19: =DV18/DV15 -> 0.97304357 | DY19: 0.96642958 | DZ19: 0.97028656
A20: % Rec Bruta Merc | O20: -0.24518897 | P20: -0.26298287 | Q20: -0.25655799 | R20: -0.26919788 | S20: -0.2431114 | T20: -0.2580594 | U20: -0.24558981 | V20: -0.25811649 | W20: -0.2407578 | X20: -0.25226686 | Y20: -0.24687792 | Z20: -0.25326891 | AA20: -0.24019275 | AB20: -0.25226254 | AC20: -0.24716266 | AD20: -0.24822171 | AE20: -0.24695992 | AF20: -0.24865171 | AG20: -0.247749 | AH20: -0.24789558 | AI20: -0.24781405 | AJ20: -0.24802759 | AK20: -0.24787156 | AL20: -0.24790219 | AM20: -0.24790385 | AN20: -0.2479263 | AO20: -0.24790097 | AP20: -0.24790833 | AQ20: =+AVERAGE(AM20:AP20) -> -0.24790986 | AR20: =+AVERAGE(AN20:AQ20) -> -0.24791136 | AS20: =+AVERAGE(AO20:AR20) -> -0.24790763 | AT20: =+AVERAGE(AP20:AS20) -> -0.2479093 | AU20: =+AVERAGE(AQ20:AT20) -> -0.24790954 | AV20: =+AVERAGE(AR20:AU20) -> -0.24790946 | AW20: =+AVERAGE(AS20:AV20) -> -0.24790898 | AX20: =+AVERAGE(AT20:AW20) -> -0.24790932 | ... BF20: =+AVERAGE(BB20:BE20) -> -0.24790927 | BG20: =+BG18/BG7 -> -0.2329598 | BH20: =+BH18/BH7 -> -0.23565653 | BI20: =+BI18/BI7 -> -0.23397076 | BJ20: =+BJ18/BJ7 -> -0.2828064 | BK20: =+BK18/BK7 -> -0.28092429 | BL20: =+BL18/BL7 -> -0.28076596 | BM20: =+BM18/BM7 -> -0.27905294 | BN20: =+BN18/BN7 -> -0.28025859 | ... CK20: =+CK18/CK7 -> -0.23534834 | CL20: =+AVERAGE(CJ20:CK20) -> -0.23666814 | CM20: =+AVERAGE(CK20:CL20) -> -0.23600824 | CN20: =+AVERAGE(CL20:CM20) -> -0.23633819 | CO20: =+AVERAGE(CM20:CN20) -> -0.23617321 | CP20: =+AVERAGE(CN20:CO20) -> -0.2362557 | CT20: -0.23666814 | CV20: #DIV/0! | CW20: 0 | CX20: 0 | CY20: -0.26061314 | CZ20: -0.25234643 | DA20: -0.2494203 | DB20: -0.2475961 | DC20: -0.2478912 | DD20: -0.2479103 | DE20: -0.24791014 | DF20: =DF18/DF7 -> -0.24790952 | DH20: =DH18/DH7 -> -0.24790927 | DI20: =DI18/DI7 -> -0.24029388 | DJ20: =DJ18/DJ7 -> -0.2518407 | DK20: =DK18/DK7 -> -0.28023494 | DL20: =DL18/DL7 -> -0.29205906 | DM20: =DM18/DM7 -> -0.28138639 | DN20: =DN18/DN7 -> -0.27468161 | DO20: =DO18/DO7 -> -0.30267176 | ... DR20: =DR18/DR7 -> -0.23620971 | DS20: =+AVERAGE(DQ20:DR20) -> -0.23594703 | DT20: =+AVERAGE(DR20:DS20) -> -0.23607837 | DU20: =+AVERAGE(DS20:DT20) -> -0.2360127 | DV20: =+AVERAGE(DT20:DU20) -> -0.23604554 | DY20: -0.23327447 | DZ20: -0.23448549
A21: Imp. Prod/serv fin. | O21: -1982 | P21: -2492 | Q21: -2688 | R21: -2593 | S21: -3016 | T21: -3399 | U21: -3413 | V21: -3210 | W21: -3319 | X21: -3116 | Y21: -3583 | Z21: -3685 | AA21: -4206 | AB21: -4116 | AC21: -4632 | AD21: -4526.1127 | AE21: -4915.3262 | AF21: -5183.0161 | AG21: -5123.4708 | AH21: -5361.4626 | AI21: -5423.2773 | AJ21: -6027.0715 | AK21: -6127.2662 | AL21: -6518.6359 | AM21: -6444.4237 | AN21: -6808.671 | AO21: -6889.3307 | AP21: -7322.8157 | AQ21: =+AQ34-AQ11 -> -7465.1034 | AR21: =+AR34-AR11 -> -8663.9396 | AS21: =+AS34-AS11 -> -9427.0407 | AT21: =+AT34-AT11 -> -8938.4059 | AU21: =+AU34-AU11 -> -9808.3047 | AV21: =+AV34-AV11 -> -10958.618 | AW21: =+AW34-AW11 -> -10361.012 | AX21: =+AX34-AX11 -> -10640.038 | ... CP21: =+CP34-CP11 -> -39979.297 | CT21: -35604.697 | CV21: 0 | CW21: 0 | CX21: 0 | CY21: -9755 | CZ21: -13038 | DA21: -13703 | DB21: -17480.113 | DC21: -20583.276 | DD21: -24096.251 | DE21: -27465.241 | DF21: =+SUM(AQ21:AT21) -> -34494.49 | DG21: =+SUM(AU21:AX21) -> -41767.973 | DH21: =+SUM(AY21:BB21) -> -43902.006 | DI21: =+SUM(BC21:BF21) -> -71380 | DJ21: =+SUM(BG21:BJ21) -> -58649 | DK21: =+SUM(BK21:BN21) -> -68893 | DL21: =+SUM(BO21:BR21) -> -56625 | DM21: =+SUM(BS21:BV21) -> -77724.251 | DN21: =+SUM(BW21:BZ21) -> -168792 | DO21: =+SUM(CA21:CD21) -> -209397 | DP21: =+SUM(CE21:CH21) -> -161308 | DQ21: =+SUM(CI21:CL21) -> -154429.7 | DR21: =+SUM(CM21:CP21) -> -158806.9 | DS21: =+DS34-DS11 -> -170245.41 | DT21: =+DT34-DT11 -> -170680.44 | DU21: =+DU34-DU11 -> -171420.7 | DV21: =+DV34-DV11 -> -172130.06 | DY21: -161462.06 | DZ21: -156017.69
A22: % deduções | O22: 0.019284658 | P22: 0.015473744 | Q22: 0.019320894 | R22: 0.011563349 | S22: 0.02390653 | T22: 0.018806852 | U22: 0.022815544 | V22: 0.014809757 | W22: 0.028051996 | X22: 0.016376814 | Y22: 0.02196327 | Z22: 0.015033085 | AA22: 0.029335044 | AB22: 0.018998034 | AC22: 0.024206445 | AD22: 0.016369431 | AE22: 0.028136194 | AF22: 0.020464093 | AG22: 0.023127954 | AH22: 0.016456576 | AI22: 0.025896203 | AJ22: 0.020920604 | AK22: 0.022622381 | AL22: 0.01642423 | AM22: 0.026198178 | AN22: 0.021339736 | AO22: 0.022527366 | AP22: 0.016393215 | AQ22: =AQ21/AQ15 -> 0.027052155 | AR22: =AR21/AR15 -> 0.023106999 | AS22: =AS21/AS15 -> 0.026587003 | AT22: =AT21/AT15 -> 0.01597994 | AU22: =AU21/AU15 -> 0.0285934 | AV22: =AV21/AV15 -> 0.02396121 | AW22: =AW21/AW15 -> 0.024560603 | AX22: =AX21/AX15 -> 0.017264793 | ... CP22: =CP21/CP15 -> 0.026536129 | CT22: 0.025594056 | CV22: 0 | CW22: 0 | CX22: 0 | CY22: 0.015553501 | CZ22: 0.019366338 | DA22: 0.019115655 | DB22: 0.021114209 | DC22: 0.021104709 | DD22: 0.020678908 | DE22: 0.020845428 | DF22: =DF21/DF15 -> 0.02204366 | DG22: =DG21/DG15 -> 0.022718315 | DH22: =DH21/DH15 -> 0.022747779 | DI22: =DI21/DI15 -> 0.033062016 | DJ22: =DJ21/DJ15 -> 0.022746731 | DK22: =DK21/DK15 -> 0.02045244 | DL22: =DL21/DL15 -> 0.020191305 | DM22: =DM21/DM15 -> 0.02034962 | ... DV22: =DV21/DV15 -> 0.026956427 | DY22: 0.033570417 | DZ22: 0.029713438
A23: % Rec Bruta Serv Fin | O23: -0.050504536 | P23: -0.050847803 | Q23: -0.052354797 | R23: -0.052520711 | S23: -0.058642815 | T23: -0.056744574 | U23: -0.051909535 | V23: -0.050996902 | W23: -0.05549796 | X23: -0.050422344 | Y23: -0.051804407 | Z23: -0.052198425 | AA23: -0.060383318 | AB23: -0.054054764 | AC23: -0.058070582 | AD23: -0.056176772 | AE23: -0.057171359 | AF23: -0.056368369 | AG23: -0.056946771 | AH23: -0.056665818 | AI23: -0.056788079 | AJ23: -0.056692259 | AK23: -0.056773232 | AL23: -0.056729847 | AM23: -0.056745854 | AN23: -0.056735298 | AO23: -0.056746058 | AP23: -0.056739264 | AQ23: =+AVERAGE(AM23:AP23) -> -0.056741619 | AR23: =+AVERAGE(AN23:AQ23) -> -0.05674056 | AS23: =+AVERAGE(AO23:AR23) -> -0.056741875 | AT23: =+AVERAGE(AP23:AS23) -> -0.056740829 | AU23: =+AVERAGE(AQ23:AT23) -> -0.056741221 | AV23: =+AVERAGE(AR23:AU23) -> -0.056741121 | AW23: =+AVERAGE(AS23:AV23) -> -0.056741262 | AX23: =+AVERAGE(AT23:AW23) -> -0.056741108 | ... BF23: =+AVERAGE(BB23:BE23) -> -0.056741167 | BG23: =+BG21/BG11 -> -0.060331942 | BH23: =+BH21/BH11 -> -0.058117774 | BI23: =+BI21/BI11 -> -0.056873889 | BJ23: =+BJ21/BJ11 -> -0.059335667 | BK23: =+BK21/BK11 -> -0.060252952 | BL23: =+BL21/BL11 -> -0.059971106 | BM23: =+BM21/BM11 -> -0.056413336 | BN23: =+BN21/BN11 -> -0.056897393 | ... CK23: =+CK21/CK11 -> -0.073622742 | CL23: =+AVERAGE(CJ23:CK23) -> -0.072454695 | CM23: =+AVERAGE(CK23:CL23) -> -0.073038718 | CN23: =+AVERAGE(CL23:CM23) -> -0.072746707 | CO23: =+AVERAGE(CM23:CN23) -> -0.072892713 | CP23: =+AVERAGE(CN23:CO23) -> -0.07281971 | CT23: -0.072454695 | CV23: #DIV/0! | CW23: 0 | CX23: 0 | CY23: -0.051623043 | CZ23: -0.054319568 | DA23: -0.052429198 | DB23: -0.057099526 | DC23: -0.056779997 | DD23: -0.056744559 | DE23: -0.056741531 | DF23: =DF21/DF11 -> -0.056741218 | DG23: =DG21/DG11 -> -0.056741176 | DH23: =DH21/DH11 -> -0.05674117 | DI23: =DI21/DI11 -> -0.077958786 | DJ23: =DJ21/DJ11 -> -0.058663255 | DK23: =DK21/DK11 -> -0.058253716 | DL23: =DL21/DL11 -> -0.060676101 | DM23: =DM21/DM11 -> -0.071074909 | ... DR23: =DR21/DR11 -> -0.072873882 | DS23: =+AVERAGE(DQ23:DR23) -> -0.07297646 | DT23: =+AVERAGE(DR23:DS23) -> -0.072925171 | DU23: =+AVERAGE(DS23:DT23) -> -0.072950815 | DV23: =+AVERAGE(DT23:DU23) -> -0.072937993 | DY23: -0.078413937 | DZ23: -0.075738475
AV25: =+AV26-AU26 -> 362454 | BD25: =+BD26-BC26 -> 415808 | BH25: =+BH26-BG26 -> 391812 | BL25: =+BL26-BK26 -> 399887 | BP25: =+BP26-BO26 -> -1055255 | BX25: =+BX26-BW26 -> 1013313 | CB25: =+CB26-CA26 -> 728791
A26: Receita Liq | C26: 176353 | D26: 239469 | E26: 209955 | F26: 328027 | G26: 210204 | H26: 295782 | I26: 271867 | J26: 424275 | K26: 266752 | L26: 380860 | M26: 346787 | N26: 536839 | O26: 347555 | P26: 490872 | Q26: 444012 | R26: 648500 | S26: 431797 | T26: 566347 | U26: 511370 | V26: 673493 | W26: 419134 | X26: 613414 | Y26: 552311 | Z26: 778769 | AA26: 505695 | AB26: 702018 | AC26: 643873 | AD26: 899752 | AE26: 598767 | AF26: 836419 | AG26: 741922 | AH26: 1061434 | AI26: 709276 | AJ26: 955454 | AK26: 905058 | AL26: 1292720 | AM26: 833853 | AN26: 1060402 | AO26: 1021435 | AP26: 1454692 | AQ26: =AQ30+AQ34 -> 938614 | AR26: =AR30+AR34 -> 1255228 | AS26: =AS30+AS34 -> 1203803 | AT26: =AT30+AT34 -> 1818399 | AU26: =AU30+AU34 -> 1173947 | AV26: =AV30+AV34 -> 1536401 | AW26: =AW30+AW34 -> 1420605 | AX26: =AX30+AX34 -> 2014245 | ... CP26: =CP30+CP34 -> 5250181.9 | CT26: 4827817.4 | CU26: =+CK26/CT26-1 -> -0.26188758 | CV26: 953804 | CW26: 1202128 | CX26: 1531238 | CY26: 1930939 | CZ26: 2183007 | DA26: 2363628 | DB26: 2751338 | DC26: 3238542 | DD26: 3862508 | DE26: 4370382 | DF26: =+SUM(AQ26:AT26) -> 5216044 | DG26: =+SUM(AU26:AX26) -> 6145198 | DH26: =+SUM(AY26:BB26) -> 6451580 | DI26: =+SUM(BC26:BF26) -> 7444305 | DJ26: =+SUM(BG26:BJ26) -> 8426541 | DK26: =+SUM(BK26:BN26) -> 9588437 | DL26: =+SUM(BO26:BR26) -> 7537180 | DM26: =DM30+DM34 -> 10571556 | DN26: =DN30+DN34 -> 13271137 | DO26: =DO30+DO34 -> 13647849 | DP26: =DP30+DP34 -> 14436366 | DQ26: =DQ30+DQ34 -> 15816431 | DR26: =DR30+DR34 -> 16881176 | DS26: =DS30+DS34 -> 18291875 | DT26: =DT30+DT34 -> 19540187 | ... DV26: =DV30+DV34 -> 22297186 | DY26: 17175292 | DZ26: 18536469
