Workbook
Name \0: [1]Ativo!#REF!
Name \a: #REF!
Name \b: #REF!
Name \c: #REF!
Name \D: #REF!
Name \DCS: #REF!
Name \e: #REF!
Name \g: #REF!
Name \i: #REF!
Name \k: #REF!
Name \l: #REF!
Name \m: #REF!
Name \N: #REF!
Name \o: #REF!
Name \p: #REF!
Name \PRINT_BALANCO: #REF!
Name \s: #REF!
Name \x: #REF!
Name \Z: #REF!
Name _: #REF!
Name _: #REF!
Name ______________________cen301: {#N/A,#N/A,FALSE,"SIM95"}
Name ______________________cen31: {#N/A,#N/A,FALSE,"SIM95"}
Name ______________________mil1: {#N/A,#N/A,FALSE,"QuadroAntigo"}
Name ______________________mil2: {#N/A,#N/A,FALSE,"Lojas por Faturamento (R$)"}
Name ____________________a4: {"SCH54",#N/A,FALSE,"upside";"SCH55",#N/A,FALSE,"upside"}
Name ____________________E21: {"Despesas Diferidas Indedutíveis de 1998",#N/A,FALSE,"Impressão"}
Name ___________________a4: {"SCH54",#N/A,FALSE,"upside";"SCH55",#N/A,FALSE,"upside"}
Name ___________________CC1: {#N/A,#N/A,FALSE,"1321";#N/A,#N/A,FALSE,"1324";#N/A,#N/A,FALSE,"1333";#N/A,#N/A,FALSE,"1371"}
Name ___________________E21: {"Despesas Diferidas Indedutíveis de 1998",#N/A,FALSE,"Impressão"}
Name ___________________Jul04: {#N/A,#N/A,FALSE,"Count";#N/A,#N/A,FALSE,"Cash-Flow";#N/A,#N/A,FALSE,"Assumptions";#N/A,#N/A,FALSE,"Right"}
Name ___________________T2: {#N/A,#N/A,FALSE,"1321";#N/A,#N/A,FALSE,"1324";#N/A,#N/A,FALSE,"1333";#N/A,#N/A,FALSE,"1371"}
Name __________________a4: {"SCH54",#N/A,FALSE,"upside";"SCH55",#N/A,FALSE,"upside"}
Name __________________E21: {"Despesas Diferidas Indedutíveis de 1998",#N/A,FALSE,"Impressão"}
Name __________________Jul04: {#N/A,#N/A,FALSE,"Count";#N/A,#N/A,FALSE,"Cash-Flow";#N/A,#N/A,FALSE,"Assumptions";#N/A,#N/A,FALSE,"Right"}
Name _________________a4: {"SCH54",#N/A,FALSE,"upside";"SCH55",#N/A,FALSE,"upside"}
Name _________________E21: {"Despesas Diferidas Indedutíveis de 1998",#N/A,FALSE,"Impressão"}
Name _________________Jul04: {#N/A,#N/A,FALSE,"Count";#N/A,#N/A,FALSE,"Cash-Flow";#N/A,#N/A,FALSE,"Assumptions";#N/A,#N/A,FALSE,"Right"}
Name ________________a4: {"SCH54",#N/A,FALSE,"upside";"SCH55",#N/A,FALSE,"upside"}
Name ________________E21: {"Despesas Diferidas Indedutíveis de 1998",#N/A,FALSE,"Impressão"}
Name ________________Jul04: {#N/A,#N/A,FALSE,"Count";#N/A,#N/A,FALSE,"Cash-Flow";#N/A,#N/A,FALSE,"Assumptions";#N/A,#N/A,FALSE,"Right"}
Name _______________a4: {"SCH54",#N/A,FALSE,"upside";"SCH55",#N/A,FALSE,"upside"}
Name _______________E21: {"Despesas Diferidas Indedutíveis de 1998",#N/A,FALSE,"Impressão"}
Name _______________Jul04: {#N/A,#N/A,FALSE,"Count";#N/A,#N/A,FALSE,"Cash-Flow";#N/A,#N/A,FALSE,"Assumptions";#N/A,#N/A,FALSE,"Right"}
Name ______________a4: {"SCH54",#N/A,FALSE,"upside";"SCH55",#N/A,FALSE,"upside"}
Name ______________E21: {"Despesas Diferidas Indedutíveis de 1998",#N/A,FALSE,"Impressão"}
Name ______________Jul04: {#N/A,#N/A,FALSE,"Count";#N/A,#N/A,FALSE,"Cash-Flow";#N/A,#N/A,FALSE,"Assumptions";#N/A,#N/A,FALSE,"Right"}
Name _____________a4: {"SCH54",#N/A,FALSE,"upside";"SCH55",#N/A,FALSE,"upside"}
Name _____________E21: {"Despesas Diferidas Indedutíveis de 1998",#N/A,FALSE,"Impressão"}
Name _____________Jul04: {#N/A,#N/A,FALSE,"Count";#N/A,#N/A,FALSE,"Cash-Flow";#N/A,#N/A,FALSE,"Assumptions";#N/A,#N/A,FALSE,"Right"}
Name _____________k1: {"'Generacion'!$A$2:$N$27"}
Name _____________m1: {"'Generacion'!$A$2:$N$27"}
Name _____________n1: {"'Generacion'!$A$2:$N$27"}
Name _____________qw1: {"'Generacion'!$A$2:$N$27"}
Name _____________qw3: {"'Generacion'!$A$2:$N$27"}
Name _____________tc2: 8.07
Name _____________y1: {"'Generacion'!$A$2:$N$27"}
Name ____________a4: {"SCH54",#N/A,FALSE,"upside";"SCH55",#N/A,FALSE,"upside"}
Name ____________as4: {"'Generacion'!$A$2:$N$27"}
Name ____________as5: {"'Generacion'!$A$2:$N$27"}

Sheet Capa | Cover

Sheet Full model
B1: Pro-forma | C1: Pro-forma | D1: Pro-forma | E1: Pro-forma | F1: Pro-forma | G1: Pro-forma | H1: Pro-forma | I1: Cosméticos | J1: Cosméticos | K1: Pro-forma
A2: ATUALIZAR / AZUL Input / PRETO Fórmula | B2: Q1-24 | C2: Q2-24 | D2: Q3-24 | E2: Q4-24 | F2: 2024 | G2: Q1-25 | H2: Q2-25 | I2: Q3-25 | J2: Q4-25 | K2: 2025
A3: Operational
A5: Identified clients | B5: =B6+B7 -> 6.837163 | C5: =C6+C7 -> 7.336918 | D5: =D6+D7 -> 7.785096 | E5: =E6+E7 -> 8.341635 | F5: =F6+F7 -> 8.229739 | G5: =G6+G7 -> 8.591559 | H5: =H6+H7 -> 8.984118 | I5: =I6+I7 -> 9.368033 | ... K5: =K6+K7 -> 9.368033
A6: Brazil | B6: 6.165783 | C6: 6.59113 | D6: 6.946996 | E6: 7.391639 | F6: 7.391639 | G6: 7.581797 | H6: 7.890822 | I6: 8.202492 | J6: 9.41921 | K6: 8.202492
A7: Hispana | B7: 0.67138 | C7: 0.745788 | D7: 0.8381 | E7: 0.949996 | F7: 0.8381 | G7: 1.009762 | H7: 1.093296 | I7: 1.165541 | J7: 1.2854767 | K7: 1.165541
A9: Consultants | B9: =B10+B11 -> 3098.9537 | C9: =C10+C11 -> 3066.277 | D9: =D10+D11 -> 3071.7944 | E9: =E10+E11 -> 3044.2959 | F9: =F10+F11 -> 3070.3303 | G9: =G10+G11 -> 2911.0785 | H9: =H10+H11 -> 2884.4734 | I9: =I10+I11 -> 2767.3503 | ... K9: =K10+K11 -> 2843.8711
A10: Brazil | B10: 1590.3965 | C10: 1569.2398 | D10: 1582.641 | E10: 1563.683 | F10: 1576.4901 | G10: 1513.0463 | H10: 1518.5376 | I10: 1513.8874 | J10: 1486.7884 | K10: 1508.0649
A11: Hispana | B11: =SUM(B12:B18) -> 1508.5572 | C11: =SUM(C12:C18) -> 1497.0372 | D11: =SUM(D12:D18) -> 1489.1534 | E11: =SUM(E12:E18) -> 1480.6129 | F11: =SUM(F12:F18) -> 1493.8402 | G11: =SUM(G12:G18) -> 1398.0322 | H11: =SUM(H12:H18) -> 1365.9358 | I11: =SUM(I12:I18) -> 1253.4629 | ... K11: =SUM(K12:K18) -> 1335.8062
A12: Mexico | B12: 563.67475 | C12: 548.93275 | D12: 545.374 | E12: 535.1905 | F12: 548.293 | G12: 515.011 | H12: 497.87725 | I12: 440.3464 | J12: 413.73675 | K12: 481.02192
A13: Argentina | B13: 466.71675 | C13: 460.7025 | D13: 456.79775 | E13: 461.9722 | F13: 461.5473 | G13: 415.519 | H13: 396.2406 | I13: 343.3415 | J13: 281.3768 | K13: 385.0337
A14: Peru | B14: 129.99825 | C14: 129.56775 | D14: 131.8956 | E14: 129.4446 | F14: 130.22655 | G14: 130.291 | H14: 131.753 | I14: 130.6506 | J14: 124.978 | K14: 130.87915
A15: Colombia | B15: 192.51075 | C15: 191.4875 | D15: 190.69 | E15: 189.81825 | F15: 191.12662 | G15: 182.843 | H15: 188.15075 | I15: 189 | J15: 189.94875 | K15: 186.66458
A16: Chile | B16: 92.64925 | C16: 104.66275 | D16: 102.574 | E16: 101.26233 | F16: 100.28708 | G16: 98.966 | H16: 98.41575 | I16: 99.594 | J16: 97.406833 | K16: 99.038231
A17: Ecuador | B17: 52.8825 | C17: 51.6602 | D17: 51.555 | E17: 52.53425 | F17: 52.157988 | G17: 45.98775 | H17: 44.8102 | I17: 43.5798 | J17: 44.31375 | K17: 44.727692
A18: Uruguay | B18: 10.125 | C18: 10.0238 | D18: 10.267 | E18: 10.39075 | F18: 10.201638 | G18: 9.4145 | H18: 8.6882 | I18: 6.9506 | J18: 0 | K18: 8.4409231
A20: Number of stores | B20: =B21+B24 -> 940 | C20: =C21+C24 -> 967 | D20: =D21+D24 -> 1001 | E20: =E21+E24 -> 1076 | F20: =F21+F24 -> 1076 | G20: =G21+G24 -> 1087 | H20: =H21+H24 -> 1103 | I20: =I21+I24 -> 1122 | ... K20: =K21+K24 -> 1183
A21: Brazil | B21: =B22+B23 -> 895 | C21: =C22+C23 -> 921 | D21: =D22+D23 -> 943 | E21: =E22+E23 -> 1008 | F21: =F22+F23 -> 1008 | G21: =G22+G23 -> 1018 | H21: =H22+H23 -> 1024 | I21: =I22+I23 -> 1032 | ... K21: =K22+K23 -> 1084
A22: Own | B22: 115 | C22: 123 | D22: 128 | E22: 145 | F22: 145 | G22: 149 | H22: 154 | I22: 160 | J22: 174 | K22: 174
A23: Franchises | B23: 780 | C23: 798 | D23: 815 | E23: 863 | F23: 863 | G23: 869 | H23: 870 | I23: 872 | J23: 910 | K23: 910
A24: Hispana | B24: =B25+B26 -> 45 | C24: =C25+C26 -> 46 | D24: =D25+D26 -> 58 | E24: =E25+E26 -> 68 | F24: =F25+F26 -> 68 | G24: =G25+G26 -> 69 | H24: =H25+H26 -> 79 | I24: =I25+I26 -> 90 | ... K24: =K25+K26 -> 99
A25: Own | B25: 45 | C25: 46 | D25: 58 | E25: 68 | F25: 68 | G25: 69 | H25: 79 | I25: 90 | J25: 97 | K25: 97
A26: Franchises | B26: 0 | C26: 0 | D26: 0 | E26: 0 | F26: 0 | G26: 0 | H26: 0 | I26: 0 | J26: 2 | K26: 2
A28: % SSS
A29: Brazil | B29: 0.15389632 | C29: 0.18062463 | D29: 0.10759047 | E29: 0.12164761 | F29: 0.13760503 | G29: 0.095930404 | H29: 0.091042327 | I29: 0.063427969 | J29: 0.013699303 | K29: 0.058380708
A30: Hispana
A32: Emana Pay
A33: # active users (k) | B33: 270.069 | C33: 300.302 | D33: 363.394 | E33: 422.113 | F33: 422.113 | G33: 445.942 | H33: 465.161 | I33: 542.932 | J33: 628.233 | K33: 628.233
A34: Total payment volume | B34: 12356.811 | C34: 14507.707 | D34: 16160.598 | E34: 17015.19 | F34: 60040.307 | G34: 14445.545 | H34: 15800.453 | I34: 15845.608 | J34: 15806.022 | K34: 61897.628
A35: Credit penetration - % sell-in | B35: 0 | C35: 0.021140456 | D35: 0.099009632 | E35: 0.19344875 | F35: 0.07839971 | G35: 0.19671756 | H35: 0.21768212 | I35: 0.31695406 | J35: 0.40550821 | K35: 0.28421549
A36: NPL - 90 days (%) | B36: 0.0043333333 | C36: 0.008 | D36: 0.011333333 | E36: 0.012333333 | F36: 0.012333333 | G36: 0.027 | H36: 0.042666667 | I36: 0.047 | J36: 0.045333333 | K36: 0.045333333
A40: Receitas CC
A42: Total | B42: 0.031 | C42: 0.1 | D42: 0.185 | E42: 0.161 | F42: 0.124 | G42: 0.12811116 | H42: 0.047385036 | I42: -0.037955652 | J42: -0.034511367 | K42: 0.018202786
A43: Brazil | D43: 0.164 | E43: 0.15072 | F43: 0.11454309 | G43: 0.045150903 | H43: 0.050251975 | I43: -0.037403851 | J43: -0.047899105 | K43: -0.0014631976
A44: Natura | B44: 0.113 | C44: 0.148 | D44: 0.194 | E44: 0.211 | F44: 0.1703601 | G44: 0.081846407 | H44: 0.10257942 | I44: -0.0018503785 | J44: -0.021895333 | K44: 0.034919951
A45: Avon | B45: -0.113 | C45: -0.008 | D45: 0.144 | E45: -0.01 | F45: -0.0018013809 | G45: -0.11966359 | H45: -0.12852205 | I45: -0.17296836 | J45: -0.11527025 | K45: -0.13438702
A46: Home & Style | B46: -0.421 | C46: -0.424 | D46: -0.298 | E46: -0.358 | F46: -0.37863856 | G46: -0.15913886 | H46: 0.028142536 | I46: -0.08955691 | J46: -0.2146747 | K46: -0.10922602
A47: Others | G47: 0.47478034 | H47: -0.83882289 | I47: -0.41247374 | J47: -0.61330955 | K47: -0.39668387
A48: Hispana | D48: 0.226 | E48: 0.18279184 | F48: 0.14110667 | G48: 0.2484378 | H48: 0.042883948 | I48: -0.038705631 | J48: -0.013622513 | K48: 0.047414442
A49: Natura | B49: 0.223 | C49: 0.274 | D49: 0.347 | E49: 0.335 | F49: 0.2856559 | G49: 0.38421973 | H49: 0.1785533 | I49: 0.12292409 | J49: 0.067355751 | K49: 0.17120669
...

Sheet Histórico | Historic data
AB1: IFRS-16 | AC1: IFRS-16 | AD1: IFRS-16 | AE1: IFRS-16 | AF1: IFRS-16 | AG1: IFRS-16 | AH1: IFRS-16 | AI1: IFRS-16 | AJ1: IFRS-16 | AK1: IFRS-16 | AL1: IFRS-16 | AM1: IFRS-16 | AN1: IFRS-16 | AO1: IFRS-16 | AP1: IFRS-16 | AQ1: IFRS-16 | AR1: IFRS-16 | AS1: IFRS-16 | AT1: IFRS-16 | AU1: IFRS-16
A2: Unidades de negócio | B2: Business units | AV2: Latam + Holding | AW2: Latam + Holding | AX2: Latam + Holding | AY2: Latam + Holding | BA2: Latam + Holding | BB2: Latam + Holding
C3: 1Q15 | D3: 2Q15 | E3: 3Q15 | F3: 4Q15 | G3: 2015 | H3: 1Q16 | I3: 2Q16 | J3: 3Q16 | K3: 4Q16 | L3: 2016 | M3: 1Q17 | N3: 2Q17 | O3: 3Q17 | P3: 4Q17 | Q3: 2017 | R3: 1Q18 | S3: 2Q18 | T3: 3Q18 | U3: 4Q18 | V3: 2018 | W3: 1Q19 | X3: 2Q19 | Y3: 3Q19 | Z3: 4Q19 | AA3: 2019 | AB3: 1Q20 | AC3: 2Q20 | AD3: 3Q20 | AE3: 4Q20 | AF3: 2020 | AG3: 1Q21 | AH3: 2Q21 | AI3: 3Q21 | AJ3: 4Q21 | AK3: 2021 | AL3: 1Q22 | AM3: 2Q22 | AN3: 3Q22 | AO3: 4Q22 | AP3: 2022 | AQ3: 1Q23 | AR3: 2Q23 | AS3: 3Q23 | AT3: 4Q23 | AU3: 2023 | AV3: 1Q24 | AW3: 2Q24 | AX3: 3Q24 | AY3: 4Q24 | AZ3: 2024 | BA3: 1Q25 | BB3: 2Q25
A4: Demonstração de Resultados | B4: Income Statements | AV4: API e suas subsidiárias foram desconsolidadas e estão sendo apresentadas na linha de operações descontinuadas | AY4: Avon Internacional considerada a partir de Dez | AZ4: Avon Internacional considerada a partir de Dez
AV5: API and its subsidiaries were deconsolidated and are being presented under the discontinued operations line | AY5: Consolidating Avon International only in December | AZ5: Consolidating Avon International only in December
A6: Receita Bruta | B6: Gross Revenues | C6: 2205.8399 | D6: 2637.31 | E6: 2763.0574 | F6: 3200.2328 | G6: =F6+E6+D6+C6 -> 10806.44 | H6: 2320.028 | I6: 2815.4641 | J6: 2656.2 | K6: 3198.6641 | L6: 10993.142 | M6: =M8+M11+M14+M17 -> 2395.9488 | N6: =N8+N11+N14+N17 -> 2801.6006 | O6: =O8+O11+O14+O17 -> 3203.2068 | P6: =P8+P11+P14+P17 -> 5350.196 | Q6: =P6+O6+N6+M6 -> 13750.952 | R6: =R8+R11+R14+R17 -> 3708.4434 | S6: =S8+S11+S14+S17 -> 4301.1209 | T6: =T8+T11+T14+T17 -> 4392.9386 | U6: =U8+U11+U14+U17 -> 6111.9653 | V6: =V8+V11+V14+V17 -> 18561.961 | W6: =W8+W11+W14+W17 -> 3940.5753 | X6: =X8+X11+X14+X17 -> 4629.9414 | Y6: =Y8+Y11+Y14+Y17 -> 4705.0087 | ... AK6: =AK8+AK11+AK14+AK17 -> 51644.321 | AL6: =(AL8+AL11+AL14+AL17)+0.2 -> 10642.222 | AM6: =AM8+AM11+AM14+AM17 -> 11271.673 | AN6: =AN8+AN11+AN14+AN17-0.2 -> 11693.126 | AO6: =AO8+AO11+AO14+AO17 -> 13501.6 | AP6: =AP8+AP11+AP14+AP17 -> 47108.62 | AQ6: =AQ8+AQ11+AQ14+AQ17 -> 10342.4 | AR6: =AR8+AR11+AR14+AR17 -> 10944.63 | AS6: =AS8+AS11+AS14+AS17 -> 9822.436 | AT6: =AT8+AT11+AT14+AT17 -> 10478.9 | AU6: =AU8+AU11+AU14+AU17 -> 41588.366 | AV6: =AV8+AV11+AV14+AV17+AV20 -> 6228.1 | AW6: =AW8+AW11+AW14+AW17+AW20 -> 7782.1 | AX6: =AX8+AX11+AX14+AX17+AX20 -> 7901.4 | AY6: =AY8+AY11+AY14+AY17+AY20 -> 10140.3 | AZ6: =AZ8+AZ11+AZ14+AZ17+AZ20 -> 32051.4 | BA6: =BA8+BA11+BA14+BA17+BA20 -> 6819.9 | BB6: =BB8+BB11+BB14+BB17+BB20 -> 7545.9
A7: % variação anual | B7: % YoY growth | C7: - | D7: - | E7: - | F7: - | G7: - | H7: =H6/C6-1 -> 0.051766254 | I7: =I6/D6-1 -> 0.067551467 | J7: =J6/E6-1 -> -0.038673598 | K7: =K6/F6-1 -> -0.00049018569 | L7: =L6/G6-1 -> 0.017276912 | M7: =M6/H6-1 -> 0.032724096 | N7: =N6/I6-1 -> -0.0049240771 | O7: =O6/J6-1 -> 0.20593587 | ... AU7: =AU6/AP6-1 -> -0.11718141
A8: Natura & Co América Latina | B8: Natura & Co Latam | C8: 2132.7861 | D8: 2545.51 | E8: 2643.3574 | F8: 3012.7328 | G8: 10334.386 | H8: 2176.5148 | I8: 2676.3052 | J8: 2511.3 | K8: 2986.3732 | L8: 10353.279 | M8: 2236.5143 | N8: 2634.1489 | O8: 2671.6419 | P8: 3173.896 | Q8: 10716.201 | R8: 2327.5731 | S8: 2850.488 | T8: 2790.0844 | U8: 3631.6412 | V8: 11647.28 | W8: 2409.367 | X8: 3107.5158 | Y8: 3084.8295 | Z8: 3785.8129 | AA8: 12387.525 | AB8: 5593.2083 | AC8: 5420.6714 | AD8: 8275.9068 | AE8: 8294.7467 | AF8: 27584.533 | AG8: 6857.1875 | AH8: 7347.9368 | AI8: 7409.161 | AJ8: 8079.1461 | AK8: 29693.431 | AL8: 6286.722 | AM8: 7284.4 | AN8: 7700.042 | AO8: 7886.9 | AP8: 29158.064 | AQ8: 6445.3 | AR8: 7274 | AS8: 6930.214 | AT8: 6571.3 | AU8: =AT8+AS8+AR8+AQ8 -> 27220.814 | AV8: 6224.1 | AW8: 7778.8 | AX8: 7900.7 | AY8: 9369.6 | AZ8: 31272.7 | BA8: 6819.9 | BB8: 7545.9
A9: % receita bruta | B9: % gross revenues | C9: =C8/C6 -> 0.96688161 | D9: =D8/D6 -> 0.9651918 | E9: =E8/E6 -> 0.95667842 | F9: =F8/F6 -> 0.94141051 | G9: =G8/G6 -> 0.95631736 | H9: =H8/H6 -> 0.9381416 | I9: =I8/I6 -> 0.95057337 | J9: =J8/J6 -> 0.94544838 | ... BB9: =BB8/BB6 -> 1
A10: % variação anual | B10: % YoY growth | C10: - | D10: - | E10: - | F10: - | G10: - | H10: =H8/C8-1 -> 0.020503103 | I10: =I8/D8-1 -> 0.051382731 | J10: =J8/E8-1 -> -0.049958198 | K10: =K8/F8-1 -> -0.0087494076 | L10: =L8/G8-1 -> 0.0018281448 | M10: =M8/H8-1 -> 0.027566774 | N10: =N8/I8-1 -> -0.015751701 | O10: =O8/J8-1 -> 0.063848146 | ... BB10: =BB8/AW8-1 -> -0.029940351
A11: Avon International | B11: Avon International | C11: 0 | D11: 0 | E11: 0 | F11: 0 | G11: 0 | H11: 0 | I11: 0 | J11: 0 | K11: 0 | L11: 0 | M11: 0 | N11: 0 | O11: 0 | P11: 0 | Q11: 0 | R11: 0 | S11: 0 | T11: 0 | U11: 0 | V11: 0 | W11: 0 | X11: 0 | Y11: 0 | Z11: 0 | AA11: 0 | AB11: 2531.3979 | AC11: 1995.651 | AD11: 2958.2472 | AE11: 3406.1622 | AF11: 10891.458 | AG11: 2835.9077 | AH11: 2644.6511 | AI11: 2460.0331 | AJ11: 3248.39 | AK11: 11188.982 | AL11: 2207.3551 | AM11: 2099.7441 | AN11: 1965.095 | AO11: 2456.4 | AP11: 8728.5942 | AQ11: 1921 | AR11: 1795.1 | AS11: 1733.308 | AT11: 2038.6 | AU11: =AT11+AS11+AR11+AQ11 -> 7488.008 | AV11: 0 | AW11: 0 | AY11: 770.7 | AZ11: =AY11 -> 770.7 | BA11: 0 | BB11: 0
A12: % receita bruta | B12: % gross revenues | C12: - | D12: - | E12: - | F12: - | G12: - | H12: - | I12: - | J12: - | K12: - | L12: - | M12: - | N12: - | O12: - | P12: - | Q12: - | R12: - | S12: - | T12: - | U12: - | V12: - | W12: - | X12: - | Y12: - | Z12: - | AA12: - | AB12: =AB11/AB6 -> 0.26045723 | AC12: =AC11/AC6 -> 0.218924 | AD12: =AD11/AD6 -> 0.21749769 | AE12: =AE11/AE6 -> 0.22319757 | AF12: =AF11/AF6 -> 0.22834773 | AG12: =AG11/AG6 -> 0.2351663 | AH12: =AH11/AH6 -> 0.21618989 | AI12: =AI11/AI6 -> 0.19952973 | ... AZ12: =AZ11/AZ6 -> 0.024045752
A13: % variação anual | B13: % YoY growth | C13: - | D13: - | E13: - | F13: - | G13: - | H13: - | I13: - | J13: - | K13: - | L13: - | M13: - | N13: - | O13: - | P13: - | Q13: - | R13: - | S13: - | T13: - | U13: - | V13: - | W13: - | X13: - | Y13: - | Z13: - | AA13: - | AB13: - | AC13: - | AD13: - | AE13: - | AF13: - | AG13: =AG11/AB11-1 -> 0.12029313 | AH13: =AH11/AC11-1 -> 0.32520722 | AI13: =AI11/AD11-1 -> -0.1684153 | AJ13: =AJ11/AE11-1 -> -0.046319644 | AK13: =AK11/AF11-1 -> 0.027317146 | AL13: =AL11/AG11-1 -> -0.22164071 | AM13: =AM11/AH11-1 -> -0.20604117 | AN13: =AN11/AI11-1 -> -0.20119164 | ... AZ13: =AZ11/AU11-1 -> -0.89707543
A14: The Body Shop | B14: The Body Shop | C14: 0 | D14: 0 | E14: 0 | F14: 0 | G14: 0 | H14: 0 | I14: 0 | J14: 0 | K14: 0 | L14: 0 | M14: 0 | N14: 0 | O14: 354.87262 | P14: 1900.1 | Q14: =P14+O14+N14+M14 -> 2254.9726 | R14: 1158.8732 | S14: 1190.6804 | T14: 1307.7313 | U14: 2082.9565 | V14: =U14+T14+S14+R14 -> 5740.2414 | W14: 1219.8443 | X14: 1217.7669 | Y14: 1288.6482 | Z14: 2145.3599 | AA14: =Z14+Y14+X14+W14 -> 5871.6192 | AB14: 1213.3703 | AC14: 1272.5262 | AD14: 1814.9631 | AE14: 2741.682 | AF14: =AE14+AD14+AC14+AB14 -> 7042.5416 | AG14: 1711.1484 | AH14: 1612.3885 | AI14: 1841.5255 | AJ14: 2677.8065 | AK14: =AJ14+AI14+AH14+AG14 -> 7842.8689 | AL14: 1426.7368 | AM14: 1220.6572 | AN14: 1351.789 | AO14: 2181.7 | AP14: =AO14+AN14+AM14+AL14 -> 6180.883 | AQ14: 1191.1 | AR14: 1116.6 | AS14: 1158.914 | AT14: 1869 | AU14: =AT14+AS14+AR14+AQ14 -> 5335.614
A15: % receita bruta | B15: % gross revenues | C15: - | D15: - | E15: - | F15: - | G15: - | H15: - | I15: - | J15: - | K15: - | L15: - | M15: - | N15: - | O15: =O14/O6 -> 0.11078667 | P15: =P14/P6 -> 0.35514587 | Q15: =Q14/Q6 -> 0.16398665 | R15: =R14/R6 -> 0.31249587 | S15: =S14/S6 -> 0.27683026 | T15: =T14/T6 -> 0.29768941 | U15: =U14/U6 -> 0.34079979 | V15: =V14/V6 -> 0.30924758 | ... AU15: =AU14/AU6 -> 0.12829583
A16: % variação anual | B16: % YoY growth | C16: - | D16: - | E16: - | F16: - | G16: - | H16: - | I16: - | J16: - | K16: - | L16: - | M16: - | N16: - | O16: - | P16: - | Q16: - | R16: - | S16: - | T16: =T14/O14-1 -> 2.6850724 | U16: =U14/P14-1 -> 0.096235176 | V16: =V14/Q14-1 -> 1.5455925 | W16: =W14/R14-1 -> 0.052612327 | X16: =X14/S14-1 -> 0.022748753 | Y16: =Y14/T14-1 -> -0.014592531 | Z16: =Z14/U14-1 -> 0.029959063 | AA16: =AA14/V14-1 -> 0.02288716 | ... AU16: =AU14/AP14-1 -> -0.13675537
A17: Aesop | B17: Aesop | C17: 73.053874 | D17: 91.8 | E17: 119.7 | F17: 187.5 | G17: 472.05387 | H17: 143.51321 | I17: 139.1589 | J17: 144.9 | K17: 212.29092 | L17: 639.86303 | M17: 159.43454 | N17: 167.4517 | O17: 176.69238 | P17: 276.2 | Q17: 779.77861 | R17: 221.99708 | S17: 259.95249 | T17: 295.12288 | U17: 397.36756 | V17: 1174.44 | W17: 311.36407 | X17: 304.65869 | Y17: 331.53106 | Z17: 501.40634 | AA17: 1448.9602 | AB17: 381.07751 | AC17: 426.87638 | AD17: 552.16405 | AE17: 818.15864 | AF17: 2178.2766 | AG17: 654.915 | AH17: 628.02448 | AI17: 618.43583 | AJ17: 1017.664 | AK17: 2919.0393 | AL17: 721.20768 | AM17: 666.87161 | AN17: 676.4 | AO17: 976.6 | AP17: =AO17+AN17+AM17+AL17 -> 3041.0793 | AQ17: 785 | AR17: 758.93 | AS17: 0 | AT17: 0 | AU17: =AT17+AS17+AR17+AQ17 -> 1543.93
A18: % receita bruta | B18: % gross revenues | C18: =C17/C6 -> 0.033118393 | D18: =D17/D6 -> 0.034808195 | E18: =E17/E6 -> 0.043321576 | F18: =F17/F6 -> 0.058589487 | G18: =G17/G6 -> 0.043682644 | H18: =H17/H6 -> 0.061858396 | I18: =I17/I6 -> 0.049426629 | J18: =J17/J6 -> 0.054551615 | ... AU18: =AU17/AU6 -> 0.037124084
A19: % variação anual | B19: % YoY growth | C19: - | D19: - | E19: - | F19: - | G19: - | H19: =H17/C17-1 -> 0.96448461 | I19: =I17/D17-1 -> 0.51589217 | J19: =J17/E17-1 -> 0.21052632 | K19: =K17/F17-1 -> 0.13221824 | L19: =L17/G17-1 -> 0.3554873 | M19: =M17/H17-1 -> 0.11093981 | N19: =N17/I17-1 -> 0.20331288 | O19: =O17/J17-1 -> 0.21940908 | ... AU19: =AU17/AP17-1 -> -0.49230853
A20: Corporativo & Outros | B20: Holding & Others | AV20: 4 | AW20: 3.3 | AX20: 0.7 | AY20: 0 | AZ20: =AY20+AX20+AW20+AV20 -> 8 | BA20: 0 | BB20: 0
A23: Impostos e deduções | B23: Taxes and deductions | C23: =C35-C6 -> -564.03993 | D23: =D35-D6 -> -708.40998 | E23: =E35-E6 -> -767.15737 | F23: =F35-F6 -> -867.83281 | G23: =G35-G6 -> -2907.4401 | H23: =H35-H6 -> -630.32713 | I23: =I35-I6 -> -789.80616 | J23: =J35-J6 -> -753.6 | ... AO23: =AO35-AO6 -> -3111.8 | AP23: =AO23+AN23+AM23+AL23 -> -10759.408 | AQ23: =AQ35-AQ6 -> -2320.9 | AR23: =AR35-AR6 -> -2492.64 | AS23: =AS35-AS6 -> -2305.175 | AT23: =AT35-AT6 -> -2593 | AU23: =AT23+AS23+AR23+AQ23 -> -9711.715 | AV23: =AV35-AV6 -> -1645.5 | AW23: =AW35-AW6 -> -1998.1 | AX23: =AX35-AX6 -> -1925.1 | AY23: =AY35-AY6 -> -2393 | AZ23: =AZ35-AZ6 -> -7961.8 | BA23: =BA35-BA6 -> -1676.9002 | BB23: =BB35-BB6 -> -1858.5
A24: % receita bruta | B24: % gross revenues | C24: =C23/C6 -> -0.25570302 | D24: =D23/D6 -> -0.26861081 | E24: =E23/E6 -> -0.27764801 | F24: =F23/F6 -> -0.27117803 | G24: =G23/G6 -> -0.26904698 | H24: =H23/H6 -> -0.27168945 | I24: =I23/I6 -> -0.28052432 | J24: =J23/J6 -> -0.28371358 | ... BB24: =BB23/BB6 -> -0.24629269
A25: Natura & Co América Latina | B25: Natura & Co Latam | C25: =C37-C8 -> -557.16401 | D25: =D37-D8 -> -701.12481 | E25: =E37-E8 -> -756.91355 | F25: =F37-F8 -> -851.71692 | G25: =G37-G8 -> -2866.9193 | H25: =H37-H8 -> -616.83689 | I25: =I37-I8 -> -776.72522 | J25: =J37-J8 -> -740 | ... AO25: =AO37-AO8 -> -1943.7 | AP25: =AL25+AM25+AN25+AO25 -> -7130.7657 | AQ25: =AQ37-AQ8 -> -1581.6 | AR25: =AR37-AR8 -> -1811.1 | AS25: =AS37-AS8 -> -1698.18 | AT25: =AT37-AT8 -> -1689.1 | AU25: =AT25+AS25+AR25+AQ25 -> -6779.98 | AV25: =AV37-AV8 -> -1645.5 | AW25: =AW37-AW8 -> -1998.1 | AX25: =AX37-AX8 -> -1925.1 | AY25: =AY37-AY8 -> -2279 | AZ25: =AZ37-AZ8 -> -7847.8 | BA25: =BA37-BA8 -> -1676.9002 | BB25: =BB37-BB8 -> -1858.5
A26: % receita bruta | B26: % gross revenues | C26: =C25/C8 -> -0.26123765 | D26: =D25/D8 -> -0.27543589 | E26: =E25/E8 -> -0.28634552 | F26: =F25/F8 -> -0.28270576 | G26: =G25/G8 -> -0.27741554 | H26: =H25/H8 -> -0.28340579 | I26: =I25/I8 -> -0.29022296 | J26: =J25/J8 -> -0.2946681 | ... BB26: =BB25/BB8 -> -0.24629269
A27: Avon International | B27: Avon International | C27: - | D27: - | E27: - | F27: - | G27: - | H27: - | I27: - | J27: - | K27: - | L27: - | M27: - | N27: - | O27: - | P27: - | Q27: - | R27: - | S27: - | T27: - | U27: - | V27: - | W27: - | X27: - | Y27: - | Z27: - | AA27: - | AB27: =AB40-AB11 -> -409.88054 | AC27: =AC40-AC11 -> -345.63338 | AD27: =AD40-AD11 -> -500.91094 | AE27: =AE40-AE11 -> -537.65816 | AF27: =AF40-AF11 -> -1794.083 | AG27: =AG40-AG11 -> -472.43437 | AH27: =AH40-AH11 -> -440.64635 | AI27: =AI40-AI11 -> -406.3121 | ... AO27: =AO40-AO11 -> -393.8 | AP27: =AL27+AM27+AN27+AO27 -> -1532.6538 | AQ27: =AQ40-AQ11 -> -314.4 | AR27: =AR40-AR11 -> -284.8 | AS27: =AS40-AS11 -> -277.522 | AT27: =AT40-AT11 -> -324.5 | AU27: =AT27+AS27+AR27+AQ27 -> -1201.222 | AV27: =AV40-AV11 -> 0 | AW27: =AW40-AW11 -> 0 | AX27: =AX40-AX11 -> 0 | AY27: =AY40-AY11 -> -114 | AZ27: =AZ40-AZ11 -> -114 | BA27: =BA40-BA11 -> 0
A28: % receita bruta | B28: % gross revenues | C28: - | D28: - | E28: - | F28: - | G28: - | H28: - | I28: - | J28: - | K28: - | L28: - | M28: - | N28: - | O28: - | P28: - | Q28: - | R28: - | S28: - | T28: - | U28: - | V28: - | W28: - | X28: - | Y28: - | Z28: - | AA28: - | AB28: =AB27/AB11 -> -0.16191865 | AC28: =AC27/AC11 -> -0.1731933 | AD28: =AD27/AD11 -> -0.16932694 | AE28: =AE27/AE11 -> -0.15784867 | AF28: =AF27/AF11 -> -0.16472386 | AG28: =AG27/AG11 -> -0.16659018 | AH28: =AH27/AH11 -> -0.16661795 | AI28: =AI27/AI11 -> -0.1651653 | ... BA28: =BA27/BA11 -> #DIV/0!
A29: The Body Shop | B29: The Body Shop | C29: - | D29: - | E29: - | F29: - | G29: - | H29: - | I29: - | J29: - | K29: - | L29: - | M29: - | N29: - | O29: =O43-O14 -> -109.3564 | P29: =P43-P14 -> -689.1 | Q29: =Q43-Q14 -> -798.4564 | R29: =R43-R14 -> -351.61709 | S29: =S43-S14 -> -383.98965 | T29: =T43-T14 -> -381.88416 | U29: =U43-U14 -> -736.74823 | V29: =V43-V14 -> -1854.2391 | ... AO29: =AO43-AO14 -> -677.3 | AP29: =AL29+AM29+AN29+AO29 -> -1773.609 | AQ29: =AQ43-AQ14 -> -341.2 | AR29: =AR43-AR14 -> -316.3 | AS29: =AS43-AS14 -> -329.473 | AT29: =AT43-AT14 -> -579.4 | AU29: =AT29+AS29+AR29+AQ29 -> -1566.373 | AV29: =AV43-AV14 -> 0 | AW29: =AW43-AW14 -> 0 | AX29: =AX43-AX14 -> 0 | AY29: =AY43-AY14 -> 0 | AZ29: =AZ43-AZ14 -> 0 | BA29: =BA43-BA14 -> 0
A30: % receita bruta | B30: % gross revenues | C30: - | D30: - | E30: - | F30: - | G30: - | H30: - | I30: - | J30: - | K30: - | L30: - | M30: - | N30: - | O30: =O29/O14 -> -0.30815678 | P30: =P29/P14 -> -0.36266512 | Q30: =Q29/Q14 -> -0.35408696 | R30: =R29/R14 -> -0.3034129 | S30: =S29/S14 -> -0.32249599 | T30: =T29/T14 -> -0.29202036 | U30: =U29/U14 -> -0.35370313 | V30: =V29/V14 -> -0.32302459 | ... BA30: =BA29/BA14 -> #DIV/0!
A31: Aesop | B31: Aesop | C31: =C46-C17 -> -6.875917 | D31: =D46-D17 -> -7.2851704 | E31: =E46-E17 -> -10.243822 | F31: =F46-F17 -> -16.115897 | G31: =G46-G17 -> -40.520807 | H31: =H46-H17 -> -13.490242 | I31: =I46-I17 -> -13.080937 | J31: =J46-J17 -> -13.6 | ... AO31: =AO46-AO17 -> -97 | AP31: =AL31+AM31+AN31+AO31 -> -322.32256 | AQ31: =AQ46-AQ17 -> -83.7 | AR31: =AR46-AR17 -> -80.44 | AS31: 0 | AT31: 0 | AU31: =AT31+AS31+AR31+AQ31 -> -164.14 | AV31: =AV46-AV17 -> 0 | AW31: =AW46-AW17 -> 0 | AX31: =AX46-AX17 -> 0 | AY31: =AY46-AY17 -> 0 | AZ31: =AZ46-AZ17 -> 0 | BA31: =BA46-BA17 -> 0
A32: % receita bruta | B32: % gross revenues | C32: =C31/C17 -> -0.094121182 | D32: =D31/D17 -> -0.079359155 | E32: =E31/E17 -> -0.085579135 | F32: =F31/F17 -> -0.085951452 | G32: =G31/G17 -> -0.08583937 | H32: =H31/H17 -> -0.094 | I32: =I31/I17 -> -0.094 | J32: =J31/J17 -> -0.093857833 | ... AR32: =AR31/AR17 -> -0.10599133 | AS32: - | AT32: - | AU32: - | AV32: =AV31/AV17 -> #DIV/0! | AW32: =AW31/AW17 -> #DIV/0! | AX32: =AX31/AX17 -> #DIV/0! | AY32: =AY31/AY17 -> #DIV/0! | AZ32: =AZ31/AZ17 -> #DIV/0! | BA32: =BA31/BA17 -> #DIV/0!
A35: Receita Líquida | B35: Net Revenues | C35: 1641.8 | D35: 1928.9 | E35: 1995.9 | F35: 2332.4 | G35: =F35+E35+D35+C35 -> 7899 | H35: 1689.7009 | I35: 2025.658 | J35: 1902.6 | K35: 2294.7123 | L35: =K35+J35+I35+H35 -> 7912.6711 | M35: =M37+M40+M43+M46 -> 1728.607 | N35: =N37+N40+N43+N46 -> 2025.8189 | O35: =O37+O40+O43+O46 -> 2365.4217 | P35: =P37+P40+P43+P46 -> 3732.816 | Q35: =Q37+Q40+Q43+Q46 -> 9852.6636 | R35: =R37+R40+R43+R46 -> 2687.6263 | S35: =S37+S40+S43+S46 -> 3100.0425 | T35: =T37+T40+T43+T46 -> 3241.9013 | ... AK35: =AK37+AK40+AK43+AK46 -> 40164.687 | AL35: =AL37+AL40+AL43+AL46+0.1 -> 8253.3959 | AM35: =AM37+AM40+AM43+AM46 -> 8702.4135 | AN35: =AN37+AN40+AN43+AN46-0.157 -> 9003.603 | AO35: =AO37+AO40+AO43+AO46 -> 10389.8 | AP35: =AP37+AP40+AP43+AP46 -> 36349.269 | AQ35: =AQ37+AQ40+AQ43+AQ46 -> 8021.5 | AR35: =AR37+AR40+AR43+AR46 -> 8451.99 | AS35: =AS37+AS40+AS43+AS46 -> 7517.261 | AT35: =AT37+AT40+AT43+AT46 -> 7885.9 | AU35: =AU37+AU40+AU43+AU46 -> 31876.651 | AV35: =AV37+AV40+AV43+AV46+AV49 -> 4582.6 | AW35: =AW37+AW40+AW43+AW46+AW49 -> 5784 | AX35: =AX37+AX40+AX43+AX46+AX49 -> 5976.3 | AY35: =AY37+AY40+AY43+AY46+AY49 -> 7747.3 | AZ35: =AZ37+AZ40+AZ43+AZ46+AZ49 -> 24089.6 | BA35: =BA37+BA40+BA43+BA46+BA49 -> 5142.9998 | BB35: =BB37+BB40+BB43+BB46+BB49 -> 5687.4
A36: % variação anual | B36: % YoY growth | C36: - | D36: - | E36: - | F36: - | G36: - | H36: =H35/C35-1 -> 0.029175821 | I36: =I35/D35-1 -> 0.050162255 | J36: =J35/E35-1 -> -0.046745829 | K36: =K35/F35-1 -> -0.016158335 | L36: =L35/G35-1 -> 0.0017307428 | M36: =M35/H35-1 -> 0.023025468 | N36: =N35/I35-1 -> 7.9422867e-05 | O36: =O35/J35-1 -> 0.24325751 | ... BB36: =BB35/AW35-1 -> -0.016701245
A37: Natura & Co América Latina | B37: Natura & Co Latam | C37: =C35-C46 -> 1575.622 | D37: =D35-D46 -> 1844.3852 | E37: =E35-E46 -> 1886.4438 | F37: =F35-F46 -> 2161.0159 | G37: =G35-G46 -> 7467.4669 | H37: =H35-H46 -> 1559.6779 | I37: =I35-I46 -> 1899.58 | J37: =J35-J46 -> 1771.3 | ... L37: =L35-L46 -> 7332.9346 | M37: 1584.1593 | N37: 1874.1076 | O37: 1959.8222 | P37: 2271.616 | Q37: =P37+O37+N37+M37 -> 7689.7052 | R37: 1679.2408 | S37: 2057.8348 | T37: 2048.6728 | U37: 2629.3372 | V37: 8447.3733 | W37: 1755.994 | X37: 2252.0018 | Y37: 2241.817 | Z37: 2762.5192 | AA37: =Z37+Y37+X37+W37 -> 9012.332 | AB37: 4162.3357 | AC37: 3975.7474 | AD37: 6083.6203 | AE37: 6320.6409 | AF37: =AE37+AD37+AC37+AB37 -> 20542.344 | AG37: 5185.9449 | AH37: 5533.671 | AI37: 5551.4876 | AJ37: 6142.2974 | AK37: =AJ37+AI37+AH37+AG37 -> 22413.401 | AL37: 4751.5204 | AM37: 5555.0449 | AN37: 5777.533 | AO37: 5943.2 | AP37: =AO37+AN37+AM37+AL37 -> 22027.298 | AQ37: 4863.7 | AR37: 5462.9 | AS37: 5232.034 | AT37: 4882.2 | AU37: =AT37+AS37+AR37+AQ37 -> 20440.834 | AV37: 4578.6 | AW37: 5780.7 | AX37: 5975.6 | AY37: 7090.6 | AZ37: 23424.9 | BA37: 5142.9998 | BB37: 5687.4
A38: % receita Líquida | B38: % net revenues | C38: =C37/C35 -> 0.95969183 | D38: =D37/D35 -> 0.95618496 | E38: =E37/E35 -> 0.94515949 | F38: =F37/F35 -> 0.92652028 | G38: =G37/G35 -> 0.94536865 | H38: =H37/H35 -> 0.92304971 | I38: =I37/I35 -> 0.9377595 | J38: =J37/J35 -> 0.93098917 | ... BB38: =BB37/BB35 -> 1
A39: % variação anual | B39: % YoY growth | C39: - | D39: - | E39: - | F39: - | G39: - | H39: =H37/C37-1 -> -0.010119273 | I39: =I37/D37-1 -> 0.029925874 | J39: =J37/E37-1 -> -0.061037504 | K39: =K37/F37-1 -> -0.027135002 | L39: =L37/G37-1 -> -0.018015788 | M39: =M37/H37-1 -> 0.015696466 | N39: =N37/I37-1 -> -0.013409486 | O39: =O37/J37-1 -> 0.10643156 | ... BB39: =BB37/AW37-1 -> -0.016139914
A40: Avon International | B40: Avon International | AB40: 2121.5174 | AC40: 1650.0176 | AD40: 2457.3363 | AE40: 2868.5041 | AF40: =AE40+AD40+AC40+AB40 -> 9097.3753 | AG40: 2363.4733 | AH40: 2204.0048 | AI40: 2053.721 | AJ40: 2708.1258 | AK40: =AJ40+AI40+AH40+AG40 -> 9329.3249 | AL40: 1841.9755 | AM40: 1643.7729 | AN40: 1647.592 | AO40: 2062.6 | AP40: =AO40+AN40+AM40+AL40 -> 7195.9404 | AQ40: 1606.6 | AR40: 1510.3 | AS40: 1455.786 | AT40: 1714.1 | AU40: =AT40+AS40+AR40+AQ40 -> 6286.786 | AV40: 0 | AW40: 0 | AY40: 656.7 | AZ40: =AY40 -> 656.7 | BA40: 0 | BB40: 0
A41: % receita Líquida | B41: % net revenues | C41: - | D41: - | E41: - | F41: - | G41: - | H41: - | I41: - | J41: - | K41: - | L41: - | M41: - | N41: - | O41: - | P41: - | Q41: - | R41: - | S41: - | T41: - | U41: - | V41: - | W41: - | X41: - | Y41: - | Z41: - | AA41: - | AB41: =AB40/AB35 -> 0.28219198 | AC41: =AC40/AC35 -> 0.23614923 | AD41: =AD40/AD35 -> 0.23583948 | AE41: =AE40/AE35 -> 0.2390963 | AF41: =AF40/AF35 -> 0.24639457 | AG41: =AG40/AG35 -> 0.24996879 | AH41: =AH40/AH35 -> 0.23158205 | AI41: =AI40/AI35 -> 0.21506679 | ... AZ41: =AZ40/AZ35 -> 0.027260727
A42: % variação anual | B42: % YoY growth | C42: - | D42: - | E42: - | F42: - | G42: - | H42: - | I42: - | J42: - | K42: - | L42: - | M42: - | N42: - | O42: - | P42: - | Q42: - | R42: - | S42: - | T42: - | U42: - | V42: - | W42: - | X42: - | Y42: - | Z42: - | AA42: - | AB42: - | AC42: - | AD42: - | AE42: - | AF42: - | AG42: =AG40/AB40-1 -> 0.11404853 | AH42: =AH40/AC40-1 -> 0.3357462 | AI42: =AI40/AD40-1 -> -0.1642491 | AJ42: =AJ40/AE40-1 -> -0.055910069 | AK42: =AK40/AF40-1 -> 0.025496317 | AL42: =AL40/AG40-1 -> -0.2206489 | AM42: =AM40/AH40-1 -> -0.25418814 | AN42: =AN40/AI40-1 -> -0.19775276 | ... AZ42: =AZ40/AU40-1 -> -0.89554281
A43: The Body Shop | B43: The Body Shop | O43: 245.51622 | P43: 1211 | Q43: =P43+O43+N43+M43 -> 1456.5162 | R43: 807.25615 | S43: 806.69075 | T43: 925.84714 | U43: 1346.2082 | V43: =U43+T43+S43+R43 -> 3886.0023 | W43: 889.31654 | X43: 867.45611 | Y43: 935.70065 | Z43: 1436.8352 | AA43: =Z43+Y43+X43+W43 -> 4129.3085 | AB43: 893.24157 | AC43: 979.19455 | AD43: 1384.6085 | AE43: 2075.8775 | AF43: =AE43+AD43+AC43+AB43 -> 5332.9222 | AG43: 1319.7313 | AH43: 1217.5649 | AI43: 1390.5863 | AJ43: 1893.8932 | AK43: =AJ43+AI43+AH43+AG43 -> 5821.7757 | AL43: 1017.4059 | AM43: 909.43307 | AN43: 976.035 | AO43: 1504.4 | AP43: =AO43+AN43+AM43+AL43 -> 4407.274 | AQ43: 849.9 | AR43: 800.3 | AS43: 829.441 | AT43: 1289.6 | AU43: =AT43+AS43+AR43+AQ43 -> 3769.241
A44: % receita Líquida | B44: % net revenues | C44: - | D44: - | E44: - | F44: - | G44: - | H44: - | I44: - | J44: - | K44: - | L44: - | M44: - | N44: - | O44: =O43/O35 -> 0.10379385 | P44: =P43/P35 -> 0.32441996 | Q44: =Q43/Q35 -> 0.14782969 | R44: =R43/R35 -> 0.30036027 | S44: =S43/S35 -> 0.26021926 | T44: =T43/T35 -> 0.28558771 | U44: =U43/U35 -> 0.31050386 | V44: =V43/V35 -> 0.29005606 | ... AU44: =AU43/AU35 -> 0.11824457
...

Sheet Natura Avon desde l since 2020
C1: IFRS-16 | D1: IFRS-16 | E1: IFRS-16 | F1: IFRS-16 | G1: IFRS-16 | H1: IFRS-16 | I1: IFRS-16 | J1: IFRS-16 | K1: IFRS-16 | L1: IFRS-16 | M1: IFRS-16 | N1: IFRS-16 | O1: IFRS-16 | P1: IFRS-16 | Q1: IFRS-16 | R1: IFRS-16 | S1: IFRS-16 | T1: IFRS-16 | U1: IFRS-16 | V1: IFRS-16 | W1: IFRS-16 | X1: IFRS-16 | Y1: Pro-forma | Z1: Pro-forma | AA1: Pro-forma
C2: 1Q20 | D2: 2Q20 | E2: 3Q20 | F2: 4Q20 | G2: 2020 | H2: 1Q21 | I2: 2Q21 | J2: 3Q21 | K2: 4Q21 | L2: 2021 | M2: 1Q22 | N2: 2Q22 | O2: 3Q22 | P2: 4Q22 | Q2: 2022 | R2: 1Q23 | S2: 2Q23 | T2: 3Q23 | U2: 4Q23 | V2: 2023 | W2: 1Q24 | X2: 2Q24 | Y2: 3Q24 | Z2: 4Q24 | AA2: 2024 | AB2: 1Q25
A3: Demonstração de Resultados | B3: Income Statements | T3: API e suas subsidiárias foram desconsolidadas e estão sendo apresentadas na linha de operações descontinuadas
T4: API and its subsidiaries were deconsolidated and are being presented under the discontinued operations line.
A5: Receita Bruta | B5: Gross Revenues | C5: =C7+C10 -> 8124.6062 | D5: =D7+D10 -> 7416.3224 | E5: =E7+E10 -> 11234.154 | F5: =F7+F10 -> 11700.909 | G5: =G7+G10 -> 38475.992 | H5: =H7+H10 -> 9693.0951 | I5: =I7+I10 -> 9992.5879 | J5: =J7+J10 -> 9869.1941 | ... O5: =O7+O10 -> 9665.137 | P5: =P7+P10+P13 -> 10343.107 | Q5: =Q7+Q10+Q13 -> 37886.365 | R5: =R7+R10+R13 -> 8367.5872 | S5: =S7+S10+S13 -> 9069.6489 | T5: 6764.4 | U5: =U7+U10+U13 -> 8626.9832 | V5: =V7+V10+V13 -> 34718.6 | W5: =W7+W10+W13 -> 8038.9594 | X5: =X7+X10+X13 -> 9648.9983 | Y5: =Y7+Y10+Y13 -> 9833.1205 | Z5: =Z7+Z10+Z13 -> 11636.6 | AA5: =AA7+AA10+AA13 -> 39157.678 | AB5: =AB7+AB10+AB13 -> 8646.4
A6: % variação anual | B6: % YoY growth | C6: - | D6: - | E6: - | F6: - | G6: - | H6: =H5/C5-1 -> 0.19305414 | I6: =I5/D5-1 -> 0.34737777 | J6: =J5/E5-1 -> -0.12150091 | K6: =K5/F5-1 -> -0.031909726 | L6: =L5/G5-1 -> 0.062543462 | M6: =M5/H5-1 -> -0.12369816 | N6: =N5/I5-1 -> -0.060889516 | O6: =O5/J5-1 -> -0.020676162 | ... AA6: =AA5/V5-1 -> 0.12785879
A7: Natura & Co América Latina | B7: Natura & Co Latam | C7: 5593.2083 | D7: 5420.6714 | E7: 8275.9068 | F7: 8294.7467 | G7: 27584.533 | H7: 6857.1875 | I7: 7347.9368 | J7: 7409.161 | K7: 8079.1461 | L7: 29693.431 | M7: 6286.722 | N7: 7284.4 | O7: 7700.042 | P7: 7886.9483 | Q7: 29158.112 | R7: 6444.3922 | S7: 7272.7127 | T7: 6762.7 | U7: 6571.2565 | V7: 27220.754 | W7: 6371.9325 | X7: 7944.6426 | Y7: =AA7-Z7-X7-W7 -> 8045.9249 | Z7: 9454.9 | AA7: 31817.4 | AB7: 6986.1
A8: % receita bruta | B8: % gross revenues | C8: =C7/C5 -> 0.68842824 | D8: =D7/D5 -> 0.73091097 | E8: =E7/E5 -> 0.73667379 | F8: =F7/F5 -> 0.70889764 | G8: =G7/G5 -> 0.71692846 | H8: =H7/H5 -> 0.70743012 | I8: =I7/I5 -> 0.73533872 | J8: =J7/J5 -> 0.75073617 | ... AB8: =AB7/AB5 -> 0.80797789
A9: % variação anual | B9: % YoY growth | C9: - | D9: - | E9: - | F9: - | G9: - | H9: =H7/C7-1 -> 0.22598463 | I9: =I7/D7-1 -> 0.35553998 | J9: =J7/E7-1 -> -0.10473122 | K9: =K7/F7-1 -> -0.025992424 | L9: =L7/G7-1 -> 0.076452196 | M9: =M7/H7-1 -> -0.083192339 | N9: =N7/I7-1 -> -0.0086468927 | O9: =O7/J7-1 -> 0.039259647 | ... AB9: =AB7/W7-1 -> 0.096386383
A10: Avon International | B10: Avon International | C10: 2531.3979 | D10: 1995.651 | E10: 2958.2472 | F10: 3406.1622 | G10: 10891.458 | H10: 2835.9077 | I10: 2644.6511 | J10: 2460.0331 | K10: 3248.39 | L10: 11188.982 | M10: 2207.3551 | N10: 2099.7441 | O10: 1965.095 | P10: 2456.4587 | Q10: 8728.6529 | R10: 1921.0335 | S10: 1795.1244 | T10: 0 | U10: 2038.6266 | V10: 7488.0681 | W10: 1662.9955 | X10: 1701.0089 | Y10: =AA10-Z10-X10-W10 -> 1786.4956 | Z10: 2181.7 | AA10: 7332.2 | AB10: 1660.3
A11: % receita bruta | B11: % gross revenues | C11: =C10/C5 -> 0.31157176 | D11: =D10/D5 -> 0.26908903 | E11: =E10/E5 -> 0.26332621 | F11: =F10/F5 -> 0.29110236 | G11: =G10/G5 -> 0.28307154 | H11: =H10/H5 -> 0.29256988 | I11: =I10/I5 -> 0.26466128 | J11: =J10/J5 -> 0.24926383 | ... AB11: =AB10/AB5 -> 0.19202211
A12: % variação anual | B12: % YoY growth | C12: - | D12: - | E12: - | F12: - | G12: - | H12: =H10/C10-1 -> 0.12029313 | I12: =I10/D10-1 -> 0.32520722 | J12: =J10/E10-1 -> -0.1684153 | K12: =K10/F10-1 -> -0.046319644 | L12: =L10/G10-1 -> 0.027317146 | M12: =M10/H10-1 -> -0.22164071 | N12: =N10/I10-1 -> -0.20604117 | O12: =O10/J10-1 -> -0.20119164 | ... AB12: =AB10/W10-1 -> -0.0016208413
A13: Corporativo | B13: Corporate | C13: 0 | D13: 0 | E13: 0 | F13: 0 | G13: 0 | H13: 0 | I13: 0 | J13: 0 | K13: 0 | L13: 0 | M13: 0 | N13: 0 | O13: 0 | P13: -0.3 | Q13: -0.4 | R13: 2.1615664 | S13: 1.8117957 | T13: 0.7 | U13: 17.1 | V13: 9.777954 | W13: 4.0315118 | X13: 3.3467597 | Y13: ='Histórico | Historic data'!AX20 -> 0.7 | Z13: ='Histórico | Historic data'!AY20 -> 0 | AA13: =Z13+Y13+X13+W13 -> 8.0782715 | AB13: 0
A15: Impostos e deduções | B15: Taxes and deductions | C15: =C23-C5 -> -1840.7531 | D15: =D23-D5 -> -1790.5574 | E15: =E23-E5 -> -2693.1975 | F15: =F23-F5 -> -2511.7639 | G15: =G23-G5 -> -8836.2719 | H15: =H23-H5 -> -2143.6769 | I15: =I23-I5 -> -2254.9122 | J15: =J23-J5 -> -2263.9855 | ... AB15: =AB23-AB5 -> -1967
A16: % receita bruta | B16: % gross revenues | C16: =C15/C5 -> -0.22656521 | D16: =D15/D5 -> -0.24143467 | E16: =E15/E5 -> -0.239733 | F16: =F15/F5 -> -0.214664 | G16: =G15/G5 -> -0.22965677 | H16: =H15/H5 -> -0.22115505 | I16: =I15/I5 -> -0.22565848 | J16: =J15/J5 -> -0.22939923 | ... AB16: =AB15/AB5 -> -0.22749352
A17: Natura & Co América Latina | B17: Natura & Co Latam | C17: =C25-C7 -> -1430.8726 | D17: =D25-D7 -> -1444.924 | E17: =E25-E7 -> -2192.2865 | F17: =F25-F7 -> -1974.1057 | G17: =G25-G7 -> -7042.1888 | H17: =H25-H7 -> -1671.2425 | I17: =I25-I7 -> -1814.2658 | J17: =J25-J7 -> -1857.6734 | ... P17: =P25-P7 -> -1943.7483 | Q17: =M17+N17+O17+P17 -> -7130.8141 | R17: =R25-R7 -> -1580.6922 | S17: =S25-S7 -> -1810.8795 | T17: =T25-T7 -> -1673.5 | U17: =U25-U7 -> -1689.0457 | V17: =U17+T17+S17+R17 -> -6754.1174 | W17: =W25-W7 -> -1667.3786 | X17: =X25-X7 -> -2022.2002 | Y17: =Y25-Y7 -> -1949.5212 | Z17: =Z25-Z7 -> -2294.8 | AA17: =AA25-AA7 -> -7933.9 | AB17: =AB25-AB7 -> -1701
A18: % receita bruta | B18: % gross revenues | C18: =C17/C7 -> -0.25582323 | D18: =D17/D7 -> -0.26655812 | E18: =E17/E7 -> -0.26489986 | F18: =F17/F7 -> -0.2379947 | G18: =G17/G7 -> -0.25529483 | H18: =H17/H7 -> -0.24372129 | I18: =I17/I7 -> -0.2469082 | J18: =J17/J7 -> -0.25072655 | ... AB18: =AB17/AB7 -> -0.24348349
A19: Avon International | B19: Avon International | C19: =C28-C10 -> -409.88054 | D19: =D28-D10 -> -345.63338 | E19: =E28-E10 -> -500.91094 | F19: =F28-F10 -> -537.65816 | G19: =G28-G10 -> -1794.083 | H19: =H28-H10 -> -472.43437 | I19: =I28-I10 -> -440.64635 | J19: =J28-J10 -> -406.3121 | ... P19: =P28-P10 -> -393.85869 | Q19: =M19+N19+O19+P19 -> -1532.7125 | R19: =R28-R10 -> -314.43346 | S19: =S28-S10 -> -284.8049 | T19: =T28-T10 -> 0 | U19: =U28-U10 -> -324.56786 | V19: =V28-V10 -> -1201.3233 | W19: =W28-W10 -> -266.32818 | X19: =X28-X10 -> -274.16613 | Y19: =Y28-Y10 -> -290.80569 | ... AB19: =AB28-AB10 -> -266
A20: % receita bruta | B20: % gross revenues | C20: =C19/C10 -> -0.16191865 | D20: =D19/D10 -> -0.1731933 | E20: =E19/E10 -> -0.16932694 | F20: =F19/F10 -> -0.15784867 | G20: =G19/G10 -> -0.16472386 | H20: =H19/H10 -> -0.16659018 | I20: =I19/I10 -> -0.16661795 | J20: =J19/J10 -> -0.1651653 | ... S20: =S19/S10 -> -0.15865468 | T20: 0 | U20: =U19/U10 -> -0.15920908 | V20: =V19/V10 -> -0.16043168 | W20: =W19/W10 -> -0.16014967 | X20: =X19/X10 -> -0.16117854 | Y20: =Y19/Y10 -> -0.16277996 | Z20: =Z19/Z10 -> -0.15410001 | AA20: =AA19/AA10 -> -0.15922915 | AB20: =AB19/AB10 -> -0.16021201
A21: Corporativo | B21: Corporate | C21: 0 | D21: 0 | E21: 0 | F21: 0 | G21: 0 | H21: 0 | I21: 0 | J21: 0 | K21: 0 | L21: 0 | M21: 0 | N21: 0 | O21: 0 | P21: =P30-P12 -> 0.0054256904 | Q21: =Q30-Q12 -> -0.0087865662 | R21: =R30-R12 -> 0.0019282583 | S21: 0 | T21: 0 | U21: =U13-U31 -> 0 | V21: =V13-V31 -> 0.067575588 | W21: =W13-W31 -> -9.094947e-13 | X21: =X13-X31 -> 4.5474735e-13 | Y21: =Y13-Y31 -> 0 | Z21: =Z13-Z31 -> 0 | AA21: =AA13-AA31 -> -4.5474735e-13 | AB21: =AB13-AB31 -> 0
A23: Receita Líquida | B23: Net Revenues | C23: =C25+C28 -> 6283.8531 | D23: =D25+D28 -> 5625.7651 | E23: =E25+E28 -> 8540.9565 | F23: =F25+F28 -> 9189.145 | G23: =G25+G28 -> 29639.72 | H23: =H25+H28 -> 7549.4182 | I23: =I25+I28 -> 7737.6758 | J23: =J25+J28 -> 7605.2086 | ... O23: =O25+O28 -> 7425.125 | P23: =P25+P28+P31 -> 8005.9 | Q23: =Q25+Q28+Q31 -> 29223.339 | R23: =R25+R28+R31 -> 6472.4155 | S23: =S25+S28+S31 -> 6973.7485 | T23: 5090 | U23: =U25+U28+U31 -> 6613.3696 | V23: =V25+V28+V31 -> 26737.3 | W23: =W25+W28+W31 -> 6105.2526 | X23: =X25+X28+X31 -> 7352.632 | Y23: =Y25+Y28+Y31 -> 7592.7937 | Z23: =Z25+Z28+Z31 -> 9005.6 | AA23: =AA25+AA28+AA31 -> 30056.278 | AB23: =AB25+AB28+AB31 -> 6679.4
A24: % variação anual | B24: % YoY growth | C24: - | D24: - | E24: - | F24: - | G24: - | H24: =H23/C23-1 -> 0.20139954 | I24: =I23/D23-1 -> 0.37539974 | J24: =J23/E23-1 -> -0.10956009 | K24: =K23/F23-1 -> -0.036861076 | L24: =L23/G23-1 -> 0.070952295 | M24: =M23/H23-1 -> -0.12662199 | N24: =N23/I23-1 -> -0.069640805 | O24: =O23/J23-1 -> -0.02367898 | ... T24: =T23/O23-1 -> -0.31448966 | U24: -0.24099598 | V24: =V23/Q23-1 -> -0.085070317 | W24: =W23/R23-1 -> -0.056727335 | X24: =X23/S23-1 -> 0.054329959 | Y24: =Y23/T23-1 -> 0.49170799 | Z24: =Z23/U23-1 -> 0.3617264 | AA24: =AA23/V23-1 -> 0.12413289 | AB24: =AB23/W23-1 -> 0.094041543
A25: Natura & Co América Latina | B25: Natura & Co Latam | C25: 4162.3357 | D25: 3975.7474 | E25: 6083.6203 | F25: 6320.6409 | G25: =F25+E25+D25+C25 -> 20542.344 | H25: 5185.9449 | I25: 5533.671 | J25: 5551.4876 | K25: 6142.2974 | L25: =K25+J25+I25+H25 -> 22413.401 | M25: 4751.5204 | N25: 5555.0449 | O25: 5777.533 | P25: 5943.2 | Q25: =P25+O25+N25+M25 -> 22027.298 | R25: 4863.7 | S25: 5461.8332 | T25: 5089.2 | U25: 4882.2109 | V25: 20440.845 | W25: 4704.5538 | X25: 5922.4425 | Y25: =AA25-Z25-X25-W25 -> 6096.4037 | Z25: 7160.1 | AA25: 23883.5 | AB25: 5285.1
A26: % receita Líquida | B26: % net revenues | C26: =C25/C23 -> 0.66238591 | D26: =D25/D23 -> 0.70670342 | E26: =E25/E23 -> 0.71228793 | F26: =F25/F23 -> 0.68783776 | G26: =G25/G23 -> 0.69306811 | H26: =H25/H23 -> 0.68693306 | I26: =I25/I23 -> 0.71515933 | J26: =J25/J23 -> 0.72995862 | ... T26: =T25/T23 -> 0.99984283 | U26: 0.61910498 | V26: =V25/V23 -> 0.7645067 | W26: =W25/W23 -> 0.7705748 | X26: =X25/X23 -> 0.80548604 | Y26: =Y25/Y23 -> 0.80291971 | Z26: =Z25/Z23 -> 0.79507196 | AA26: =AA25/AA23 -> 0.79462599 | AB26: =AB25/AB23 -> 0.79125371
A27: % variação anual | B27: % YoY growth | C27: - | D27: - | E27: - | F27: - | G27: - | H27: =H25/C25-1 -> 0.24592183 | I27: =I25/D25-1 -> 0.39185678 | J27: =J25/E25-1 -> -0.08746974 | K27: =K25/F25-1 -> -0.028216049 | L27: =L25/G25-1 -> 0.091082914 | M27: =M25/H25-1 -> -0.083769603 | N27: =N25/I25-1 -> 0.0038625183 | O27: =O25/J25-1 -> 0.040717989 | ... T27: =T25/O25-1 -> -0.11913961 | U27: -0.17852335 | V27: =V25/Q25-1 -> -0.072022152 | W27: =W25/R25-1 -> -0.032721213 | X27: =X25/S25-1 -> 0.084332351 | Y27: =Y25/T25-1 -> 0.19791003 | Z27: =Z25/U25-1 -> 0.46656918 | AA27: =AA25/V25-1 -> 0.16842039 | AB27: =AB25/W25-1 -> 0.1234009
A28: Avon International | B28: Avon International | C28: 2121.5174 | D28: 1650.0176 | E28: 2457.3363 | F28: 2868.5041 | G28: =F28+E28+D28+C28 -> 9097.3753 | H28: 2363.4733 | I28: 2204.0048 | J28: 2053.721 | K28: 2708.1258 | L28: =K28+J28+I28+H28 -> 9329.3249 | M28: 1841.9755 | N28: 1643.7729 | O28: 1647.592 | P28: 2062.6 | Q28: =P28+O28+N28+M28 -> 7195.9404 | R28: 1606.6 | S28: 1510.3195 | T28: 0 | U28: 1714.0588 | V28: 6286.7448 | W28: 1396.6673 | X28: 1426.8428 | Y28: =AA28-Z28-X28-W28 -> 1495.6899 | Z28: 1845.5 | AA28: 6164.7 | AB28: 1394.3
A29: % receita Líquida | B29: % net revenues | C29: =C28/C23 -> 0.33761409 | D29: =D28/D23 -> 0.29329658 | E29: =E28/E23 -> 0.28771207 | F29: =F28/F23 -> 0.31216224 | G29: =G28/G23 -> 0.30693189 | H29: =H28/H23 -> 0.31306694 | I29: =I28/I23 -> 0.28484067 | J29: =J28/J23 -> 0.27004138 | ... T29: =T28/T23 -> 0 | U29: 0.21736263 | V29: =V28/V23 -> 0.23513013 | W29: =W28/W23 -> 0.22876486 | X29: =X28/X23 -> 0.19405878 | Y29: =Y28/Y23 -> 0.19698809 | Z29: =Z28/Z23 -> 0.20492804 | AA29: =AA28/AA23 -> 0.20510523 | AB29: =AB28/AB23 -> 0.20874629
A30: % variação anual | B30: % YoY growth | C30: - | D30: - | E30: - | F30: - | G30: - | H30: =H28/C28-1 -> 0.11404853 | I30: =I28/D28-1 -> 0.3357462 | J30: =J28/E28-1 -> -0.1642491 | K30: =K28/F28-1 -> -0.055910069 | L30: =L28/G28-1 -> 0.025496317 | M30: =M28/H28-1 -> -0.2206489 | N30: =N28/I28-1 -> -0.25418814 | O30: =O28/J28-1 -> -0.19775276 | ... T30: =T28/O28-1 -> -1 | U30: -0.1689615 | V30: =V28/Q28-1 -> -0.12634841 | W30: =W28/R28-1 -> -0.13066894 | X30: =X28/S28-1 -> -0.055270914 | Y30: =Y28/T28-1 -> #DIV/0! | Z30: =Z28/U28-1 -> 0.07668421 | AA30: =AA28/V28-1 -> -0.019413029 | AB30: =AB28/W28-1 -> -0.0016949452
A31: Corporativo | B31: Corporate | C31: 0 | D31: 0 | E31: 0 | F31: 0 | G31: 0 | H31: 0 | I31: 0 | J31: 0 | K31: 0 | L31: 0 | M31: 0 | N31: 0 | O31: 0 | P31: 0.1 | Q31: 0.1 | R31: 2.1155004 | S31: 1.5957851 | T31: 0.7 | U31: 17.1 | V31: 9.7103784 | W31: 4.0315118 | X31: 3.3467597 | Y31: ='Histórico | Historic data'!AX49 -> 0.7 | Z31: ='Histórico | Historic data'!AY49 -> 0 | AA31: =Z31+Y31+X31+W31 -> 8.0782715 | AB31: 0
A33: CMV | B33: COGS | C33: =C44-C23 -> -2645.2966 | D33: =D44-D23 -> -2141.0289 | E33: =E44-E23 -> -3362.1985 | F33: =F44-F23 -> -3736.1974 | G33: =G44-G23 -> -11884.721 | H33: =H44-H23 -> -2993.1904 | I33: =I44-I23 -> -3019.6954 | J33: =J44-J23 -> -2953.1594 | ... AB33: =AB44-AB23 -> -2253.3
A34: % receita Líquida | B34: % net revenues | C34: =C33/C23 -> -0.42096729 | D34: =D33/D23 -> -0.3805756 | E34: =E33/E23 -> -0.39365597 | F34: =F33/F23 -> -0.40658815 | G34: =G33/G23 -> -0.4009728 | H34: =H33/H23 -> -0.39647961 | I34: =I33/I23 -> -0.39025872 | J34: =J33/J23 -> -0.38830748 | ... AB34: =AB33/AB23 -> -0.33735066
A35: % variação anual | B35: % YoY growth | C35: - | D35: - | E35: - | F35: - | G35: - | H35: =H33/C33-1 -> 0.13151409 | I35: =I33/D33-1 -> 0.41039452 | J35: =J33/E33-1 -> -0.12165823 | K35: =K33/F33-1 -> -0.045752342 | L35: =L33/G33-1 -> 0.054404422 | M35: =M33/H33-1 -> -0.11144375 | N35: =N33/I33-1 -> -0.022321271 | O35: =O33/J33-1 -> -0.0023166383 | ... AB35: =AB33/W33-1 -> 0.05933965
A36: Natura & Co América Latina | B36: Natura & Co Latam | C36: =C47-C25 -> -1718.0934 | D36: =D47-D25 -> -1508.4989 | E36: =E47-E25 -> -2384.0139 | F36: =F47-F25 -> -2452.1509 | G36: =G47-G25 -> -8062.757 | H36: =H47-H25 -> -2047.0304 | I36: =I47-I25 -> -2177.4328 | J36: =J47-J25 -> -2158.9091 | ... T36: =T47-T25 -> -1839.1 | U36: -1797.4193 | V36: =R36+S36+T36+U36 -> -7335.1971 | W36: -1603.9854 | X36: -2052.7109 | Y36: =Y47-Y25 -> -1987.0038 | Z36: =Z47-Z25 -> -2623.2 | AA36: =AA47-AA25 -> -8266.9 | AB36: =AB47-AB25 -> -1739.3
A37: % receita Líquida | B37: % net revenues | C37: =C36/C25 -> -0.41277146 | D37: =D36/D25 -> -0.37942523 | E37: =E36/E25 -> -0.39187421 | F37: =F36/F25 -> -0.38795922 | G37: =G36/G25 -> -0.39249449 | H37: =H36/H25 -> -0.3947266 | I37: =I36/I25 -> -0.39348795 | J37: =J36/J25 -> -0.38888839 | ... AB37: =AB36/AB25 -> -0.329095
A38: % variação anual | B38: % YoY growth | C38: - | D38: - | E38: - | F38: - | G38: - | H38: =H36/C36-1 -> 0.19145469 | I38: =I36/D36-1 -> 0.44344347 | J38: =J36/E36-1 -> -0.094422605 | K38: =K36/F36-1 -> -0.00099261205 | L38: =L36/G36-1 -> 0.09554203 | M38: =M36/H36-1 -> -0.06446841 | N38: =N36/I36-1 -> 0.044370636 | O38: =O36/J36-1 -> 0.056436344 | ... AB38: =AB36/W36-1 -> 0.084361518
A39: Avon International | B39: Avon International | C39: =C50-C28 -> -927.20321 | D39: =D50-D28 -> -632.53004 | E39: =E50-E28 -> -978.18466 | F39: =F50-F28 -> -1284.0465 | G39: =G50-G28 -> -3821.9644 | H39: =H50-H28 -> -946.15995 | I39: =I50-I28 -> -842.2626 | J39: =J50-J28 -> -794.25034 | ... S39: =S50-S28 -> -553.58818 | T39: 0 | U39: -645.03125 | V39: =R39+S39+T39+U39 -> -1769.8392 | W39: -519.79901 | X39: -555.37952 | Y39: =Y50-Y28 -> -547.22147 | Z39: =Z50-Z28 -> -748.6 | AA39: =AA50-AA28 -> -2371 | AB39: =AB50-AB28 -> -514
A40: % receita Líquida | B40: % net revenues | C40: =C39/C28 -> -0.4370472 | D40: =D39/D28 -> -0.38334744 | E40: =E39/E28 -> -0.39806708 | F40: =F39/F28 -> -0.44763629 | G40: =G39/G28 -> -0.42011726 | H40: =H39/H28 -> -0.40032606 | I40: =I39/I28 -> -0.38215098 | J40: =J39/J28 -> -0.38673721 | ... S40: =S39/S28 -> -0.36653713 | T40: 0 | U40: =U39/U28 -> -0.37631805 | V40: =V39/V28 -> -0.28151918 | W40: =W39/W28 -> -0.37217097 | X40: =X39/X28 -> -0.38923666 | Y40: =Y39/Y28 -> -0.36586558 | Z40: =Z39/Z28 -> -0.40563533 | AA40: =AA39/AA28 -> -0.38460915 | AB40: =AB39/AB28 -> -0.36864376
A41: % variação anual | B41: % YoY growth | C41: - | D41: - | E41: - | F41: - | G41: - | H41: =H39/C39-1 -> 0.020445079 | I41: =I39/D39-1 -> 0.33157723 | J41: =J39/E39-1 -> -0.1880364 | K41: =K39/F39-1 -> -0.13123025 | L41: =L39/G39-1 -> -0.032378839 | M41: =M39/H39-1 -> -0.21307557 | N41: =N39/I39-1 -> -0.19473442 | O41: =O39/J39-1 -> -0.16201735 | ... AB41: =AB39/W39-1 -> -0.011156251
A42: Corporativo | B42: Corporate | C42: 0 | D42: 0 | E42: 0 | F42: 0 | G42: 0 | H42: 0 | I42: 0 | J42: 0 | K42: 0 | L42: 0 | M42: 0 | N42: 0 | O42: 0 | P42: 0 | Q42: 0 | R42: =R33-R36-R39 -> -0.65771298 | S42: =S33-S36-S39 -> -0.53782895 | T42: 0 | U42: =U33-U36-U39 -> -2.1 | V42: =V33-V36-V39 -> -1592.3776 | W42: =W33-W36-W39 -> -3.2954593 | X42: =X33-X36-X39 -> -2.8814657 | Y42: =Y33-Y36-Y39 -> -0.7 | Z42: =Z33-Z36-Z39 -> 0 | AA42: =AA33-AA36-AA39 -> -6.8769249 | AB42: =AB33-AB36-AB39 -> 0
A44: Lucro Bruto | B44: Gross Profit | C44: =C47+C50 -> 3638.5565 | D44: =D47+D50 -> 3484.7362 | E44: =E47+E50 -> 5178.758 | F44: =F47+F50 -> 5452.9476 | G44: =G47+G50 -> 17754.998 | H44: =H47+H50 -> 4556.2279 | I44: =I47+I50 -> 4717.9803 | J44: =J47+J50 -> 4652.0492 | ... N44: =N47+N50 -> 4246.5258 | O44: =O47+O50+O53 -> 4478.807 | P44: =P47+P50+P53 -> 4793.4 | Q44: =Q47+Q50+Q53 -> 17452.611 | R44: =R47+R50+R53 -> 4158.3448 | S44: =S47+S50+S53 -> 4463.1378 | T44: =T47+T50+T53 -> 3250.6 | U44: =U47+U50+U53 -> 4168.8191 | V44: =V47+V50+V53 -> 16039.886 | ... AB44: =AB47+AB50+AB53 -> 4426.1
...

Sheet Graphs (2)
B2: Revenue
B4: Consolidated Net Revenue Growth | I4: Net Revenue by Geography
C5: 2T-22 | D5: 2T-23 | J5: 2T-23 | K5: 2T-22
C6: Net Revenue | J6: Net Revenue
C7: Q2-22 | D7: Q2-23 | E7: Δ% RC | F7: Δ% CC | J7: Q2-23 | K7: Q2-22 | L7: Δ% RC
B8: Natura & Co Latam | C8: 5555.0449 | D8: 5462.9 | E8: =#REF! -> #REF! | F8: =#REF! -> #REF! | H8: Brasil | I8: Brazil | J8: 30.5 | K8: 30.5
B9: Avon International | C9: 1643.7729 | D9: 1510.3 | E9: =#REF! -> #REF! | F9: =#REF! -> #REF! | H9: Latam Hispânica | I9: Hispanic Latam | J9: 28.7 | K9: 28.7
B10: The Body Shop | C10: 909.43307 | D10: 800.3 | E10: =#REF! -> #REF! | F10: =#REF! -> #REF! | H10: EMEA | I10: EMEA | J10: 23.3 | K10: 23.3
B11: Consolidated | C11: 8108.2509 | D11: 7773.5 | E11: =#REF! -> #REF! | F11: =#REF! -> #REF! | H11: Ásia Pacífico | I11: Asia Pacific | J11: 11.9 | K11: 11.9
H12: América do Norte | I12: North America | J12: 5.7 | K12: 5.7
I13: Consolidated | J13: =SUM(J8:J10) -> 82.5 | K13: =SUM(K8:K10) -> 82.5
C19: Q2-23
B24: Underlying Net Income
C26: Q2-23
A27: Lucro Líquido 2T-23 | B27: Net income Q2-23 | C27: =#REF! -> #REF!
A28: (-) Custos de Transformação / Integração | B28: (-) Transformation / Integration Cost | C28: =#REF! -> #REF!
A29: (-) Custos de Reestruturação / Operações Descontinuadas e outros efeitos | B29: (-) Reestructuring Costs / Descontinued Operations and other effects | C29: =SUM(C30:C33) -> #REF!
A30: Restructuring Cost | B30: Restructuring Cost | C30: =#REF! -> #REF!
A31: Net Non Recurring Items | B31: Net Non Recurring Items | C31: =#REF! -> #REF!
A32: Discontinued Operations | B32: Discontinued Operations | C32: =-#REF! -> #REF!
A33: Non Controlling Interest | B33: Non Controlling Interest | C33: =#REF! -> #REF!
A34: (-) PPA | B34: (-) PPA | C34: =SUM(C35:C38) -> 120.10545
A35: PPA financial result | B35: PPA financial result | C35: 5.0421244
A36: PPA Depreciation | B36: PPA Depreciation | C36: 136.12051
A37: PPA taxes | B37: PPA taxes | C37: -15.574796
A38: PPA EBITDA | B38: PPA EBITDA | C38: -5.4823851
A39: (=) Lucro Líquido Underlying | B39: (=) Underlying Net Income | C39: =C27+C28+C29+C34-0.1 -> #REF!
B45: Net Debt/EBITDA ratio
B58: Natura Brand
C60: 2T-21 | D60: 2T-22 | E60: Var. % | F60: 3T-21 | G60: 3T-22 | H60: Var. % | I60: 4T-21 | J60: 4T-22 | K60: Var. % | L60: 1T-22 | M60: 1T-23 | N60: Var. % | O60: 2T-22 | P60: 2T-23 | Q60: Var. %
C61: Q2-21 | D61: Q2-22 | E61: Ch. % | F61: Q3-21 | G61: Q3-22 | H61: Ch. % | I61: Q4-21 | J61: Q4-22 | K61: Ch. % | L61: Q1-22 | M61: Q1-23 | N61: Ch. % | O61: Q2-22 | P61: Q2-23 | Q61: Ch. %
B62: Gross Revenue Brazil | C62: 2539.3429 | D62: 2852.5751 | E62: =D62/C62-1 -> 0.12335169 | F62: 2367.1755 | G62: 2775 | H62: =G62/F62-1 -> 0.17228318 | I62: 2918.5073 | J62: 3409.6 | K62: =J62/I62-1 -> 0.16826844 | L62: 2074.0596 | M62: 2587.7 | N62: =M62/L62-1 -> 0.24764979 | O62: =D62 -> 2852.5751 | P62: 3270.7 | Q62: =P62/O62-1 -> 0.14657806
B63: Total consultants Brazil - average of the period | C63: 1175.5014 | D63: 1123.6727 | E63: =D63/C63-1 -> -0.044090746 | F63: 1186.9536 | G63: 1146.5805 | H63: =G63/F63-1 -> -0.034014051 | I63: 1137.0372 | J63: 1156.336 | K63: =J63/I63-1 -> 0.016972913 | L63: 1091.3664 | M63: 1130.9144 | N63: =M63/L63-1 -> 0.036237143 | O63: =D63 -> 1123.6727 | P63: =#REF! -> #REF! | Q63: =P63/O63-1 -> #REF!
B64: Productivity | C64: 2.160221 | D64: 2.5386175 | E64: =D64/C64-1 -> 0.17516562 | F64: 1.9943286 | G64: 2.42024 | H64: =G64/F64-1 -> 0.21356131 | I64: 2.5667651 | J64: 2.9486239 | K64: =J64/I64-1 -> 0.14877046 | L64: 1.9004246 | M64: 2.2881484 | N64: =M64/L64-1 -> 0.20401956 | O64: =O62/O63 -> 2.5386175 | P64: =P62/P63 -> #REF! | Q64: =P64/O64-1 -> #REF!
A66: Crescimento da produtividade | B66: Productivity growth | C66: Published
A67: 2T-22 | B67: Q2-22 | C67: =E64 -> 0.17516562
A68: 3T-22 | B68: Q3-22 | C68: =H64 -> 0.21356131
A69: 4T-22 | B69: Q4-22 | C69: =K64 -> 0.14877046
A70: 1T-23 | B70: Q1-23 | C70: =N64 -> 0.20401956
A71: 2T-23 | B71: Q2-23 | C71: =Q64 -> #REF!
...
