Workbook

Sheet 2011
B2: 2011 | H2: Pro-Forma
B3: (R$ million) | C3: Consolidated | H3: Brazil | M3: Latam | R3: Aesop
C4: 1Q16 | D4: 2Q16 | E4: 3Q16 | F4: 4Q16 | G4: 2016 | H4: 1Q16 | I4: 2Q16 | J4: 3Q16 | K4: 4Q16 | L4: 2016 | M4: 1Q16 | N4: 2Q16 | O4: 3Q16 | P4: 4Q16 | Q4: 2016 | R4: 1Q16 | S4: 2Q16 | T4: 3Q16 | U4: 4Q16 | V4: 2016
B5: Total Consultants - end of period ('000)2 | C5: 1230.203 | D5: 1296.068 | E5: 1361.622 | F5: 1421.137 | G5: 1421.137 | H5: 1032.703 | I5: 1079.09 | J5: 1131.381 | K5: 1175.471 | L5: 1175.471 | M5: 200.73 | N5: 216.978 | O5: 230.241 | P5: 245.666 | Q5: 245.666 | R5: 0 | S5: 0 | T5: 0 | U5: 0 | V5: 0
B6: Total Consultants - average of period ('000) | C6: 1224.075 | D6: 1278.2551 | E6: 1331.7338 | F6: 1400.3214 | G6: 1313.4067 | H6: 1027.1592 | I6: 1065.6626 | J6: 1106.162 | K6: 1160.4164 | L6: 1093.1687 | M6: 196.91575 | N6: 212.5925 | O6: 225.57175 | P6: 239.905 | Q6: 220.23794 | R6: 0 | S6: 0 | T6: 0 | U6: 0 | V6: 2.8117647
B7: Units sold – items for resale (in million) | C7: 100.04548 | D7: 109.05143 | E7: 118.33295 | F7: 131.11265 | G7: 458.6425 | H7: 90.138928 | I7: 97.589054 | J7: 104.98966 | K7: 117.8009 | L7: 410.51854 | M7: 9.9065488 | N7: 11.762371 | O7: 13.343293 | P7: 14.011742 | Q7: 49.023955 | R7: 0 | S7: 0 | T7: 0 | U7: 0 | V7: 0
B8: Gross Revenue | C8: 1556.0408 | D8: 1885.14 | E8: 1862.033 | F8: 2232.5505 | G8: 7535.7644 | H8: 1438.6805 | I8: 1735.4978 | J8: 1693.8738 | K8: 2030.8336 | L8: 6898.8858 | M8: 114.14621 | N8: 145.1292 | O8: 164.65121 | P8: 195.21775 | Q8: 619.14437 | R8: 0 | S8: 0 | T8: 0 | U8: 0 | V8: 0
B9: Net Revenue | C9: 1145.8458 | D9: 1393.6157 | E9: 1381.4341 | F9: 1670.4781 | G9: 5591.3737 | H9: 1052.4712 | I9: 1274.8356 | J9: 1249.3315 | K9: 1510.9831 | L9: 5087.6214 | M9: 90.687387 | N9: 115.00673 | O9: 129.16957 | P9: 154.06088 | Q9: 488.92457 | R9: 0 | S9: 0 | T9: 0 | U9: 0 | V9: 0
B10: Gross Profit | C10: 802.6242 | D10: 980.5712 | E10: 967.6474 | F10: 1174.231 | G10: 3925.0738 | H10: 747.25816 | I10: 907.51096 | J10: 884.14609 | K10: 1072.3465 | L10: 3611.2617 | M10: 53.404121 | N10: 70.992005 | O10: 82.011998 | P10: 99.702193 | Q10: 306.11032 | R10: 0 | S10: 0 | T10: 0 | U10: 0 | V10: 0
B11: Selling, Marketing and Logistics Expenses | C11: -422.91433 | D11: -486.37843 | E11: -500.2152 | F11: -543.23171 | G11: -1952.7397 | H11: -368.89844 | I11: -422.6431 | J11: -426.31034 | K11: -468.67585 | L11: -1686.5277 | M11: -50.283491 | N11: -60.096632 | O11: -69.555041 | P11: -68.726791 | Q11: -248.66195 | R11: 0 | S11: 0 | T11: 0 | U11: 0 | V11: 0
B12: Administrative, R&D, IT and Projects Expenses | C12: -133.08488 | D12: -170.97857 | E12: -177.90611 | F12: -198.76389 | G12: -680.73345 | H12: -107.46669 | I12: -147.24085 | J12: -152.52419 | K12: -170.66229 | L12: -577.89402 | M12: -24.005328 | N12: -21.492179 | O12: -24.07874 | P12: -26.553767 | Q12: -96.130015 | R12: 0 | S12: 0 | T12: 0 | U12: 0 | V12: 0
B13: Employee profit sharing | C13: -17.90767 | D13: -21.32938 | E13: 14.198864 | F13: -5.1298083 | G13: -30.167993 | H13: -17.90767 | I13: -21.32938 | J13: 14.198864 | K13: -5.1298083 | L13: -30.167993 | M13: 0 | N13: 0 | O13: 0 | P13: 0 | Q13: 0 | R13: 0 | S13: 0 | T13: 0 | U13: 0 | V13: 0
B14: Management compensation | C14: -3.221523 | D14: -3.669664 | E14: -2.8198158 | F14: 0.26755978 | G14: -9.443443 | H14: -3.221523 | I14: -3.669664 | J14: -2.8208158 | K14: 0.26755978 | L14: -9.444443 | M14: 0 | N14: 0 | O14: 0 | P14: 0 | Q14: 0 | R14: 0 | S14: 0 | T14: 0 | U14: 0 | V14: 0
B15: Other Operating Income / (Expenses), net | C15: 13.796681 | D15: 2.9949368 | E15: 4.2173332 | F15: 42.07007 | G15: 63.079021 | H15: 14.683209 | I15: 3.7351698 | J15: 5.0128209 | K15: 42.225394 | L15: 65.656594 | M15: -0.8865281 | N15: -0.74023307 | O15: -0.79587818 | P15: 0.17124048 | Q15: -2.2513989 | R15: 0 | S15: 0 | T15: 0 | U15: 0 | V15: 0
B16: Financial Income / (Expenses), net | C16: -10.196478 | D16: -21.077064 | E16: -4.444381 | F16: -41.605239 | G16: -77.323162 | H16: -9.8355022 | I16: -21.909656 | J16: -1.7224324 | K16: -40.00168 | L16: -73.46927 | M16: -0.36097581 | N16: 0.8325917 | O16: -2.7219486 | P16: -1.6035588 | Q16: -3.8538915 | R16: 0 | S16: 0 | T16: 0 | U16: 0 | V16: 0
... B27: EBITDA Margin | C27: 0.23049876 | D27: 0.23487488 | E27: 0.24125476 | F27: 0.29953743 | G27: 0.25485502 | H27: 0.27325653 | I27: 0.26746727 | J27: 0.2786022 | K27: 0.33052377 | L27: 0.29012649 | M27: -0.22310863 | N27: -0.086616598 | O27: -0.082937321 | P27: 0.041436086 | Q27: -0.070611975 | R27: 0 | S27: 0 | T27: 0 | U27: 0 | V27: 0
B29: (*) EBITDA = Income from operations before financial effects + depreciation & amortization.

Sheet 2012
B2: 2012 | H2: Pro-Forma
B3: (R$ million) | C3: Consolidated | H3: Brazil | M3: Latam | R3: Aesop
C4: 1Q16 | D4: 2Q16 | E4: 3Q16 | F4: 4Q16 | G4: 2016 | H4: 1Q16 | I4: 2Q16 | J4: 3Q16 | K4: 4Q16 | L4: 2016 | M4: 1Q16 | N4: 2Q16 | O4: 3Q16 | P4: 4Q16 | Q4: 2016 | R4: 1Q16 | S4: 2Q16 | T4: 3Q16 | U4: 4Q16 | V4: 2016
B5: Total Consultants - end of period ('000)2 | C5: 1434.832 | D5: 1505.543 | E5: 1518.032 | F5: 1572.811 | G5: 1572.811 | H5: 1178.6 | I5: 1226.01 | J5: 1226.611 | K5: 1268.422 | L5: 1268.422 | M5: 256.232 | N5: 279.533 | O5: 291.421 | P5: 304.389 | Q5: 304.389 | R5: 0 | S5: 0 | T5: 0 | U5: 0 | V5: 0
B6: Total Consultants - average of period ('000) | C6: 1418.7711 | D6: 1487.7993 | E6: 1513.0603 | F6: 1555.7809 | G6: 1497.7119 | H6: 1165.403 | I6: 1215.0522 | J6: 1226.0178 | K6: 1253.791 | L6: 1216.7734 | M6: 253.36805 | N6: 272.74713 | O6: 287.04245 | P6: 301.98985 | Q6: 280.9385 | R6: 0 | S6: 0 | T6: 0 | U6: 0 | V6: 2.7427647
B7: Units sold – items for resale (in million) | C7: 112.48091 | D7: 120.87453 | E7: 128.92689 | F7: 140.17584 | G7: 499.45816 | H7: 100.64471 | I7: 108.22248 | J7: 111.78118 | K7: 125.1509 | L7: 445.79927 | M7: 11.836199 | N7: 12.652046 | O7: 14.145708 | P7: 15.024936 | Q7: 53.658889 | R7: 0 | S7: 0 | T7: 0 | U7: 0 | V7: 0
B8: Gross Revenue | C8: 1712.0708 | D8: 2148.6894 | E8: 2154.1686 | F8: 2551.1652 | G8: 8566.094 | H8: 1540.0606 | I8: 1928.0387 | J8: 1903.5776 | K8: 2257.7688 | L8: 7629.4457 | M8: 167.90557 | N8: 216.18091 | O8: 247.48391 | P8: 287.52178 | Q8: 919.09216 | R8: 0 | S8: 0 | T8: 0 | U8: 0 | V8: 0
B9: Net Revenue | C9: 1275.8349 | D9: 1608.2831 | E9: 1586.5325 | F9: 1875.019 | G9: 6345.6696 | H9: 1140.2118 | I9: 1434.2918 | J9: 1391.7752 | K9: 1644.9524 | L9: 5611.2312 | M9: 132.19128 | N9: 170.254 | O9: 192.15941 | P9: 225.15474 | Q9: 719.75943 | R9: 0 | S9: 0 | T9: 0 | U9: 0 | V9: 0
B10: Gross Profit | C10: 910.50349 | D10: 1136.9716 | E10: 1131.5235 | F10: 1298.6258 | G10: 4477.6243 | H10: 820.10542 | I10: 1016.8144 | J10: 994.93044 | K10: 1139.8719 | L10: 3971.7222 | M10: 87.856218 | N10: 117.7409 | O10: 134.74557 | P10: 155.27134 | Q10: 495.61402 | R10: 0 | S10: 0 | T10: 0 | U10: 0 | V10: 0
B11: Selling, Marketing and Logistics Expenses | C11: -488.2704 | D11: -550.58603 | E11: -535.2573 | F11: -638.09129 | G11: -2212.205 | H11: -412.95987 | I11: -453.07171 | J11: -435.55655 | K11: -533.69935 | L11: -1835.2875 | M11: -71.836019 | N11: -93.752908 | O11: -96.338146 | P11: -99.726016 | Q11: -361.65309 | R11: 0 | S11: 0 | T11: 0 | U11: 0 | V11: 0
B12: Administrative, R&D, IT and Projects Expenses | C12: -164.97596 | D12: -194.40926 | E12: -203.84506 | F12: -208.30805 | G12: -771.53833 | H12: -140.1127 | I12: -164.42147 | J12: -170.94036 | K12: -168.99045 | L12: -644.46497 | M12: -24.777252 | N12: -29.832986 | O12: -32.634344 | P12: -36.320645 | Q12: -123.56523 | R12: 0 | S12: 0 | T12: 0 | U12: 0 | V12: 0
B13: Employee profit sharing | C13: -12.56845 | D13: -29.040665 | E13: -28.106121 | F13: -21.083202 | G13: -90.798438 | H13: -8.4594952 | I13: -24.931711 | J13: -23.997166 | K13: -16.974248 | L13: -74.36262 | M13: -2.5421652 | N13: -2.5421652 | O13: -2.5421652 | P13: -5.3785326 | Q13: -13.005028 | R13: 0 | S13: 0 | T13: 0 | U13: 0 | V13: 0
B14: Management compensation | C14: -3.978 | D14: -6.3500359 | E14: -5.2265271 | F14: -5.184854 | G14: -20.739417 | H14: -3.978 | I14: -6.3500359 | J14: -5.2265271 | K14: -5.184854 | L14: -20.739417 | M14: 0 | N14: 0 | O14: 0 | P14: 0 | Q14: 0 | R14: 0 | S14: 0 | T14: 0 | U14: 0 | V14: 0
B15: Other Operating Income / (Expenses), net | C15: -2.0620274 | D15: 0.42265731 | E15: -9.4938804 | F15: -0.50348582 | G15: -11.636736 | H15: -1.2861846 | I15: 1.15831 | J15: -8.5175542 | K15: 2.7464708 | L15: -5.898958 | M15: -0.77584283 | N15: -0.73165271 | O15: -0.776645 | P15: -2.2626764 | Q15: -4.5468169 | R15: 0 | S15: 0 | T15: 0 | U15: 0 | V15: 0
B16: Financial Income / (Expenses), net | C16: -15.215829 | D16: -39.759813 | E16: 0.42453376 | F16: -17.797014 | G16: -72.348121 | H16: -16.405593 | I16: -40.824182 | J16: -0.91572749 | K16: -11.672277 | L16: -69.817779 | M16: 1.1897639 | N16: 1.064369 | O16: 1.3402613 | P16: -6.1247364 | Q16: -2.5303422 | R16: 0 | S16: 0 | T16: 0 | U16: 0 | V16: 0
... B27: EBITDA Margin | C27: 0.21330265 | D27: 0.24348687 | E27: 0.24267486 | F27: 0.24700638 | G27: 0.23825508 | H27: 0.24981783 | I27: 0.28021947 | J27: 0.27578294 | K27: 0.27547111 | L27: 0.27154939 | M27: -0.077235118 | N27: -0.04314244 | O27: 0.023994376 | P27: 0.06117868 | Q27: 0.0011537648 | R27: 0 | S27: 0 | T27: 0 | U27: 0 | V27: 0
B29: (*) EBITDA = Income from operations before financial effects + depreciation & amortization.

Sheet 2013
B2: 2013 | H2: Pro-Forma
B3: (R$ million) | C3: Consolidated | H3: Brazil | M3: Latam | R3: Aesop
C4: 1Q16 | D4: 2Q16 | E4: 3Q16 | F4: 4Q16 | G4: 2016 | H4: 1Q16 | I4: 2Q16 | J4: 3Q16 | K4: 4Q16 | L4: 2016 | M4: 1Q16 | N4: 2Q16 | O4: 3Q16 | P4: 4Q16 | Q4: 2016 | R4: 1Q16 | S4: 2Q16 | T4: 3Q16 | U4: 4Q16 | V4: 2016
B5: Total Consultants - end of period ('000)2 | C5: 1556.835 | D5: 1574.791 | E5: 1604.078 | F5: 1656.483 | G5: 1656.483 | H5: 1257.566 | I5: 1248.887 | J5: 1257.722 | K5: 1289.93 | L5: 1289.93 | M5: 299.269 | N5: 325.904 | O5: 346.356 | P5: 366.553 | Q5: 366.553 | R5: 0 | S5: 0 | T5: 0 | U5: 0 | V5: 0
B6: Total Consultants - average of period ('000) | C6: 1557.1759 | D6: 1571.114 | E6: 1596.7398 | F6: 1642.8992 | G6: 1596.1532 | H6: 1256.2262 | I6: 1256.337 | J6: 1256.3708 | K6: 1283.1928 | L6: 1264.8023 | M6: 300.94967 | N6: 314.77705 | O6: 340.369 | P6: 359.7064 | Q6: 331.3509 | R6: 0 | S6: 0 | T6: 0 | U6: 0 | V6: 0
B7: Units sold – items for resale (in million) | C7: 111.59892 | D7: 128.31231 | E7: 146.38114 | F7: 170.03848 | G7: 556.33085 | H7: 98.207473 | I7: 111.3823 | J7: 126.24715 | K7: 144.0599 | L7: 479.89683 | M7: 13.391449 | N7: 16.930006 | O7: 20.133987 | P7: 25.978573 | Q7: 76.434015 | R7: 0 | S7: 0 | T7: 0 | U7: 2.0268502 | V7: 2.0268502
B8: Gross Revenue | C8: 1832.3545 | D8: 2313.3312 | E8: 2396.4113 | F8: 2909.6027 | G8: 9451.6997 | H8: 1596.6526 | I8: 1981.9082 | J8: 2007.536 | K8: 2454.1797 | L8: 8040.2765 | M8: 222.10012 | N8: 298.85379 | O8: 347.20753 | P8: 389.53321 | Q8: 1257.6947 | R8: 10.513517 | S8: 28.550824 | T8: 38.623227 | U8: 60.21951 | V8: 137.90708
B9: Net Revenue | C9: 1351.2634 | D9: 1715.8385 | E9: 1777.7223 | F9: 2165.5837 | G9: 7010.308 | H9: 1164.5173 | I9: 1450.6913 | J9: 1467.3405 | K9: 1797.6754 | L9: 5880.2245 | M9: 173.64954 | N9: 233.23654 | O9: 269.11295 | P9: 302.94781 | Q9: 978.94684 | R9: 10.513517 | S9: 28.550824 | T9: 38.623227 | U9: 60.21951 | V9: 137.90708
B10: Gross Profit | C10: 947.32441 | D10: 1212.2225 | E10: 1257.5222 | F10: 1482.2189 | G10: 4899.188 | H10: 816.47574 | I10: 1019.1694 | J10: 1033.0735 | K10: 1213.2122 | L10: 4081.9308 | M10: 120.17965 | N10: 165.84472 | O10: 189.11371 | P10: 214.25959 | Q10: 689.39767 | R10: 8.8554993 | S10: 24.842629 | T10: 33.300237 | U10: 51.156044 | V10: 118.15441
B11: Selling, Marketing and Logistics Expenses | C11: -503.45677 | D11: -616.99934 | E11: -619.97796 | F11: -710.42831 | G11: -2434.2024 | H11: -414.59097 | I11: -500.14298 | J11: -484.13011 | K11: -548.52584 | L11: -1934.3551 | M11: -84.531347 | N11: -109.56809 | O11: -127.57069 | P11: -149.32082 | Q11: -470.99094 | R11: -1.2090002 | S11: -3.7453251 | T11: -4.9810945 | U11: -6.9178933 | V11: -16.853313
B12: Administrative, R&D, IT and Projects Expenses | C12: -223.75708 | D12: -250.04311 | E12: -289.05882 | F12: -284.74426 | G12: -978.30328 | H12: -171.42178 | I12: -185.04052 | J12: -208.67036 | K12: -202.07751 | L12: -702.66358 | M12: -36.669531 | N12: -39.408857 | O12: -46.620373 | P12: -48.573016 | Q12: -171.27178 | R12: -12.174848 | S12: -20.424501 | T12: -30.421113 | U12: -32.189123 | V12: -95.209585
B13: Employee profit sharing | C13: n/a | D13: n/a | E13: n/a | F13: 7.7561933 | G13: -61 | H13: n/a | I13: n/a | J13: n/a | K13: 6.4222787 | L13: -53.981121 | M13: -1.785 | N13: -3.2059812 | O13: -0.97332866 | P13: 1.102172 | Q13: -4.8621379 | R13: 0 | S13: 0 | T13: 0 | U13: 0 | V13: 0
B14: Management compensation | C14: n/a | D14: n/a | E14: n/a | F14: -1.376 | G14: -18.6 | H14: n/a | I14: n/a | J14: n/a | K14: -1.376 | L14: -18.554 | M14: 0 | N14: 0 | O14: 0 | P14: 0 | Q14: 0 | R14: 0 | S14: 0 | T14: 0 | U14: 0 | V14: 0
B15: Other Operating Income / (Expenses), net | C15: -0.30969414 | D15: 17.600429 | E15: -3.1248175 | F15: -5.5050107 | G15: 8.8609066 | H15: -0.33128979 | I15: 17.76247 | J15: -2.8601476 | K15: -2.9391877 | L15: 11.631845 | M15: 0.66628165 | N15: -0.40178625 | O15: 0.57821055 | P15: -1.7148108 | Q15: -0.8721049 | R15: -0.32634875 | S15: 0.68142964 | T15: -0.28913036 | U15: 0.06046266 | V15: 0.12641318
B16: Financial Income / (Expenses), net | C16: -37.792542 | D16: -11.410723 | E16: -84.982842 | F16: -24.066619 | G16: -158.25273 | H16: -37.282343 | I16: -8.0486679 | J16: -83.699852 | K16: -19.315627 | L16: -148.34649 | M16: -0.43947605 | N16: -3.6655009 | O16: -1.8746974 | P16: -6.7992183 | Q16: -12.778893 | R16: -0.07072364 | S16: 0.30344543 | T16: 0.59170775 | U16: 2.0482261 | V16: 2.8726557
B17: Income Tax and Social Contribution | C17: -57.395621 | D17: -110.66879 | E17: -77.22227 | F17: -164.64174 | G17: -409.92843 | H17: -55.84857 | I17: -102.68201 | J17: -70.356545 | K17: -154.67364 | L17: -383.56077 | M17: -1.4845131 | N17: -7.650724 | O17: -6.5065539 | P17: -9.1455334 | Q17: -24.787324 | R17: -0.062537854 | S17: -0.33605658 | T17: -0.35917156 | U17: -0.8225697 | V17: -1.5803357
B18: Noncontrolling shareholders | C18: -0.17875649 | D18: -0.48652279 | E18: 0.63278314 | F18: -5.1656754 | G18: -5.1981716 | H18: 0 | I18: 0 | J18: 0 | K18: 0 | L18: 0 | M18: 0 | N18: 0 | O18: 0 | P18: 0 | Q18: 0 | R18: -0.17875649 | S18: -0.48652279 | T18: 0.63278314 | U18: -5.1656754 | V18: -5.1981716
B19: Net Income** | C19: 124.63394 | D19: 240.21443 | E19: 183.6633 | F19: 294.04743 | G19: 842.58411 | H19: 137.00079 | I19: 241.0177 | J19: 183.35651 | K19: 290.72664 | L19: 852.10164 | M19: -4.0639315 | N19: 1.9437844 | O19: 6.1462804 | P19: -0.19163931 | Q19: 3.834494 | R19: -5.1667152 | S19: 0.83509922 | T19: -1.5257822 | U19: 8.169471 | V19: 2.3120727
B20: EBITDA* | C20: 262.06915 | D20: 409.8839 | E20: 398.31688 | F20: 538.66685 | G20: 1608.9618 | H20: 269.5405 | I20: 395.60355 | J20: 385.9065 | K20: 506.03283 | L20: 1557.0834 | M20: -0.059402655 | N20: 15.533353 | O20: 17.2029 | P20: 20.388062 | Q20: 53.064913 | R20: -4.4033439 | S20: 2.1893324 | T20: -0.65219016 | U20: 16.617837 | V20: 13.751635
B23: Gross Margin | C23: 0.70106569 | D23: 0.70648986 | E23: 0.70737831 | F23: 0.6844431 | G23: 0.69885489 | H23: 0.70112804 | I23: 0.70254051 | J23: 0.70404485 | K23: 0.67487834 | L23: 0.69417942 | M23: 0.6920816 | N23: 0.71105806 | O23: 0.70272988 | P23: 0.70724917 | Q23: 0.70422381 | R23: 0.84229656 | S23: 0.87011953 | T23: 0.86218162 | U23: 0.84949286 | V23: 0.85676827
B24: Selling, Marketing and Logistics Expenses/Net Revenue | C24: 0.37258226 | D24: 0.35959057 | E24: 0.34874848 | F24: 0.32805396 | G24: 0.34723187 | H24: 0.35601958 | I24: 0.34476183 | J24: 0.32993713 | K24: 0.30513064 | L24: 0.32895939 | M24: 0.4867928 | N24: 0.4697724 | O24: 0.47404143 | P24: 0.49289288 | Q24: 0.48112004 | R24: 0.11499483 | S24: 0.13118098 | T24: 0.12896629 | U24: 0.11487794 | V24: 0.12220775
B25: Administrative, R&D, IT and Projects Expenses/Net Revenue | C25: 0.16559102 | D25: 0.14572648 | E25: 0.16260066 | F25: 0.13148615 | G25: 0.13955211 | H25: 0.14720415 | I25: 0.12755334 | J25: 0.14220991 | K25: 0.11241046 | L25: 0.11949605 | M25: 0.21116975 | N25: 0.16896519 | O25: 0.1732372 | P25: 0.1603346 | Q25: 0.17495513 | R25: 1.1580185 | S25: 0.71537343 | T25: 0.78763779 | U25: 0.53452981 | V25: 0.6903894
B26: Net Margin | C26: 0.092235121 | D26: 0.13999828 | E26: 0.10331383 | F26: 0.13578207 | G26: 0.12019217 | H26: 0.11764599 | I26: 0.16613989 | J26: 0.12495839 | K26: 0.16172366 | L26: 0.14490971 | M26: -0.023403065 | N26: 0.0083339616 | O26: 0.022839036 | P26: -0.00063258193 | Q26: 0.0039169583 | R26: -0.49143547 | S26: 0.029249567 | T26: -0.039504266 | U26: 0.13566153 | V26: 0.016765439
B27: EBITDA Margin | C27: 0.19394379 | D27: 0.23888256 | E27: 0.22406023 | F27: 0.24873979 | G27: 0.22951371 | H27: 0.23146114 | I27: 0.27270002 | J27: 0.26299724 | K27: 0.28149289 | L27: 0.26479999 | M27: -0.00034208357 | N27: 0.066599139 | O27: 0.063924461 | P27: 0.067298925 | Q27: 0.054206123 | R27: -0.41882691 | S27: 0.076681934 | T27: -0.016885957 | U27: 0.27595437 | V27: 0.099716673
B29: (*) EBITDA = Income from operations before financial effects + depreciation & amortization.

Sheet 2014
B2: 2014 | H2: Pro-Forma
B3: (R$ million) | C3: Consolidated | H3: Brazil | M3: Latam | R3: Aesop
C4: 1Q16 | D4: 2Q16 | E4: 3Q16 | F4: 4Q16 | G4: 2016 | H4: 1Q16 | I4: 2Q16 | J4: 3Q16 | K4: 4Q16 | L4: 2016 | M4: 1Q16 | N4: 2Q16 | O4: 3Q16 | P4: 4Q16 | Q4: 2016 | R4: 1Q16 | S4: 2Q16 | T4: 3Q16 | U4: 4Q16 | V4: 2016
B5: Total Consultants - end of period ('000)2 | C5: 1650.518 | D5: 1698.971 | E5: 1728.761 | F5: 1742.8 | G5: =F5 -> 1742.8 | H5: 1276.356 | I5: 1300.685 | J5: 1314.237 | K5: 1318.531 | L5: =K5 -> 1318.531 | M5: 374.162 | N5: 396.7 | O5: 413 | P5: 422.5 | Q5: =P5 -> 422.5 | R5: 0 | S5: 0 | T5: 0 | U5: 0 | V5: =U5 -> 0
B6: Total Consultants - average of period ('000) | C6: 1636.6418 | D6: 1691.9816 | E6: 1712.273 | F6: 1745.5 | G6: 1699.3 | H6: 1261.0715 | I6: 1303.1762 | J6: 1303.3878 | K6: 1323.8388 | L6: 1299.6 | M6: 375.57025 | N6: 387.2 | O6: 407.4 | P6: 421.6 | Q6: 399.7 | R6: 0 | S6: 0 | T6: 0 | U6: 0 | V6: =AVERAGE(R6:U6) -> 0
B7: Units sold – items for resale (in million) | C7: 129.12184 | D7: 131.56056 | E7: 130.6423 | F7: 143.4 | G7: =SUM(C7:F7) -> 534.7247 | H7: 110.17118 | I7: 111.54147 | J7: 107.58417 | K7: 117.57353 | L7: =SUM(H7:K7) -> 446.87035 | M7: 18.17 | N7: 19 | O7: 22.06 | P7: 24.3 | Q7: =SUM(M7:P7) -> 83.53 | R7: 0.62674495 | S7: 0.80099796 | T7: 0.75173918 | U7: 1.2 | V7: =SUM(R7:U7) -> 3.3794821
B8: Gross Revenue | C8: 2085.3 | D8: 2421.55 | E8: 2512.47 | F8: 2931.0015 | G8: =SUM(C8:F8) -> 9950.3215 | H8: 1734.7385 | I8: 2017.3875 | J8: 2059.6295 | K8: 2373.8574 | L8: =SUM(H8:K8) -> 8185.6129 | M8: 296.79435 | N8: 343.86012 | O8: 387.10748 | P8: 456.37059 | Q8: =SUM(M8:P8) -> 1484.1325 | R8: 50.63114 | S8: 56.12109 | T8: 62.581744 | U8: 95.835562 | V8: =SUM(R8:U8) -> 265.16954
B9: Net Revenue | C9: 1556.19 | D9: 1802.64 | E9: 1867.4 | F9: 2182.2 | G9: =SUM(C9:F9) -> 7408.43 | H9: 1270.496 | I9: 1476.8052 | J9: 1506.8768 | K9: 1735.0197 | L9: =SUM(H9:K9) -> 5989.1977 | M9: 236.86053 | N9: 271.04631 | O9: 300.59187 | P9: 355.5 | Q9: =SUM(M9:P9) -> 1163.9987 | R9: 46.28075 | S9: 51.298986 | T9: 57.220766 | U9: 87.6 | V9: =SUM(R9:U9) -> 242.4005
B10: Gross Profit | C10: 1082.4 | D10: 1230.5 | E10: 1316.6 | F10: 1504.5 | G10: =SUM(C10:F10) -> 5134 | H10: 873.7 | I10: 992.1 | J10: 1062.4 | K10: 1185.6 | L10: =SUM(H10:K10) -> 4113.8 | M10: 165.11703 | N10: 190.95031 | O10: 202.4 | P10: 240.9 | Q10: =SUM(M10:P10) -> 799.36734 | R10: 41.766173 | S10: 44.760879 | T10: 49.858352 | U10: 75.051006 | V10: =SUM(R10:U10) -> 211.43641
B11: Selling, Marketing and Logistics Expenses | C11: -602.73527 | D11: -660.66729 | E11: -664.64799 | F11: -752.49336 | G11: =SUM(C11:F11) -> -2680.5439 | H11: -471.20817 | I11: -517.35994 | J11: -508.64119 | K11: -579.75959 | L11: =SUM(H11:K11) -> -2076.9689 | M11: -120.71837 | N11: -134.77989 | O11: -145.86781 | P11: -160.7 | Q11: =SUM(M11:P11) -> -562.06607 | R11: -7.2241904 | S11: -4.5633139 | T11: -6.2205077 | U11: -8.4 | V11: =SUM(R11:U11) -> -26.408012
B12: Administrative, R&D, IT and Projects Expenses | C12: -263.77685 | D12: -257.97478 | E12: -278.06645 | F12: -308.78423 | G12: =SUM(C12:F12) -> -1108.6023 | H12: -189.15368 | I12: -176.95675 | J12: -190.37872 | K12: -208.21675 | L12: =SUM(H12:K12) -> -764.7059 | M12: -40.434628 | N12: -42.338498 | O12: -43.656053 | P12: -55.8 | Q12: =SUM(M12:P12) -> -182.22918 | R12: -31.745609 | S12: -35.991579 | T12: -41.505644 | U12: -41.8 | V12: =SUM(R12:U12) -> -151.04283
B13: Other Operating Income / (Expenses), net | C13: 11.258362 | D13: 4.1977652 | E13: 1.509271 | F13: 2.8206388 | G13: =SUM(C13:F13) -> 19.786037 | H13: 5.5853201 | I13: 4.3584763 | J13: 1.3565188 | K13: 3.1057729 | L13: =SUM(H13:K13) -> 14.406088 | M13: -0.55882832 | N13: -0.21365088 | O13: 0.33860043 | P13: -0.33815707 | Q13: =SUM(M13:P13) -> -0.77203585 | R13: 6.2318701 | S13: 0.052939786 | T13: -0.18584826 | U13: 0.1 | V13: =SUM(R13:U13) -> 6.1989616
B14: Financial Income / (Expenses), net | C14: -51.892256 | D14: -61.170013 | E14: -63.657058 | F14: -91.559809 | G14: =SUM(C14:F14) -> -268.27914 | H14: -51.914331 | I14: -58.973704 | J14: -61.947636 | K14: -94.221378 | L14: =SUM(H14:K14) -> -267.05705 | M14: 0.11957006 | N14: -0.39196334 | O14: -0.21102199 | P14: -0.8 | Q14: =SUM(M14:P14) -> -1.2834153 | R14: -0.097494573 | S14: -1.8043453 | T14: -1.4983996 | U14: 3.5 | V14: =SUM(R14:U14) -> 0.099760461
B15: Income Tax and Social Contribution | C15: -57.125354 | D15: -78.369559 | E15: -98.210926 | F15: -121.46628 | G15: =SUM(C15:F15) -> -355.17212 | H15: -52.205817 | I15: -70.717839 | J15: -81.525933 | K15: -101.79073 | L15: =SUM(H15:K15) -> -306.24032 | M15: -4.6579893 | N15: -5.0994366 | O15: -12.971037 | P15: -13.4 | Q15: =SUM(M15:P15) -> -36.128463 | R15: -0.26154851 | S15: -2.5522838 | T15: -3.7139555 | U15: -6.3 | V15: =SUM(R15:U15) -> -12.827788
B16: Noncontrolling shareholders | C16: -0.94616339 | D16: -0.69445523 | E16: 1.0596154 | F16: -7.8212299 | G16: =SUM(C16:F16) -> -8.4022331 | H16: 0 | I16: 0 | J16: 0 | K16: 0 | L16: =SUM(H16:K16) -> 0 | M16: 0 | N16: 0 | O16: 0 | P16: 0 | Q16: =SUM(M16:P16) -> 0 | R16: -0.94616339 | S16: -0.69445523 | T16: 1.0596154 | U16: -7.8 | V16: =SUM(R16:U16) -> -8.3810032
B17: Net Income** | C17: 117.2 | D17: 175.84876 | E17: 214.63335 | F17: 225.18015 | G17: =SUM(C17:F17) -> 732.86226 | H17: 114.8 | I17: 172.5 | J17: 221.2 | K17: 204.8 | L17: =SUM(H17:K17) -> 713.3 | M17: -1.1332195 | N17: 8.1268727 | O17: 0.059586019 | P17: 9.7960988 | Q17: =SUM(M17:P17) -> 16.849338 | R17: 7.7230378 | S17: -0.79215891 | T17: -2.2063876 | U17: 14.4 | V17: =SUM(R17:U17) -> 19.124491
B18: EBITDA* | C18: 283.61593 | D18: 352.33377 | E18: 427.09048 | F18: 491.42663 | G18: =SUM(C18:F18) -> 1554.4668 | H18: 269.9 | I18: 331.94 | J18: 409.14 | K18: 440.74 | L18: =SUM(H18:K18) -> 1451.72 | M18: 5.8439602 | N18: 16.388381 | O18: 15.814939 | P18: 26.631277 | Q18: =SUM(M18:P18) -> 64.678557 | R18: 11.766065 | S18: 7.6566219 | T18: 6.2309026 | U18: 27.4 | V18: =SUM(R18:U18) -> 53.053589
B21: Gross Margin | C21: 0.696 | D21: 0.683 | E21: 0.70850731 | F21: 0.689 | G21: 0.693 | H21: 0.688 | I21: 0.672 | J21: 0.705 | K21: 0.683 | L21: 0.687 | M21: 0.69710657 | N21: 0.70449332 | O21: 0.673 | P21: 0.678 | Q21: 0.687 | R21: 0.90245239 | S21: 0.87254901 | T21: 0.87133318 | U21: 0.857 | V21: 0.872
B22: Selling, Marketing and Logistics Expenses/Net Revenue | C22: 0.38725625 | D22: 0.367 | E22: 0.35601579 | F22: 0.345 | G22: 0.362 | H22: 0.37081311 | I22: 0.35 | J22: 0.33769927 | K22: 0.334 | L22: 0.347 | M22: 0.50966016 | N22: 0.4972578 | O22: 0.485 | P22: 0.452 | Q22: 0.483 | R22: 0.15609493 | S22: 0.088955246 | T22: 0.10871067 | U22: 0.095 | V22: 0.109
B23: Administrative, R&D, IT and Projects Expenses/Net Revenue | C23: 0.17 | D23: 0.143 | E23: 0.149 | F23: 0.141 | G23: 0.15 | H23: 0.149 | I23: 0.12 | J23: 0.126 | K23: 0.12 | L23: 0.128 | M23: 0.17071071 | N23: 0.15620393 | O23: 0.145 | P23: 0.157 | Q23: 0.15722866 | R23: 0.68593549 | S23: 0.70160411 | T23: 0.72535981 | U23: 0.477 | V23: 0.623
B24: Net Margin | C24: 0.075274046 | D24: 0.097550725 | E24: 0.11494493 | F24: 0.10318775 | G24: 0.099 | H24: 0.09 | I24: 0.117 | J24: 0.147 | K24: 0.118 | L24: 0.119 | M24: -0.0047843325 | N24: 0.029983337 | O24: 0 | P24: 0.028 | Q24: 0.014 | R24: 0.16687365 | S24: -0.015441999 | T24: -0.038559211 | U24: 0.164 | V24: 0.079
B25: EBITDA Margin | C25: 0.18225038 | D25: 0.1954544 | E25: 0.22872441 | F25: 0.22519395 | G25: 0.21 | H25: 0.212 | I25: 0.225 | J25: 0.272 | K25: 0.254 | L25: 0.242 | M25: 0.02467258 | N25: 0.0604634 | O25: 0.053 | P25: 0.075 | Q25: 0.056 | R25: 0.25423237 | S25: 0.14925484 | T25: 0.10889233 | U25: 0.313 | V25: 0.219
B27: (*) EBITDA = Income from operations before financial effects + depreciation & amortization.

Sheet VP
B1: FATOR | C1: HOJE | D1: PROJ | E1: DIAS | L1: Preço Gmat3 | M1: {=+_FV(H11,"Price")} -> 10.52 | O1: CAGR
B2: =(1+WACC!E8)^(E2/360) -> 1.1115876 | C2: =+TODAY() -> 46118 | D2: 46387 | E2: =+DAYS360(C2,D2) -> 265 | L2: Mkt Cap | M2: {=+_FV(H11,"Market cap",TRUE)/1000000} -> 14460.35
C3: FCF | L3: LL 26 | M3: =+Resumo!Q38 -> 1022.7266
B4: Soma dos FCF | C4: =+SUM(WACC!F16:I16) -> 3455.7632 | D4: GR% | L4: P/E 2026 hj | M4: =+M2/M3 -> 14.139018
B5: (+) Perpetuidade | C5: =+C31 -> 3039.735 | D5: =+I15 -> 0.0675 | L5: Upside | M5: =+M7/M4-1 -> -0.47938661
B6: EV | C6: =+C4+C5 -> 6495.4982
B7: (-) Total Debt | C7: =+PROJ!BO157 -> 6357.221 | L7: P/E tgt | M7: =+M9*M27+P9*P27 -> 7.3609622
B8: (+) Caixa | C8: =+PROJ!BO155 -> 2654.1155
B9: (+) VP Outros Ativos Fin Líquidos | C9: =+PROJ!BO156 -> 1180.547 | L9: Lula | M9: 0.5 | O9: Not Lula | P9: =1-M9 -> 0.5
B10: (+) Investimentos | C10: 0
B11: (+) Outros Ativos Não Oper. | C11: 0 | H11: #VALUE! | I11: 2025
B12: (-) Opções | C12: 0 | H12: ROE1 | I12: 0.12 | L12: ROE1 | M12: =+I12 -> 0.12 | O12: ROE1 | P12: =+M12 -> 0.12
B13: (+) Ajuste Dividendos | C13: =+PROJ!BO233 -> 0 | H13: ROE2 | I13: 0.15 | L13: ROE2 | M13: =+I13 -> 0.15 | O13: ROE2 | P13: =+M13 -> 0.15
B14: (-) Minoritários | C14: 0 | H14: G1 | I14: =+Resumo!V38 -> 0.11561801 | L14: G1 | M14: =+I14 -> 0.11561801 | O14: G1 | P14: =+M14 -> 0.11561801
B15: Valor de Mercado Proj | C15: =+C6-C7+C8+C9+C10+C11-C12+C13-C14 -> 3972.9397 | H15: G2 | I15: =+I19+I20+I21 -> 0.0675 | L15: G2 | M15: =+M19+M20+M21 -> 0.07 | O15: G2 | P15: =+P19+P20+P21 -> 0.075
B16: Num Ações | C16: {=+_FV(H11,"Shares outstanding",TRUE)/1000000} -> 1374.558 | H16: Ke | I16: =+(I22+I19)+(I24*I23) -> 0.1525 | L16: Ke | M16: =+(M22+M19)+(M24*M23) -> 0.16 | O16: Ke | P16: =+(P22+P19)+(P24*P23) -> 0.13
B17: Cot R$ DEZ/2026 PROJ | C17: =+C15/C16 -> 2.8903398 | H17: N (moat) | I17: 5 | L17: N (moat) | M17: =+I17 -> 5 | O17: N (moat) | P17: =+M17 -> 5
B18: Cot R$ HOJE PROJ | C18: =+C17/B2 -> 2.6001907
B19: Cot R$ 12m | C19: =+C18*(1+WACC!F8) -> 3.0097207 | H19: INFL | I19: =+MACRO!$BP$8 -> 0.0425 | L19: INFL | M19: 0.045 | O19: INFL | P19: 0.04
H20: GDP Perp | I20: 0.025 | L20: GDP Perp | M20: 0.025 | O20: GDP Perp | P20: 0.035
B21: Cot R$ HJ | C21: {=+_FV(H11,"Price")} -> 10.52 | H21: Aj. G2 | I21: 0 | L21: Aj. G2 | M21: 0 | O21: Aj. G2 | P21: =+M21 -> 0
B22: var% | C22: =+C17/C21-1 -> -0.72525287 | H22: BNTNB | I22: 0.065 | L22: BNTNB | M22: =+[1]BRASIL!$P$3 -> 0.07 | O22: BNTNB | P22: =+[1]BRASIL!$R$3 -> 0.045
H23: ERP | I23: 0.045 | L23: ERP | M23: 0.045 | O23: ERP | P23: =+M23 -> 0.045
B24: Valor de Mercado hj | C24: =+C21*C16 -> 14460.35 | H24: Beta | I24: 1 | L24: Beta | M24: =+I24 -> 1 | O24: Beta | P24: =+M24 -> 1
H26: P/E Target | I26: =+(((1-I14/I12)*(1+I14)*(1-(((1+I14)^I17)/((1+I16)^I17))))/(I16-I14))+(((1-I15/I13)*((1+I14)^I17)*(1+I15))/((I16-I15)*((1+I16)^I17))) -> 6.0364122
B27: Noplat 2030 | C27: =+PROJ!BS62 -> 1355.8745 | H27: UPSIDE 2026 | L27: P/E Target 2026 | M27: =+(((1-M14/M12)*(1+M14)*(1-(((1+M14)^M17)/((1+M16)^M17))))/(M16-M14))+(((1-M15/M13)*((1+M14)^M17)*(1+M15))/((M16-M15)*((1+M16)^M17))) -> 5.3797464 | O27: P/E Target 2026 | P27: =+(((1-P14/P12)*(1+P14)*(1-(((1+P14)^P17)/((1+P16)^P17))))/(P16-P14))+(((1-P15/P13)*((1+P14)^P17)*(1+P15))/((P16-P15)*((1+P16)^P17))) -> 9.3421781
B28: ROIC | C28: 0.1
B29: G | C29: =D5 -> 0.0675
B30: Wacc | C30: =WACC!I3 -> 0.155 | H30: =22*8 -> 176
B31: Perp | C31: =(C27*(1+C29)*(1-C29/C28)/(C30-C29))/WACC!I15 -> 3039.735 | H31: =8/H30 -> 0.045454545

Sheet WACC
B1: DRE | D1: 2025 | E1: =+D1+1 -> 2026 | F1: =+E1+1 -> 2027 | G1: =+F1+1 -> 2028 | H1: =+G1+1 -> 2029 | I1: =+H1+1 -> 2030
B3: WACC % | E3: =+E4*E5+(1-E4)*(E8) -> 0.14615487 | F3: =+F4*F5+(1-F4)*(F8) -> 0.1504099 | G3: =+G4*G5+(1-G4)*(G8) -> 0.15241889 | H3: =+H4*H5+(1-H4)*(H8) -> 0.155 | I3: =+H3 -> 0.155
B4: Alavancagem | E4: =+IF(Resumo!Q70/Resumo!Q71>0,Resumo!Q70/Resumo!Q71,0) -> 0.14853513 | F4: =+IF(Resumo!R70/Resumo!R71>0,Resumo!R70/Resumo!R71,0) -> 0.095799238 | G4: =+IF(Resumo!S70/Resumo!S71>0,Resumo!S70/Resumo!S71,0) -> 0.034350734 | H4: =+IF(Resumo!T70/Resumo!T71>0,Resumo!T70/Resumo!T71,0) -> 0 | I4: =+IF(Resumo!U70/Resumo!U71>0,Resumo!U70/Resumo!U71,0) -> 0
B5: Rdebt % | E5: =+(E6)*(1-E7) -> 0.09801 | F5: =+(F6)*(1-F7) -> 0.08349 | G5: =+(G6)*(1-G7) -> 0.07986 | H5: =+(H6)*(1-H7) -> 0.0726 | I5: =+(I6)*(1-I7) -> 0.06534
B6: Debt Bruto % | E6: =110%*MACRO!BO6 -> 0.1485 | F6: =110%*MACRO!BP6 -> 0.1265 | G6: =110%*MACRO!BQ6 -> 0.121 | H6: =110%*MACRO!BR6 -> 0.11 | I6: =110%*MACRO!BS6 -> 0.099
B7: IR % | E7: 0.34 | F7: 0.34 | G7: 0.34 | H7: 0.34 | I7: 0.34
B8: Requity % | E8: =+E9+E10*E12+E11 -> 0.15455358 | F8: =+F9+F10*F12+F11 -> 0.1575 | G8: =+G9+G10*G12+G11 -> 0.155 | H8: =+H9+H10*H12+H11 -> 0.155 | I8: =+I9+I10*I12+I11 -> 0.155
B9: Juros Real | E9: 0.07 | F9: =+E9 -> 0.07 | G9: =+F9 -> 0.07 | H9: =+G9 -> 0.07 | I9: =+H9 -> 0.07
B10: Equity risk premium | E10: 0.045 | F10: 0.045 | G10: 0.045 | H10: 0.045 | I10: 0.045
B11: IPCA | E11: =+MACRO!BO8 -> 0.039553578 | F11: =+MACRO!BP8 -> 0.0425 | G11: =+MACRO!BQ8 -> 0.04 | H11: =+MACRO!BR8 -> 0.04 | I11: =+MACRO!BS8 -> 0.04
B12: Beta | E12: 1 | F12: =+E12 -> 1 | G12: =+F12 -> 1 | H12: =+G12 -> 1 | I12: =+H12 -> 1
B14: FCFF | C14: =-VP!C24 -> -14460.35 | E14: =+PROJ!BO68 -> 1106.8179 | F14: =+PROJ!BP68 -> 1263.7787 | G14: =+PROJ!BQ68 -> 1172.0042 | H14: =+PROJ!BR68 -> 1190.0232 | I14: =+PROJ!BS68 -> 1230.9881 | J14: =+I14*(1+VP!D5)/(WACC!I3-VP!D5) -> 15018.055
B15: FD | E15: 1 | F15: =+E15*(1+F3) -> 1.1504099 | G15: =+F15*(1+G3) -> 1.3257541 | H15: =+G15*(1+H3) -> 1.531246 | I15: =+H15*(1+I3) -> 1.7685891
B16: VP | E16: =+E14/E15 -> 1106.8179 | F16: =+F14/F15 -> 1098.5464 | G16: =+G14/G15 -> 884.02834 | H16: =+H14/H15 -> 777.16007 | I16: =+I14/I15 -> 696.02834 | J16: =+I16*(1+VP!D5)/(WACC!I3-VP!D5) -> 8491.5457
C17: IRR | D17: =+IRR(C14:J14,0) -> 0.076282772
B19: Yield | D19: =+D14/VP!$C$24 -> 0 | E19: =+E14/VP!$C$24 -> 0.076541569 | F19: =+F14/VP!$C$24 -> 0.087396132 | G19: =+G14/VP!$C$24 -> 0.081049503 | H19: =+H14/VP!$C$24 -> 0.082295602 | I19: =+I14/VP!$C$24 -> 0.085128515

Sheet Resumo
B1: NATURA | N1: Preço: | O1: =+VP!C21 -> 10.52 | X1: BBG
B2: DRE - MILLONES BRL | C2: 2015 | G2: =+C2+1 -> 2016 | H2: =+G2+1 -> 2017 | I2: =+H2+1 -> 2018 | J2: =+I2+1 -> 2019 | K2: =+J2+1 -> 2020 | L2: =+K2+1 -> 2021 | M2: =+L2+1 -> 2022 | N2: =+M2+1 -> 2023 | O2: =+N2+1 -> 2024 | ... U2: =+T2+1 -> 2030 | X2: 2026 | Y2: 2027
B3: Receita Bruta | C3: =+PROJ!BD5 -> 7899 | G3: =+PROJ!BE5 -> 7912.6711 | H3: =+PROJ!BF5 -> 9852.7476 | I3: =+FAT!BH8 -> 18514.468 | J3: =+FAT!BJ8 -> 19708.1 | K3: =+FAT!BK8 -> 47697 | L3: =+FAT!BL8 -> 51644.2 | M3: =+FAT!BM8 -> 47108.6 | N3: =+FAT!BN8 -> 38175.466 | O3: =+FAT!BO8 -> 31586.823 | P3: =+FAT!BP8 -> 29494.8 | Q3: =+FAT!BQ8 -> 30341.943 | ... U3: =+FAT!BU8 -> 35383.328 | AD3: BRL | AE3: 5.5
B4: y-o-y | G4: =+G3/C3-1 -> 0.0017307428 | H4: =+H3/G3-1 -> 0.24518604 | I4: =+I3/H3-1 -> 0.87911727 | J4: =+J3/I3-1 -> 0.064470219 | K4: =+K3/J3-1 -> 1.4201724 | L4: =+L3/K3-1 -> 0.082755729 | M4: =+M3/L3-1 -> -0.087823996 | N4: =+N3/M3-1 -> -0.18962852 | O4: =+O3/N3-1 -> -0.17258842 | ... U4: =+U3/T3-1 -> 0.035344534 | AD4: Interest | AE4: 0.06
B6: Natura & co Latam | J6: =+FAT!BJ36 -> 25344 | K6: =+FAT!BK36 -> 27584.5 | L6: =+FAT!BL36 -> 29693.4 | M6: =+FAT!BM36 -> 29158 | N6: =+FAT!BN36 -> 27220.844 | O6: =+FAT!BO36 -> 31586.823 | P6: =+FAT!BP36 -> 29494.8 | Q6: =+FAT!BQ36 -> 30341.943 | ... U6: =+FAT!BU36 -> 35383.328 | V6: =+O69-700 -> 13760.35
B7: yoy | K7: =+K6/J6-1 -> 0.088403567 | L7: =+L6/K6-1 -> 0.076452355 | M7: =+M6/L6-1 -> -0.018030943 | N7: =+N6/M6-1 -> -0.066436516 | O7: =+O6/N6-1 -> 0.16039102 | P7: =+P6/O6-1 -> -0.066230874 | Q7: =+Q6/P6-1 -> 0.028721766 | R7: =+R6/Q6-1 -> 0.044724877 | ... U7: =+U6/T6-1 -> 0.035344534 | V7: =+V6/O6 -> 0.43563578
B8: %RB | J8: =+J6/J$3 -> 1.2859687 | K8: =+K6/K$3 -> 0.57832778 | L8: =+L6/L$3 -> 0.57496098 | M8: =+M6/M$3 -> 0.6189528 | N8: =+N6/N$3 -> 0.71304549 | O8: =+O6/O$3 -> 1 | P8: =+P6/P$3 -> 1 | Q8: =+Q6/Q$3 -> 1 | ... U8: =+U6/U$3 -> 1
B9: Avon Int | J9: =+FAT!BJ40 -> 10926.2 | K9: =+FAT!BK40 -> 10891.5 | L9: =+FAT!BL40 -> 11189 | M9: =+FAT!BM40 -> 8728.6 | N9: =+FAT!BN40 -> 7488.008 | O9: =+FAT!BO40 -> 0 | V9: =(300*20*5.5)/2 -> 16500 | AE9: 2024
B10: yoy | K10: =+K9/J9-1 -> -0.0031758525 | L10: =+L9/K9-1 -> 0.027314879 | M10: =+M9/L9-1 -> -0.21989454 | N10: =+N9/M9-1 -> -0.14212955 | O10: =+O9/N9-1 -> -1 | AD10: Net Rev 2024 | AE10: 49000 | AF10: =+AE10*0.47*0.1 -> 2303 | AG10: =+AF10+AE10 -> 51303
B11: %RB | K11: =+K9/K$3 -> 0.22834769 | L11: =+L9/L$3 -> 0.2166555 | M11: =+M9/M$3 -> 0.18528676 | N11: =+N9/N$3 -> 0.19614713 | O11: =+O9/O$3 -> 0 | Q11: =+Q12-Q14 -> 1584.0686
P12: 23195 | Q12: 23271 | R12: 24342 | AB12: =+O9*0.1 -> 0
Q13: =+Q12/P14-1 -> 0.047420115 | R13: =+R12/Q12-1 -> 0.046022947
B14: Receita Líquida | C14: =+PROJ!BD5 -> 7899 | G14: =+PROJ!BE5 -> 7912.6711 | H14: =+PROJ!BF5 -> 9852.7476 | I14: =+PROJ!BG5 -> 13365.13 | J14: =+PROJ!BH5 -> 19447.159 | K14: =+PROJ!BI5 -> 36921.9 | L14: =+PROJ!BJ5 -> 40164.6 | M14: =+PROJ!BK5 -> 36349.2 | N14: =+PROJ!BL5 -> 29224.396 | ... U14: =+PROJ!BS5 -> 25310.623 | X14: 23271 | Y14: 24342 | AB14: =+O6*1 -> 31586.823 | AD14: EBITDA mrgn | AE14: 0.14 | AF14: 0.16
B15: y-o-y | J15: =+J14/I14-1 -> 0.4550669 | K15: =+K14/J14-1 -> 0.89857552 | L15: =+L14/K14-1 -> 0.087825924 | M15: =+M14/L14-1 -> -0.094994099 | N15: =+N14/M14-1 -> -0.19600993 | O15: =+O14/N14-1 -> -0.19817405 | P15: =+P14/O14-1 -> -0.051868691 | Q15: =+Q14/P14-1 -> -0.023878295 | ... U15: =+U14/T14-1 -> 0.03565074 | AB15: =+AB14+AB12 -> 31586.823 | AD15: EBITDA | AE15: =+AE14*AE10 -> 6860 | AF15: =+AF14*AE10 -> 7840 | AG15: =+AG10*AE14 -> 7182.42
B17: CPV | C17: =+PROJ!BD7 -> -2416.024 | G17: =+PROJ!BE7 -> -2446.9186 | H17: =+PROJ!BF7 -> -2911.0774 | I17: =+PROJ!BG7 -> -3761.8972 | J17: =+PROJ!BH7 -> -6191.727 | K17: =+PROJ!BI7 -> -13229.4 | L17: =+PROJ!BJ7 -> -14011.4 | M17: =+PROJ!BK7 -> -13155.3 | N17: =+PROJ!BL7 -> -10238.485 | ... U17: =+PROJ!BS7 -> -8536.7894
B18: Lucro Bruto | C18: =+PROJ!BD8 -> 5482.976 | G18: =+PROJ!BE8 -> 5465.7526 | H18: =+PROJ!BF8 -> 6941.6308 | I18: =+PROJ!BG8 -> 9603.2333 | J18: =+PROJ!BH8 -> 13255.432 | K18: =+PROJ!BI8 -> 23692.5 | L18: =+PROJ!BJ8 -> 26153.2 | M18: =+PROJ!BK8 -> 23193.9 | N18: =+PROJ!BL8 -> 18985.911 | ... U18: =+PROJ!BS8 -> 16773.834 | X18: =+X19*X14 -> 15505.467 | Y18: =+Y19*Y14 -> 16219.075 | AD18: EBITDA ex Brasil | AE18: =+AE15*0.47 -> 3224.2 | AF18: =+AF15*0.47 -> 3684.8
B19: mg Bruta | C19: =+C18/C3 -> 0.69413546 | G19: =+G18/G3 -> 0.69075948 | H19: =+H18/H3 -> 0.70453756 | I19: =+I18/I14 -> 0.71852896 | J19: =+J18/J14 -> 0.68161277 | K19: =+K18/K14 -> 0.64169233 | L19: =+L18/L14 -> 0.65115052 | M19: =+M18/M14 -> 0.63808557 | N19: =+N18/N14 -> 0.64965965 | O19: =+O18/O14 -> 0.65396864 | P19: =+P18/P14 -> 0.66314943 | ... U19: =+U18/U14 -> 0.66271911 | X19: 0.6663 | Y19: 0.6663
AD20: Upside x FX | AE20: =+AE18*0.1 -> 322.42 | AF20: =+AF18*0.1 -> 368.48
B21: SG&A | C21: =+PROJ!BD11 -> -4226.5 | G21: =+PROJ!BE11 -> -4382.8754 | H21: =+PROJ!BF11 -> -5582.9717 | I21: =+PROJ!BG11 -> -8339.3549 | J21: =+PROJ!BH11 -> -9059.9 | K21: =+PROJ!BI11 -> -22902.7 | L21: =+PROJ!BJ11 -> -25034.9 | M21: =+PROJ!BK11 -> -23652.3 | N21: =+PROJ!BL11 -> -19559.341 | ... U21: =+PROJ!BS11 -> -14610.249 | X21: =+X27-X18 -> -13325.467 | Y21: =+Y27-Y18 -> -13732.075 | AD21: EBITDA Final | AE21: =+AE15+AE20 -> 7182.42 | AF21: =+AF15+AF20 -> 8208.48
B22: % Net Rev | C22: =+C21/C3 -> -0.53506773 | G22: =+G21/G3 -> -0.55390592 | H22: =+H21/H3 -> -0.5666411 | I22: =+I21/I14 -> -0.6239636 | J22: =+J21/J14 -> -0.46587268 | K22: =+K21/K14 -> -0.62030123 | L22: =+L21/L14 -> -0.62330759 | M22: =+M21/M14 -> -0.65069658 | N22: =+N21/N14 -> -0.66928128 | O22: =+O21/O14 -> -0.61549484 | P22: =+P21/P14 -> -0.60434039 | ... U22: =+U21/U14 -> -0.57723783
B23: Vendas | K23: =+FAT!BK70 -> -16426.3 | L23: =+FAT!BL70 -> -17833.8 | M23: =+FAT!BM70 -> -16160.6 | N23: =+FAT!BN70 -> -13235.732 | O23: =+FAT!BO70 -> -10213.499 | P23: =+FAT!BP70 -> -9409.8 | Q23: =+FAT!BQ70 -> -9433.8152 | R23: =+FAT!BR70 -> -9742.7696 | ... U23: =+FAT!BU70 -> -10883.568
B24: G&A | K24: =+FAT!BK74 -> -5582.5 | L24: =+FAT!BL74 -> -6399.5 | M24: =+FAT!BM74 -> -6160.9 | N24: =+FAT!BN74 -> -4528.033 | O24: =+FAT!BO74 -> -2974.0579 | P24: =+FAT!BP74 -> -3085.3 | Q24: =+FAT!BQ74 -> -3085.728 | R24: =+FAT!BR74 -> -3240.0144 | ... U24: =+FAT!BU74 -> -3540.4512
B25: Outras | K25: =+FAT!BK80+FAT!BK81+FAT!BK83+FAT!BK79 -> -893.9 | L25: =+FAT!BL80+FAT!BL81+FAT!BL83+FAT!BL79 -> -801.6 | M25: =+FAT!BM80+FAT!BM81+FAT!BM83+FAT!BM79 -> -1330.8 | N25: =+FAT!BN80+FAT!BN81+FAT!BN83+FAT!BN79 -> -1795.576 | O25: =+FAT!BO80+FAT!BO81+FAT!BO83+FAT!BO79 -> -1235.2587 | P25: =+FAT!BP80+FAT!BP81+FAT!BP83+FAT!BP79 -> -931.8 | Q25: =+FAT!BQ80+FAT!BQ81+FAT!BQ83+FAT!BQ79 -> -136.23 | R25: =+FAT!BR80+FAT!BR81+FAT!BR83+FAT!BR79 -> -136.23 | ... U25: =+FAT!BU80+FAT!BU81+FAT!BU83+FAT!BU79 -> -186.23
B27: EBIT | C27: =+PROJ!BD21 -> 1256.476 | G27: =+PROJ!BE21 -> 1082.8772 | H27: =+PROJ!BF21 -> 1358.6591 | I27: =+PROJ!BG21 -> 1263.8784 | J27: =+PROJ!BH21 -> 4195.532 | K27: =+PROJ!BI21 -> 789.8 | L27: =+PROJ!BJ21 -> 1118.3 | M27: =+PROJ!BK21 -> -458.4 | N27: =+PROJ!BL21 -> -573.43029 | ... U27: =+PROJ!BS21 -> 2163.5845 | X27: 2180 | Y27: 2487
B28: Resultado Financeiro | C28: =+PROJ!BD26 -> -381.5 | G28: =+PROJ!BE26 -> -655.9 | H28: =+PROJ!BF26 -> -387.4 | I28: =+PROJ!BG26 -> -583.3 | J28: =+PROJ!BH26 -> -840.0928 | K28: =+PROJ!BI26 -> -1035.4 | L28: =+PROJ!BJ26 -> #REF! | M28: =+PROJ!BK26 -> -1900.9 | N28: =+PROJ!BL26 -> -2573.204 | ... U28: =+PROJ!BS26 -> -343.41379 | X28: =+X29-X27 -> -850 | Y28: =+Y29-Y27 -> -945
B29: EBT | C29: =+PROJ!BD32 -> 874.97604 | G29: =+PROJ!BE32 -> 426.97721 | H29: =+PROJ!BF32 -> 971.25905 | I29: =+PROJ!BG32 -> 680.57842 | J29: =+PROJ!BH32 -> 3355.4392 | K29: =+PROJ!BI32 -> -245.6 | L29: =+PROJ!BJ32 -> #REF! | M29: =+PROJ!BK32 -> -2359.3 | N29: =+PROJ!BL32 -> -3146.6343 | ... U29: =+PROJ!BS32 -> 1820.1707 | X29: 1330 | Y29: 1542 | AA29: =+X29*-0.34 -> -452.2
B30: Res Não Operacional e Descontinuadas | G30: =+PROJ!BE40 -> 0 | H30: =+PROJ!BF40 -> 0 | I30: =+PROJ!BG40 -> 0 | J30: =+PROJ!BH40 -> 0 | K30: =+PROJ!BI40 -> -143.1 | L30: =+PROJ!BJ40 -> -98.6 | M30: =+PROJ!BK40 -> -380.4 | N30: =+PROJ!BL40 -> 5924.492 | ... U30: =+PROJ!BS40 -> 0
B31: IR & CS | C31: =+PROJ!BD34 -> #REF! | G31: =+PROJ!BE34 -> #REF! | H31: =+PROJ!BF34 -> #REF! | I31: =+PROJ!BG34 -> #REF! | J31: =+PROJ!BH34 -> #REF! | K31: =+PROJ!BI34 -> -274.8 | L31: =+PROJ!BJ34 -> 1048 | M31: =+PROJ!BK34 -> -119.6 | N31: =+PROJ!BL34 -> 200.252 | ... U31: =+PROJ!BS34 -> -235.92839
B32: taxa efectiva | K32: =+K31/#REF! -> #REF! | L32: =+L31/#REF! -> #REF! | M32: =+M31/#REF! -> #REF! | N32: =+N31/#REF! -> #REF! | O32: =+O31/#REF! -> #REF! | P32: =+P31/#REF! -> #REF! | Q32: =+Q31/#REF! -> #REF! | R32: =+R31/#REF! -> #REF! | ... U32: =+U31/#REF! -> #REF!
B34: Participações | C34: =+PROJ!BD35 -> #REF! | G34: =+PROJ!BE35 -> #REF! | H34: =+PROJ!BF35 -> #REF! | I34: =+PROJ!BG35 -> #REF! | J34: =+PROJ!BH35 -> #REF! | K34: =+PROJ!BI35 -> 1.1188925 | L34: =+PROJ!BJ35 -> #REF! | M34: =+PROJ!BK35 -> 0.050693002 | N34: =+PROJ!BL35 -> -0.063640062 | ... U34: =+PROJ!BS35 -> -0.12961882
B35: Minoritários | C35: =+PROJ!BD41 -> -9.2 | G35: =+PROJ!BE41 -> -11.539987 | H35: =+PROJ!BF41 -> 0 | I35: =+PROJ!BG41 -> 0 | J35: =+PROJ!BH41 -> 0 | K35: =+PROJ!BI41 -> -13.4 | L35: =+PROJ!BJ41 -> -7.3009 | M35: =+PROJ!BK41 -> 1 | N35: =+PROJ!BL41 -> 0.923 | ... U35: =+PROJ!BS41 -> 0
B36: Tax | O36: =+PROJ!BM34 -> -957.5 | P36: =+PROJ!BN34 -> 42.5 | Q36: =+PROJ!BO34 -> -8.8737041 | R36: =+PROJ!BP34 -> 28.389143 | S36: =+PROJ!BQ34 -> -2.7376295 | T36: =+PROJ!BR34 -> -55.125261 | U36: =+PROJ!BS34 -> -235.92839 | X36: =+X38-X29 -> -90 | Y36: =+Y38-Y29 -> -42 | AA36: 200 | AD36: =2533-580 -> 1953
B37: rate | O37: =+O36/O29 -> -5.0360824 | P37: =+P36/P29 -> 0.10114551 | Q37: =+Q36/Q29 -> -0.008601882 | R37: =+R36/R29 -> 0.022371528 | S37: =+S36/S29 -> -0.0019333148 | T37: =+T36/T29 -> -0.033617665 | U37: =+U36/U29 -> -0.12961882 | X37: =+X36/X29 -> -0.067669173 | Y37: =+Y36/Y29 -> -0.027237354 | AA37: 140
B38: Lucro Líquido Op. Cont. | C38: =+PROJ!BD42 -> #REF! | G38: =+PROJ!BE42 -> #REF! | H38: =+PROJ!BF42 -> #REF! | I38: =+PROJ!BG42 -> #REF! | J38: =+PROJ!BH42 -> #REF! | K38: =+PROJ!BI42 -> -676.9 | L38: =+PROJ!BJ42 -> #REF! | M38: =+PROJ!BK42 -> -2858.3 | N38: =+PROJ!BL42 -> 2979.0327 | O38: =+PROJ!BM37 -> -767.37205 | P38: =+PROJ!BN42 -> -2202.7133 | Q38: =+PROJ!BO42 -> 1022.7266 | R38: =+PROJ!BP42 -> 1297.3746 | S38: =+PROJ!BQ42 -> 1413.2912 | T38: =+PROJ!BR42 -> 1584.6454 | U38: =+PROJ!BS42 -> 1584.2423 | V38: =(+U38/Q38)^(1/4)-1 -> 0.11561801 | X38: 1240 | Y38: 1500 | AA38: =+AA37+AA36+AA29 -> -112.2 | AD38: =+AD36*0.7 -> 1367.1
B39: y-o-y | G39: =+G38/C38-1 -> #REF! | H39: =+H38/G38-1 -> #REF! | I39: =+I38/H38-1 -> #REF! | J39: =+J38/I38-1 -> #REF! | K39: =+K38/J38-1 -> #REF! | L39: =+L38/K38-1 -> #REF! | M39: =+M38/L38-1 -> #REF! | N39: =+N38/M38-1 -> -2.0422393 | O39: =+O38/N38-1 -> -1.257591 | ... U39: =+U38/T38-1 -> -0.00025435973 | AA39: =+AA38/X29 -> -0.084360902 | AD39: =+AD38+700 -> 2067.1
B41: Op. Descontinuadas | O41: =+PROJ!BM40 -> -8163.4 | P41: =+PROJ!BN40 -> -2665.4 | Q41: =+PROJ!BO40 -> 0 | R41: =+PROJ!BP40 -> 0 | S41: =+PROJ!BQ40 -> 0 | T41: =+PROJ!BR40 -> 0 | U41: =+PROJ!BS40 -> 0
B42: Minoritarios | O42: =+PROJ!BM41 -> 0.2 | P42: =+PROJ!BN41 -> 0 | Q42: =+PROJ!BO41 -> 0 | R42: =+PROJ!BP41 -> 0 | S42: =+PROJ!BQ41 -> 0 | T42: =+PROJ!BR41 -> 0 | U42: =+PROJ!BS41 -> 0
B43: LL Reportado | O43: =+PROJ!BM42 -> -8930.5721 | P43: =+PROJ!BN42 -> -2202.7133 | Q43: =+PROJ!BO42 -> 1022.7266 | R43: =+PROJ!BP42 -> 1297.3746 | S43: =+PROJ!BQ42 -> 1413.2912 | T43: =+PROJ!BR42 -> 1584.6454 | U43: =+PROJ!BS42 -> 1584.2423
B46: FLUXO DE CAIXA FIRMA | C46: 2015 | G46: =+C46+1 -> 2016 | H46: =+G46+1 -> 2017 | I46: =+H46+1 -> 2018 | J46: =+I46+1 -> 2019 | K46: =+J46+1 -> 2020 | L46: =+K46+1 -> 2021 | M46: =+L46+1 -> 2022 | N46: =+M46+1 -> 2023 | O46: =+N46+1 -> 2024 | ... U46: =+T46+1 -> 2030
B47: EBITDA | C47: =+FAT!BE115 -> 1495.9 | G47: =+FAT!BF115 -> 1372.7955 | H47: =+FAT!BG115 -> 1741.9646 | I47: =+FAT!BH115 -> 1850.9154 | J47: =+FAT!BJ115 -> 5312.832 | K47: =+FAT!BK115 -> 3508.6 | L47: =+FAT!BL115 -> 3909.9 | M47: =+FAT!BM115 -> 2133.5 | N47: =+FAT!BN115 -> 1521.4556 | O47: =+FAT!BO115 -> 1850.5519 | P47: =+FAT!BP115 -> 2215.8867 | Q47: =+FAT!BQ115 -> 2605.4186 | ... U47: =+FAT!BU115 -> 2876.1208 | X47: 3081 | Y47: 3307
...

Sheet FAT
AM1: ---> Proforma sin Int. | BO1: ---> Proforma sin Int.
B2: Inflação IPC-A | C2: =+MACRO!C8 -> 0.013475174 | D2: =+MACRO!D8 -> 0.013475174 | E2: =+MACRO!E8 -> 0.013475174 | F2: =+MACRO!F8 -> 0.013475174 | G2: =+MACRO!G8 -> 0.026 | H2: =+MACRO!H8 -> 0.017496397 | I2: =+MACRO!I8 -> 0.010430578 | J2: =+MACRO!J8 -> 0.007417894 | ... AX2: =+MACRO!AX8 -> 0.0115 | BB2: 0.0060105353 | BE2: =+MACRO!BD8 -> 0.1067 | BF2: =+MACRO!BE8 -> 0.062665012 | BG2: =+MACRO!BF8 -> 0.029473499 | BH2: =+MACRO!BG8 -> 0.030601831 | BJ2: =+MACRO!BH8 -> 0.042901847 | BK2: =+MACRO!BI8 -> 0.044908326 | BL2: =+MACRO!BJ8 -> 0.099766039 | BM2: =+MACRO!BK8 -> 0.057740344 | BN2: =+MACRO!BL8 -> 0.047250272 | BO2: =+MACRO!BM8 -> 0.046425617 | BP2: =+MACRO!BN8 -> 0.042643849 | BQ2: =+MACRO!BO8 -> 0.039553578 | ... BU2: =+MACRO!BS8 -> 0.04
B3: R$ million | C3: 1Q15 | D3: 2Q15 | E3: 3Q15 | F3: 4Q15 | G3: 1Q16 | H3: 2Q16 | I3: 3Q16 | J3: 4Q16 | K3: Q1-17 | L3: Q2-17 | M3: Q3-17(a) | N3: Q4-17(a) | O3: Q1-18(a) | P3: Q2-18 | Q3: Q3-18 | R3: Q4-18 | S3: Q1-19 | T3: Q2-19 | U3: Q3-19 | V3: Q4-19 | W3: Q1-20 | X3: Q2-20 | Y3: Q3-20 | Z3: Q4-20 | AA3: Q1-21 | AB3: Q2-21 | AC3: Q3-21 | AD3: Q4-21 | AE3: Q1-22 | AF3: Q2-22 | AG3: Q3-22 | AH3: Q4-22 | AI3: Q1-23 | AJ3: Q2-23 | AK3: Q3-23 | AL3: Q4-23 | AM3: Q1-24 | AN3: Q2-24 | AO3: Q3-24 | AP3: Q4-24 | AQ3: Q1-25 | AR3: Q2-25 | AS3: Q3-25 | AT3: Q4-25 | AU3: Q1-26 | AV3: Q2-26 | AW3: Q3-26 | AX3: Q4-26 | BB3: Q4-25 | BE3: 2015 | BF3: =+BE3+1 -> 2016 | BG3: =+BF3+1 -> 2017 | BH3: 2018 | BI3: 2019 | BJ3: 2019 PROFORMA | BK3: 2020 | BL3: =+BK3+1 -> 2021 | BM3: =+BL3+1 -> 2022 | BN3: =+BM3+1 -> 2023 | BO3: =+BN3+1 -> 2024 | BP3: =+BO3+1 -> 2025 | BQ3: =+BP3+1 -> 2026 | BR3: =+BQ3+1 -> 2027 | BS3: =+BR3+1 -> 2028 | ... BU3: =+BT3+1 -> 2030
B4: Total Consultants - end of period ('000) | C4: 1714.9 | D4: 1810.6 | E4: 1835 | F4: 1883 | G4: 1824.125 | H4: 1863.799 | I4: 1820.9 | J4: 1800.067 | K4: 1838.32 | L4: 1775.372 | M4: 1745.209 | N4: 1718.756 | O4: 1643.342 | P4: 1684.523 | Q4: =636.8+1082.1 -> 1718.9 | R4: =644.8+1058.7 -> 1703.5 | S4: =634.4+1036.1 -> 1670.5 | T4: =1049.8+659.2 -> 1709 | U4: =628.1+1056.4 -> 1684.5 | V4: =+#REF!+V339 -> #REF! | W4: =+#REF!+W339 -> #REF! | X4: =+#REF!+X339 -> #REF! | Y4: =+#REF!+Y339 -> #REF! | Z4: =+#REF!+Z339 -> #REF! | AA4: =+#REF!+AA339 -> #REF! | AB4: =+#REF!+AB339 -> #REF! | AC4: =+#REF!+AC339 -> #REF! | ... AX4: =+#REF!+AX339 -> #REF! | BB4: #REF! | BE4: =+F4 -> 1883 | BF4: =+J4 -> 1800.067 | BG4: =+N4 -> 1718.756 | BH4: =+R4 -> 1703.5 | BJ4: =+V4 -> #REF! | BK4: =+Z4 -> #REF! | BL4: =+AA4 -> #REF! | BM4: =+AH4 -> #REF! | BN4: =+AI4 -> #REF! | BO4: =+AM4 -> #REF! | BP4: =+AQ4 -> #REF! | BQ4: =+AU4 -> #REF! | BR4: =+#REF!+BR339 -> #REF! | BS4: =+#REF!+BS339 -> #REF! | BT4: =+#REF!+BT339 -> #REF! | BU4: =+#REF!+BU339 -> #REF!
B5: Total Consultants - average of period ('000) | C5: 1713 | D5: 1781.4 | E5: 1825.9 | F5: 1871.4 | G5: 1848.0495 | H5: 1855.3599 | I5: 1832.6 | J5: 1812.5381 | K5: 1822.9274 | L5: 1794.3739 | M5: 1747.6962 | N5: 1734.5326 | O5: 1633.1827 | P5: 1666.2007 | Q5: =633.8+1061.9 -> 1695.7 | R5: =644.4+1068.4 -> 1712.8 | S5: =636.6+1018.2 -> 1654.8 | T5: =1039.1+650.2 -> 1689.3 | U5: =+#REF!+U342 -> #REF! | V5: =+#REF!+V342 -> #REF! | W5: =+#REF!+W342 -> #REF! | X5: =+#REF!+X342 -> #REF! | Y5: =+#REF!+Y342 -> #REF! | Z5: =+#REF!+Z342 -> #REF! | AA5: =+#REF!+AA342 -> #REF! | AB5: =+#REF!+AB342 -> #REF! | ... AX5: =+#REF!+AX342 -> #REF! | BB5: #REF! | BE5: =+F5 -> 1871.4 | BF5: =+J5 -> 1812.5381 | BG5: =+N5 -> 1734.5326 | BH5: =+R5 -> 1712.8 | BJ5: =+V5 -> #REF! | BK5: =+Z5 -> #REF! | BL5: =+AA5 -> #REF! | BM5: =+AH5 -> #REF! | BN5: =+AI5 -> #REF! | BO5: =+AM5 -> #REF! | BP5: =+AQ5 -> #REF! | BQ5: =+AU5 -> #REF! | BR5: =+#REF!+BR342 -> #REF! | BS5: =+#REF!+BS342 -> #REF! | BT5: =+#REF!+BT342 -> #REF! | BU5: =+#REF!+BU342 -> #REF!
B6: Units sold – items for resale (in million) | C6: 114.81 | D6: 120.42 | E6: 129.66 | F6: 139.62 | G6: 109.1861 | H6: 116.89729 | I6: 112.8 | J6: 128.46677 | K6: 101.83594 | L6: 107.58112 | M6: 116.21644 | N6: 134.05381 | O6: 104.67395 | P6: 122.16681 | Q6: =35.4+89.6 -> 125 | R6: =40.4+99.4 -> 139.8 | S6: =33.5+73.4 -> 106.9 | T6: =81.8+38.5 -> 120.3 | U6: =+#REF!+U344 -> #REF! | V6: =+#REF!+V344 -> #REF! | W6: =+#REF!+W344 -> #REF! | X6: =+#REF!+X344 -> #REF! | Y6: =+#REF!+Y344 -> #REF! | Z6: =+#REF!+Z344 -> #REF! | AA6: =+#REF!+AA344 -> #REF! | AB6: =+#REF!+AB344 -> #REF! | ... AX6: =+#REF!+AX344 -> #REF! | BB6: #REF! | BE6: =+SUM(C6:F6) -> 504.51 | BF6: =+SUM(G6:J6) -> 467.35016 | BG6: =+SUM(K6:N6) -> 459.68731 | BH6: =+SUM(O6:R6) -> 491.64076 | BJ6: =+SUM(S6:V6) -> #REF! | BK6: =+SUM(W6:Z6) -> #REF! | BL6: =+SUM(AA6:AD6) -> #REF! | BM6: =+SUM(AE6:AH6) -> #REF! | BN6: =+SUM(AI6:AL6) -> #REF! | BO6: =+SUM(AM6:AP6) -> #REF! | BP6: =+SUM(AQ6:AT6) -> #REF! | BQ6: =+SUM(AU6:AX6) -> #REF! | BR6: =+#REF!+BR344 -> #REF! | BS6: =+#REF!+BS344 -> #REF! | BT6: =+#REF!+BT344 -> #REF! | BU6: =+#REF!+BU344 -> #REF!
B8: Gross Revenue | C8: 2205.8399 | D8: 2637.31 | E8: 2763.0574 | F8: 3200.2328 | G8: 2320.028 | H8: 2815.4641 | I8: 2656.2 | J8: 3198.6641 | K8: 2395.9488 | L8: 2801.6006 | M8: 3203.2068 | N8: 5350.1 | O8: 3708.4434 | P8: 4301.1209 | Q8: 4392.9386 | R8: 6111.9653 | S8: 3940.6 | T8: 4629.9 | U8: 4705 | V8: 6432.6 | W8: =+W36+W40+W44+W48 -> 9719.1 | X8: =+X36+X40+X44+X48 -> 9115.8 | Y8: =+Y36+Y40+Y44+Y48 -> 13601.3 | Z8: =+Z36+Z40+Z44+Z48 -> 15260.8 | AA8: =+AA36+AA40+AA44+AA48 -> 12059.1 | AB8: =+AB36+AB40+AB44+AB48 -> 12233 | AC8: =+AC36+AC40+AC44+AC48 -> 12329.1 | AD8: =+AD36+AD40+AD44+AD48 -> 15023 | ... AX8: =+AX36+AX40+AX44+AX48 -> 9319.9503 | BB8: 8402.5252 | BC8: =+AT8/BB8-1 -> -0.016724167 | BE8: =+SUM(C8:F8) -> 10806.44 | BF8: =+SUM(G8:J8) -> 10990.356 | BG8: =+SUM(K8:N8) -> 13750.856 | BH8: =+SUM(O8:R8) -> 18514.468 | BJ8: =+SUM(S8:V8) -> 19708.1 | BK8: =+SUM(W8:Z8) -> 47697 | BL8: =+SUM(AA8:AD8) -> 51644.2 | BM8: =+SUM(AE8:AH8) -> 47108.6 | BN8: =+SUM(AI8:AL8) -> 38175.466 | BO8: =+SUM(AM8:AP8) -> 31586.823 | BP8: =+SUM(AQ8:AT8) -> 29494.8 | BQ8: =+SUM(AU8:AX8) -> 30341.943 | BR8: =+BR36+BR40+BR44+BR48 -> 31698.982 | BS8: =+BS36+BS40+BS44+BS48 -> 32921.722 | BT8: =+BT36+BT40+BT44+BT48 -> 34175.414 | BU8: =+BU36+BU40+BU44+BU48 -> 35383.328
G9: =+G8/C8-1 -> 0.051766254 | H9: =+H8/D8-1 -> 0.067551467 | I9: =+I8/E8-1 -> -0.038673598 | J9: =+J8/F8-1 -> -0.00049018569 | K9: =+K8/G8-1 -> 0.032724096 | L9: =+L8/H8-1 -> -0.0049240771 | M9: =+M8/I8-1 -> 0.20593587 | N9: =+N8/J8-1 -> 0.67260451 | ... AX9: =+AX8/AT8-1 -> 0.12805014 | BB9: -0.10321409 | BF9: =+BF8/BE8-1 -> 0.017019124 | BG9: =+BG8/BF8-1 -> 0.25117475 | BH9: =+BH8/BG8-1 -> 0.34642293 | BJ9: =+BJ8/BH8-1 -> 0.064470219 | BK9: =+BK8/BJ8-1 -> 1.4201724 | BL9: =+BL8/BK8-1 -> 0.082755729 | BM9: =+BM8/BL8-1 -> -0.087823996 | BN9: =+BN8/BM8-1 -> -0.18962852 | BO9: =+BO8/BN8-1 -> -0.17258842 | BP9: =+BP8/BO8-1 -> -0.066230874 | BQ9: =+BQ8/BP8-1 -> 0.028721766 | BR9: =+BR8/BQ8-1 -> 0.044724877 | ... BU9: =+BU8/BT8-1 -> 0.035344534
B11: Natura Brasil | C11: 1703.7 | D11: 1979.2 | E11: 1952.8 | F11: 2256.3 | G11: 1611.7 | H11: 2003.5 | I11: 1849.5 | J11: 2293.1 | K11: 1682.7651 | L11: 1943.7478 | M11: 1931.4179 | N11: 2389.5056 | O11: 1663.6544 | P11: 2045.3235 | Q11: 2158.1 | R11: 2673.7 | S11: 1686.9 | T11: 2224.5 | U11: 2219.5 | V11: 2734 | BE11: =+SUM(C11:F11) -> 7892 | BF11: =+SUM(G11:J11) -> 7757.8 | BG11: =+SUM(K11:N11) -> 7947.4365 | BH11: =+SUM(O11:R11) -> 8540.7779 | BJ11: =+SUM(S11:V11) -> 8864.9
B12: % Sales | C12: 0.77235261 | D12: 0.75047225 | E12: 0.70677004 | F12: 0.70505202 | G12: 0.69468418 | H12: 0.71160404 | I12: 0.69629546 | J12: 0.71688888 | K12: 0.70233768 | L12: 0.69379905 | M12: 0.60296384 | N12: 0.44662822 | O12: 0.44862489 | P12: 0.4755272 | Q12: 0.49126569 | R12: 0.4374534 | S12: 0.42808202 | T12: 0.48046394 | U12: =+U11/U$8 -> 0.4717322 | V12: =+V11/V$8 -> 0.42502254 | BE12: =+BE11/BE$8 -> 0.73030526 | BF12: =+BF11/BF$8 -> 0.70587339 | BG12: =+BG11/BG$8 -> 0.57795939 | BH12: =+BH11/BH$8 -> 0.4613029 | BJ12: =+BJ11/BJ$8 -> 0.44980998
B13: yoy | G13: -0.054000243 | H13: 0.012261191 | I13: -0.05292079 | J13: 0.016290228 | K13: 0.044101865 | L13: -0.029821795 | M13: 0.044291916 | N13: 0.042047645 | O13: -0.011329649 | P13: 0.052245557 | Q13: 0.11736564 | R13: 0.11893438 | S13: 0.013944822 | T13: 0.087615509 | U13: =+U11/Q11-1 -> 0.028450952 | V13: =+V11/R11-1 -> 0.022553016 | BF13: =+BF11/BE11-1 -> -0.017004562 | BG13: =+BG11/BF11-1 -> 0.024444622 | BH13: =+BH11/BG11-1 -> 0.074658208 | BJ13: =+BJ11/BH11-1 -> 0.037949956
B15: Natura Latam | C15: 425.6 | D15: 561.6 | E15: 686.9 | F15: 750.5 | G15: 560.8 | H15: 668.2 | I15: 658.6 | J15: 687.7 | K15: 551.79426 | L15: 688.29958 | M15: 738.92014 | N15: 782.04328 | O15: 661.76527 | P15: 802.82208 | Q15: 629.6 | R15: 954 | S15: 720.2 | T15: 880.4 | U15: 863.2 | V15: 1048.5 | BE15: =+SUM(C15:F15) -> 2424.6 | BF15: =+SUM(G15:J15) -> 2575.3 | BG15: =+SUM(K15:N15) -> 2761.0573 | BH15: =+SUM(O15:R15) -> 3048.1873 | BJ15: =+SUM(S15:V15) -> 3512.3
B16: % Sales | C16: 0.1929294 | D16: 0.21296182 | E16: 0.24859978 | F16: 0.23452909 | G16: 0.24170145 | H16: 0.23734405 | I16: 0.2479482 | J16: 0.21499415 | K16: 0.23030302 | L16: 0.24568084 | M16: 0.23068137 | N16: 0.14617358 | O16: 0.17845762 | P16: 0.18664902 | Q16: 0.14332092 | R16: 0.15608727 | S16: 0.18276405 | T16: 0.19015529 | U16: =+U15/U$8 -> 0.1834644 | V16: =+V15/V$8 -> 0.16299785 | BE16: =+BE15/BE$8 -> 0.22436621 | BF16: =+BF15/BF$8 -> 0.23432361 | BG16: =+BG15/BG$8 -> 0.20079166 | BH16: =+BH15/BH$8 -> 0.16463813 | BJ16: =+BJ15/BJ$8 -> 0.17821606
B17: yoy | G17: 0.31765005 | H17: 0.1897766 | I17: -0.041193262 | J17: -0.083743673 | K17: -0.015978259 | L17: 0.030028316 | M17: 0.12195587 | N17: 0.13719647 | O17: 0.19936007 | P17: 0.16635259 | Q17: -0.14794581 | R17: 0.21988133 | S17: 0.088244183 | T17: 0.096661684 | U17: =+U15/Q15-1 -> 0.37102922 | V17: =+V15/R15-1 -> 0.099056604 | BF17: =+BF15/BE15-1 -> 0.062154582 | BG17: =+BG15/BF15-1 -> 0.072130339 | BH17: =+BH15/BG15-1 -> 0.1039928 | BJ17: =+BJ15/BH15-1 -> 0.15225857
B19: Aesop | C19: 73.053874 | D19: 91.8 | E19: 119.7 | F19: 187.5 | G19: 143.51321 | H19: 139.1589 | I19: 144.9 | J19: 212.29092 | K19: 159.43454 | L19: 167.4517 | M19: 176.69238 | N19: 276.16212 | O19: 221.99708 | P19: 259.95249 | Q19: 295.12288 | R19: 397.36756 | S19: 297.79249 | T19: 313.79691 | U19: 331.5 | V19: 501.4 | BE19: =+SUM(C19:F19) -> 472.05387 | BF19: =+SUM(G19:J19) -> 639.86303 | BG19: =+SUM(K19:N19) -> 779.74073 | BH19: =+SUM(O19:R19) -> 1174.44 | BJ19: =+SUM(S19:V19) -> 1444.4894
B20: % Sales | C20: 0.033118393 | D20: 0.034808195 | E20: 0.043321576 | F20: 0.058589487 | G20: 0.061858396 | H20: 0.049426629 | I20: 0.054551615 | J20: 0.066368619 | K20: 0.066543383 | L20: 0.059770012 | M20: 0.055161088 | N20: 0.051618122 | O20: 0.059862603 | P20: 0.060438312 | Q20: 0.067181198 | R20: 0.065014695 | S20: 0.075570343 | T20: 0.067776174 | U20: =+U19/U$8 -> 0.070456961 | V20: =+V19/V$8 -> 0.077946709 | BE20: =+BE19/BE$8 -> 0.043682644 | BF20: =+BF19/BF$8 -> 0.058220409 | BG20: =+BG19/BG$8 -> 0.056704886 | BH20: =+BH19/BH$8 -> 0.063433634 | BJ20: =+BJ19/BJ$8 -> 0.073294199
B21: yoy | G21: 0.96448461 | H21: 0.51589217 | I21: 0.21052632 | J21: 0.13221824 | K21: 0.11093981 | L21: 0.20331288 | M21: 0.21940908 | N21: 0.30086637 | O21: 0.39240266 | P21: 0.55240282 | Q21: 0.67026379 | R21: 0.43889236 | S21: 0.3414253 | T21: 0.20713178 | U21: =+U19/Q19-1 -> 0.12326094 | V21: =+V19/R19-1 -> 0.26180406 | BF21: =+BF19/BE19-1 -> 0.3554873 | BG21: =+BG19/BF19-1 -> 0.21860569 | BH21: =+BH19/BG19-1 -> 0.50619297 | BJ21: =+BJ19/BH19-1 -> 0.22993886
B24: The body Shop | M24: 354.87262 | N24: 1900.0621 | O24: 1158.8732 | P24: 1190.6804 | Q24: 1307.7313 | R24: 2082.9565 | S24: 1231.7175 | T24: 1208.288 | U24: 1288.6 | V24: 2145.4 | BE24: =+SUM(C24:F24) -> 0 | BF24: =+SUM(G24:J24) -> 0 | BG24: =+SUM(K24:N24) -> 2254.9347 | BH24: =+SUM(O24:R24) -> 5740.2414 | BJ24: =+SUM(S24:V24) -> 5874.0055
B25: % Sales | M25: 0.11078667 | N25: 0.35514516 | O25: 0.31249587 | P25: 0.27683026 | Q25: 0.29768941 | R25: 0.34079979 | S25: 0.31257104 | T25: 0.26097498 | U25: =+U24/U$8 -> 0.27387885 | V25: =+V24/V$8 -> 0.33351988 | BE25: =+BE24/BE$8 -> 0 | BF25: =+BF24/BF$8 -> 0 | BG25: =+BG24/BG$8 -> 0.16398504 | BH25: =+BH24/BH$8 -> 0.31004085 | BJ25: =+BJ24/BJ$8 -> 0.29805032
B26: yoy | Q26: 2.6850724 | R26: 0.096257041 | S26: 0.062857789 | T26: 0.01478788 | U26: =+U24/Q24-1 -> -0.014629386 | V26: =+V24/R24-1 -> 0.029978323 | BH26: =+BH24/BG24-1 -> 1.5456353 | BJ26: =+BJ24/BH24-1 -> 0.023302867
B29: Others | C29: 3.5284691 | D29: 4.6356993 | E29: 3.6157452 | F29: 5.8545154 | G29: 4.0739035 | H29: 4.5759303 | I29: 3.2 | J29: 5.5923698 | K29: 1.9548775 | L29: 2.1014764 | M29: 1.3038131 | N29: 2.3268632 | O29: 2.0730762 | P29: 2.3880338 | Q29: 2.3844217 | R29: 3.9412434 | S29: 3.990054 | T29: 2.915047 | U29: =+U8-U11-U15-U19-U24 -> 2.2 | V29: =+V8-V11-V15-V19-V24 -> 3.3 | BE29: =+SUM(C29:F29) -> 17.634429 | BF29: =+SUM(G29:J29) -> 17.442204 | BG29: =+SUM(K29:N29) -> 7.6870302 | BH29: =+SUM(O29:R29) -> 10.786775 | BJ29: =+SUM(S29:V29) -> 12.405101
B30: % Sales | C30: 0.0015996034 | D30: 0.0017577377 | E30: 0.001308603 | F30: 0.001829403 | G30: 0.0017559717 | H30: 0.0016252845 | I30: 0.0012047286 | J30: 0.0017483454 | K30: 0.00081590954 | L30: 0.00075009852 | M30: 0.00040703368 | N30: 0.00043491957 | O30: 0.00055901519 | P30: 0.00055521198 | Q30: 0.00054278512 | R30: 0.00064484061 | S30: 0.0010125499 | T30: 0.00062961339 | U30: =+U29/U$8 -> 0.00046758767 | V30: =+V29/V$8 -> 0.00051301185 | BE30: =+BE29/BE$8 -> 0.0016318444 | BF30: =+BF29/BF$8 -> 0.0015870462 | BG30: =+BG29/BG$8 -> 0.00055902193 | BH30: =+BH29/BH$8 -> 0.00058261329 | BJ30: =+BJ29/BJ$8 -> 0.00062944175
B31: yoy | G31: 0.15458103 | H31: -0.012893193 | I31: -0.11498189 | J31: -0.044776663 | K31: -0.52014634 | L31: -0.54075427 | M31: -0.59255842 | N31: -0.58392179 | O31: 0.060463481 | P31: 0.13636004 | Q31: 0.82880642 | R31: 0.69380108 | S31: 0.92470205 | T31: 0.22068916 | U31: =+U29/Q29-1 -> -0.077344416 | V31: =+V29/R29-1 -> -0.16270079 | BF31: =+BF29/BE29-1 -> -0.010900576 | BG31: =+BG29/BF29-1 -> -0.5592856 | BH31: =+BH29/BG29-1 -> 0.4032435 | BJ31: =+BJ29/BH29-1 -> 0.1500287
B33: Gross Revenue | S33: =+S36+S40+S44+S48 -> 9683.3099 | T33: =+T36+T40+T44+T48 -> 10531.185 | U33: =+U36+U40+U44+U48 -> 10458.9 | V33: =+V36+V40+V44+V48 -> 12915.3 | W33: =+W36+W40+W44+W48 -> 9719.1 | X33: =+X36+X40+X44+X48 -> 9115.8 | Y33: =+Y36+Y40+Y44+Y48 -> 13601.3 | Z33: =+Z36+Z40+Z44+Z48 -> 15260.8 | ... AL33: =+AL36+AL40+AL44+AL48 -> 8609.9 | AM33: 6231.5 | AN33: 7778.8 | AO33: 7900.7339 | AP33: 9369.6 | AQ33: 6819.9 | AR33: 7545.9 | AS33: 6866.6 | AT33: =+AT36 -> 8262 | AU33: =+AU36 -> 6020.787 | AV33: =+AV36 -> 7623.5828 | AW33: =+AW36 -> 7377.6227 | AX33: =+AX36 -> 9319.9503 | BB33: 8402.5252 | BC33: =+AT33/BB33-1 -> -0.016724167 | BJ33: =+BJ36+BJ40+BJ44+BJ48 -> 43588.695 | BK33: =+BK36+BK40+BK44+BK48 -> 47697 | BL33: =+BL36+BL40+BL44+BL48 -> 51644.2 | BM33: =+BM36+BM40+BM44+BM48 -> 47108.6 | BN33: =+BN36+BN40+BN44+BN48 -> 38175.466 | BO33: =+BO36 -> 31586.823 | BP33: =+BP36 -> 29494.8 | BQ33: =+BQ36 -> 30341.943 | BR33: =+BR36 -> 31698.982 | BS33: =+BS36 -> 32921.722 | BT33: =+BT36 -> 34175.414 | BU33: =+BU36 -> 35383.328
W34: =+W33/S33-1 -> 0.0036960558 | X34: =+X33/T33-1 -> -0.1343994 | Y34: =+Y33/U33-1 -> 0.30045225 | Z34: =+Z33/V33-1 -> 0.18160631 | AA34: =+AA33/W33-1 -> 0.24076303 | AB34: =+AB33/X33-1 -> 0.34195573 | AC34: =+AC33/Y33-1 -> -0.093535177 | AD34: =+AD33/Z33-1 -> -0.015582407 | ... AX34: =+AX33/AT33-1 -> 0.12805014 | BB34: -0.10321409 | BK34: =+BK33/BJ33-1 -> 0.09425162 | BL34: =+BL33/BK33-1 -> 0.082755729 | BM34: =+BM33/BL33-1 -> -0.087823996 | BN34: =+BN33/BM33-1 -> -0.18962852 | BO34: =+BO33/BN33-1 -> -0.17258842 | BP34: =+BP33/BO33-1 -> -0.066230874 | BQ34: =+BQ33/BP33-1 -> 0.028721766 | BR34: =+BR33/BQ33-1 -> 0.044724877 | ... BU34: =+BU33/BT33-1 -> 0.035344534
