Workbook

Sheet RESUMO
O2: =+TODAY() -> 46071
B3: REGIONAL (mln MXN) | C3: 2020 | D3: =+C3+1 -> 2021 | E3: =+D3+1 -> 2022 | F3: =+E3+1 -> 2023 | G3: =+F3+1 -> 2024 | H3: =+G3+1 -> 2025 | I3: =+H3+1 -> 2026 | J3: =+I3+1 -> 2027 | K3: =+J3+1 -> 2028 | ... R3: =+Q3+1 -> 2035 | T3: #VALUE!
B5: Gross Loan | C5: =+FAT!AM7 -> 110416 | D5: =+FAT!AN7 -> 117952 | E5: =+FAT!AO7 -> 136876 | F5: =+FAT!AP7 -> 155301 | G5: =+FAT!AQ7 -> 177176 | H5: =+FAT!AR7 -> 190842 | I5: =+FAT!AS7 -> 206164.96 | J5: =+FAT!AT7 -> 226042.93 | ... R5: =+FAT!BB7 -> 350896.08
B6: yoy | D6: =+D5/C5-1 -> 0.068250978 | E6: =+E5/D5-1 -> 0.16043814 | F6: =+F5/E5-1 -> 0.13461089 | G6: =+G5/F5-1 -> 0.1408555 | H6: =+H5/G5-1 -> 0.077132343 | I6: =+I5/H5-1 -> 0.080291332 | J6: =+J5/I5-1 -> 0.096417803 | K6: =+K5/J5-1 -> 0.062909369 | ... R6: =+R5/Q5-1 -> 0.05035676
B7: A Vencer | C7: =+FAT!AM9 -> 108864 | D7: =+FAT!AN9 -> 115817 | E7: =+FAT!AO9 -> 135100 | F7: =+FAT!AP9 -> 153248 | G7: =+FAT!AQ9 -> 174951 | H7: =+FAT!AR9 -> 188396 | I7: =+FAT!AS9 -> 203501.18 | J7: =+FAT!AT9 -> 222959.31 | ... R7: =+FAT!BB9 -> 344805.56
B8: Vencidos (NPL) | C8: =+FAT!AM10 -> 1552 | D8: =+FAT!AN10 -> 2135 | E8: =+FAT!AO10 -> 1776 | F8: =+FAT!AP10 -> 2053 | G8: =+FAT!AQ10 -> 2225 | H8: =+FAT!AR10 -> 2446 | I8: =+FAT!AS10 -> 2663.7783 | J8: =+FAT!AT10 -> 3083.6166 | ... R8: =+FAT!BB10 -> 6090.5186
B9: % portfolio | C9: =+C8/AVERAGE(B5:C5) -> 0.014055934 | D9: =+D8/AVERAGE(C5:D5) -> 0.018697891 | E9: =+E8/AVERAGE(D5:E5) -> 0.013938814 | F9: =+F8/AVERAGE(E5:F5) -> 0.014053125 | G9: =+G8/AVERAGE(F5:G5) -> 0.013384384 | H9: =+H8/AVERAGE(G5:H5) -> 0.013292828 | I9: =+I8/AVERAGE(H5:I5) -> 0.013419303 | J9: =+J8/AVERAGE(I5:J5) -> 0.014269136 | ... R9: =+R8/AVERAGE(Q5:R5) -> 0.017783333
B11: Net Interest Rev | C11: =+FAT!AM137 -> 7512 | D11: =+FAT!AN137 -> 7568 | E11: =+FAT!AO137 -> 10361 | F11: =+FAT!AP137 -> 12386 | G11: =+FAT!AQ137 -> 14377 | H11: =+FAT!AR137 -> 15465 | I11: =+FAT!AS137 -> 15792.26 | J11: =+FAT!AT137 -> 16840.707 | ... R11: =+FAT!BB137 -> 27721.717 | T11: share price | U11: {=+_FV(T3,"Price")} -> 162.48
B12: yoy | D12: =+D11/C11-1 -> 0.0074547391 | E12: =+E11/D11-1 -> 0.36905391 | F12: =+F11/E11-1 -> 0.19544446 | G12: =+G11/F11-1 -> 0.160746 | H12: =+H11/G11-1 -> 0.075676428 | I12: =+I11/H11-1 -> 0.021161322 | J12: =+J11/I11-1 -> 0.06638997 | K12: =+K11/J11-1 -> 0.086613231 | ... R12: =+R11/Q11-1 -> 0.054268164 | T12: Shares | U12: {=+_FV(T3,"Shares outstanding",TRUE)/1000000} -> 327.9313 | V12: =+U12*U11 -> 53282.278
B13: NIM | C13: =+FAT!AM142 -> 0.056879466 | D13: =+FAT!AN142 -> 0.052181048 | E13: =+FAT!AO142 -> 0.060077177 | F13: =+FAT!AP142 -> 0.058380743 | G13: =+FAT!AQ142 -> 0.06576973 | H13: =+FAT!AR142 -> 0.064616569 | I13: =+FAT!AS142 -> 0.061138133 | J13: =+FAT!AT142 -> 0.06042198 | ... R13: =+FAT!BB142 -> 0.058370491 | T13: TP price | U13: =8*H35/H41 -> 161.43625
B15: Var yoy | D15: =+(D13/C13-1)*10000 -> -826.03067 | E15: =+(E13/D13-1)*10000 -> 1513.2178 | F15: =+(F13/E13-1)*10000 -> -282.37577 | G15: =+(G13/F13-1)*10000 -> 1265.655 | H15: =+(H13/G13-1)*10000 -> -175.33308 | I15: =+(I13/H13-1)*10000 -> -538.31956
B16: TIIE | D16: =+macro!DI51 -> 0.0571 | E16: =+macro!DJ51 -> 0.105 | F16: =+macro!DK51 -> 0.115025 | G16: =+macro!DL51 -> 0.10245 | H16: =+macro!DM51 -> 0.075 | I16: =+macro!DN51 -> 0.068
B17: Var yoy | D17: =+(D16/C16-1)*10000 -> #DIV/0! | E17: =+(E16/D16-1)*10000 -> 8388.7916 | F17: =+(F16/E16-1)*10000 -> 954.7619 | G17: =+(G16/F16-1)*10000 -> -1093.2406 | H17: =+(H16/G16-1)*10000 -> -2679.3558 | I17: =+(I16/H16-1)*10000 -> -933.33333
B18: dif | D18: =+D15/D17*100 -> #DIV/0! | E18: =+E15/E17*100 -> 18.038567 | F18: =+F15/F17*100 -> -29.575517 | G18: =+G15/G17*100 -> -115.77094 | H18: =+H15/H17*100 -> 6.5438523 | I18: =+I15/I17*100 -> 57.677096
B20: Other Revenues | C20: =+FAT!AM164 -> 2649 | D20: =+FAT!AN164 -> 3092 | E20: =+FAT!AO164 -> 2851 | F20: =+FAT!AP164 -> 2613 | G20: =+FAT!AQ164 -> 3041 | H20: =+FAT!AR164 -> 3231 | I20: =+FAT!AS164 -> 3563.0088 | J20: =+FAT!AT164 -> 3869.2195 | ... R20: =+FAT!BB164 -> 5841.1515
B21: yoy | D21: =+D20/C20-1 -> 0.16723292 | E21: =+E20/D20-1 -> -0.077943079 | F21: =+F20/E20-1 -> -0.083479481 | G21: =+G20/F20-1 -> 0.1637964 | H21: =+H20/G20-1 -> 0.062479448 | I21: =+I20/H20-1 -> 0.10275728 | J21: =+J20/I20-1 -> 0.085941608 | K21: =+K20/J20-1 -> 0.059442913 | ... R21: =+R20/Q20-1 -> 0.051940993 | T21: ROE1 | U21: =+AVERAGE(H48:R48) -> 0.1465045
B23: Provisions | C23: =+FAT!AM160 -> -1064 | D23: =+FAT!AN160 -> -853 | E23: =+FAT!AO160 -> -444 | F23: =+FAT!AP160 -> -1270 | G23: =+FAT!AQ160 -> -1648 | H23: =+FAT!AR160 -> -1757 | I23: =+FAT!AS160 -> -1959.5548 | J23: =+FAT!AT160 -> -2014.9948 | ... R23: =+FAT!BB160 -> -3251.4327 | T23: ROE2 | U23: 0.15
B24: % portfolio | C24: =+C23/AVERAGE(B5:C5) -> -0.0096362846 | D24: =+D23/AVERAGE(C5:D5) -> -0.0074703987 | E24: =+E23/AVERAGE(D5:E5) -> -0.0034847034 | F24: =+F23/AVERAGE(E5:F5) -> -0.0086933605 | G24: =+G23/AVERAGE(F5:G5) -> -0.0099134677 | H24: =+H23/AVERAGE(G5:H5) -> -0.009548446 | I24: =+I23/AVERAGE(H5:I5) -> -0.0098716396 | J24: =+J23/AVERAGE(I5:J5) -> -0.0093241928 | ... R24: =+R23/AVERAGE(Q5:R5) -> -0.0094936593
B26: Other Expenses | C26: =+FAT!AM183 -> -4747 | D26: =+FAT!AN183 -> -4857 | E26: =+FAT!AO183 -> -5369.5 | F26: =+FAT!AP183 -> -6139 | G26: =+FAT!AQ183 -> -6910 | H26: =+FAT!AR183 -> -7896.5 | I26: =+FAT!AS183 -> -8578.7002 | J26: =+FAT!AT183 -> -8698.0681 | ... R26: =+FAT!BB183 -> -11281.06 | T26: G1 | U26: 0.02
B27: yoy | D27: =+D26/C26-1 -> 0.02317253 | E27: =+E26/D26-1 -> 0.10551781 | F27: =+F26/E26-1 -> 0.14330943 | G27: =+G26/F26-1 -> 0.12559049 | H27: =+H26/G26-1 -> 0.14276411 | I27: =+I26/H26-1 -> 0.086392736 | J27: =+J26/I26-1 -> 0.013914446 | K27: =+K26/J26-1 -> 0.034460836 | ... R27: =+R26/Q26-1 -> 0.032970452 | T27: ROE1 | U27: =+AVERAGE(H54:R54) -> #DIV/0!
B28: Ratio eficiencia | C28: =+C26/(C11+C20) -> -0.46717843 | D28: =+D26/(D11+D20) -> -0.45562852 | E28: =+E26/(E11+E20) -> -0.40641084 | F28: =+F26/(F11+F20) -> -0.40929395 | G28: =+G26/(G11+G20) -> -0.39671604 | H28: =+H26/(H11+H20) -> -0.42236307 | I28: =+I26/(I11+I20) -> -0.443223 | J28: =+J26/(J11+J20) -> -0.41999511 | ... R28: =+R26/(R11+R20) -> -0.33611727 | T28: G2 | U28: 0.02
B30: EBT | C30: =+FAT!AM210 -> 4780 | D30: =+FAT!AN210 -> 5390 | E30: =+FAT!AO210 -> 7398.5 | F30: =+FAT!AP210 -> 7590 | G30: =+FAT!AQ210 -> 8860 | H30: =+FAT!AR210 -> 9042.5 | I30: =+FAT!AS210 -> 8817.0136 | J30: =+FAT!AT210 -> 9996.864 | ... R30: =+FAT!BB210 -> 19030.376 | T30: Ke | U30: =+(U36+U33)+(U38*U37) -> 0.135
T31: N (moat) | U31: 5
B32: Tax | C32: =+FAT!AM212 -> -1180 | D32: =+FAT!AN212 -> -1206 | E32: =+FAT!AO212 -> -1571 | F32: =+FAT!AP212 -> -1918 | G32: =+FAT!AQ212 -> -2310 | H32: =+FAT!AR212 -> -2425 | I32: =+FAT!AS212 -> -2424.6787 | J32: =+FAT!AT212 -> -2749.1376 | ... R32: =+FAT!BB212 -> -5233.3535
B33: rate | C33: =+C32/C30 -> -0.24686192 | D33: =+D32/D30 -> -0.22374768 | E33: =+E32/E30 -> -0.21234034 | F33: =+F32/F30 -> -0.25270092 | G33: =+G32/G30 -> -0.26072235 | H33: =+H32/H30 -> -0.26817805 | I33: =+I32/I30 -> -0.275 | J33: =+J32/J30 -> -0.275 | ... R33: =+R32/R30 -> -0.275 | T33: INFL | U33: 0.04
T34: GDP Perp | U34: 0.02
B35: Net Income | C35: =+FAT!AM217 -> 3619 | D35: =+FAT!AN217 -> 4202 | E35: =+FAT!AO217 -> 5820.5 | F35: =+FAT!AP217 -> 5673 | G35: =+FAT!AQ217 -> 6519 | H35: =+FAT!AR217 -> 6617.5 | I35: =+FAT!AS217 -> 6392.3348 | J35: =+FAT!AT217 -> 7247.7264 | ... R35: =+FAT!BB217 -> 13797.023 | T35: Aj. G2 | U35: 0
B36: yoy | D36: =+D35/C35-1 -> 0.16109422 | E36: =+E35/D35-1 -> 0.38517373 | F36: =+F35/E35-1 -> -0.025341466 | G36: =+G35/F35-1 -> 0.14912745 | H36: =+H35/G35-1 -> 0.015109679 | I36: =+I35/H35-1 -> -0.034025716 | J36: =+J35/I35-1 -> 0.1338152 | K36: =+K35/J35-1 -> 0.11965909 | ... R36: =+R35/Q35-1 -> 0.06737007 | T36: BNTNB | U36: 0.05
T37: ERP | U37: 0.045
B38: MULTIPLOS | C38: =+C$3 -> 2020 | D38: =+D$3 -> 2021 | E38: =+E$3 -> 2022 | F38: =+F$3 -> 2023 | G38: =+G$3 -> 2024 | H38: =+H$3 -> 2025 | I38: =+I$3 -> 2026 | J38: =+J$3 -> 2027 | ... R38: =+R$3 -> 2035 | T38: Beta | U38: 1
B39: Mkt Cap | C39: {=+_FV($T$3,"Market cap",TRUE)/1000000} -> 53282.278 | D39: {=+_FV($T$3,"Market cap",TRUE)/1000000} -> 53282.278 | E39: {=+_FV($T$3,"Market cap",TRUE)/1000000} -> 53282.278 | F39: {=+_FV($T$3,"Market cap",TRUE)/1000000} -> 53282.278 | G39: {=+_FV($T$3,"Market cap",TRUE)/1000000} -> 53282.278 | H39: {=+_FV($T$3,"Market cap",TRUE)/1000000} -> 53282.278 | I39: {=+_FV($T$3,"Market cap",TRUE)/1000000} -> 53282.278 | J39: {=+_FV($T$3,"Market cap",TRUE)/1000000} -> 53282.278 | ... R39: {=+_FV($T$3,"Market cap",TRUE)/1000000} -> 53282.278
T40: P/E Target | U40: =+(((1-U26/U21)*(1+U26)*(1-(((1+U26)^U31)/((1+U30)^U31))))/(U30-U26))+(((1-U28/U23)*((1+U26)^U31)*(1+U28))/((U30-U28)*((1+U30)^U31))) -> 7.6752797
B41: Shares | C41: {=+_FV($T$3,"Shares outstanding",TRUE)/1000000} -> 327.9313 | D41: {=+_FV($T$3,"Shares outstanding",TRUE)/1000000} -> 327.9313 | E41: {=+_FV($T$3,"Shares outstanding",TRUE)/1000000} -> 327.9313 | F41: {=+_FV($T$3,"Shares outstanding",TRUE)/1000000} -> 327.9313 | G41: {=+_FV($T$3,"Shares outstanding",TRUE)/1000000} -> 327.9313 | H41: {=+_FV($T$3,"Shares outstanding",TRUE)/1000000} -> 327.9313 | I41: {=+_FV($T$3,"Shares outstanding",TRUE)/1000000} -> 327.9313 | J41: {=+_FV($T$3,"Shares outstanding",TRUE)/1000000} -> 327.9313 | ... R41: {=+_FV($T$3,"Shares outstanding",TRUE)/1000000} -> 327.9313 | T41: vs 2025 | U41: =+U40/H46-1 -> -0.046753147
B43: EPS | C43: =+C35/C41 -> 11.035848 | D43: =+D35/D41 -> 12.813659 | E43: =+E35/E41 -> 17.749144 | F43: =+F35/F41 -> 17.299355 | G43: =+G35/G41 -> 19.879164 | H43: =+H35/H41 -> 20.179532 | I43: =+I35/I41 -> 19.492908 | J43: =+J35/J41 -> 22.101356 | ... R43: =+R35/R41 -> 42.072906
B45: P/BV | C45: =+C39/PROJ!AM67 -> 2.4011842 | D45: =+D39/PROJ!AN67 -> 2.1829842 | E45: =+E39/PROJ!AO67 -> 2.1111926 | F45: =+F39/PROJ!AP67 -> 1.8828991 | G45: =+G39/PROJ!AQ67 -> 1.6441088 | H45: =+H39/PROJ!AR67 -> 1.4189215 | I45: =+I39/PROJ!AS67 -> 1.2698854 | J45: =+J39/PROJ!AT67 -> 1.1267525 | ... R45: =+R39/PROJ!BB67 -> 0.48247619
B46: P/E | C46: =+C39/C35 -> 14.722928 | D46: =+D39/D35 -> 12.680218 | E46: =+E39/E35 -> 9.1542441 | F46: =+F39/F35 -> 9.3922576 | G46: =+G39/G35 -> 8.1733821 | H46: =+H39/H35 -> 8.0517231 | I46: =+I39/I35 -> 8.335339 | J46: =+J39/J35 -> 7.3515851 | ... R46: =+R39/R35 -> 3.8618678
B48: ROE | C48: =+PROJ!AM75 -> 0.16937135 | D48: =+PROJ!AN75 -> 0.17947103 | E48: =+PROJ!AO75 -> 0.24941348 | F48: =+PROJ!AP75 -> 0.20827903 | G48: =+PROJ!AQ75 -> 0.2094256 | H48: =+PROJ!AR75 -> 0.18682321 | I48: =+PROJ!AS75 -> 0.15935678 | J48: =+PROJ!AT75 -> 0.1532666 | ... R48: =+PROJ!BB75 -> 0.12493338
B50: div yield | G50: =+PROJ!AQ72/RESUMO!G39 -> 0.023387496 | H50: =+PROJ!AR72/RESUMO!H39 -> 0.030587093 | I50: =+PROJ!AS72/RESUMO!I39 -> 0.037259105 | J50: =+PROJ!AT72/RESUMO!J39 -> 0.035991338 | K50: =+PROJ!AU72/RESUMO!K39 -> 0.040807526 | L50: =+PROJ!AV72/RESUMO!L39 -> 0.045690517 | M50: =+PROJ!AW72/RESUMO!M39 -> 0.04987724 | N50: =+PROJ!AX72/RESUMO!N39 -> 0.054470668 | ... R50: =+PROJ!BB72/RESUMO!R39 -> 0.072779461

Sheet FAT
A1: IPC | B1: =+PROJ!B1 -> 0.004426325 | C1: =+PROJ!C1 -> -0.0017105416 | D1: =+PROJ!D1 -> 0.0062246488 | E1: =+PROJ!E1 -> 0.019164534 | F1: =+PROJ!F1 -> 0.0085336153 | G1: =+PROJ!G1 -> -0.00088919673 | H1: =+PROJ!H1 -> 0.012843934 | I1: =+PROJ!I1 -> 0.010701667 | ... AG1: =+PROJ!AG1 -> 0.013734568 | AI1: 0.013734568 | AL1: =+PROJ!AL1 -> 0.02828577 | AM1: =+PROJ!AM1 -> 0.031500746 | AN1: =+PROJ!AN1 -> 0.073551079 | AO1: =+PROJ!AO1 -> 0.078170287 | AP1: =+PROJ!AP1 -> 0.046608896 | AQ1: =+PROJ!AQ1 -> 0.042123394 | AR1: =+PROJ!AR1 -> 0.035 | AS1: =+PROJ!AS1 -> 0.035 | ... BA1: =+PROJ!BA1 -> 0.035 | BB1: =+BA1 -> 0.035
A2: MX POLICY RATE | B2: =+PROJ!B2 -> 0.08515 | C2: =+PROJ!C2 -> 0.084887 | D2: =+PROJ!D2 -> 0.080275 | E2: =+PROJ!E2 -> #VALUE! | F2: =+PROJ!F2 -> #VALUE! | G2: =+PROJ!G2 -> 0.052843 | H2: =+PROJ!H2 -> 0.0475 | I2: =+PROJ!I2 -> 0.0425 | ... AG2: =+PROJ!AG2 -> 0.068 | AI2: 0.075 | AL2: =+PROJ!AL2 -> #VALUE! | AM2: =+PROJ!AM2 -> 0.0425 | AN2: =+PROJ!AN2 -> 0.0571 | AO2: =+PROJ!AO2 -> 0.105 | AP2: =+PROJ!AP2 -> 0.115025 | AQ2: =+PROJ!AQ2 -> 0.10245 | AR2: =+PROJ!AR2 -> 0.075 | AS2: =+PROJ!AS2 -> 0.068 | ... BA2: =+PROJ!BA2 -> 0.068 | BB2: =+BA2 -> 0.068
AL3: 43830 | AM3: =+EOMONTH(AL3,12) -> 44196 | AN3: =+EOMONTH(AM3,12) -> 44561 | AO3: =+EOMONTH(AN3,12) -> 44926 | AP3: =+EOMONTH(AO3,12) -> 45291 | AQ3: =+EOMONTH(AP3,12) -> 45657 | AR3: =+EOMONTH(AQ3,12) -> 46022 | AS3: =+EOMONTH(AR3,12) -> 46387
A4: REGIONAL (mln mex) | B4: 43555 | C4: =+EOMONTH(B4,3) -> 43646 | D4: =+EOMONTH(C4,3) -> 43738 | E4: =+EOMONTH(D4,3) -> 43830 | F4: =+EOMONTH(E4,3) -> 43921 | G4: =+EOMONTH(F4,3) -> 44012 | H4: =+EOMONTH(G4,3) -> 44104 | I4: =+EOMONTH(H4,3) -> 44196 | J4: =+EOMONTH(I4,3) -> 44286 | ... AG4: =+EOMONTH(AF4,3) -> 46387 | AI4: 46022 | AL4: 2019 | AM4: =+AL4+1 -> 2020 | AN4: =+AM4+1 -> 2021 | AO4: =+AN4+1 -> 2022 | AP4: =+AO4+1 -> 2023 | AQ4: =+AP4+1 -> 2024 | AR4: =+AQ4+1 -> 2025 | AS4: =+AR4+1 -> 2026 | AT4: =+AS4+1 -> 2027 | ... BB4: =+BA4+1 -> 2035
A5: NET LOAN PORTFOLIO | B5: =+B7+B12+B13+B14 -> 100362 | C5: =+C7+C12+C13+C14 -> 104484 | D5: =+D7+D12+D13+D14 -> 105991 | E5: =+E7+E12+E13+E14 -> 105777 | F5: =+F7+F12+F13+F14 -> 111108 | G5: =+G7+G12+G13+G14 -> 109380 | H5: =+H7+H12+H13+H14 -> 109040 | I5: =+I7+I12+I13+I14 -> 107985 | ... AH5: =+AH7+AH12+AH13+AH14 -> 0 | AI5: 189518.56 | AJ5: =+AB5/AI5-1 -> -0.024797364 | AL5: =+AL7+AL12+AL13+AL14 -> 105777 | AM5: =+AM7+AM12+AM13+AM14 -> 107985 | AN5: =+AN7+AN12+AN13+AN14 -> 115218 | AO5: =+AO7+AO12+AO13+AO14 -> 134094 | AP5: =+AP7+AP12+AP13+AP14 -> 152171 | AQ5: =+AQ7+AQ12+AQ13+AQ14 -> 174115 | AR5: =+AR7+AR12+AR13+AR14 -> 187878 | AS5: =+AS7+AS12+AS13+AS14 -> 202742.41 | ... BB5: =+BB7+BB12+BB13+BB14 -> 348403.06
A7: Total Gross Loans | B7: =+B9+B10 -> 102244 | C7: =+C9+C10 -> 106344 | D7: =+D9+D10 -> 107965 | E7: =+E9+E10 -> 107933 | F7: =+F9+F10 -> 113373 | G7: =+G9+G10 -> 111569 | H7: =+H9+H10 -> 111149 | I7: =+I9+I10 -> 110416 | ... AG7: =+AG9+AG10 -> 206164.96 | AI7: 192858.96 | AJ7: =+AB7/AI7-1 -> -0.024675836 | AL7: =+AL9+AL10 -> 107933 | AM7: =+AM9+AM10 -> 110416 | AN7: =+AN9+AN10 -> 117952 | AO7: =+AO9+AO10 -> 136876 | AP7: =+AP9+AP10 -> 155301 | AQ7: =+AQ9+AQ10 -> 177176 | AR7: =+AR9+AR10 -> 190842 | AS7: =+AS9+AS10 -> 206164.96 | ... BB7: =+BB9+BB10 -> 350896.08
A8: yoy | F8: =+F7/B7-1 -> 0.10884746 | G8: =+G7/C7-1 -> 0.049133002 | H8: =+H7/D7-1 -> 0.029491039 | I8: =+I7/E7-1 -> 0.023005012 | J8: =+J7/F7-1 -> -0.0051334974 | K8: =+K7/G7-1 -> 0.025992883 | L8: =+L7/H7-1 -> 0.037031372 | M8: =+M7/I7-1 -> 0.068250978 | ... AG8: =+AG7/AC7-1 -> 0.080291332 | AI8: 0.088516255 | AM8: =+AM7/AL7-1 -> 0.023005012 | AN8: =+AN7/AM7-1 -> 0.068250978 | AO8: =+AO7/AN7-1 -> 0.16043814 | AP8: =+AP7/AO7-1 -> 0.13461089 | AQ8: =+AQ7/AP7-1 -> 0.1408555 | AR8: =+AR7/AQ7-1 -> 0.077132343 | AS8: =+AS7/AR7-1 -> 0.080291332 | AT8: =+AT7/AS7-1 -> 0.096417803 | ... BB8: =+BB7/BA7-1 -> 0.05035676
A9: STAGE 1 & 2 | B9: =+B19+B28 -> 100438 | C9: =+C19+C28 -> 104573 | D9: =+D19+D28 -> 106243 | E9: =+E19+E28 -> 106015 | F9: =+F19+F28 -> 111306 | G9: =+G19+G28 -> 109850 | H9: =+H19+H28 -> 109787 | I9: =+I19+I28 -> 108864 | ... AG9: =+AG19+AG28 -> 203501.18 | AI9: 189560.97 | AL9: =+SUMIFS($B9:AF9,$B$4:AF$4,"="&AL$3) -> 106015 | AM9: =+SUMIFS($B9:AG9,$B$4:AG$4,"="&AM$3) -> 108864 | AN9: =+SUMIFS($B9:AG9,$B$4:AG$4,"="&AN$3) -> 115817 | AO9: =+SUMIFS($B9:AG9,$B$4:AG$4,"="&AO$3) -> 135100 | AP9: =+SUMIFS($B9:AG9,$B$4:AG$4,"="&AP$3) -> 153248 | AQ9: =+SUMIFS($B9:AG9,$B$4:AG$4,"="&AQ$3) -> 174951 | AR9: =+SUMIFS($B9:AG9,$B$4:AG$4,"="&AR$3) -> 188396 | AS9: =+SUMIFS($B9:$AG9,$B$4:$AG$4,"="&AS$3) -> 203501.18 | AT9: =+AT19+AT28 -> 222959.31 | AU9: =+AU19+AU28 -> 236823.55 | AV9: =+AV19+AV28 -> 251586.53 | AW9: =+AW19+AW28 -> 267308.86 | AX9: =+AX19+AX28 -> 284055.45 | AY9: =+AY19+AY28 -> 298047.8 | AZ9: =+AZ19+AZ28 -> 312804.44 | BA9: =+BA19+BA28 -> 328373.24 | BB9: =+BB19+BB28 -> 344805.56
A10: STAGE 3 | B10: =+B42+B45 -> 1806 | C10: =+C42+C45 -> 1771 | D10: =+D42+D45 -> 1722 | E10: =+E42+E45 -> 1918 | F10: =+F42+F45 -> 2067 | G10: =+G42+G45 -> 1719 | H10: =+H42+H45 -> 1362 | I10: =+I42+I45 -> 1552 | ... AB10: =+AB42+AB45 -> 3064 | AC10: =+AC56 -> 2446 | AD10: =+AD56 -> 2498.1249 | AE10: =+AE56 -> 2579.6557 | AF10: =+AF56 -> 2622.3429 | AG10: =+AG56 -> 2663.7783 | AI10: 3297.986 | AL10: =+SUMIFS($B10:AF10,$B$4:AF$4,"="&AL$3) -> 1918 | AM10: =+SUMIFS($B10:AG10,$B$4:AG$4,"="&AM$3) -> 1552 | AN10: =+SUMIFS($B10:AG10,$B$4:AG$4,"="&AN$3) -> 2135 | AO10: =+SUMIFS($B10:AG10,$B$4:AG$4,"="&AO$3) -> 1776 | AP10: =+SUMIFS($B10:AG10,$B$4:AG$4,"="&AP$3) -> 2053 | AQ10: =+SUMIFS($B10:AG10,$B$4:AG$4,"="&AQ$3) -> 2225 | AR10: =+SUMIFS($B10:AG10,$B$4:AG$4,"="&AR$3) -> 2446 | AS10: =+SUMIFS($B10:$AG10,$B$4:$AG$4,"="&AS$3) -> 2663.7783 | AT10: =+AT56 -> 3083.6166 | AU10: =+AU56 -> 3439.5962 | AV10: =+AV56 -> 3700.1881 | AW10: =+AW56 -> 4127.4541 | AX10: =+AX56 -> 4549.1772 | AY10: =+AY56 -> 4942.4458 | AZ10: =+AZ56 -> 5306.8873 | BA10: =+BA56 -> 5699.9949 | BB10: =+BB56 -> 6090.5186
A12: Allowances | B12: =-B69 -> -2187 | C12: =-C69 -> -2319 | D12: =-D69 -> -2231 | E12: =-E69 -> -2342 | F12: =-F69 -> -2447 | G12: =-G69 -> -2369 | H12: =-H69 -> -2307 | I12: =-I69 -> -2626 | ... AG12: =-AG69 -> -4189.545 | AI12: -4049.3953 | AJ12: =+AB12/AI12-1 -> -0.014667707 | AL12: =+SUMIFS($B12:AF12,$B$4:AF$4,"="&AL$3) -> -2342 | AM12: =+SUMIFS($B12:AG12,$B$4:AG$4,"="&AM$3) -> -2626 | AN12: =+SUMIFS($B12:AG12,$B$4:AG$4,"="&AN$3) -> -2827 | AO12: =+SUMIFS($B12:AG12,$B$4:AG$4,"="&AO$3) -> -3055 | AP12: =+SUMIFS($B12:AG12,$B$4:AG$4,"="&AP$3) -> -3426 | AQ12: =+SUMIFS($B12:AG12,$B$4:AG$4,"="&AQ$3) -> -3653 | AR12: =+SUMIFS($B12:AG12,$B$4:AG$4,"="&AR$3) -> -3731 | AS12: =+SUMIFS($B12:$AG12,$B$4:$AG$4,"="&AS$3) -> -4189.545 | AT12: =-AT69 -> -4435.9287 | AU12: =-AU69 -> -4541.193 | AV12: =-AV69 -> -4543.139 | AW12: =-AW69 -> -4591.5907 | AX12: =-AX69 -> -4465.6921 | AY12: =-AY69 -> -4213.418 | AZ12: =-AZ69 -> -3844.7111 | BA12: =-BA69 -> -3389.8961 | BB12: =-BB69 -> -2813.0216
A13: Other receivables | B13: 305 | C13: 459 | D13: 257 | E13: 186 | F13: 182 | G13: 180 | H13: 198 | I13: 195 | J13: 188 | K13: 182 | L13: 174 | M13: 93 | N13: 91 | O13: 89 | P13: 53 | Q13: 52 | R13: 51 | S13: 46 | T13: 45 | U13: 44 | V13: 43 | W13: 42 | X13: 41 | Y13: 40 | Z13: 39 | AA13: 38 | AB13: 38 | AC13: 36 | AD13: =+AC13 -> 36 | AE13: =+AD13 -> 36 | AF13: =+AE13 -> 36 | AG13: =+AF13 -> 36 | AI13: 38 | AL13: =+SUMIFS($B13:AF13,$B$4:AF$4,"="&AL$3) -> 186 | AM13: =+SUMIFS($B13:AG13,$B$4:AG$4,"="&AM$3) -> 195 | AN13: =+SUMIFS($B13:AG13,$B$4:AG$4,"="&AN$3) -> 93 | AO13: =+SUMIFS($B13:AG13,$B$4:AG$4,"="&AO$3) -> 52 | AP13: =+SUMIFS($B13:AG13,$B$4:AG$4,"="&AP$3) -> 44 | AQ13: =+SUMIFS($B13:AG13,$B$4:AG$4,"="&AQ$3) -> 40 | AR13: =+SUMIFS($B13:AG13,$B$4:AG$4,"="&AR$3) -> 36 | AS13: =+SUMIFS($B13:$AG13,$B$4:$AG$4,"="&AS$3) -> 36 | AT13: 45 | AU13: 45 | AV13: 45 | AW13: 45 | AX13: 45 | AY13: 45 | AZ13: 45 | BA13: 45 | BB13: 45
A14: Deferred Items | N14: 240 | O14: 229 | P14: 252 | Q14: 221 | R14: 114 | S14: 170 | T14: 238 | U14: 252 | V14: 280 | W14: 313 | X14: 332 | Y14: 552 | Z14: 597 | AA14: 634 | AB14: 671 | AC14: 731 | AD14: =+AC14 -> 731 | AE14: =+AD14 -> 731 | AF14: =+AE14 -> 731 | AG14: =+AF14 -> 731 | AI14: 671 | AL14: =+SUMIFS($B14:AF14,$B$4:AF$4,"="&AL$3) -> 0 | AM14: =+SUMIFS($B14:AG14,$B$4:AG$4,"="&AM$3) -> 0 | AN14: =+SUMIFS($B14:AG14,$B$4:AG$4,"="&AN$3) -> 0 | AO14: =+SUMIFS($B14:AG14,$B$4:AG$4,"="&AO$3) -> 221 | AP14: =+SUMIFS($B14:AG14,$B$4:AG$4,"="&AP$3) -> 252 | AQ14: =+SUMIFS($B14:AG14,$B$4:AG$4,"="&AQ$3) -> 552 | AR14: =+SUMIFS($B14:AG14,$B$4:AG$4,"="&AR$3) -> 731 | AS14: =+SUMIFS($B14:$AG14,$B$4:$AG$4,"="&AS$3) -> 731 | AT14: 275 | AU14: 275 | AV14: 275 | AW14: 275 | AX14: 275 | AY14: 275 | AZ14: 275 | BA14: 275 | BB14: 275
AQ15: =+AQ5/AP5-1 -> 0.14420619 | AR15: =+AR5/AQ5-1 -> 0.079045458 | AS15: =+AS5/AR5-1 -> 0.079117371
A16: LOAN BREAKDOWN STAGE 1&2
A17: MORTGAGE | B17: 10648 | C17: 10920 | D17: 10998 | E17: 11144 | F17: 11061 | G17: 11046 | H17: 11272 | I17: 11218 | J17: 11186 | K17: 11319 | L17: 11382 | M17: 11513 | N17: 11647 | O17: 11814 | P17: 12255 | Q17: 12778 | R17: 13139 | S17: 13678 | T17: 14056 | U17: 14526 | V17: =14270+516 -> 14786 | W17: =14842+517 -> 15359 | X17: =488+15236 -> 15724 | Y17: =15585+533 -> 16118 | Z17: =15844+543 -> 16387 | AA17: =16086+589 -> 16675 | AB17: =16515+566 -> 17081 | AC17: =16802+532 -> 17334 | AD17: =+Z17*(1+AD21) -> 17697.96 | AE17: =+AA17*(1+AE21) -> 18009 | AF17: =+AB17*(1+AF21) -> 18447.48 | AG17: =+AC17*(1+AG21) -> 18720.72 | AI17: 17407.44 | AL17: =+SUMIFS($B17:AF17,$B$4:AF$4,"="&AL$3) -> 11144 | AM17: =+SUMIFS($B17:AG17,$B$4:AG$4,"="&AM$3) -> 11218 | AN17: =+SUMIFS($B17:AG17,$B$4:AG$4,"="&AN$3) -> 11513 | AO17: =+SUMIFS($B17:AG17,$B$4:AG$4,"="&AO$3) -> 12778 | AP17: =+SUMIFS($B17:AG17,$B$4:AG$4,"="&AP$3) -> 14526 | AQ17: =+SUMIFS($B17:AG17,$B$4:AG$4,"="&AQ$3) -> 16118 | AR17: =+SUMIFS($B17:AG17,$B$4:AG$4,"="&AR$3) -> 17334 | AS17: =+SUMIFS($B17:$AG17,$B$4:$AG$4,"="&AS$3) -> 18720.72 | AT17: =+AS17*(1+AT21) -> 20218.378 | AU17: =+AT17*(1+AU21) -> 21431.48 | AV17: =+AU17*(1+AV21) -> 22717.369 | AW17: =+AV17*(1+AW21) -> 24080.411 | AX17: =+AW17*(1+AX21) -> 25525.236 | AY17: =+AX17*(1+AY21) -> 26673.872 | AZ17: =+AY17*(1+AZ21) -> 27874.196 | BA17: =+AZ17*(1+BA21) -> 29128.535 | BB17: =+BA17*(1+BB21) -> 30439.319
A18: CONSUMER | B18: 3785 | C18: 4148 | D18: 4415 | E18: 4609 | F18: 4757 | G18: 4668 | H18: 5001 | I18: 5229 | J18: 5353 | K18: 5637 | L18: 5978 | M18: 6412 | N18: 6861 | O18: 7423 | P18: 8101 | Q18: 9472 | R18: 10147 | S18: 11076 | T18: 11500 | U18: 11801 | V18: =11355+328 -> 11683 | W18: =338+11478 -> 11816 | X18: =316+11699 -> 12015 | Y18: =12069+314 -> 12383 | Z18: =12129+331 -> 12460 | AA18: =12599+326 -> 12925 | AB18: =12935+341 -> 13276 | AC18: =13475+344 -> 13819 | AD18: =+Z18*(1+AD22) -> 13332.2 | AE18: =+AA18*(1+AE22) -> 13959 | AF18: =+AB18*(1+AF22) -> 14603.6 | AG18: =+AC18*(1+AG22) -> 15200.9 | AI18: 13373.64 | AL18: =+SUMIFS($B18:AF18,$B$4:AF$4,"="&AL$3) -> 4609 | AM18: =+SUMIFS($B18:AG18,$B$4:AG$4,"="&AM$3) -> 5229 | AN18: =+SUMIFS($B18:AG18,$B$4:AG$4,"="&AN$3) -> 6412 | AO18: =+SUMIFS($B18:AG18,$B$4:AG$4,"="&AO$3) -> 9472 | AP18: =+SUMIFS($B18:AG18,$B$4:AG$4,"="&AP$3) -> 11801 | AQ18: =+SUMIFS($B18:AG18,$B$4:AG$4,"="&AQ$3) -> 12383 | AR18: =+SUMIFS($B18:AG18,$B$4:AG$4,"="&AR$3) -> 13819 | AS18: =+SUMIFS($B18:$AG18,$B$4:$AG$4,"="&AS$3) -> 15200.9 | AT18: =+AS18*(1+AT22) -> 16720.99 | AU18: =+AT18*(1+AU22) -> 18393.089 | AV18: =+AU18*(1+AV22) -> 20232.398 | AW18: =+AV18*(1+AW22) -> 22255.638 | AX18: =+AW18*(1+AX22) -> 24481.201 | AY18: =+AX18*(1+AY22) -> 26929.322 | AZ18: =+AY18*(1+AZ22) -> 29622.254 | BA18: =+AZ18*(1+BA22) -> 32584.479 | BB18: =+BA18*(1+BB22) -> 35842.927
A19: TOTAL INDIVUDUALS | B19: =+B17+B18 -> 14433 | C19: =+C17+C18 -> 15068 | D19: =+D17+D18 -> 15413 | E19: =+E17+E18 -> 15753 | F19: =+F17+F18 -> 15818 | G19: =+G17+G18 -> 15714 | H19: =+H17+H18 -> 16273 | I19: =+I17+I18 -> 16447 | ... AG19: =+AG17+AG18 -> 33921.62 | AI19: 30781.08 | AL19: =+SUMIFS($B19:AF19,$B$4:AF$4,"="&AL$3) -> 15753 | AM19: =+SUMIFS($B19:AG19,$B$4:AG$4,"="&AM$3) -> 16447 | AN19: =+SUMIFS($B19:AG19,$B$4:AG$4,"="&AN$3) -> 17925 | AO19: =+SUMIFS($B19:AG19,$B$4:AG$4,"="&AO$3) -> 22250 | AP19: =+SUMIFS($B19:AG19,$B$4:AG$4,"="&AP$3) -> 26327 | AQ19: =+SUMIFS($B19:AG19,$B$4:AG$4,"="&AQ$3) -> 28501 | AR19: =+SUMIFS($B19:AG19,$B$4:AG$4,"="&AR$3) -> 31153 | AS19: =+SUMIFS($B19:$AG19,$B$4:$AG$4,"="&AS$3) -> 33921.62 | AT19: =+AT17+AT18 -> 36939.368 | AU19: =+AU17+AU18 -> 39824.569 | AV19: =+AV17+AV18 -> 42949.767 | AW19: =+AW17+AW18 -> 46336.049 | AX19: =+AX17+AX18 -> 50006.437 | AY19: =+AY17+AY18 -> 53603.193 | AZ19: =+AZ17+AZ18 -> 57496.449 | BA19: =+BA17+BA18 -> 61713.014 | BB19: =+BB17+BB18 -> 66282.246
A21: MORTGAGE | F21: =+F17/B17-1 -> 0.038786627 | G21: =+G17/C17-1 -> 0.011538462 | H21: =+H17/D17-1 -> 0.024913621 | I21: =+I17/E17-1 -> 0.0066403446 | J21: =+J17/F17-1 -> 0.011300967 | K21: =+K17/G17-1 -> 0.024714829 | L21: =+L17/H17-1 -> 0.0097586941 | M21: =+M17/I17-1 -> 0.026297023 | ... AC21: =+AC17/Y17-1 -> 0.075443603 | AD21: 0.08 | AE21: =+AD21 -> 0.08 | AF21: =+AE21 -> 0.08 | AG21: =+AF21 -> 0.08 | AI21: 0.08 | AM21: =+AM17/AL17-1 -> 0.0066403446 | AN21: =+AN17/AM17-1 -> 0.026297023 | AO21: =+AO17/AN17-1 -> 0.10987579 | AP21: =+AP17/AO17-1 -> 0.13679762 | AQ21: =+AQ17/AP17-1 -> 0.10959659 | AR21: =+AR17/AQ17-1 -> 0.075443603 | AS21: =+AS17/AR17-1 -> 0.08 | AT21: 0.08 | AU21: 0.06 | AV21: =+AU21 -> 0.06 | AW21: =+AV21 -> 0.06 | AX21: =+AW21 -> 0.06 | AY21: 0.045 | AZ21: =+AY21 -> 0.045 | BA21: =+AZ21 -> 0.045 | BB21: =+BA21 -> 0.045
A22: CONSUMER | F22: =+F18/B18-1 -> 0.25680317 | G22: =+G18/C18-1 -> 0.12536162 | H22: =+H18/D18-1 -> 0.13272933 | I22: =+I18/E18-1 -> 0.13451942 | J22: =+J18/F18-1 -> 0.12528905 | K22: =+K18/G18-1 -> 0.20758355 | L22: =+L18/H18-1 -> 0.19536093 | M22: =+M18/I18-1 -> 0.22623829 | ... AC22: =+AC18/Y18-1 -> 0.11596544 | AD22: 0.07 | AE22: 0.08 | AF22: 0.1 | AG22: 0.1 | AI22: 0.08 | AM22: =+AM18/AL18-1 -> 0.13451942 | AN22: =+AN18/AM18-1 -> 0.22623829 | AO22: =+AO18/AN18-1 -> 0.47723019 | AP22: =+AP18/AO18-1 -> 0.2458826 | AQ22: =+AQ18/AP18-1 -> 0.049317854 | AR22: =+AR18/AQ18-1 -> 0.11596544 | AS22: =+AS18/AR18-1 -> 0.1 | AT22: =+AS22 -> 0.1 | AU22: =+AT22 -> 0.1 | AV22: =+AU22 -> 0.1 | AW22: =+AV22 -> 0.1 | AX22: =+AW22 -> 0.1 | AY22: =+AX22 -> 0.1 | AZ22: =+AY22 -> 0.1 | BA22: =+AZ22 -> 0.1 | BB22: =+BA22 -> 0.1
A23: TOTAL INDIVUDUALS | F23: =+F19/B19-1 -> 0.095960646 | G23: =+G19/C19-1 -> 0.042872312 | H23: =+H19/D19-1 -> 0.055797054 | I23: =+I19/E19-1 -> 0.044055101 | J23: =+J19/F19-1 -> 0.045580984 | K23: =+K19/G19-1 -> 0.079037801 | L23: =+L19/H19-1 -> 0.066797763 | M23: =+M19/I19-1 -> 0.089864413 | ... AG23: =+AG19/AC19-1 -> 0.088871698 | AI23: 0.08 | AM23: =+AM19/AL19-1 -> 0.044055101 | AN23: =+AN19/AM19-1 -> 0.089864413 | AO23: =+AO19/AN19-1 -> 0.24128312 | AP23: =+AP19/AO19-1 -> 0.18323596 | AQ23: =+AQ19/AP19-1 -> 0.082576822 | AR23: =+AR19/AQ19-1 -> 0.093049367 | AS23: =+AS19/AR19-1 -> 0.088871698 | AT23: =+AT19/AS19-1 -> 0.088962367 | ... BB23: =+BB19/BA19-1 -> 0.074040007
A25: BUSINESS LOANS | B25: 83810 | C25: 87155 | D25: 89002 | E25: 89415 | F25: 94760 | G25: 93438 | H25: 92866 | I25: 91665 | J25: 93575 | K25: 92751 | L25: 93179 | M25: 96398 | N25: 98858 | O25: 100619 | P25: 101940 | Q25: 111004 | R25: 115885 | S25: 117884 | T25: 121957 | U25: 123970 | V25: =126661+1956 -> 128617 | W25: =2014+130405 -> 132419 | X25: =1983+134954 -> 136937 | Y25: =139487+2339 -> 141826 | Z25: =141603+2134 -> 143737 | AA25: =143596+2002 -> 145598 | AB25: =146603+2446 -> 149049 | AC25: =146415+2839 -> 149254 | AD25: =+Z25*(1+AD30) -> 150923.85 | AE25: =+AA25*(1+AE30) -> 152877.9 | AF25: =+AB25*(1+AF30) -> 160972.92 | AG25: =+AC25*(1+AG30) -> 161194.32 | AI25: 153172.08 | AL25: =+SUMIFS($B25:AF25,$B$4:AF$4,"="&AL$3) -> 89415 | AM25: =+SUMIFS($B25:AG25,$B$4:AG$4,"="&AM$3) -> 91665 | AN25: =+SUMIFS($B25:AG25,$B$4:AG$4,"="&AN$3) -> 96398 | AO25: =+SUMIFS($B25:AG25,$B$4:AG$4,"="&AO$3) -> 111004 | AP25: =+SUMIFS($B25:AG25,$B$4:AG$4,"="&AP$3) -> 123970 | AQ25: =+SUMIFS($B25:AG25,$B$4:AG$4,"="&AQ$3) -> 141826 | AR25: =+SUMIFS($B25:AG25,$B$4:AG$4,"="&AR$3) -> 149254 | AS25: =+SUMIFS($B25:$AG25,$B$4:$AG$4,"="&AS$3) -> 161194.32 | AT25: =+AS25*(1+AT30) -> 177313.75 | AU25: =+AT25*(1+AU30) -> 187952.58 | AV25: =+AU25*(1+AV30) -> 199229.73 | AW25: =+AV25*(1+AW30) -> 211183.52 | AX25: =+AW25*(1+AX30) -> 223854.53 | AY25: =+AX25*(1+AY30) -> 233927.98 | AZ25: =+AY25*(1+AZ30) -> 244454.74 | BA25: =+AZ25*(1+BA30) -> 255455.2 | BB25: =+BA25*(1+BB30) -> 266950.69
A26: FINANCIAL ENTITIES | B26: 2137 | C26: 2342 | D26: 1821 | E26: 760 | F26: 711 | G26: 681 | H26: 633 | I26: 689 | J26: 684 | K26: 2926 | L26: 2813 | M26: 1494 | N26: 1990 | O26: 2053 | P26: 2056 | Q26: 1846 | R26: 2271 | S26: 2208 | T26: 2133 | U26: 2673 | V26: =3263+3 -> 3266 | W26: 4307 | X26: 4244 | Y26: 4447 | Z26: 5756 | AA26: 5581 | AB26: 5492 | AC26: 4953 | AD26: =+Z26*(1+AD31) -> 6216.48 | AE26: =+AA26*(1+AE31) -> 6027.48 | AF26: =+AB26*(1+AF31) -> 5931.36 | AG26: =+AC26*(1+AG31) -> 5349.24 | AI26: 5469.81 | AL26: =+SUMIFS($B26:AF26,$B$4:AF$4,"="&AL$3) -> 760 | AM26: =+SUMIFS($B26:AG26,$B$4:AG$4,"="&AM$3) -> 689 | AN26: =+SUMIFS($B26:AG26,$B$4:AG$4,"="&AN$3) -> 1494 | AO26: =+SUMIFS($B26:AG26,$B$4:AG$4,"="&AO$3) -> 1846 | AP26: =+SUMIFS($B26:AG26,$B$4:AG$4,"="&AP$3) -> 2673 | AQ26: =+SUMIFS($B26:AG26,$B$4:AG$4,"="&AQ$3) -> 4447 | AR26: =+SUMIFS($B26:AG26,$B$4:AG$4,"="&AR$3) -> 4953 | AS26: =+SUMIFS($B26:$AG26,$B$4:$AG$4,"="&AS$3) -> 5349.24 | AT26: =+AS26*(1+AT31) -> 5670.1944 | AU26: =+AT26*(1+AU31) -> 6010.4061 | AV26: =+AU26*(1+AV31) -> 6371.0304 | AW26: =+AV26*(1+AW31) -> 6753.2923 | AX26: =+AW26*(1+AX31) -> 7158.4898 | AY26: =+AX26*(1+AY31) -> 7480.6218 | AZ26: =+AY26*(1+AZ31) -> 7817.2498 | BA26: =+AZ26*(1+BA31) -> 8169.0261 | BB26: =+BA26*(1+BB31) -> 8536.6322
A27: GOVERNMENT ENTITIES | B27: 58 | C27: 8 | D27: 7 | E27: 87 | F27: 17 | G27: 17 | H27: 15 | I27: 63 | J27: 49 | K27: 0 | L27: 0 | M27: 0 | N27: 0 | O27: 0 | P27: 0 | Q27: 0 | R27: 90 | S27: 71 | T27: 103 | U27: 278 | V27: 257 | W27: =49+177 -> 226 | X27: 196 | Y27: 177 | Z27: 166 | AA27: 153 | AB27: 138 | AC27: 3036 | AD27: =+AC27 -> 3036 | AE27: =+AD27 -> 3036 | AF27: =+AE27 -> 3036 | AG27: =+AF27 -> 3036 | AI27: 138 | AL27: =+SUMIFS($B27:AF27,$B$4:AF$4,"="&AL$3) -> 87 | AM27: =+SUMIFS($B27:AG27,$B$4:AG$4,"="&AM$3) -> 63 | AN27: =+SUMIFS($B27:AG27,$B$4:AG$4,"="&AN$3) -> 0 | AO27: =+SUMIFS($B27:AG27,$B$4:AG$4,"="&AO$3) -> 0 | AP27: =+SUMIFS($B27:AG27,$B$4:AG$4,"="&AP$3) -> 278 | AQ27: =+SUMIFS($B27:AG27,$B$4:AG$4,"="&AQ$3) -> 177 | AR27: =+SUMIFS($B27:AG27,$B$4:AG$4,"="&AR$3) -> 3036 | AS27: =+SUMIFS($B27:$AG27,$B$4:$AG$4,"="&AS$3) -> 3036 | AT27: =+AS27 -> 3036 | AU27: =+AT27 -> 3036 | AV27: =+AU27 -> 3036 | AW27: =+AV27 -> 3036 | AX27: =+AW27 -> 3036 | AY27: =+AX27 -> 3036 | AZ27: =+AY27 -> 3036 | BA27: =+AZ27 -> 3036 | BB27: =+BA27 -> 3036
A28: TOTAL COMMERCIAL | B28: =+SUM(B25:B27) -> 86005 | C28: =+SUM(C25:C27) -> 89505 | D28: =+SUM(D25:D27) -> 90830 | E28: =+SUM(E25:E27) -> 90262 | F28: =+SUM(F25:F27) -> 95488 | G28: =+SUM(G25:G27) -> 94136 | H28: =+SUM(H25:H27) -> 93514 | I28: =+SUM(I25:I27) -> 92417 | ... AG28: =+SUM(AG25:AG27) -> 169579.56 | AI28: 158779.89 | AL28: =+SUMIFS($B28:AF28,$B$4:AF$4,"="&AL$3) -> 90262 | AM28: =+SUMIFS($B28:AG28,$B$4:AG$4,"="&AM$3) -> 92417 | AN28: =+SUMIFS($B28:AG28,$B$4:AG$4,"="&AN$3) -> 97892 | AO28: =+SUMIFS($B28:AG28,$B$4:AG$4,"="&AO$3) -> 112850 | AP28: =+SUMIFS($B28:AG28,$B$4:AG$4,"="&AP$3) -> 126921 | AQ28: =+SUMIFS($B28:AG28,$B$4:AG$4,"="&AQ$3) -> 146450 | AR28: =+SUMIFS($B28:AG28,$B$4:AG$4,"="&AR$3) -> 157243 | AS28: =+SUMIFS($B28:$AG28,$B$4:$AG$4,"="&AS$3) -> 169579.56 | AT28: =+SUM(AT25:AT27) -> 186019.95 | AU28: =+SUM(AU25:AU27) -> 196998.98 | AV28: =+SUM(AV25:AV27) -> 208636.76 | AW28: =+SUM(AW25:AW27) -> 220972.81 | AX28: =+SUM(AX25:AX27) -> 234049.02 | AY28: =+SUM(AY25:AY27) -> 244444.6 | AZ28: =+SUM(AZ25:AZ27) -> 255307.99 | BA28: =+SUM(BA25:BA27) -> 266660.23 | BB28: =+SUM(BB25:BB27) -> 278523.32
A30: BUSINESS LOANS | I30: =+I25/E25-1 -> 0.025163563 | J30: =+J25/F25-1 -> -0.012505276 | K30: =+K25/G25-1 -> -0.007352469 | L30: =+L25/H25-1 -> 0.0033704477 | M30: =+M25/I25-1 -> 0.051633666 | N30: =+N25/J25-1 -> 0.056457387 | O30: =+O25/K25-1 -> 0.084829274 | P30: =+P25/L25-1 -> 0.094023331 | ... AC30: =+AC25/Y25-1 -> 0.052374036 | AD30: 0.05 | AE30: 0.05 | AF30: 0.08 | AG30: 0.08 | AI30: 0.08 | AM30: =+AM25/AL25-1 -> 0.025163563 | AN30: =+AN25/AM25-1 -> 0.051633666 | AO30: =+AO25/AN25-1 -> 0.15151767 | AP30: =+AP25/AO25-1 -> 0.1168066 | AQ30: =+AQ25/AP25-1 -> 0.14403485 | AR30: =+AR25/AQ25-1 -> 0.052374036 | AS30: =+AS25/AR25-1 -> 0.08 | AT30: 0.1 | AU30: 0.06 | AV30: 0.06 | AW30: 0.06 | AX30: 0.06 | AY30: 0.045 | AZ30: =+AY30 -> 0.045 | BA30: =+AZ30 -> 0.045 | BB30: =+BA30 -> 0.045
A31: FINANCIAL ENTITIES | I31: =+I26/E26-1 -> -0.093421053 | J31: =+J26/F26-1 -> -0.037974684 | K31: =+K26/G26-1 -> 3.2966226 | L31: =+L26/H26-1 -> 3.4439179 | M31: =+M26/I26-1 -> 1.1683599 | N31: =+N26/J26-1 -> 1.9093567 | O31: =+O26/K26-1 -> -0.29835954 | P31: =+P26/L26-1 -> -0.26910771 | ... AC31: =+AC26/Y26-1 -> 0.11378457 | AD31: 0.08 | AE31: 0.08 | AF31: 0.08 | AG31: 0.08 | AI31: 0.23 | AM31: =+AM26/AL26-1 -> -0.093421053 | AN31: =+AN26/AM26-1 -> 1.1683599 | AO31: =+AO26/AN26-1 -> 0.2356091 | AP31: =+AP26/AO26-1 -> 0.44799567 | AQ31: =+AQ26/AP26-1 -> 0.66367377 | AR31: =+AR26/AQ26-1 -> 0.11378457 | AS31: =+AS26/AR26-1 -> 0.08 | AT31: 0.06 | AU31: 0.06 | AV31: 0.06 | AW31: 0.06 | AX31: 0.06 | AY31: 0.045 | AZ31: =+AY31 -> 0.045 | BA31: =+AZ31 -> 0.045 | BB31: =+BA31 -> 0.045
A32: GOVERNMENT ENTITIES | V32: =+V27/R27-1 -> 1.8555556 | W32: =+W27/S27-1 -> 2.1830986 | X32: =+X27/T27-1 -> 0.90291262 | Y32: =+Y27/U27-1 -> -0.36330935 | Z32: =+Z27/V27-1 -> -0.3540856 | AA32: =+AA27/W27-1 -> -0.32300885 | AB32: =+AB27/X27-1 -> -0.29591837 | AC32: =+AC27/Y27-1 -> 16.152542 | AM32: =+AM27/AL27-1 -> -0.27586207 | AN32: =+AN27/AM27-1 -> -1 | AO32: =+AO27/AN27-1 -> #DIV/0! | AP32: =+AP27/AO27-1 -> #DIV/0! | AQ32: =+AQ27/AP27-1 -> -0.36330935 | AR32: =+AR27/AQ27-1 -> 16.152542 | AS32: =+AS27/AR27-1 -> 0 | AT32: =+AT27/AS27-1 -> 0 | ... BB32: =+BB27/BA27-1 -> 0
A33: TOTAL COMMERCIAL | I33: =+I28/E28-1 -> 0.023874942 | J33: =+J28/F28-1 -> -0.012357574 | K33: =+K28/G28-1 -> 0.016369933 | L33: =+L28/H28-1 -> 0.026498706 | M33: =+M28/I28-1 -> 0.059242347 | N33: =+N28/J28-1 -> 0.069347245 | O33: =+O28/K28-1 -> 0.07311057 | P33: =+P28/L28-1 -> 0.083381948 | ... AG33: =+AG28/AC28-1 -> 0.078455384 | AI33: 0.084191806 | AM33: =+AM28/AL28-1 -> 0.023874942 | AN33: =+AN28/AM28-1 -> 0.059242347 | AO33: =+AO28/AN28-1 -> 0.15280105 | AP33: =+AP28/AO28-1 -> 0.12468764 | AQ33: =+AQ28/AP28-1 -> 0.15386737 | AR33: =+AR28/AQ28-1 -> 0.073697508 | AS33: =+AS28/AR28-1 -> 0.078455384 | AT33: =+AT28/AS28-1 -> 0.096947925 | ... BB33: =+BB28/BA28-1 -> 0.044487663
A35: TOTAL STAGE 1&2 | I35: =+I28+I19 -> 108864 | J35: =+J28+J19 -> 110847 | K35: =+K28+K19 -> 112633 | L35: =+L28+L19 -> 113352 | M35: =+M28+M19 -> 115817 | N35: =+N28+N19 -> 119356 | O35: =+O28+O19 -> 121909 | P35: =+P28+P19 -> 124352 | ... AG35: =+AG28+AG19 -> 203501.18 | AI35: 189560.97 | AL35: =+SUMIFS($B35:AF35,$B$4:AF$4,"="&AL$3) -> 0 | AM35: =+SUMIFS($B35:AG35,$B$4:AG$4,"="&AM$3) -> 108864 | AN35: =+SUMIFS($B35:AG35,$B$4:AG$4,"="&AN$3) -> 115817 | AO35: =+SUMIFS($B35:AG35,$B$4:AG$4,"="&AO$3) -> 135100 | AP35: =+SUMIFS($B35:AG35,$B$4:AG$4,"="&AP$3) -> 153248 | AQ35: =+SUMIFS($B35:AG35,$B$4:AG$4,"="&AQ$3) -> 174951 | AR35: =+SUMIFS($B35:AG35,$B$4:AG$4,"="&AR$3) -> 188396 | AS35: =+SUMIFS($B35:$AG35,$B$4:$AG$4,"="&AS$3) -> 203501.18 | AT35: =+AT28+AT19 -> 222959.31 | AU35: =+AU28+AU19 -> 236823.55 | AV35: =+AV28+AV19 -> 251586.53 | AW35: =+AW28+AW19 -> 267308.86 | AX35: =+AX28+AX19 -> 284055.45 | AY35: =+AY28+AY19 -> 298047.8 | AZ35: =+AZ28+AZ19 -> 312804.44 | BA35: =+BA28+BA19 -> 328373.24 | BB35: =+BB28+BB19 -> 344805.56
A36: YOY | M36: =+M35/I35-1 -> 0.06386868 | N36: =+N35/J35-1 -> 0.076763467 | O36: =+O35/K35-1 -> 0.08235597 | P36: =+P35/L35-1 -> 0.09704284 | Q36: =+Q35/M35-1 -> 0.16649542 | R36: =+R35/N35-1 -> 0.18579711 | S36: =+S35/O35-1 -> 0.18873094 | T36: =+T35/P35-1 -> 0.20423475 | ... AG36: =+AG35/AC35-1 -> 0.080177817 | AI36: 0.083508925 | AM36: =+AM35/AL35-1 -> #DIV/0! | AN36: =+AN35/AM35-1 -> 0.06386868 | AO36: =+AO35/AN35-1 -> 0.16649542 | AP36: =+AP35/AO35-1 -> 0.13433013 | AQ36: =+AQ35/AP35-1 -> 0.14162012 | AR36: =+AR35/AQ35-1 -> 0.076850089 | AS36: =+AS35/AR35-1 -> 0.080177817 | AT36: =+AT35/AS35-1 -> 0.095616812 | ... BB36: =+BB35/BA35-1 -> 0.050041599
A38: LOAN BREAKDOWN STAGE 3 | B38: =+B42+B45 -> 1806 | C38: =+C42+C45 -> 1771 | D38: =+D42+D45 -> 1722 | E38: =+E42+E45 -> 1918 | F38: =+F42+F45 -> 2067 | G38: =+G42+G45 -> 1719 | H38: =+H42+H45 -> 1362 | I38: =+I42+I45 -> 1552 | ... AC38: =+AC42+AC45 -> 2446 | AD38: =+AD56 -> 2498.1249 | AE38: =+AE56 -> 2579.6557 | AF38: =+AF56 -> 2622.3429 | AG38: =+AG56 -> 2663.7783 | AI38: 3297.986 | AM38: =+SUMIFS($B38:AG38,$B$4:AG$4,"="&AM$3) -> 1552 | AN38: =+SUMIFS($B38:AG38,$B$4:AG$4,"="&AN$3) -> 2135 | AO38: =+SUMIFS($B38:AG38,$B$4:AG$4,"="&AO$3) -> 1776 | AP38: =+SUMIFS($B38:AG38,$B$4:AG$4,"="&AP$3) -> 2053 | AQ38: =+SUMIFS($B38:AG38,$B$4:AG$4,"="&AQ$3) -> 2225 | AR38: =+SUMIFS($B38:AG38,$B$4:AG$4,"="&AR$3) -> 2446 | AS38: =+SUMIFS($B38:$AG38,$B$4:$AG$4,"="&AS$3) -> 2663.7783
A39: % total gross loan | B39: =+B38/AVERAGE(A7:B7) -> 0.017663628 | C39: =+C38/AVERAGE(B7:C7) -> 0.016980843 | D39: =+D38/AVERAGE(C7:D7) -> 0.016070254 | E39: =+E38/AVERAGE(D7:E7) -> 0.01776765 | F39: =+F38/AVERAGE(E7:F7) -> 0.018680018 | G39: =+G38/AVERAGE(F7:G7) -> 0.01528394 | H39: =+H38/AVERAGE(G7:H7) -> 0.012230713 | I39: =+I38/AVERAGE(H7:I7) -> 0.014009433 | ... AG39: =+AG38/AVERAGE(AF7:AG7) -> 0.012937913 | AI39: 0.017314128 | AM39: =+AM38/AVERAGEIFS($B$7:$AG$7,$B$4:$AG$4,">"&AL$3,$B$4:$AG$4,"<="&AM$3) -> 0.013903477 | AN39: =+AN38/AVERAGEIFS($B$7:$AG$7,$B$4:$AG$4,">"&AM$3,$B$4:$AG$4,"<="&AN$3) -> 0.018545986 | AO39: =+AO38/AVERAGEIFS($B$7:$AG$7,$B$4:$AG$4,">"&AN$3,$B$4:$AG$4,"<="&AO$3) -> 0.013993645 | AP39: =+AP38/AVERAGEIFS($B$7:$AG$7,$B$4:$AG$4,">"&AO$3,$B$4:$AG$4,"<="&AP$3) -> 0.013750515 | AQ39: =+AQ38/AVERAGEIFS($B$7:$AG$7,$B$4:$AG$4,">"&AP$3,$B$4:$AG$4,"<="&AQ$3) -> 0.013178606 | AR39: =+AR38/AVERAGEIFS($B$7:$AG$7,$B$4:$AG$4,">"&AQ$3,$B$4:$AG$4,"<="&AR$3) -> 0.013156727 | AS39: =+AS38/AVERAGEIFS($B$7:$AG$7,$B$4:$AG$4,">"&AR$3,$B$4:$AG$4,"<="&AS$3) -> 0.013286136
A40: MORTGAGE | B40: 217 | C40: 217 | D40: 222 | E40: 252 | F40: 293 | G40: 268 | H40: 264 | I40: 306 | J40: 333 | K40: 330 | L40: 318 | M40: 319 | N40: 290 | O40: 290 | P40: 274 | Q40: 272 | R40: 265 | S40: 246 | T40: 230 | U40: 230 | V40: 232 | W40: 226 | X40: 223 | Y40: 219 | Z40: 224 | AA40: 221 | AB40: 230 | AC40: 218 | AM40: =+SUMIFS($B40:AG40,$B$4:AG$4,"="&AM$3) -> 306 | AN40: =+SUMIFS($B40:AG40,$B$4:AG$4,"="&AN$3) -> 319 | AO40: =+SUMIFS($B40:AG40,$B$4:AG$4,"="&AO$3) -> 272 | AP40: =+SUMIFS($B40:AG40,$B$4:AG$4,"="&AP$3) -> 230 | AQ40: =+SUMIFS($B40:AG40,$B$4:AG$4,"="&AQ$3) -> 219 | AR40: =+SUMIFS($B40:AG40,$B$4:AG$4,"="&AR$3) -> 218 | AS40: =+SUMIFS($B40:$AG40,$B$4:$AG$4,"="&AS$3) -> 0
A41: CONSUMER | B41: 68 | C41: 79 | D41: 91 | E41: 104 | F41: 107 | G41: 84 | H41: 64 | I41: 150 | J41: 213 | K41: 142 | L41: 122 | M41: 109 | N41: 106 | O41: 106 | P41: 128 | Q41: 146 | R41: 175 | S41: 264 | T41: 335 | U41: 361 | V41: 308 | W41: 318 | X41: 227 | Y41: 213 | Z41: 293 | AA41: 324 | AB41: 319 | AC41: 348 | AM41: =+SUMIFS($B41:AG41,$B$4:AG$4,"="&AM$3) -> 150 | AN41: =+SUMIFS($B41:AG41,$B$4:AG$4,"="&AN$3) -> 109 | AO41: =+SUMIFS($B41:AG41,$B$4:AG$4,"="&AO$3) -> 146 | AP41: =+SUMIFS($B41:AG41,$B$4:AG$4,"="&AP$3) -> 361 | AQ41: =+SUMIFS($B41:AG41,$B$4:AG$4,"="&AQ$3) -> 213 | AR41: =+SUMIFS($B41:AG41,$B$4:AG$4,"="&AR$3) -> 348 | AS41: =+SUMIFS($B41:$AG41,$B$4:$AG$4,"="&AS$3) -> 0
A42: TOTAL INDIVUDUALS | B42: =+B40+B41 -> 285 | C42: =+C40+C41 -> 296 | D42: =+D40+D41 -> 313 | E42: =+E40+E41 -> 356 | F42: =+F40+F41 -> 400 | G42: =+G40+G41 -> 352 | H42: =+H40+H41 -> 328 | I42: =+I40+I41 -> 456 | ... AC42: =+AC40+AC41 -> 566 | AM42: =+SUMIFS($B42:AG42,$B$4:AG$4,"="&AM$3) -> 456 | AN42: =+SUMIFS($B42:AG42,$B$4:AG$4,"="&AN$3) -> 428 | AO42: =+SUMIFS($B42:AG42,$B$4:AG$4,"="&AO$3) -> 418 | AP42: =+SUMIFS($B42:AG42,$B$4:AG$4,"="&AP$3) -> 591 | AQ42: =+SUMIFS($B42:AG42,$B$4:AG$4,"="&AQ$3) -> 432 | AR42: =+SUMIFS($B42:AG42,$B$4:AG$4,"="&AR$3) -> 566 | AS42: =+SUMIFS($B42:$AG42,$B$4:$AG$4,"="&AS$3) -> 0
AM43: =+SUMIFS($B43:AG43,$B$4:AG$4,"="&AM$3) -> 0 | AN43: =+SUMIFS($B43:AG43,$B$4:AG$4,"="&AN$3) -> 0 | AO43: =+SUMIFS($B43:AG43,$B$4:AG$4,"="&AO$3) -> 0 | AP43: =+SUMIFS($B43:AG43,$B$4:AG$4,"="&AP$3) -> 0 | AQ43: =+SUMIFS($B43:AG43,$B$4:AG$4,"="&AQ$3) -> 0 | AR43: =+SUMIFS($B43:AG43,$B$4:AG$4,"="&AR$3) -> 0 | AS43: =+SUMIFS($B43:$AG43,$B$4:$AG$4,"="&AS$3) -> 0
A44: BUSINESS LOANS | B44: 1521 | C44: 1475 | D44: 1409 | E44: 1562 | F44: 1667 | G44: 1367 | H44: 1034 | I44: 1096 | J44: 1398 | K44: 1364 | L44: 1473 | M44: 1707 | N44: 1474 | O44: 1246 | P44: 1252 | Q44: 1358 | R44: 1326 | S44: 1413 | T44: 1461 | U44: 1462 | V44: 1497 | W44: 1611 | X44: 1667 | Y44: 1793 | Z44: 1963 | AA44: 2245 | AB44: 2515 | AC44: 1880 | AM44: =+SUMIFS($B44:AG44,$B$4:AG$4,"="&AM$3) -> 1096 | AN44: =+SUMIFS($B44:AG44,$B$4:AG$4,"="&AN$3) -> 1707 | AO44: =+SUMIFS($B44:AG44,$B$4:AG$4,"="&AO$3) -> 1358 | AP44: =+SUMIFS($B44:AG44,$B$4:AG$4,"="&AP$3) -> 1462 | AQ44: =+SUMIFS($B44:AG44,$B$4:AG$4,"="&AQ$3) -> 1793 | AR44: =+SUMIFS($B44:AG44,$B$4:AG$4,"="&AR$3) -> 1880 | AS44: =+SUMIFS($B44:$AG44,$B$4:$AG$4,"="&AS$3) -> 0
A45: TOTAL COMMERCIAL | B45: =+B44 -> 1521 | C45: =+C44 -> 1475 | D45: =+D44 -> 1409 | E45: =+E44 -> 1562 | F45: =+F44 -> 1667 | G45: =+G44 -> 1367 | H45: =+H44 -> 1034 | I45: =+I44 -> 1096 | ... AC45: =+AC44 -> 1880 | AM45: =+SUMIFS($B45:AG45,$B$4:AG$4,"="&AM$3) -> 1096 | AN45: =+SUMIFS($B45:AG45,$B$4:AG$4,"="&AN$3) -> 1707 | AO45: =+SUMIFS($B45:AG45,$B$4:AG$4,"="&AO$3) -> 1358 | AP45: =+SUMIFS($B45:AG45,$B$4:AG$4,"="&AP$3) -> 1462 | AQ45: =+SUMIFS($B45:AG45,$B$4:AG$4,"="&AQ$3) -> 1793 | AR45: =+SUMIFS($B45:AG45,$B$4:AG$4,"="&AR$3) -> 1880 | AS45: =+SUMIFS($B45:$AG45,$B$4:$AG$4,"="&AS$3) -> 0
A47: NON PERFORMING LOANS
A48: Balance ate beginning of period | J48: =+I56 -> 1552 | K48: =+J56 -> 1944 | L48: =+K56 -> 1836 | M48: =+L56 -> 1913 | N48: =+M56 -> 2135 | O48: =+N56 -> 1870 | P48: =+O56 -> 1642 | Q48: =+P56 -> 1654 | ... AG48: =+AF56 -> 2622.3429 | AI48: 3064 | AM48: =+AL56 -> 0 | AN48: =+AM56 -> 1552 | AO48: =+AN56 -> 2135 | AP48: =+AO56 -> 1845 | AQ48: =+AP56 -> 2053 | AR48: =+AQ56 -> 2250 | AS48: =+AR56 -> 2446 | AT48: =+AS56 -> 2663.7783 | ... BB48: =+BA56 -> 5699.9949
...

Sheet Graficos
V2: RFR | W2: =+FAT!AQ$2 -> 0.10245 | X2: =+FAT!AR$2 -> 0.075 | Y2: =+FAT!AS$2 -> 0.068
K5: NIM | L5: RFR | W5: 2024 | X5: 2025 | Y5: 2026
K6: =+X23 -> 0.085917318 | L6: =+M6-1% -> 0.0505 | M6: =+N6-1% -> 0.0605 | N6: =+O6-1% -> 0.0705 | O6: 0.0805 | P6: =+O6+1% -> 0.0905 | Q6: =+P6+1% -> 0.1005 | R6: =+Q6+1% -> 0.1105 | S6: =+R6+1% -> 0.1205 | V6: Portfolio | W6: =+FAT!AQ5 -> 174115 | X6: =+W6*(1+X7) -> 187878 | Y6: =+X6*(1+Y7) -> 202742.41
J7: portfolio growth | K7: =+K8-2% -> 0.04 | L7: 0.084314903 | M7: 0.084398865 | N7: 0.084482826 | O7: 0.084566788 | P7: 0.08465075 | Q7: 0.084734711 | R7: 0.084818673 | S7: 0.084902635 | V7: yoy | X7: =+FAT!AR15 -> 0.079045458 | Y7: =+FAT!AS15 -> 0.079117371
K8: =+K9-2% -> 0.06 | L8: 0.084801078 | M8: 0.084981312 | N8: 0.085161545 | O8: 0.085341779 | P8: 0.085522013 | Q8: 0.085702247 | R8: 0.085882481 | S8: 0.086062715
K9: =+K10-2% -> 0.08 | L9: 0.085277903 | M9: 0.085552558 | N9: 0.085827212 | O9: 0.086101867 | P9: 0.086376522 | Q9: 0.086651176 | R9: 0.086925831 | S9: 0.087200486
K10: 0.1 | L10: 0.085745646 | M10: 0.086112923 | N10: 0.0864802 | O10: 0.086847477 | P10: 0.087214754 | Q10: 0.087582031 | R10: 0.087949308 | S10: 0.088316585 | V10: NII | W10: =+FAT!AQ80 -> 0.18516271 | X10: =+X11+X12 -> 0.1588909 | Y10: =+Y11+Y12 -> 0.15629343
K11: =+K10+2% -> 0.12 | L11: 0.086204563 | M11: 0.086662715 | N11: 0.087120867 | O11: 0.087579019 | P11: 0.08803717 | Q11: 0.088495322 | R11: 0.088953474 | S11: 0.089411626 | V11: RFR | W11: =+W$2 -> 0.10245 | X11: =+X$2 -> 0.075 | Y11: =+Y$2 -> 0.068
K12: 0.13 | L12: 0.08643079 | M12: 0.086933739 | N12: 0.087436688 | O12: 0.087939638 | P12: 0.088442587 | Q12: 0.088945536 | R12: 0.089448485 | S12: 0.089951434 | W12: =+FAT!AQ82 -> 0.07646771 | X12: =+FAT!AR82 -> 0.083890897 | Y12: =+FAT!AS82 -> 0.088293427
K13: =+K12+2% -> 0.15 | L13: 0.086876931 | M13: 0.087468224 | N13: 0.088059518 | O13: 0.088650812 | P13: 0.089242106 | Q13: 0.0898334 | R13: 0.090424694 | S13: 0.091015988
V14: Int Income | W14: =+W10*AVERAGE(V6:W6) -> 32239.605 | X14: =+X10*AVERAGE(W6:X6) -> 28758.696 | Y14: =+Y10*AVERAGE(X6:Y6) -> 30525.701
V16: FUNDING | W16: =+FAT!AQ102 -> 212483 | X16: =+FAT!AR102 -> 246304 | Y16: =+FAT!AS102 -> 243821.69
V17: Cost | W17: =+FAT!AQ127 -> -15831 | X17: =-X18*AVERAGE(W16:X16) -> -13207.962 | Y17: =-Y18*AVERAGE(X16:Y16) -> -14679.461
V18: rate | X18: =+X19*X20 -> 0.057577753 | Y18: =+Y19*Y20 -> 0.059900801
V19: RFR | W19: =+W$2 -> 0.10245 | X19: =+X$2 -> 0.075 | Y19: =+Y$2 -> 0.068
V20: dif | X20: =+FAT!AR133 -> 0.76770337 | Y20: =+FAT!AS133 -> 0.88089413
V22: Net Interest earning | W22: =+W14+W17 -> 16408.605 | X22: =+X14+X17 -> 15550.734 | Y22: =+Y14+Y17 -> 15846.241
V23: NIM | W23: =+W22/AVERAGE(W6) -> 0.094240044 | X23: =+X22/AVERAGE(W6:X6) -> 0.085917318 | Y23: =+Y22/AVERAGE(X6:Y6) -> 0.081133706
V25: PDD | X25: =+FAT!AR160 -> -1757 | Y25: =+FAT!AS160 -> -1959.5548
V27: Other Income & Expenses | X27: =+FAT!AR164+FAT!AR183 -> -4665.5 | Y27: =+FAT!AS164+FAT!AS183 -> -5015.6915
V29: EBT | X29: =+X14+X17+X25+X27 -> 9128.2339 | Y29: =+Y14+Y17+Y25+Y27 -> 8870.9946
V31: tax | X31: =+X32*X29 -> -2447.992 | Y31: =+Y32*Y29 -> -2439.5235
V32: rate | X32: =+FAT!AR213 -> -0.26817805 | Y32: =+FAT!AS213 -> -0.275
V34: NI | X34: =+X29+X31 -> 6680.242 | Y34: =+Y29+Y31 -> 6431.4711

Sheet macro
A1: 45909 | B1: 2009 | C1: 2009 | D1: 2009 | E1: 2009 | F1: 2010 | G1: 2010 | H1: 2010 | I1: 2010 | J1: 2011 | K1: 2011 | L1: 2011 | M1: 2011 | N1: 2012 | O1: 2012 | P1: 2012 | Q1: 2012 | R1: 2013 | S1: 2013 | T1: 2013 | U1: 2013 | V1: 2014 | W1: 2014 | X1: 2014 | Y1: 2014 | Z1: 2015 | AA1: 2015 | AB1: 2015 | AC1: 2015 | AD1: 2016 | AE1: 2016 | AF1: 2016 | AG1: 2016 | AH1: 2017 | AI1: 2017 | AJ1: 2017 | AK1: 2017 | AL1: 2018 | AM1: 2018 | AN1: 2018 | AO1: 2018 | AP1: 2019 | AQ1: 2019 | AR1: 2019 | AS1: 2019 | AT1: 2020 | AU1: 2020 | AV1: 2020 | AW1: 2020 | AX1: 2021 | AY1: 2021 | AZ1: 2021 | BA1: 2021 | BB1: 2022 | BC1: 2022 | BD1: 2022 | BE1: 2022 | BF1: 2023 | BG1: 2023 | BH1: 2023 | BI1: 2023 | BJ1: 2024 | BK1: 2024 | BL1: 2024 | BM1: 2024 | BN1: 2025 | BO1: 2025 | BP1: 2025 | BQ1: 2025 | BR1: 2026 | BS1: 2026 | BT1: 2026 | BU1: 2026 | CY1: 2011 | CZ1: 2012 | DA1: 2013 | DB1: 2014 | DC1: 2015 | DD1: 2016 | DE1: 2017 | DF1: 2018 | DG1: 2019 | DH1: 2020 | DI1: 2021 | DJ1: 2022 | DK1: 2023 | DL1: 2024 | DM1: 2025 | DN1: 2026 | DO1: 2027 | DP1: 2028 | DQ1: 2029 | DR1: 2030 | DS1: 2031 | DT1: 2032 | DU1: 2033 | DV1: 2034 | DW1: 2035 | DX1: 2036 | DY1: 2037 | DZ1: 2038 | EA1: 2039 | EB1: 2040
A2: FX Medio | B2: 39903 | C2: 39994 | D2: 40086 | E2: 40178 | F2: 40268 | G2: 40359 | H2: 40451 | I2: 40543 | J2: 40633 | K2: 40724 | L2: 40816 | M2: 40908 | N2: 40999 | O2: 41090 | P2: 41182 | Q2: 41274 | R2: 41364 | S2: 41455 | T2: 41547 | U2: 41639 | V2: 41729 | W2: 41820 | X2: 41912 | Y2: 42004 | Z2: 42094 | AA2: 42185 | AB2: 42277 | AC2: 42369 | AD2: 42460 | AE2: 42551 | AF2: 42643 | AG2: 42735 | AH2: 42825 | AI2: 42916 | AJ2: 43008 | AK2: 43100 | AL2: 43190 | AM2: 43281 | AN2: 43373 | AO2: 43465 | AP2: 43555 | AQ2: 43646 | AR2: 43738 | AS2: 43830 | AT2: 43921 | AU2: 44012 | AV2: 44104 | AW2: 44196 | AX2: 44286 | AY2: 44377 | AZ2: 44469 | BA2: 44561 | BB2: 44651 | BC2: 44742 | BD2: 44834 | BE2: 44926 | BF2: 45016 | BG2: 45107 | BH2: 45199 | BI2: 45291 | BJ2: 45382 | BK2: 45473 | BL2: 45565 | BM2: 45657 | BN2: 45747 | BO2: 45838 | BP2: 45930 | BQ2: 46022 | BR2: 46112 | BS2: 46203 | BT2: 46295 | BU2: 46387 | CY2: 40908 | CZ2: 41274 | DA2: 41639 | DB2: 42004 | DC2: 42369 | DD2: 42735 | DE2: 43100 | DF2: 43465 | DG2: 43830 | DH2: 44196 | DI2: 44561 | DJ2: 44926 | DK2: 45291 | DL2: 45657 | DM2: 46022 | DN2: 46387 | DO2: 46752 | DP2: 47118 | DQ2: 47483 | DR2: 47848 | DS2: 48213 | DT2: 48579 | DU2: 48944 | DV2: 49309 | DW2: 49674 | DX2: 50040 | DY2: 50405 | DZ2: 50770 | EA2: 51135 | EB2: 51501
A3: CLP Medio | B3: 606.59778 | C3: 566.21015 | D3: 545.48909 | E3: 517.95692 | F3: 519.07683 | G3: 530.63538 | H3: 510.71379 | I3: 479.94864 | J3: 481.68391 | K3: 469.22906 | L3: 471.926 | M3: 509.33056 | N3: 495.6692 | O3: 498.04086 | P3: 484.56667 | Q3: 478.17018 | R3: 472.40951 | S3: 484.81083 | T3: 508.39131 | U3: 517.35194 | V3: 552.58476 | W3: 554.67548 | X3: 577.71323 | Y3: 598.60697 | Z3: 624.50937 | AA3: 616.72525 | AB3: 679.16576 | AC3: 698.02887 | AD3: 701.10444 | AE3: 677.39812 | AF3: 661.67106 | AG3: 665.72097 | AH3: 655.33344 | AI3: 664.86758 | AJ3: 642.3659 | AK3: 633.45758 | AL3: 601.95 | AM3: 621.69859 | AN3: 663.30813 | AO3: 679.75 | AP3: 667.58922 | AQ3: 683.62206 | AR3: 706.46062 | AS3: 755.16121 | AT3: 804.15 | AU3: 822.41607 | AV3: 780.83266 | AW3: 760.92806 | AX3: 724.3727 | AY3: 715.49738 | AZ3: 773.73422 | BA3: 826.76571 | BB3: 808.16859 | BC3: 845.12719 | BD3: 927.20625 | BE3: 913.69063 | BF3: 810.09438 | BG3: 801.18231 | BH3: 853.25046 | BI3: 895.51492 | BJ3: 946.47422 | BK3: 934.1581 | BL3: 930.77226 | BM3: 963.48419 | BN3: 963.2173 | BO3: 946.92742 | BP3: 949.1 | BQ3: 967.1535 | BR3: 969.50006 | BS3: 968.10099 | BT3: 967.16756 | BU3: 970.92464 | CY3: 483.04238 | CZ3: 489.11173 | DA3: 495.7409 | DB3: 570.89511 | DC3: 654.60732 | DD3: 676.47365 | DE3: 649.00613 | DF3: 641.67668 | DG3: 703.20828 | DH3: 792.0817 | DI3: 760.0925 | DJ3: 873.54817 | DK3: 840.01052 | DL3: 943.72219 | DM3: 956.59956 | DN3: 968.92331 | DO3: 977.2099 | DP3: 986.79038 | DQ3: 996.4648 | DR3: 1006.2341 | DS3: 1016.0991 | DT3: 1026.0609 | DU3: 1036.1203 | DV3: 1046.2783 | DW3: 1056.536 | DX3: 1066.8941 | DY3: 1077.3539 | DZ3: 1087.9162 | EA3: 1098.582 | EB3: 1109.3524
A4: PEN Medio | B4: 3.1852984 | C4: 3.0233354 | D4: 2.9570773 | E4: 2.8775046 | F4: 2.8492222 | G4: 2.8403477 | H4: 2.8052455 | I4: 2.8042828 | J4: 2.778725 | K4: 2.7841172 | L4: 2.7412569 | M4: 2.7131642 | N4: 2.6816818 | O4: 2.6657377 | P4: 2.6159737 | Q4: 2.5819314 | R4: 2.5692667 | S4: 2.6583 | T4: 2.785637 | U4: 2.7808469 | V4: 2.8097556 | W4: 2.7918758 | X4: 2.8226385 | Y4: 2.9316698 | Z4: 3.060629 | AA4: 3.1437172 | AB4: 3.2135032 | AC4: 3.324 | AD4: 3.4504758 | AE4: 3.3176609 | AF4: 3.3413923 | AG4: 3.3939836 | AH4: 3.2878554 | AI4: 3.2639279 | AJ4: 3.2458097 | AK4: 3.2464145 | AL4: 3.2386934 | AM4: 3.2588952 | AN4: 3.2926565 | AO4: 3.3575127 | AP4: 3.3231698 | AQ4: 3.320454 | AR4: 3.3403484 | AS4: 3.3607344 | AT4: 3.3953895 | AU4: 3.4328016 | AV4: 3.5436682 | AW4: 3.6018156 | AX4: 3.6617603 | AY4: 3.7947613 | AZ4: 4.0495762 | BA4: 4.023073 | BB4: 3.8033031 | BC4: 3.7478113 | BD4: 3.8924 | BE4: 3.8939952 | BF4: 3.8158516 | BG4: 3.6973836 | BH4: 3.677746 | BI4: 3.7821435 | BJ4: 3.7602279 | BK4: 3.7436238 | BL4: 3.7567984 | BM4: 3.755929 | BN4: 3.699819 | BO4: 3.6524661 | BP4: 3.52625 | BQ4: 3.5031389 | BR4: 3.5046621 | BS4: 3.5164007 | BT4: 3.5088907 | BU4: 3.4911886 | CY4: 2.7543158 | CZ4: 2.6363311 | DA4: 2.6985127 | DB4: 2.8389849 | DC4: 3.1854623 | DD4: 3.3758782 | DE4: 3.2610019 | DF4: 3.2869394 | DG4: 3.3361767 | DH4: 3.4934187 | DI4: 3.8822927 | DJ4: 3.8343774 | DK4: 3.7432812 | DL4: 3.7541448 | DM4: 3.5954185 | DN4: 3.5052855 | DO4: 3.488621 | DP4: 3.4971715 | DQ4: 3.505743 | DR4: 3.5143355 | DS4: 3.5229491 | DT4: 3.5315838 | DU4: 3.5402396 | DV4: 3.5489167 | DW4: 3.557615 | DX4: 3.5663347 | DY4: 3.5750757 | DZ4: 3.5838381 | EA4: 3.592622 | EB4: 3.6014275
A5: COP Medio | B5: 2418.3827 | C5: 2228.1545 | D5: 2013.6042 | E5: 1964.8087 | F5: 1942.5883 | G5: 1949.568 | H5: 1831.725 | I5: 1868.0247 | J5: 1877.542 | K5: 1796.3937 | L5: 1796.1932 | M5: 1918.9842 | N5: 1795.6903 | O5: 1785.7197 | P5: 1796.4274 | Q5: 1805.8551 | R5: 1788.4047 | S5: 1860.2492 | T5: 1906.1563 | U5: 1913.1643 | V5: 2006.2579 | W5: 1913.2035 | X5: 1911.1348 | Y5: 2177.52 | Z5: 2474.2625 | AA5: 2499.0377 | AB5: 2947.5812 | AC5: 3062.2818 | AD5: 3251.7006 | AE5: 2992.0048 | AF5: 2947.6774 | AG5: 3019.9071 | AH5: 2922.1529 | AI5: 2925.0843 | AJ5: 2974.5891 | AK5: 2988.1213 | AL5: 2855.7705 | AM5: 2842.0557 | AN5: 2960.7506 | AO5: 3165.4894 | AP5: 3134.0035 | AQ5: 3242.2911 | AR5: 3343.7847 | AS5: 3404.0021 | AT5: 3551.7089 | AU5: 3842.9453 | AV5: 3731.553 | AW5: 3655.2125 | AX5: 3560.9698 | AY5: 3695.246 | AZ5: 3847.7811 | BA5: 3886.9744 | BB5: 3907.8169 | BC5: 3923.7174 | BD5: 4388.037 | BE5: 4820.8119 | BF5: 4756.8162 | BG5: 4406.0674 | BH5: 4044.2606 | BI5: 4072.6468 | BJ5: 3919.6002 | BK5: 3928.7761 | BL5: 4097.1941 | BM5: 4352.0903 | BN5: 4183.6351 | BO5: 4196.3313 | BP5: 4014.4 | BQ5: 3923.8842 | BR5: 3950.7297 | BS5: 3995.0301 | BT5: 3985.4183 | BU5: 3958.3043 | CY5: 1847.2783 | CZ5: 1795.9231 | DA5: 1866.9936 | DB5: 2002.0291 | DC5: 2745.7908 | DD5: 3052.8225 | DE5: 2952.4869 | DF5: 2956.0165 | DG5: 3281.0203 | DH5: 3695.3549 | DI5: 3747.7428 | DJ5: 4260.0958 | DK5: 4319.9477 | DL5: 4074.4152 | DM5: 4079.5627 | DN5: 3972.3706 | DO5: 3981.9162 | DP5: 4040.4738 | DQ5: 4099.8925 | DR5: 4160.185 | DS5: 4221.3642 | DT5: 4283.4431 | DU5: 4346.4349 | DV5: 4410.3531 | DW5: 4475.2112 | DX5: 4541.0231 | DY5: 4607.8029 | DZ5: 4675.5647 | EA5: 4744.323 | EB5: 4814.0925
A6: ARS Medio | B6: 3.5468159 | C6: 3.7285016 | D6: 3.8299703 | E6: 3.8138855 | F6: 3.8389516 | G6: 3.9002217 | H6: 3.9410406 | I6: 3.9677548 | J6: 4.0120367 | K6: 4.0810934 | L6: 4.1662323 | M6: 4.2566983 | N6: 4.3408852 | O6: 4.4511586 | P6: 4.6086984 | Q6: 4.7986885 | R6: 5.0128667 | S6: 5.23905 | T6: 5.5843875 | U6: 6.052065 | V6: 7.5982217 | W6: 8.0574119 | X6: 8.2977031 | Y6: 8.5110082 | Z6: 8.6872441 | AA6: 8.9553656 | AB6: 9.2494297 | AC6: 10.161588 | AD6: 14.475107 | AE6: 14.230345 | AF6: 14.953745 | AG6: 15.451003 | AH6: 15.679418 | AI6: 15.739711 | AJ6: 17.28517 | AK6: 17.549547 | AL6: 19.676355 | AM6: 23.585497 | AN6: 31.999838 | AO6: 37.101193 | AP6: 38.9995 | AQ6: 44.01039 | AR6: 50.524956 | AS6: 59.356035 | AT6: 61.469492 | AU6: 67.704447 | AV6: 73.351394 | AW6: 79.922541 | AX6: 88.652315 | AY6: 94.015784 | AZ6: 97.259108 | BA6: 100.50011 | BB6: 106.59146 | BC6: 118.03298 | BD6: 135.83682 | BE6: 162.69439 | BF6: 192.43875 | BG6: 232.70614 | BH6: 312.9949 | BI6: 445.28678 | BJ6: 833.69708 | BK6: 885.61801 | BL6: 941.26712 | BM6: 999.70919 | BN6: 1055.0398 | BO6: 1150.9686 | BP6: 1320 | BQ6: 1416.6708 | BR6: 1447.927 | BS6: 1499.09 | BT6: 1545.2668 | BU6: 1588.0966 | CY6: 4.1290152 | CZ6: 4.5498577 | DA6: 5.4720923 | DB6: 8.1160862 | DC6: 9.2634069 | DD6: 14.77755 | DE6: 16.563462 | DF6: 28.090721 | DG6: 48.22272 | DH6: 70.611968 | DI6: 95.10683 | DJ6: 130.78891 | DK6: 295.85664 | DL6: 915.07285 | DM6: 1235.6698 | DN6: 1520.0951 | DO6: 1655.1544 | DP6: 1752.5164 | DQ6: 1855.6057 | DR6: 1964.7589 | DS6: 2080.333 | DT6: 2202.7055 | DU6: 2332.2764 | DV6: 2469.4692 | DW6: 2614.732 | DX6: 2768.5398 | DY6: 2931.3951 | DZ6: 3103.8301 | EA6: 3286.4083 | EB6: 3479.7265
A7: BRL Medio | B7: 2.3156937 | C7: 2.0763862 | D7: 1.8667515 | E7: 1.7403045 | F7: 1.8005262 | G7: 1.7937871 | H7: 1.750954 | I7: 1.6974274 | J7: 1.6672532 | K7: 1.5955032 | L7: 1.6363062 | M7: 1.8018852 | N7: 1.7688921 | O7: 1.9657306 | P7: 2.0278078 | Q7: 2.0581984 | R7: 1.9971567 | S7: 2.0685968 | T7: 2.287647 | U7: 2.2741508 | V7: 2.3640328 | W7: 2.2288148 | X7: 2.2749106 | Y7: 2.5455281 | Z7: 2.8724557 | AA7: 3.0698672 | AB7: 3.5365185 | AC7: 3.8447127 | AD7: 3.8989492 | AE7: 3.5001825 | AF7: 3.2465262 | AG7: 3.2940226 | AH7: 3.1442698 | AI7: 3.2176426 | AJ7: 3.1631156 | AK7: 3.2488361 | AL7: 3.2426656 | AM7: 3.6088714 | AN7: 3.9477672 | AO7: 3.8127226 | AP7: 3.7658705 | AQ7: 3.9215968 | AR7: 3.9723576 | AS7: 4.1152754 | AT7: 4.4726371 | AU7: 5.3855984 | AV7: 5.3801877 | AW7: 5.3956413 | AX7: 5.4849459 | AY7: 5.2936492 | AZ7: 5.2323169 | BA7: 5.5865206 | BB7: 5.2249758 | BC7: 4.9274355 | BD7: 5.24656 | BE7: 5.2607887 | BF7: 5.192381 | BG7: 4.9428049 | BH7: 4.8850281 | BI7: 4.957625 | BJ7: 4.951523 | BK7: 5.2154889 | BL7: 5.546103 | BM7: 5.8342016 | BN7: 5.8486541 | BO7: 5.6625197 | BP7: 5.43105 | BQ7: 5.4463357 | BR7: 5.494773 | BS7: 5.533904 | BT7: 5.5349543 | BU7: 5.5456013 | CY7: 1.675237 | CZ7: 1.9551572 | DA7: 2.1568878 | DB7: 2.3533216 | DC7: 3.3308885 | DD7: 3.4849201 | DE7: 3.193466 | DF7: 3.6530067 | DG7: 3.9437751 | DH7: 5.1585161 | DI7: 5.3993582 | DJ7: 5.16494 | DK7: 4.9944597 | DL7: 5.3868291 | DM7: 5.5971399 | DN7: 5.5273081 | DO7: 5.6291691 | DP7: 5.7654833 | DQ7: 5.9050984 | DR7: 6.0480945 | DS7: 6.1945532 | DT7: 6.3445586 | DU7: 6.4981964 | DV7: 6.6555547 | DW7: 6.8167235 | DX7: 6.9817952 | DY7: 7.1508641 | DZ7: 7.3240272 | EA7: 7.5013835 | EB7: 7.6830347
A8: PYG Medio | B8: 5073.9453 | C8: 5043.2538 | D8: 4968.9227 | E8: 4790.553 | F8: 4685.6889 | G8: 4737.8438 | H8: 4781.4773 | I8: 4802.2348 | J8: 4508.3594 | K8: 4027.2692 | L8: 3942.2955 | M8: 4311 | N8: 4450.8769 | O8: 4407.7308 | P8: 4436.0769 | Q8: 4408.4848 | R8: 4089.3203 | S8: 4219.8692 | T8: 4457.0606 | U8: 4467.7303 | V8: 4527.7453 | W8: 4419.9077 | X8: 4292.9742 | Y8: 4615.7258 | Z8: 4760.0297 | AA8: 5052.8492 | AB8: 5308.8212 | AC8: 5698.0258 | AD8: 5791.8031 | AE8: 5611.6815 | AF8: 5551.5121 | AG8: 5737.1846 | AH8: 5664.1308 | AI8: 5579.74 | AJ8: 5602.0385 | AK8: 5641.9077 | AL8: 5578.6246 | AM8: 5619.5815 | AN8: 5782.2723 | AO8: 5939.0939 | AP8: 6069.1556 | AQ8: 6263.8125 | AR8: 6177.6308 | AS8: 6450.3125 | AT8: 6539.9453 | AU8: 6611.1862 | AV8: 6943.6515 | AW8: 6999.8015 | AX8: 6717.3333 | AY8: 6632.0063 | AZ8: 6893.1303 | BA8: 6862.7258 | BB8: 6975.7703 | BC8: 6858.3175 | BD8: 6907.8985 | BE8: 7201.5631 | BF8: 7286.5469 | BG8: 7216.1869 | BH8: 7276.2063 | BI8: 7390.3719 | BJ8: 7296.2125 | BK8: 7479.0046 | BL8: 7632.7273 | BM8: 7829.5152 | BN8: 7916.0625 | BO8: 7989.0262 | BP8: 7550.4 | BQ8: 7189.1682 | BR8: 7253.8919 | BS8: 7308.7723 | BT8: 7326.5325 | BU8: 7352.7429 | CY8: 4197.231 | CZ8: 4425.7924 | DA8: 4308.4951 | DB8: 4464.0883 | DC8: 5204.9315 | DD8: 5673.0453 | DE8: 5621.9542 | DF8: 5729.8931 | DG8: 6240.2278 | DH8: 6773.6461 | DI8: 6776.2989 | DJ8: 6985.8873 | DK8: 7292.328 | DL8: 7559.3649 | DM8: 7661.1642 | DN8: 7310.4849 | DO8: 7473.2924 | DP8: 7686.4386 | DQ8: 7905.664 | DR8: 8131.142 | DS8: 8363.0508 | DT8: 8601.5739 | DU8: 8846.9 | DV8: 9099.223 | DW8: 9358.7425 | DX8: 9625.6638 | DY8: 9900.198 | DZ8: 10182.562 | EA8: 10472.98 | EB8: 10771.68
A9: MXN Medio | B9: 14.371277 | C9: 13.316355 | D9: 13.267964 | E9: 13.066306 | F9: 12.765022 | G9: 12.564428 | H9: 12.798624 | I9: 12.385903 | J9: 12.061261 | K9: 11.722303 | L9: 12.331148 | M9: 13.648677 | N9: 12.976945 | O9: 13.536628 | P9: 13.161551 | Q9: 12.945545 | R9: 12.63973 | S9: 12.474511 | T9: 12.913488 | U9: 13.024082 | V9: 13.229828 | W9: 12.9965 | X9: 13.118111 | Y9: 13.895885 | Z9: 14.956191 | AA9: 15.32064 | AB9: 16.438 | AC9: 16.7702 | AD9: 18.0272 | AE9: 18.1073 | AF9: 18.7626 | AG9: 19.8451 | AH9: 20.29942 | AI9: 18.548848 | AJ9: 17.818892 | AK9: 18.986402 | AL9: 18.718333 | AM9: 19.415462 | AN9: 18.942154 | AO9: 19.83728 | AP9: 19.200492 | AQ9: 19.1074 | AR9: 19.437526 | AS9: 19.244785 | AT9: 20.000129 | AU9: 23.316534 | AV9: 22.082652 | AW9: 20.534918 | AX9: 20.340297 | AY9: 20.020471 | AZ9: 20.033242 | BA9: 20.748074 | BB9: 20.501794 | BC9: 20.030058 | BD9: 20.233745 | BE9: 19.670035 | BF9: 18.651975 | BG9: 17.673632 | BH9: 17.070366 | BI9: 17.553212 | BJ9: 16.977138 | BK9: 17.246688 | BL9: 18.947241 | BM9: 20.084412 | BN9: 20.418702 | BO9: 19.492834 | BP9: 18.692 | BQ9: 18.676296 | BR9: 18.757961 | BS9: 18.851136 | BT9: 18.851209 | BU9: 18.840123 | CY9: 12.440847 | CZ9: 13.155167 | DA9: 12.762953 | DB9: 13.310081 | DC9: 15.871258 | DD9: 18.68555 | DE9: 18.91339 | DF9: 19.228307 | DG9: 19.247551 | DH9: 21.483558 | DI9: 20.285521 | DJ9: 20.108908 | DK9: 17.737297 | DL9: 18.31387 | DM9: 19.319958 | DN9: 18.825107 | DO9: 19.019094 | DP9: 19.298787 | DQ9: 19.582592 | DR9: 19.870572 | DS9: 20.162786 | DT9: 20.459298 | DU9: 20.76017 | DV9: 21.065466 | DW9: 21.375252 | DX9: 21.689594 | DY9: 22.008559 | DZ9: 22.332214 | EA9: 22.660629 | EB9: 22.993874
